ts_recv,ts_event,rtype,publisher_id,instrument_id,action,side,price,size,channel_id,order_id,flags,ts_in_delta,sequence,symbol
2025-07-17T19:11:25.333366621Z,2025-07-17T19:11:25.333201547Z,160,2,1108,A,A,14.210000000,100,0,540044317,130,165074,437113709,ARL
2025-07-17T19:11:29.146717927Z,2025-07-17T19:11:29.146552554Z,160,2,1108,A,A,13.260000000,20,0,540120857,130,165373,437167301,ARL
2025-07-17T19:11:29.146853096Z,2025-07-17T19:11:29.146687361Z,160,2,1108,C,A,13.570000000,100,0,540040205,0,165735,437167310,ARL
2025-07-17T19:11:29.146853096Z,2025-07-17T19:11:29.146687361Z,160,2,1108,A,A,13.370000000,100,0,540120893,130,165735,437167310,ARL
2025-07-17T19:11:29.147600395Z,2025-07-17T19:11:29.147434605Z,160,2,1108,C,A,14.480000000,100,0,540040185,0,165790,437167330,ARL
2025-07-17T19:11:29.147600395Z,2025-07-17T19:11:29.147434605Z,160,2,1108,A,A,14.410000000,100,0,540120921,130,165790,437167330,ARL
2025-07-17T19:11:40.886218722Z,2025-07-17T19:11:40.886053211Z,160,2,1108,C,A,13.260000000,20,0,540120857,130,165511,437286913,ARL
2025-07-17T19:11:40.886268176Z,2025-07-17T19:11:40.886102783Z,160,2,1108,C,A,13.370000000,100,0,540120893,130,165393,437286924,ARL
2025-07-17T19:11:40.887008814Z,2025-07-17T19:11:40.886843598Z,160,2,1108,C,A,14.410000000,100,0,540120921,0,165216,437286947,ARL
2025-07-17T19:11:40.887008814Z,2025-07-17T19:11:40.886843598Z,160,2,1108,A,A,14.460000000,100,0,540293797,130,165216,437286947,ARL
2025-07-17T19:11:40.887566320Z,2025-07-17T19:11:40.887400928Z,160,2,1108,A,A,13.570000000,100,0,540293801,130,165392,437286956,ARL
2025-07-17T19:12:12.786465494Z,2025-07-17T19:12:12.786299693Z,160,2,1108,C,A,13.570000000,100,0,540293801,0,165801,437719795,ARL
2025-07-17T19:12:12.786465494Z,2025-07-17T19:12:12.786299693Z,160,2,1108,A,A,13.370000000,100,0,540867849,130,165801,437719795,ARL
2025-07-17T19:12:12.787196547Z,2025-07-17T19:12:12.787031065Z,160,2,1108,C,A,14.460000000,100,0,540293797,0,165482,437719797,ARL
2025-07-17T19:12:12.787196547Z,2025-07-17T19:12:12.787031065Z,160,2,1108,A,A,14.410000000,100,0,540867865,130,165482,437719797,ARL
2025-07-17T19:12:21.147769926Z,2025-07-17T19:12:21.147604655Z,160,2,1108,A,A,13.350000000,20,0,541034433,130,165271,437842024,ARL
2025-07-17T19:12:26.453624349Z,2025-07-17T19:12:26.453458790Z,160,2,1108,C,A,13.350000000,20,0,541034433,130,165559,437907389,ARL
2025-07-17T19:12:27.533136918Z,2025-07-17T19:12:27.532971742Z,160,2,1108,A,A,13.350000000,20,0,541140113,130,165176,437920337,ARL
2025-07-17T19:12:31.147275812Z,2025-07-17T19:12:31.147108251Z,160,2,1108,C,A,13.350000000,20,0,541140113,128,167561,437959561,ARL
2025-07-17T19:12:53.148502261Z,2025-07-17T19:12:53.148337019Z,160,2,1108,A,A,13.350000000,20,0,541617377,130,165242,438232627,ARL
2025-07-17T19:13:05.148155381Z,2025-07-17T19:13:05.147989872Z,160,2,1108,C,A,13.350000000,20,0,541617377,130,165509,438405929,ARL
2025-07-17T19:13:22.769566708Z,2025-07-17T19:13:22.769401356Z,160,2,1108,A,A,13.350000000,20,0,542223213,130,165352,438689104,ARL
2025-07-17T19:14:25.086642710Z,2025-07-17T19:14:25.086477280Z,160,2,1108,A,A,13.330000000,20,0,543458993,130,165430,439596575,ARL
2025-07-17T19:14:27.899341242Z,2025-07-17T19:14:27.899173490Z,160,2,1108,C,A,13.370000000,100,0,540867849,0,167752,439732239,ARL
2025-07-17T19:14:27.899341242Z,2025-07-17T19:14:27.899173490Z,160,2,1108,A,A,13.340000000,100,0,543611309,130,167752,439732239,ARL
2025-07-17T19:14:27.900299006Z,2025-07-17T19:14:27.900132970Z,160,2,1108,C,A,14.410000000,100,0,540867865,0,166036,439732603,ARL
2025-07-17T19:14:27.900299006Z,2025-07-17T19:14:27.900132970Z,160,2,1108,A,A,14.380000000,100,0,543611557,130,166036,439732603,ARL
2025-07-17T19:14:27.919885090Z,2025-07-17T19:14:27.919719845Z,160,2,1108,C,A,13.700000000,100,0,536854185,130,165245,439735680,ARL
2025-07-17T19:14:27.919950695Z,2025-07-17T19:14:27.919785290Z,160,2,1108,A,A,13.610000000,100,0,543615245,130,165405,439735682,ARL
2025-07-17T19:14:38.697943366Z,2025-07-17T19:14:38.697777950Z,160,2,1108,C,A,13.340000000,100,0,543611309,130,165416,439915119,ARL
2025-07-17T19:14:38.698685313Z,2025-07-17T19:14:38.698518896Z,160,2,1108,C,A,14.380000000,100,0,543611557,0,166417,439915121,ARL
2025-07-17T19:14:38.698685313Z,2025-07-17T19:14:38.698518896Z,160,2,1108,A,A,14.480000000,100,0,543831653,130,166417,439915121,ARL
2025-07-17T19:14:38.699376446Z,2025-07-17T19:14:38.699211049Z,160,2,1108,A,A,13.340000000,100,0,543831665,130,165397,439915126,ARL
2025-07-17T19:14:38.712995328Z,2025-07-17T19:14:38.712829740Z,160,2,1108,C,A,13.610000000,100,0,543615245,130,165588,439915408,ARL
2025-07-17T19:14:38.713049964Z,2025-07-17T19:14:38.712884712Z,160,2,1108,A,A,13.710000000,100,0,543831809,130,165252,439915411,ARL
2025-07-17T19:14:38.713880223Z,2025-07-17T19:14:38.713715129Z,160,2,1108,C,A,13.710000000,100,0,543831809,130,165094,439915413,ARL
2025-07-17T19:14:38.713925998Z,2025-07-17T19:14:38.713760756Z,160,2,1108,A,A,13.610000000,100,0,543831813,130,165242,439915414,ARL
2025-07-17T19:14:38.749159215Z,2025-07-17T19:14:38.748994008Z,160,2,1108,C,A,14.480000000,100,0,543831653,0,165207,439915574,ARL
2025-07-17T19:14:38.749159215Z,2025-07-17T19:14:38.748994008Z,160,2,1108,A,A,14.380000000,100,0,543832073,130,165207,439915574,ARL
2025-07-17T19:14:49.150558020Z,2025-07-17T19:14:49.150392448Z,160,2,1108,C,A,13.350000000,20,0,542223213,130,165572,440024917,ARL
2025-07-17T19:14:55.890150814Z,2025-07-17T19:14:55.889985497Z,160,2,1108,A,A,13.270000000,20,0,544118533,130,165317,440115580,ARL
2025-07-17T19:15:11.079651310Z,2025-07-17T19:15:11.079485714Z,160,2,1108,C,A,13.340000000,100,0,543831665,0,165596,440323818,ARL
2025-07-17T19:15:11.079651310Z,2025-07-17T19:15:11.079485714Z,160,2,1108,A,A,13.280000000,100,0,544417113,130,165596,440323818,ARL
2025-07-17T19:15:11.080394976Z,2025-07-17T19:15:11.080229575Z,160,2,1108,C,A,14.380000000,100,0,543832073,0,165401,440323830,ARL
2025-07-17T19:15:11.080394976Z,2025-07-17T19:15:11.080229575Z,160,2,1108,A,A,14.310000000,100,0,544417137,130,165401,440323830,ARL
2025-07-17T19:15:11.081910554Z,2025-07-17T19:15:11.081744995Z,160,2,1108,C,A,15.460000000,100,0,540040529,0,165559,440323879,ARL
2025-07-17T19:15:11.081910554Z,2025-07-17T19:15:11.081744995Z,160,2,1108,A,A,15.280000000,100,0,544417157,130,165559,440323879,ARL
2025-07-17T19:15:11.082171937Z,2025-07-17T19:15:11.082006523Z,160,2,1108,C,A,17.070000000,100,0,540040509,0,165414,440323890,ARL
2025-07-17T19:15:11.082171937Z,2025-07-17T19:15:11.082006523Z,160,2,1108,A,A,16.870000000,100,0,544417161,130,165414,440323890,ARL
2025-07-17T19:15:11.082762192Z,2025-07-17T19:15:11.082596540Z,160,2,1108,C,A,14.210000000,100,0,540044317,0,165652,440323906,ARL
2025-07-17T19:15:11.082762192Z,2025-07-17T19:15:11.082596540Z,160,2,1108,A,A,14.050000000,100,0,544417169,130,165652,440323906,ARL
2025-07-17T19:15:22.262214317Z,2025-07-17T19:15:22.262048952Z,160,2,1108,C,A,13.330000000,20,0,543458993,130,165365,440490553,ARL
2025-07-17T19:15:23.267407620Z,2025-07-17T19:15:23.267242349Z,160,2,1108,A,A,13.250000000,20,0,544664281,130,165271,440513445,ARL
2025-07-17T19:15:28.477764083Z,2025-07-17T19:15:28.477598688Z,160,2,1108,C,A,13.270000000,20,0,544118533,130,165395,440596578,ARL
2025-07-17T19:15:29.479086454Z,2025-07-17T19:15:29.478921123Z,160,2,1108,A,A,13.230000000,20,0,544794561,130,165331,440615012,ARL
2025-07-17T19:15:40.709882003Z,2025-07-17T19:15:40.709716391Z,160,2,1108,C,A,13.250000000,20,0,544664281,130,165612,440769942,ARL
2025-07-17T19:15:41.724155665Z,2025-07-17T19:15:41.723990141Z,160,2,1108,A,A,13.210000000,20,0,545039709,130,165524,440799114,ARL
2025-07-17T19:15:53.152383322Z,2025-07-17T19:15:53.152218038Z,160,2,1108,C,A,13.230000000,20,0,544794561,130,165284,440985603,ARL
2025-07-17T19:15:58.749489246Z,2025-07-17T19:15:58.749323308Z,160,2,1108,A,A,13.190000000,20,0,545405721,130,165938,441085449,ARL
2025-07-17T19:16:18.031755696Z,2025-07-17T19:16:18.031585267Z,160,2,1108,C,A,13.190000000,20,0,545405721,128,170429,441425509,ARL
2025-07-17T19:16:18.031926744Z,2025-07-17T19:16:18.031760801Z,160,2,1108,C,A,13.210000000,20,0,545039709,128,165943,441425606,ARL
2025-07-17T19:16:19.344802582Z,2025-07-17T19:16:19.344637294Z,160,2,1108,A,A,13.270000000,20,0,545864661,130,165288,441441032,ARL
2025-07-17T19:16:30.332722576Z,2025-07-17T19:16:30.332557193Z,160,2,1108,A,A,13.250000000,20,0,546171293,130,165383,441680775,ARL
2025-07-17T19:16:43.177543386Z,2025-07-17T19:16:43.177378031Z,160,2,1108,C,A,13.280000000,100,0,544417113,130,165355,441873789,ARL
2025-07-17T19:16:43.177788113Z,2025-07-17T19:16:43.177622876Z,160,2,1108,C,A,13.360000000,10,0,534450593,130,165237,441873792,ARL
2025-07-17T19:16:43.178283825Z,2025-07-17T19:16:43.178118210Z,160,2,1108,C,A,14.310000000,100,0,544417137,0,165615,441873794,ARL
2025-07-17T19:16:43.178283825Z,2025-07-17T19:16:43.178118210Z,160,2,1108,A,A,14.360000000,100,0,546397793,130,165615,441873794,ARL
2025-07-17T19:16:43.179001246Z,2025-07-17T19:16:43.178835674Z,160,2,1108,A,A,13.370000000,100,0,546397801,130,165572,441873795,ARL
2025-07-17T19:16:43.179246072Z,2025-07-17T19:16:43.179080617Z,160,2,1108,A,A,13.270000000,10,0,546397821,130,165455,441873798,ARL
2025-07-17T19:16:43.179657292Z,2025-07-17T19:16:43.179491682Z,160,2,1108,C,A,15.280000000,100,0,544417157,0,165610,441873799,ARL
2025-07-17T19:16:43.179657292Z,2025-07-17T19:16:43.179491682Z,160,2,1108,A,A,15.460000000,100,0,546397829,130,165610,441873799,ARL
2025-07-17T19:16:43.179667019Z,2025-07-17T19:16:43.179501098Z,160,2,1108,C,A,16.870000000,100,0,544417161,0,165921,441873800,ARL
2025-07-17T19:16:43.179667019Z,2025-07-17T19:16:43.179501098Z,160,2,1108,A,A,17.070000000,100,0,546397833,130,165921,441873800,ARL
2025-07-17T19:16:43.186296870Z,2025-07-17T19:16:43.186131386Z,160,2,1108,C,A,13.610000000,100,0,543831813,130,165484,441873894,ARL
2025-07-17T19:16:43.186347572Z,2025-07-17T19:16:43.186182309Z,160,2,1108,A,A,13.710000000,100,0,546397901,130,165263,441873895,ARL
2025-07-17T19:16:43.187182345Z,2025-07-17T19:16:43.187017206Z,160,2,1108,C,A,13.710000000,100,0,546397901,130,165139,441873904,ARL
2025-07-17T19:16:43.187230549Z,2025-07-17T19:16:43.187065236Z,160,2,1108,A,A,13.640000000,100,0,546397909,130,165313,441873905,ARL
2025-07-17T19:16:43.228395415Z,2025-07-17T19:16:43.228229689Z,160,2,1108,C,A,14.360000000,100,0,546397793,0,165726,441874327,ARL
2025-07-17T19:16:43.228395415Z,2025-07-17T19:16:43.228229689Z,160,2,1108,A,A,14.410000000,100,0,546398201,130,165726,441874327,ARL
2025-07-17T19:16:51.051066010Z,2025-07-17T19:16:51.050900458Z,160,2,1108,C,A,13.250000000,20,0,546171293,130,165552,441997473,ARL
2025-07-17T19:16:51.051171981Z,2025-07-17T19:16:51.051006682Z,160,2,1108,C,A,13.270000000,20,0,545864661,130,165299,441997474,ARL
2025-07-17T19:16:52.457807128Z,2025-07-17T19:16:52.457641803Z,160,2,1108,A,A,13.260000000,20,0,546563097,130,165325,442011792,ARL
2025-07-17T19:16:58.049385047Z,2025-07-17T19:16:58.049219583Z,160,2,1108,C,A,13.260000000,20,0,546563097,130,165464,442070018,ARL
2025-07-17T19:16:58.049610684Z,2025-07-17T19:16:58.049444969Z,160,2,1108,C,A,13.370000000,100,0,546397801,0,165715,442070022,ARL
2025-07-17T19:16:58.049610684Z,2025-07-17T19:16:58.049444969Z,160,2,1108,A,A,13.280000000,100,0,546647769,130,165715,442070022,ARL
2025-07-17T19:16:58.050354623Z,2025-07-17T19:16:58.050189135Z,160,2,1108,C,A,14.410000000,100,0,546398201,0,165488,442070030,ARL
2025-07-17T19:16:58.050354623Z,2025-07-17T19:16:58.050189135Z,160,2,1108,A,A,14.310000000,100,0,546647789,130,165488,442070030,ARL
2025-07-17T19:16:58.050670853Z,2025-07-17T19:16:58.050505383Z,160,2,1108,C,A,15.460000000,100,0,546397829,0,165470,442070032,ARL
2025-07-17T19:16:58.050670853Z,2025-07-17T19:16:58.050505383Z,160,2,1108,A,A,15.280000000,100,0,546647793,130,165470,442070032,ARL
2025-07-17T19:16:58.052129269Z,2025-07-17T19:16:58.051963308Z,160,2,1108,C,A,17.070000000,100,0,546397833,0,165961,442070047,ARL
2025-07-17T19:16:58.052129269Z,2025-07-17T19:16:58.051963308Z,160,2,1108,A,A,16.870000000,100,0,546647801,130,165961,442070047,ARL
2025-07-17T19:16:58.069374981Z,2025-07-17T19:16:58.069209356Z,160,2,1108,C,A,13.640000000,100,0,546397909,130,165625,442070156,ARL
2025-07-17T19:16:58.069427777Z,2025-07-17T19:16:58.069262316Z,160,2,1108,A,A,13.550000000,100,0,546648073,130,165461,442070157,ARL
2025-07-17T19:17:02.518153932Z,2025-07-17T19:17:02.517988737Z,160,2,1108,A,A,13.260000000,20,0,546728229,130,165195,442129426,ARL
2025-07-17T19:17:10.654205427Z,2025-07-17T19:17:10.654039842Z,160,2,1108,A,A,13.240000000,20,0,546910541,130,165585,442262048,ARL
2025-07-17T19:17:13.185785099Z,2025-07-17T19:17:13.185619422Z,160,2,1108,C,A,14.310000000,100,0,546647789,0,165677,442300162,ARL
2025-07-17T19:17:13.185785099Z,2025-07-17T19:17:13.185619422Z,160,2,1108,A,A,14.270000000,100,0,546958289,130,165677,442300162,ARL
2025-07-17T19:17:21.155277355Z,2025-07-17T19:17:21.155112001Z,160,2,1108,C,A,13.260000000,20,0,546728229,130,165354,442404602,ARL
2025-07-17T19:17:31.155267778Z,2025-07-17T19:17:31.155102643Z,160,2,1108,A,A,13.220000000,20,0,547347277,130,165135,442591492,ARL
2025-07-17T19:17:58.899092408Z,2025-07-17T19:17:58.898926868Z,160,2,1108,C,A,13.220000000,20,0,547347277,130,165540,443112065,ARL
2025-07-17T19:18:05.398376495Z,2025-07-17T19:18:05.398211306Z,160,2,1108,A,A,13.050000000,1,0,548252957,130,165189,443300632,ARL
2025-07-17T19:18:11.055991897Z,2025-07-17T19:18:11.055826636Z,160,2,1108,A,A,13.050000000,20,0,548364629,130,165261,443391141,ARL
2025-07-17T19:18:11.057623181Z,2025-07-17T19:18:11.057457744Z,160,2,1108,C,A,14.170000000,100,0,493143725,0,165437,443391159,ARL
2025-07-17T19:18:11.057623181Z,2025-07-17T19:18:11.057457744Z,160,2,1108,A,A,13.930000000,100,0,548364649,130,165437,443391159,ARL
2025-07-17T19:18:11.067413590Z,2025-07-17T19:18:11.067248079Z,160,2,1108,C,A,14.170000000,100,0,493143729,0,165511,443391412,ARL
2025-07-17T19:18:11.067413590Z,2025-07-17T19:18:11.067248079Z,160,2,1108,A,A,13.930000000,100,0,548364829,130,165511,443391412,ARL
2025-07-17T19:18:19.152905543Z,2025-07-17T19:18:19.152740292Z,160,2,1108,C,A,13.050000000,1,0,548252957,130,165251,443520923,ARL
2025-07-17T19:18:22.614418318Z,2025-07-17T19:18:22.614252710Z,160,2,1108,C,A,13.050000000,20,0,548364629,130,165608,443579317,ARL
2025-07-17T19:18:22.615069964Z,2025-07-17T19:18:22.614904081Z,160,2,1108,C,A,13.930000000,100,0,548364829,0,165883,443579336,ARL
2025-07-17T19:18:22.615069964Z,2025-07-17T19:18:22.614904081Z,160,2,1108,A,A,14.090000000,100,0,548629397,130,165883,443579336,ARL
2025-07-17T19:18:22.616079087Z,2025-07-17T19:18:22.615913603Z,160,2,1108,C,A,13.930000000,100,0,548364649,0,165484,443579355,ARL
2025-07-17T19:18:22.616079087Z,2025-07-17T19:18:22.615913603Z,160,2,1108,A,A,14.090000000,100,0,548629413,130,165484,443579355,ARL
2025-07-17T19:18:28.006629061Z,2025-07-17T19:18:28.006463270Z,160,2,1108,C,A,13.280000000,100,0,546647769,0,165791,443671525,ARL
2025-07-17T19:18:28.006629061Z,2025-07-17T19:18:28.006463270Z,160,2,1108,A,A,13.250000000,100,0,548746353,130,165791,443671525,ARL
2025-07-17T19:18:30.146867782Z,2025-07-17T19:18:30.146702401Z,160,2,1108,A,B,13.000000000,1,0,548790945,130,165381,443701690,ARL
2025-07-17T19:18:30.146937371Z,2025-07-17T19:18:30.146771786Z,160,2,1108,T,A,13.000000000,1,0,0,130,165585,443701691,ARL
2025-07-17T19:18:30.146937371Z,2025-07-17T19:18:30.146771786Z,160,2,1108,F,B,13.000000000,1,0,548790945,130,165585,443701691,ARL
2025-07-17T19:18:30.146937371Z,2025-07-17T19:18:30.146771786Z,160,2,1108,C,B,13.000000000,1,0,548790945,130,165585,443701691,ARL
2025-07-17T19:18:30.147553324Z,2025-07-17T19:18:30.147388020Z,160,2,1108,C,A,13.270000000,10,0,546397821,130,165304,443701694,ARL
2025-07-17T19:18:30.148944760Z,2025-07-17T19:18:30.148779415Z,160,2,1108,A,A,13.240000000,20,0,548790961,130,165345,443701705,ARL
2025-07-17T19:18:32.538156086Z,2025-07-17T19:18:32.537990838Z,160,2,1108,A,A,13.200000000,20,0,548839929,130,165248,443738334,ARL
2025-07-17T19:18:34.696606803Z,2025-07-17T19:18:34.696441519Z,160,2,1108,A,B,12.950000000,1,0,548888273,130,165284,443773819,ARL
2025-07-17T19:19:09.037409685Z,2025-07-17T19:19:09.037244199Z,160,2,1108,C,A,13.250000000,100,0,548746353,130,165486,444367351,ARL
2025-07-17T19:19:09.039558871Z,2025-07-17T19:19:09.039393496Z,160,2,1108,A,A,13.370000000,100,0,549715865,130,165375,444367371,ARL
2025-07-17T19:19:11.529455590Z,2025-07-17T19:19:11.529289188Z,160,2,1108,C,A,13.200000000,20,0,548839929,128,166402,444419061,ARL
2025-07-17T19:19:11.529683471Z,2025-07-17T19:19:11.529516137Z,160,2,1108,C,A,13.240000000,20,0,546910541,128,167334,444419156,ARL
2025-07-17T19:19:12.578254352Z,2025-07-17T19:19:12.578089044Z,160,2,1108,A,A,13.240000000,20,0,549805945,130,165308,444438987,ARL
2025-07-17T19:19:18.397750435Z,2025-07-17T19:19:18.397585130Z,160,2,1108,C,B,12.950000000,1,0,548888273,130,165305,444552870,ARL
2025-07-17T19:19:18.501495378Z,2025-07-17T19:19:18.501329611Z,160,2,1108,C,A,13.370000000,100,0,549715865,0,165767,444559742,ARL
2025-07-17T19:19:18.501495378Z,2025-07-17T19:19:18.501329611Z,160,2,1108,A,A,13.250000000,100,0,549960685,130,165767,444559742,ARL
2025-07-17T19:19:31.159871581Z,2025-07-17T19:19:31.159706268Z,160,2,1108,A,B,12.650000000,20,0,550218121,130,165313,444740360,ARL
2025-07-17T19:19:33.301399144Z,2025-07-17T19:19:33.301233153Z,160,2,1108,T,N,12.860000000,3,0,0,130,165991,444785300,ARL
2025-07-17T19:19:38.942043811Z,2025-07-17T19:19:38.941878606Z,160,2,1108,C,B,12.650000000,20,0,550218121,130,165205,444863270,ARL
2025-07-17T19:20:05.552853154Z,2025-07-17T19:20:05.552687689Z,160,2,1108,C,A,13.250000000,100,0,549960685,130,165465,445293320,ARL
2025-07-17T19:20:05.555560740Z,2025-07-17T19:20:05.555395594Z,160,2,1108,A,A,13.370000000,100,0,550995909,130,165146,445293355,ARL
2025-07-17T19:20:05.558102733Z,2025-07-17T19:20:05.557936981Z,160,2,1108,A,A,13.220000000,20,0,550995989,130,165752,445293398,ARL
2025-07-17T19:20:17.141447773Z,2025-07-17T19:20:17.141282552Z,160,2,1108,C,A,13.240000000,20,0,549805945,130,165221,445467700,ARL
2025-07-17T19:20:18.142084653Z,2025-07-17T19:20:18.141919346Z,160,2,1108,A,A,13.200000000,20,0,551261941,130,165307,445494911,ARL
2025-07-17T19:20:21.794497271Z,2025-07-17T19:20:21.794330942Z,160,2,1108,C,A,13.220000000,20,0,550995989,130,166329,445558747,ARL
2025-07-17T19:20:33.160173841Z,2025-07-17T19:20:33.160007692Z,160,2,1108,A,A,13.180000000,20,0,551574285,130,166149,445730090,ARL
2025-07-17T19:20:39.368092020Z,2025-07-17T19:20:39.367926559Z,160,2,1108,C,A,13.200000000,20,0,551261941,130,165461,445826028,ARL
2025-07-17T19:20:40.268982118Z,2025-07-17T19:20:40.268815307Z,160,2,1108,C,A,13.180000000,20,0,551574285,128,166811,445864737,ARL
2025-07-17T19:20:40.269247479Z,2025-07-17T19:20:40.269078696Z,160,2,1108,C,A,13.370000000,100,0,550995909,0,168783,445864851,ARL
2025-07-17T19:20:40.269247479Z,2025-07-17T19:20:40.269078696Z,160,2,1108,A,A,13.250000000,100,0,551746749,128,168783,445864851,ARL
2025-07-17T19:20:41.303194355Z,2025-07-17T19:20:41.303028324Z,160,2,1108,A,A,13.230000000,20,0,551777657,130,166031,445890802,ARL
2025-07-17T19:20:41.303245453Z,2025-07-17T19:20:41.303080259Z,160,2,1108,C,A,13.250000000,100,0,551746749,130,165194,445890805,ARL
2025-07-17T19:20:41.305563233Z,2025-07-17T19:20:41.305398120Z,160,2,1108,A,A,13.370000000,100,0,551777901,130,165113,445890879,ARL
2025-07-17T19:20:44.303304706Z,2025-07-17T19:20:44.303139572Z,160,2,1108,A,A,13.210000000,20,0,551837093,130,165134,445931368,ARL
2025-07-17T19:20:52.704397245Z,2025-07-17T19:20:52.704230213Z,160,2,1108,C,A,13.210000000,20,0,551837093,128,167032,446045253,ARL
2025-07-17T19:20:52.704560403Z,2025-07-17T19:20:52.704395071Z,160,2,1108,C,A,13.230000000,20,0,551777657,130,165332,446045257,ARL
2025-07-17T19:20:52.704815354Z,2025-07-17T19:20:52.704649927Z,160,2,1108,C,A,13.370000000,100,0,551777901,0,165427,446045270,ARL
2025-07-17T19:20:52.704815354Z,2025-07-17T19:20:52.704649927Z,160,2,1108,A,A,13.250000000,100,0,551988425,130,165427,446045270,ARL
2025-07-17T19:20:53.734396113Z,2025-07-17T19:20:53.734230832Z,160,2,1108,A,A,13.230000000,20,0,552006653,130,165281,446057917,ARL
2025-07-17T19:20:53.734443460Z,2025-07-17T19:20:53.734278361Z,160,2,1108,C,A,13.250000000,100,0,551988425,130,165099,446057918,ARL
2025-07-17T19:20:53.735561403Z,2025-07-17T19:20:53.735396332Z,160,2,1108,A,A,13.370000000,100,0,552006689,130,165071,446057935,ARL
2025-07-17T19:20:55.161301896Z,2025-07-17T19:20:55.161136347Z,160,2,1108,C,A,13.230000000,20,0,552006653,130,165549,446087254,ARL
2025-07-17T19:20:55.161570906Z,2025-07-17T19:20:55.161405402Z,160,2,1108,C,A,13.370000000,100,0,552006689,0,165504,446087276,ARL
2025-07-17T19:20:55.161570906Z,2025-07-17T19:20:55.161405402Z,160,2,1108,A,A,13.250000000,100,0,552038829,130,165504,446087276,ARL
2025-07-17T19:21:15.161292656Z,2025-07-17T19:21:15.161127285Z,160,2,1108,A,A,13.230000000,20,0,552460685,130,165371,446418356,ARL
2025-07-17T19:21:15.161356418Z,2025-07-17T19:21:15.161191011Z,160,2,1108,C,A,13.250000000,100,0,552038829,130,165407,446418357,ARL
2025-07-17T19:21:15.163556529Z,2025-07-17T19:21:15.163391136Z,160,2,1108,A,A,13.370000000,100,0,552460733,130,165393,446418363,ARL
2025-07-17T19:21:28.338297082Z,2025-07-17T19:21:28.338131370Z,160,2,1108,C,A,13.370000000,100,0,552460733,0,165712,446609370,ARL
2025-07-17T19:21:28.338297082Z,2025-07-17T19:21:28.338131370Z,160,2,1108,A,A,13.250000000,100,0,552716281,130,165712,446609370,ARL
2025-07-17T19:21:29.163178405Z,2025-07-17T19:21:29.163013258Z,160,2,1108,A,A,13.210000000,20,0,552734593,130,165147,446625595,ARL
2025-07-17T19:21:41.158654820Z,2025-07-17T19:21:41.158489414Z,160,2,1108,C,A,13.230000000,20,0,552460685,130,165406,446770127,ARL
2025-07-17T19:21:51.163416855Z,2025-07-17T19:21:51.163251447Z,160,2,1108,A,A,13.190000000,20,0,553080369,130,165408,446893673,ARL
2025-07-17T19:22:07.164391617Z,2025-07-17T19:22:07.164226408Z,160,2,1108,C,A,13.210000000,20,0,552734593,130,165209,447086942,ARL
2025-07-17T19:22:10.549249072Z,2025-07-17T19:22:10.549081648Z,160,2,1108,A,A,13.170000000,20,0,553452257,130,167424,447154711,ARL
2025-07-17T19:22:13.739306039Z,2025-07-17T19:22:13.739140647Z,160,2,1108,C,A,13.190000000,20,0,553080369,130,165392,447225869,ARL
2025-07-17T19:22:15.895426978Z,2025-07-17T19:22:15.895261605Z,160,2,1108,A,A,13.150000000,20,0,553576505,130,165373,447254477,ARL
2025-07-17T19:22:50.107334298Z,2025-07-17T19:22:50.107164375Z,160,2,1108,C,A,13.150000000,20,0,553576505,128,169923,447785619,ARL
2025-07-17T19:22:50.107436157Z,2025-07-17T19:22:50.107270981Z,160,2,1108,C,A,13.170000000,20,0,553452257,130,165176,447785638,ARL
2025-07-17T19:22:50.107496136Z,2025-07-17T19:22:50.107329413Z,160,2,1108,C,A,13.250000000,100,0,552716281,128,166723,447785642,ARL
2025-07-17T19:22:50.109586494Z,2025-07-17T19:22:50.109417934Z,160,2,1108,A,A,13.370000000,100,0,554259533,128,168560,447785890,ARL
2025-07-17T19:22:51.854843266Z,2025-07-17T19:22:51.854677057Z,160,2,1108,A,A,13.220000000,20,0,554336877,128,166209,447842138,ARL
2025-07-17T19:23:06.080024951Z,2025-07-17T19:23:06.079848246Z,160,2,1108,C,A,13.220000000,20,0,554336877,128,176705,448052018,ARL
2025-07-17T19:23:09.739397854Z,2025-07-17T19:23:09.739232515Z,160,2,1108,A,A,13.220000000,20,0,554704861,130,165339,448110937,ARL
2025-07-17T19:23:36.341608299Z,2025-07-17T19:23:36.341442675Z,160,2,1108,C,A,13.370000000,100,0,554259533,0,165624,448513293,ARL
2025-07-17T19:23:36.341608299Z,2025-07-17T19:23:36.341442675Z,160,2,1108,A,A,13.250000000,100,0,555267229,130,165624,448513293,ARL
2025-07-17T19:24:50.342956753Z,2025-07-17T19:24:50.342791311Z,160,2,1108,C,A,13.250000000,100,0,555267229,0,165442,449546995,ARL
2025-07-17T19:24:50.342956753Z,2025-07-17T19:24:50.342791311Z,160,2,1108,A,A,13.230000000,100,0,556663321,130,165442,449546995,ARL
2025-07-17T19:24:50.343698364Z,2025-07-17T19:24:50.343533049Z,160,2,1108,C,A,14.030000000,100,0,536853765,130,165315,449547001,ARL
2025-07-17T19:24:50.344062100Z,2025-07-17T19:24:50.343896855Z,160,2,1108,A,A,13.820000000,100,0,556663353,130,165245,449547008,ARL
2025-07-17T19:24:56.504459590Z,2025-07-17T19:24:56.504293814Z,160,2,1108,C,B,12.460000000,2,0,534686481,0,165776,449619530,ARL
2025-07-17T19:24:56.504459590Z,2025-07-17T19:24:56.504293814Z,160,2,1108,A,B,12.360000000,2,0,556764729,130,165776,449619530,ARL
2025-07-17T19:24:56.504479117Z,2025-07-17T19:24:56.504313542Z,160,2,1108,C,A,14.270000000,100,0,546958289,0,165575,449619531,ARL
2025-07-17T19:24:56.504479117Z,2025-07-17T19:24:56.504313542Z,160,2,1108,A,A,14.140000000,100,0,556764741,130,165575,449619531,ARL
2025-07-17T19:24:56.504553228Z,2025-07-17T19:24:56.504387789Z,160,2,1108,C,A,14.250000000,100,0,493167485,0,165439,449619532,ARL
2025-07-17T19:24:56.504553228Z,2025-07-17T19:24:56.504387789Z,160,2,1108,A,A,14.040000000,100,0,556764757,130,165439,449619532,ARL
2025-07-17T19:24:56.504662701Z,2025-07-17T19:24:56.504497423Z,160,2,1108,C,A,13.560000000,4,0,531237401,130,165278,449619533,ARL
2025-07-17T19:24:56.505607305Z,2025-07-17T19:24:56.505441649Z,160,2,1108,C,A,15.280000000,100,0,546647793,0,165656,449619538,ARL
2025-07-17T19:24:56.505607305Z,2025-07-17T19:24:56.505441649Z,160,2,1108,A,A,15.090000000,100,0,556764825,130,165656,449619538,ARL
2025-07-17T19:24:56.505707619Z,2025-07-17T19:24:56.505542192Z,160,2,1108,C,A,14.090000000,100,0,548629397,0,165427,449619539,ARL
2025-07-17T19:24:56.505707619Z,2025-07-17T19:24:56.505542192Z,160,2,1108,A,A,13.990000000,100,0,556764829,130,165427,449619539,ARL
2025-07-17T19:24:56.506136864Z,2025-07-17T19:24:56.505971522Z,160,2,1108,C,A,16.870000000,100,0,546647801,0,165342,449619544,ARL
2025-07-17T19:24:56.506136864Z,2025-07-17T19:24:56.505971522Z,160,2,1108,A,A,16.670000000,100,0,556764837,130,165342,449619544,ARL
2025-07-17T19:24:56.507577441Z,2025-07-17T19:24:56.507411844Z,160,2,1108,C,A,14.090000000,100,0,548629413,0,165597,449619550,ARL
2025-07-17T19:24:56.507577441Z,2025-07-17T19:24:56.507411844Z,160,2,1108,A,A,13.990000000,100,0,556764857,130,165597,449619550,ARL
2025-07-17T19:24:56.508468495Z,2025-07-17T19:24:56.508303269Z,160,2,1108,C,A,14.050000000,100,0,544417169,130,165226,449619555,ARL
2025-07-17T19:24:56.508587880Z,2025-07-17T19:24:56.508422652Z,160,2,1108,A,A,13.890000000,100,0,556764873,130,165228,449619558,ARL
2025-07-17T19:24:56.510384892Z,2025-07-17T19:24:56.510219672Z,160,2,1108,A,A,13.120000000,20,0,556764901,130,165220,449619605,ARL
2025-07-17T19:24:56.517350161Z,2025-07-17T19:24:56.517184580Z,160,2,1108,C,A,14.250000000,100,0,493168277,0,165581,449619879,ARL
2025-07-17T19:24:56.517350161Z,2025-07-17T19:24:56.517184580Z,160,2,1108,A,A,14.040000000,100,0,556765445,130,165581,449619879,ARL
2025-07-17T19:24:56.525272630Z,2025-07-17T19:24:56.525107339Z,160,2,1108,C,A,13.550000000,100,0,546648073,130,165291,449620003,ARL
2025-07-17T19:24:56.525322674Z,2025-07-17T19:24:56.525157454Z,160,2,1108,A,A,13.380000000,100,0,556765741,130,165220,449620004,ARL
2025-07-17T19:24:56.697938056Z,2025-07-17T19:24:56.697772236Z,160,2,1108,A,A,13.900000000,100,0,556767661,130,165820,449621403,ARL
2025-07-17T19:24:56.698033960Z,2025-07-17T19:24:56.697868125Z,160,2,1108,C,A,14.260000000,100,0,390301509,130,165835,449621404,ARL
2025-07-17T19:24:56.794847513Z,2025-07-17T19:24:56.794681716Z,160,2,1108,C,A,13.990000000,100,0,390315289,130,165797,449623479,ARL
2025-07-17T19:24:56.794848205Z,2025-07-17T19:24:56.794682812Z,160,2,1108,A,A,13.640000000,100,0,556769701,130,165393,449623480,ARL
2025-07-17T19:25:04.295929157Z,2025-07-17T19:25:04.295763746Z,160,2,1108,A,A,13.980000000,700,0,556936717,130,165411,449739427,ARL
2025-07-17T19:25:04.296683599Z,2025-07-17T19:25:04.296518292Z,160,2,1108,C,A,14.200000000,700,0,387313797,130,165307,449739428,ARL
2025-07-17T19:25:21.204065011Z,2025-07-17T19:25:21.203899267Z,160,2,1108,C,A,13.230000000,100,0,556663321,0,165744,450013835,ARL
2025-07-17T19:25:21.204065011Z,2025-07-17T19:25:21.203899267Z,160,2,1108,A,A,13.130000000,100,0,557332045,130,165744,450013835,ARL
2025-07-17T19:25:21.338510932Z,2025-07-17T19:25:21.338345889Z,160,2,1108,C,A,13.130000000,100,0,557332045,130,165043,450017105,ARL
2025-07-17T19:25:21.346071718Z,2025-07-17T19:25:21.345906301Z,160,2,1108,A,A,13.230000000,100,0,557337789,130,165417,450017972,ARL
2025-07-17T19:25:36.792843505Z,2025-07-17T19:25:36.792677974Z,160,2,1108,C,A,13.360000000,2,0,497826957,0,165531,450253972,ARL
2025-07-17T19:25:36.792843505Z,2025-07-17T19:25:36.792677974Z,160,2,1108,A,A,13.270000000,2,0,557659805,130,165531,450253972,ARL
2025-07-17T19:26:04.948494630Z,2025-07-17T19:26:04.948329184Z,160,2,1108,C,A,13.230000000,100,0,557337789,130,165446,450695076,ARL
2025-07-17T19:26:05.150162376Z,2025-07-17T19:26:05.149997071Z,160,2,1108,A,A,13.280000000,100,0,558251877,130,165305,450697441,ARL
2025-07-17T19:26:11.658976253Z,2025-07-17T19:26:11.658810714Z,160,2,1108,C,A,13.280000000,100,0,558251877,0,165539,450785025,ARL
2025-07-17T19:26:11.658976253Z,2025-07-17T19:26:11.658810714Z,160,2,1108,A,A,13.230000000,100,0,558370441,130,165539,450785025,ARL
2025-07-17T19:26:12.039660000Z,2025-07-17T19:26:12.039494858Z,160,2,1108,C,A,13.230000000,100,0,558370441,130,165142,450791212,ARL
2025-07-17T19:26:12.041554682Z,2025-07-17T19:26:12.041389218Z,160,2,1108,A,A,13.250000000,100,0,558380305,130,165464,450791278,ARL
2025-07-17T19:26:35.081201294Z,2025-07-17T19:26:35.081035850Z,160,2,1108,C,A,13.250000000,100,0,558380305,130,165444,451189497,ARL
2025-07-17T19:26:35.082287012Z,2025-07-17T19:26:35.082121573Z,160,2,1108,A,A,13.390000000,100,0,558890569,130,165439,451189598,ARL
2025-07-17T19:26:37.217835012Z,2025-07-17T19:26:37.217669607Z,160,2,1108,C,A,13.390000000,100,0,558890569,0,165405,451222382,ARL
2025-07-17T19:26:37.217835012Z,2025-07-17T19:26:37.217669607Z,160,2,1108,A,A,13.280000000,100,0,558939033,130,165405,451222382,ARL
2025-07-17T19:27:00.006642987Z,2025-07-17T19:27:00.006476406Z,160,2,1108,C,A,13.280000000,100,0,558939033,0,166581,451559656,ARL
2025-07-17T19:27:00.006642987Z,2025-07-17T19:27:00.006476406Z,160,2,1108,A,A,13.230000000,100,0,559398801,130,166581,451559656,ARL
2025-07-17T19:27:11.851245321Z,2025-07-17T19:27:11.851072724Z,160,2,1108,C,A,13.120000000,20,0,556764901,128,172597,451799599,ARL
2025-07-17T19:27:12.884745896Z,2025-07-17T19:27:12.884580479Z,160,2,1108,A,A,13.110000000,20,0,559752777,130,165417,451842466,ARL
2025-07-17T19:27:12.884793916Z,2025-07-17T19:27:12.884628506Z,160,2,1108,C,A,13.230000000,100,0,559398801,130,165410,451842469,ARL
2025-07-17T19:27:12.887557957Z,2025-07-17T19:27:12.887392714Z,160,2,1108,A,A,13.280000000,100,0,559752845,130,165243,451842528,ARL
2025-07-17T19:27:21.171607902Z,2025-07-17T19:27:21.171442951Z,160,2,1108,C,A,13.110000000,20,0,559752777,130,164951,451990967,ARL
2025-07-17T19:27:27.065971525Z,2025-07-17T19:27:27.065804957Z,160,2,1108,A,A,13.110000000,20,0,560053629,130,166568,452069365,ARL
2025-07-17T19:27:27.066062391Z,2025-07-17T19:27:27.065896549Z,160,2,1108,C,A,13.280000000,100,0,559752845,0,165842,452069367,ARL
2025-07-17T19:27:27.066062391Z,2025-07-17T19:27:27.065896549Z,160,2,1108,A,A,13.230000000,100,0,560053633,130,165842,452069367,ARL
2025-07-17T19:27:37.720370067Z,2025-07-17T19:27:37.720204785Z,160,2,1108,C,A,13.110000000,20,0,560053629,130,165282,452210808,ARL
2025-07-17T19:27:49.173796868Z,2025-07-17T19:27:49.173631749Z,160,2,1108,A,A,13.110000000,20,0,560472085,130,165119,452368509,ARL
2025-07-17T19:28:22.137904480Z,2025-07-17T19:28:22.137739175Z,160,2,1108,C,A,13.240000000,20,0,548790961,130,165305,452843366,ARL
2025-07-17T19:28:22.138636982Z,2025-07-17T19:28:22.138471552Z,160,2,1108,A,A,13.110000000,20,0,561122437,130,165430,452843372,ARL
2025-07-17T19:32:44.821831008Z,2025-07-17T19:32:44.821665368Z,160,2,1108,C,A,13.230000000,100,0,560053633,0,165640,457759751,ARL
2025-07-17T19:32:44.821831008Z,2025-07-17T19:32:44.821665368Z,160,2,1108,A,A,13.120000000,100,0,567799929,130,165640,457759751,ARL
2025-07-17T19:32:45.046791753Z,2025-07-17T19:32:45.046627000Z,160,2,1108,C,A,13.120000000,100,0,567799929,130,164753,457762194,ARL
2025-07-17T19:32:45.054150285Z,2025-07-17T19:32:45.053985050Z,160,2,1108,A,A,13.230000000,100,0,567803873,130,165235,457762406,ARL
2025-07-17T19:33:14.319211781Z,2025-07-17T19:33:14.319046356Z,160,2,1108,A,A,13.110000000,82,0,568596221,130,165425,458342685,ARL
2025-07-17T19:33:16.703614934Z,2025-07-17T19:33:16.703449445Z,160,2,1108,C,B,11.760000000,100,0,489200877,0,165489,458379027,ARL
2025-07-17T19:33:16.703614934Z,2025-07-17T19:33:16.703449445Z,160,2,1108,A,B,11.620000000,100,0,568647825,130,165489,458379027,ARL
2025-07-17T19:33:16.704316462Z,2025-07-17T19:33:16.704150691Z,160,2,1108,C,B,11.760000000,100,0,489200865,0,165771,458379032,ARL
2025-07-17T19:33:16.704316462Z,2025-07-17T19:33:16.704150691Z,160,2,1108,A,B,11.620000000,100,0,568647881,130,165771,458379032,ARL
2025-07-17T19:33:30.006817953Z,2025-07-17T19:33:30.006651635Z,160,2,1108,C,A,13.230000000,100,0,567803873,0,166318,458585206,ARL
2025-07-17T19:33:30.006817953Z,2025-07-17T19:33:30.006651635Z,160,2,1108,A,A,13.120000000,100,0,568925865,128,166318,458585206,ARL
2025-07-17T19:33:31.232632784Z,2025-07-17T19:33:31.232467571Z,160,2,1108,C,A,13.120000000,100,0,568925865,130,165213,458597736,ARL
2025-07-17T19:33:31.240271060Z,2025-07-17T19:33:31.240105481Z,160,2,1108,A,A,13.230000000,100,0,568947117,130,165579,458597859,ARL
2025-07-17T19:33:49.448874821Z,2025-07-17T19:33:49.448709388Z,160,2,1108,C,A,13.230000000,100,0,568947117,0,165433,458872739,ARL
2025-07-17T19:33:49.448874821Z,2025-07-17T19:33:49.448709388Z,160,2,1108,A,A,13.120000000,100,0,569346541,130,165433,458872739,ARL
2025-07-17T19:33:49.900437790Z,2025-07-17T19:33:49.900272742Z,160,2,1108,C,A,13.120000000,100,0,569346541,130,165048,458877735,ARL
2025-07-17T19:33:49.908289286Z,2025-07-17T19:33:49.908124071Z,160,2,1108,A,A,13.230000000,100,0,569353693,130,165215,458878046,ARL
2025-07-17T19:34:00.006899910Z,2025-07-17T19:34:00.006734193Z,160,2,1108,C,A,13.230000000,100,0,569353693,0,165717,459031598,ARL
2025-07-17T19:34:00.006899910Z,2025-07-17T19:34:00.006734193Z,160,2,1108,A,A,13.120000000,100,0,569572093,130,165717,459031598,ARL
2025-07-17T19:34:00.698303545Z,2025-07-17T19:34:00.698136592Z,160,2,1108,C,A,13.120000000,100,0,569572093,128,166953,459046099,ARL
2025-07-17T19:34:00.706742286Z,2025-07-17T19:34:00.706577007Z,160,2,1108,A,A,13.230000000,100,0,569594549,130,165279,459046733,ARL
2025-07-17T19:34:00.898611690Z,2025-07-17T19:34:00.898445532Z,160,2,1108,T,N,12.795000000,32,0,0,130,166158,459052095,ARL
2025-07-17T19:34:01.299408404Z,2025-07-17T19:34:01.299242931Z,160,2,1108,C,B,11.620000000,100,0,568647825,0,165473,459062092,ARL
2025-07-17T19:34:01.299408404Z,2025-07-17T19:34:01.299242931Z,160,2,1108,A,B,11.770000000,100,0,569616941,130,165473,459062092,ARL
2025-07-17T19:34:01.311524021Z,2025-07-17T19:34:01.311358184Z,160,2,1108,C,B,11.620000000,100,0,568647881,0,165837,459062245,ARL
2025-07-17T19:34:01.311524021Z,2025-07-17T19:34:01.311358184Z,160,2,1108,A,B,11.770000000,100,0,569617137,130,165837,459062245,ARL
2025-07-17T19:34:08.719615669Z,2025-07-17T19:34:08.719450030Z,160,2,1108,A,B,12.430000000,3,0,569978205,130,165639,459333549,ARL
2025-07-17T19:34:30.007052675Z,2025-07-17T19:34:30.006887112Z,160,2,1108,C,A,13.230000000,100,0,569594549,0,165563,459783337,ARL
2025-07-17T19:34:30.007052675Z,2025-07-17T19:34:30.006887112Z,160,2,1108,A,A,13.120000000,100,0,570583349,130,165563,459783337,ARL
2025-07-17T19:34:32.946720967Z,2025-07-17T19:34:32.946550979Z,160,2,1108,C,A,13.110000000,20,0,560472085,128,169988,459864426,ARL
2025-07-17T19:34:39.379004863Z,2025-07-17T19:34:39.378839374Z,160,2,1108,A,A,13.110000000,30,0,570854541,130,165489,459980311,ARL
2025-07-17T19:34:55.449526629Z,2025-07-17T19:34:55.449360718Z,160,2,1108,C,A,14.140000000,100,0,556764741,0,165911,460222079,ARL
2025-07-17T19:34:55.449526629Z,2025-07-17T19:34:55.449360718Z,160,2,1108,A,A,14.100000000,100,0,571193365,130,165911,460222079,ARL
2025-07-17T19:34:55.453397652Z,2025-07-17T19:34:55.453232239Z,160,2,1108,C,A,13.220000000,20,0,554704861,130,165413,460222127,ARL
2025-07-17T19:34:56.458600492Z,2025-07-17T19:34:56.458435083Z,160,2,1108,A,A,13.080000000,30,0,571213437,130,165409,460235036,ARL
2025-07-17T19:34:56.458861441Z,2025-07-17T19:34:56.458695747Z,160,2,1108,C,A,13.120000000,100,0,570583349,0,165694,460235037,ARL
2025-07-17T19:34:56.458861441Z,2025-07-17T19:34:56.458695747Z,160,2,1108,A,A,13.090000000,100,0,571213441,130,165694,460235037,ARL
2025-07-17T19:34:56.919625694Z,2025-07-17T19:34:56.919455109Z,160,2,1108,C,A,13.090000000,100,0,571213441,128,170585,460242338,ARL
2025-07-17T19:34:56.927315326Z,2025-07-17T19:34:56.927149400Z,160,2,1108,A,A,13.280000000,100,0,571223317,130,165926,460243403,ARL
2025-07-17T19:35:15.643071274Z,2025-07-17T19:35:15.642905813Z,160,2,1108,C,A,13.080000000,30,0,571213437,130,165461,460587551,ARL
2025-07-17T19:35:15.644821696Z,2025-07-17T19:35:15.644655670Z,160,2,1108,C,A,13.110000000,30,0,570854541,130,166026,460587834,ARL
2025-07-17T19:35:17.192949231Z,2025-07-17T19:35:17.192783495Z,160,2,1108,A,A,13.100000000,30,0,571752069,130,165736,460634138,ARL
2025-07-17T19:35:32.197340834Z,2025-07-17T19:35:32.197170493Z,160,2,1108,C,A,13.100000000,30,0,571752069,128,170341,460874387,ARL
2025-07-17T19:35:33.513546093Z,2025-07-17T19:35:33.513380003Z,160,2,1108,A,A,13.100000000,30,0,572144097,130,166090,460913289,ARL
2025-07-17T19:35:35.187437984Z,2025-07-17T19:35:35.187273164Z,160,2,1108,C,A,13.100000000,30,0,572144097,130,164820,460943476,ARL
2025-07-17T19:35:45.189403186Z,2025-07-17T19:35:45.189236316Z,160,2,1108,A,A,13.100000000,30,0,572509489,128,166870,461204287,ARL
2025-07-17T19:35:57.811125027Z,2025-07-17T19:35:57.810958938Z,160,2,1108,C,A,13.100000000,30,0,572509489,130,166089,461406972,ARL
2025-07-17T19:36:13.190176303Z,2025-07-17T19:36:13.190011047Z,160,2,1108,A,A,13.100000000,30,0,573167513,130,165256,461670292,ARL
2025-07-17T19:37:01.190548735Z,2025-07-17T19:37:01.190383228Z,160,2,1108,C,A,13.100000000,30,0,573167513,130,165507,462448998,ARL
2025-07-17T19:37:03.191633562Z,2025-07-17T19:37:03.191467967Z,160,2,1108,A,A,13.100000000,30,0,574299189,130,165595,462490496,ARL
2025-07-17T19:37:45.353011337Z,2025-07-17T19:37:45.352845653Z,160,2,1108,C,A,13.280000000,100,0,571223317,0,165684,463186157,ARL
2025-07-17T19:37:45.353011337Z,2025-07-17T19:37:45.352845653Z,160,2,1108,A,A,13.120000000,100,0,575342841,130,165684,463186157,ARL
2025-07-17T19:38:05.177004738Z,2025-07-17T19:38:05.176836429Z,160,2,1108,A,A,13.080000000,30,0,575873457,128,168309,463562123,ARL
2025-07-17T19:38:12.555371215Z,2025-07-17T19:38:12.555205140Z,160,2,1108,T,B,13.080000000,3,0,0,130,166075,463693524,ARL
2025-07-17T19:38:12.555371215Z,2025-07-17T19:38:12.555205140Z,160,2,1108,F,A,13.080000000,3,0,575873457,130,166075,463693524,ARL
2025-07-17T19:38:12.555371215Z,2025-07-17T19:38:12.555205140Z,160,2,1108,C,A,13.080000000,3,0,575873457,130,166075,463693524,ARL
2025-07-17T19:38:12.555400385Z,2025-07-17T19:38:12.555235103Z,160,2,1108,A,B,12.750000000,1,0,576054565,130,165282,463693525,ARL
2025-07-17T19:38:12.555429447Z,2025-07-17T19:38:12.555264301Z,160,2,1108,C,A,13.120000000,100,0,575342841,130,165146,463693528,ARL
2025-07-17T19:38:12.556559372Z,2025-07-17T19:38:12.556394502Z,160,2,1108,C,B,12.750000000,1,0,576054565,130,164870,463693549,ARL
2025-07-17T19:38:12.556815626Z,2025-07-17T19:38:12.556650126Z,160,2,1108,A,A,13.280000000,100,0,576054613,130,165500,463693557,ARL
2025-07-17T19:38:27.296521048Z,2025-07-17T19:38:27.296355368Z,160,2,1108,C,A,13.280000000,100,0,576054613,0,165680,463975115,ARL
2025-07-17T19:38:27.296521048Z,2025-07-17T19:38:27.296355368Z,160,2,1108,A,A,13.090000000,100,0,576433673,130,165680,463975115,ARL
2025-07-17T19:38:27.391735155Z,2025-07-17T19:38:27.391570242Z,160,2,1108,C,A,13.090000000,100,0,576433673,130,164913,463976989,ARL
2025-07-17T19:38:27.398769576Z,2025-07-17T19:38:27.398603719Z,160,2,1108,A,A,13.090000000,100,0,576435913,130,165857,463977066,ARL
2025-07-17T19:38:28.098248754Z,2025-07-17T19:38:28.098083329Z,160,2,1108,C,A,13.090000000,100,0,576435913,130,165425,463986702,ARL
2025-07-17T19:38:28.105429462Z,2025-07-17T19:38:28.105263836Z,160,2,1108,A,A,13.090000000,100,0,576449453,130,165626,463986803,ARL
2025-07-17T19:38:28.109177333Z,2025-07-17T19:38:28.109012225Z,160,2,1108,C,A,13.090000000,100,0,576449453,130,165108,463986897,ARL
2025-07-17T19:38:28.132287395Z,2025-07-17T19:38:28.132122328Z,160,2,1108,A,A,13.090000000,100,0,576450001,130,165067,463987173,ARL
2025-07-17T19:38:28.232561294Z,2025-07-17T19:38:28.232396300Z,160,2,1108,C,A,13.090000000,100,0,576450001,130,164994,463988128,ARL
2025-07-17T19:38:28.239300991Z,2025-07-17T19:38:28.239135832Z,160,2,1108,A,A,13.090000000,100,0,576451409,130,165159,463988187,ARL
2025-07-17T19:38:29.661484886Z,2025-07-17T19:38:29.661319567Z,160,2,1108,C,A,13.090000000,100,0,576451409,130,165319,464004280,ARL
2025-07-17T19:38:29.668885457Z,2025-07-17T19:38:29.668719752Z,160,2,1108,A,A,13.090000000,100,0,576480101,130,165705,464004362,ARL
2025-07-17T19:38:30.451670181Z,2025-07-17T19:38:30.451499305Z,160,2,1108,C,A,13.090000000,100,0,576480101,128,170876,464014185,ARL
2025-07-17T19:38:30.463601484Z,2025-07-17T19:38:30.463435942Z,160,2,1108,A,A,13.090000000,100,0,576496865,130,165542,464014651,ARL
2025-07-17T19:38:33.187355993Z,2025-07-17T19:38:33.187190884Z,160,2,1108,C,A,13.090000000,100,0,576496865,130,165109,464058572,ARL
2025-07-17T19:38:33.195120384Z,2025-07-17T19:38:33.194955123Z,160,2,1108,A,A,13.090000000,100,0,576559949,130,165261,464058781,ARL
2025-07-17T19:38:33.502414681Z,2025-07-17T19:38:33.502249705Z,160,2,1108,C,A,13.090000000,100,0,576559949,130,164976,464064197,ARL
2025-07-17T19:38:33.510384950Z,2025-07-17T19:38:33.510219665Z,160,2,1108,A,A,13.090000000,100,0,576567205,130,165285,464064481,ARL
2025-07-17T19:38:34.902580029Z,2025-07-17T19:38:34.902414903Z,160,2,1108,C,A,13.090000000,100,0,576567205,130,165126,464088167,ARL
2025-07-17T19:38:34.912559270Z,2025-07-17T19:38:34.912394024Z,160,2,1108,A,A,13.090000000,100,0,576603561,130,165246,464088493,ARL
2025-07-17T19:38:35.677044215Z,2025-07-17T19:38:35.676878393Z,160,2,1108,C,A,13.090000000,100,0,576603561,130,165822,464100194,ARL
2025-07-17T19:38:35.686588517Z,2025-07-17T19:38:35.686423303Z,160,2,1108,A,A,13.090000000,100,0,576621177,130,165214,464100314,ARL
2025-07-17T19:38:35.760321708Z,2025-07-17T19:38:35.760156894Z,160,2,1108,C,A,13.090000000,100,0,576621177,130,164814,464101399,ARL
2025-07-17T19:38:35.767141975Z,2025-07-17T19:38:35.766976881Z,160,2,1108,A,A,13.090000000,100,0,576622949,130,165094,464101498,ARL
2025-07-17T19:38:36.903350429Z,2025-07-17T19:38:36.903185060Z,160,2,1108,C,A,13.110000000,82,0,568596221,130,165369,464118463,ARL
2025-07-17T19:38:39.307759066Z,2025-07-17T19:38:39.307593919Z,160,2,1108,C,A,13.090000000,100,0,576622949,130,165147,464157252,ARL
2025-07-17T19:38:39.315791653Z,2025-07-17T19:38:39.315626423Z,160,2,1108,A,A,13.090000000,100,0,576712065,130,165230,464157383,ARL
2025-07-17T19:38:39.385895960Z,2025-07-17T19:38:39.385729236Z,160,2,1108,C,A,13.090000000,100,0,576712065,130,166724,464158609,ARL
2025-07-17T19:38:39.396067406Z,2025-07-17T19:38:39.395902107Z,160,2,1108,A,A,13.090000000,100,0,576715441,130,165299,464161100,ARL
2025-07-17T19:38:39.943394910Z,2025-07-17T19:38:39.943229930Z,160,2,1108,C,A,13.090000000,100,0,576715441,130,164980,464169763,ARL
2025-07-17T19:38:39.950811752Z,2025-07-17T19:38:39.950646613Z,160,2,1108,A,A,13.090000000,100,0,576728113,130,165139,464169935,ARL
2025-07-17T19:38:41.203748973Z,2025-07-17T19:38:41.203583796Z,160,2,1108,C,A,13.090000000,100,0,576728113,130,165177,464184567,ARL
2025-07-17T19:38:41.211863737Z,2025-07-17T19:38:41.211697934Z,160,2,1108,A,A,13.090000000,100,0,576752017,130,165803,464185327,ARL
2025-07-17T19:38:41.615422204Z,2025-07-17T19:38:41.615256929Z,160,2,1108,C,A,13.090000000,100,0,576752017,130,165275,464194958,ARL
2025-07-17T19:38:41.623351593Z,2025-07-17T19:38:41.623186005Z,160,2,1108,A,A,13.090000000,100,0,576768469,130,165588,464195401,ARL
2025-07-17T19:38:43.167408173Z,2025-07-17T19:38:43.167242989Z,160,2,1108,C,A,13.090000000,100,0,576768469,130,165184,464217412,ARL
2025-07-17T19:38:43.174940475Z,2025-07-17T19:38:43.174775248Z,160,2,1108,A,A,13.090000000,100,0,576797973,130,165227,464217627,ARL
2025-07-17T19:38:43.472638993Z,2025-07-17T19:38:43.472473759Z,160,2,1108,A,A,13.750000000,700,0,576804577,130,165234,464224407,ARL
2025-07-17T19:38:43.472704223Z,2025-07-17T19:38:43.472538981Z,160,2,1108,C,A,14.140000000,700,0,390418545,130,165242,464224409,ARL
2025-07-17T19:38:48.023283836Z,2025-07-17T19:38:48.023118586Z,160,2,1108,C,A,13.090000000,100,0,576797973,130,165250,464292620,ARL
2025-07-17T19:38:48.030978603Z,2025-07-17T19:38:48.030812951Z,160,2,1108,A,A,13.090000000,100,0,576910049,130,165652,464292803,ARL
2025-07-17T19:38:49.116536754Z,2025-07-17T19:38:49.116371527Z,160,2,1108,C,A,13.090000000,100,0,576910049,130,165227,464306596,ARL
2025-07-17T19:38:49.124488103Z,2025-07-17T19:38:49.124322387Z,160,2,1108,A,A,13.090000000,100,0,576927905,130,165716,464306769,ARL
2025-07-17T19:38:49.150230994Z,2025-07-17T19:38:49.150065992Z,160,2,1108,C,A,13.090000000,100,0,576927905,130,165002,464307967,ARL
2025-07-17T19:38:49.157499365Z,2025-07-17T19:38:49.157333958Z,160,2,1108,A,A,13.090000000,100,0,576928849,130,165407,464308154,ARL
2025-07-17T19:38:49.623192590Z,2025-07-17T19:38:49.623026702Z,160,2,1108,C,A,13.090000000,100,0,576928849,130,165888,464317456,ARL
2025-07-17T19:38:49.632810583Z,2025-07-17T19:38:49.632645514Z,160,2,1108,A,A,13.090000000,100,0,576939421,130,165069,464318522,ARL
2025-07-17T19:38:52.161622483Z,2025-07-17T19:38:52.161457504Z,160,2,1108,C,A,13.090000000,100,0,576939421,130,164979,464363920,ARL
2025-07-17T19:38:52.169369568Z,2025-07-17T19:38:52.169204430Z,160,2,1108,A,A,13.090000000,100,0,576999165,130,165138,464364244,ARL
2025-07-17T19:38:53.075890467Z,2025-07-17T19:38:53.075725551Z,160,2,1108,C,A,13.090000000,100,0,576999165,130,164916,464376474,ARL
2025-07-17T19:38:53.084031672Z,2025-07-17T19:38:53.083866439Z,160,2,1108,A,A,13.090000000,100,0,577020697,130,165233,464376794,ARL
2025-07-17T19:38:53.648798714Z,2025-07-17T19:38:53.648633755Z,160,2,1108,C,A,13.090000000,100,0,577020697,130,164959,464390614,ARL
2025-07-17T19:38:53.656655757Z,2025-07-17T19:38:53.656490628Z,160,2,1108,A,A,13.090000000,100,0,577039185,130,165129,464391233,ARL
2025-07-17T19:38:54.571379542Z,2025-07-17T19:38:54.571214523Z,160,2,1108,C,A,13.090000000,100,0,577039185,130,165019,464425734,ARL
2025-07-17T19:38:54.581623325Z,2025-07-17T19:38:54.581458272Z,160,2,1108,A,A,13.090000000,100,0,577085057,130,165053,464425915,ARL
2025-07-17T19:38:58.727342037Z,2025-07-17T19:38:58.727176923Z,160,2,1108,C,A,13.090000000,100,0,577085057,130,165114,464481742,ARL
2025-07-17T19:38:58.735481532Z,2025-07-17T19:38:58.735316285Z,160,2,1108,A,A,13.090000000,100,0,577169889,130,165247,464481867,ARL
2025-07-17T19:38:58.853450743Z,2025-07-17T19:38:58.853285752Z,160,2,1108,C,A,13.090000000,100,0,577169889,130,164991,464483446,ARL
2025-07-17T19:38:58.860921744Z,2025-07-17T19:38:58.860756656Z,160,2,1108,A,A,13.090000000,100,0,577173073,130,165088,464483571,ARL
2025-07-17T19:38:59.517647636Z,2025-07-17T19:38:59.517482736Z,160,2,1108,C,A,13.090000000,100,0,577173073,130,164900,464493507,ARL
2025-07-17T19:38:59.525091455Z,2025-07-17T19:38:59.524926241Z,160,2,1108,A,A,13.090000000,100,0,577188549,130,165214,464493736,ARL
2025-07-17T19:39:01.055439789Z,2025-07-17T19:39:01.055274572Z,160,2,1108,C,A,13.090000000,100,0,577188549,130,165217,464528136,ARL
2025-07-17T19:39:01.063585980Z,2025-07-17T19:39:01.063420825Z,160,2,1108,A,A,13.090000000,100,0,577232485,130,165155,464528614,ARL
2025-07-17T19:39:01.178252182Z,2025-07-17T19:39:01.178087063Z,160,2,1108,C,A,13.090000000,100,0,577232485,130,165119,464533851,ARL
2025-07-17T19:39:01.186024060Z,2025-07-17T19:39:01.185858833Z,160,2,1108,A,A,13.090000000,100,0,577243057,130,165227,464534251,ARL
2025-07-17T19:39:02.066091948Z,2025-07-17T19:39:02.065926524Z,160,2,1108,C,A,13.090000000,100,0,577243057,130,165424,464552269,ARL
2025-07-17T19:39:02.073820018Z,2025-07-17T19:39:02.073654920Z,160,2,1108,A,A,13.090000000,100,0,577272297,130,165098,464552660,ARL
2025-07-17T19:39:03.001569725Z,2025-07-17T19:39:03.001398182Z,160,2,1108,C,A,13.090000000,100,0,577272297,130,171543,464570651,ARL
2025-07-17T19:39:03.009398870Z,2025-07-17T19:39:03.009233821Z,160,2,1108,A,A,13.090000000,100,0,577298041,130,165049,464571815,ARL
2025-07-17T19:39:07.643592468Z,2025-07-17T19:39:07.643426917Z,160,2,1108,C,A,13.090000000,100,0,577298041,130,165551,464666686,ARL
2025-07-17T19:39:07.651264941Z,2025-07-17T19:39:07.651099698Z,160,2,1108,A,A,13.090000000,100,0,577422905,130,165243,464666818,ARL
2025-07-17T19:39:08.249657334Z,2025-07-17T19:39:08.249492378Z,160,2,1108,C,A,13.090000000,100,0,577422905,130,164956,464686939,ARL
2025-07-17T19:39:08.258059468Z,2025-07-17T19:39:08.257894137Z,160,2,1108,A,A,13.090000000,100,0,577443181,130,165331,464687484,ARL
2025-07-17T19:39:12.671163101Z,2025-07-17T19:39:12.670997190Z,160,2,1108,C,A,13.090000000,100,0,577443181,130,165911,464786392,ARL
2025-07-17T19:39:12.679027582Z,2025-07-17T19:39:12.678862231Z,160,2,1108,A,A,13.090000000,100,0,577570381,130,165351,464786665,ARL
2025-07-17T19:39:14.053523526Z,2025-07-17T19:39:14.053358604Z,160,2,1108,C,A,13.090000000,100,0,577570381,130,164922,464814924,ARL
2025-07-17T19:39:14.061194340Z,2025-07-17T19:39:14.061029154Z,160,2,1108,A,A,13.090000000,100,0,577601321,130,165186,464815080,ARL
2025-07-17T19:39:15.101249758Z,2025-07-17T19:39:15.101084907Z,160,2,1108,C,A,13.090000000,100,0,577601321,130,164851,464836644,ARL
2025-07-17T19:39:15.108713278Z,2025-07-17T19:39:15.108548099Z,160,2,1108,A,A,13.090000000,100,0,577628061,130,165179,464836876,ARL
2025-07-17T19:39:17.104186463Z,2025-07-17T19:39:17.104021323Z,160,2,1108,C,A,13.090000000,100,0,577628061,130,165140,464876880,ARL
2025-07-17T19:39:17.112443885Z,2025-07-17T19:39:17.112278612Z,160,2,1108,A,A,13.090000000,100,0,577684765,130,165273,464877064,ARL
2025-07-17T19:39:18.530608639Z,2025-07-17T19:39:18.530443487Z,160,2,1108,C,A,13.090000000,100,0,577684765,130,165152,464905039,ARL
2025-07-17T19:39:18.538504183Z,2025-07-17T19:39:18.538338905Z,160,2,1108,A,A,13.090000000,100,0,577722045,130,165278,464905228,ARL
2025-07-17T19:39:27.979564217Z,2025-07-17T19:39:27.979398355Z,160,2,1108,C,A,13.090000000,100,0,577722045,130,165862,465096241,ARL
2025-07-17T19:39:27.987858368Z,2025-07-17T19:39:27.987693231Z,160,2,1108,A,A,13.090000000,100,0,577966641,130,165137,465096475,ARL
2025-07-17T19:39:30.817039965Z,2025-07-17T19:39:30.816874804Z,160,2,1108,C,A,13.090000000,100,0,577966641,130,165161,465161364,ARL
2025-07-17T19:39:30.817808348Z,2025-07-17T19:39:30.817642005Z,160,2,1108,C,A,14.100000000,100,0,571193365,0,166343,465161484,ARL
2025-07-17T19:39:30.817808348Z,2025-07-17T19:39:30.817642005Z,160,2,1108,A,A,14.140000000,100,0,578064069,130,166343,465161484,ARL
2025-07-17T19:39:30.825676959Z,2025-07-17T19:39:30.825511807Z,160,2,1108,A,A,13.090000000,100,0,578065373,130,165152,465162198,ARL
2025-07-17T19:39:30.867468371Z,2025-07-17T19:39:30.867302722Z,160,2,1108,C,A,14.140000000,100,0,578064069,0,165649,465166144,ARL
2025-07-17T19:39:30.867468371Z,2025-07-17T19:39:30.867302722Z,160,2,1108,A,A,14.110000000,100,0,578069633,130,165649,465166144,ARL
2025-07-17T19:39:32.216194064Z,2025-07-17T19:39:32.216028637Z,160,2,1108,C,A,13.090000000,100,0,578065373,130,165427,465201325,ARL
2025-07-17T19:39:32.224822084Z,2025-07-17T19:39:32.224656804Z,160,2,1108,A,A,13.090000000,100,0,578122193,130,165280,465201989,ARL
2025-07-17T19:39:32.318511948Z,2025-07-17T19:39:32.318346951Z,160,2,1108,C,A,13.090000000,100,0,578122193,130,164997,465205131,ARL
2025-07-17T19:39:32.326206076Z,2025-07-17T19:39:32.326040840Z,160,2,1108,A,A,13.090000000,100,0,578126245,130,165236,465205336,ARL
2025-07-17T19:39:32.798954964Z,2025-07-17T19:39:32.798789854Z,160,2,1108,C,A,13.090000000,100,0,578126245,130,165110,465214771,ARL
2025-07-17T19:39:32.807140904Z,2025-07-17T19:39:32.806975635Z,160,2,1108,A,A,13.090000000,100,0,578136993,130,165269,465214995,ARL
2025-07-17T19:39:33.149529134Z,2025-07-17T19:39:33.149363835Z,160,2,1108,C,A,13.090000000,100,0,578136993,130,165299,465223792,ARL
2025-07-17T19:39:33.157112826Z,2025-07-17T19:39:33.156947200Z,160,2,1108,A,A,13.090000000,100,0,578148573,130,165626,465224017,ARL
2025-07-17T19:39:33.403036709Z,2025-07-17T19:39:33.402869998Z,160,2,1108,C,A,13.090000000,100,0,578148573,128,166711,465231965,ARL
2025-07-17T19:39:33.413351895Z,2025-07-17T19:39:33.413182135Z,160,2,1108,A,A,13.090000000,100,0,578161601,128,169760,465234045,ARL
2025-07-17T19:39:34.104930984Z,2025-07-17T19:39:34.104765956Z,160,2,1108,C,A,13.090000000,100,0,578161601,130,165028,465255365,ARL
2025-07-17T19:39:34.112792939Z,2025-07-17T19:39:34.112627999Z,160,2,1108,A,A,13.090000000,100,0,578189777,130,164940,465255535,ARL
2025-07-17T19:39:34.125381301Z,2025-07-17T19:39:34.125216164Z,160,2,1108,C,A,13.090000000,100,0,578189777,130,165137,465256245,ARL
2025-07-17T19:39:34.149994023Z,2025-07-17T19:39:34.149828776Z,160,2,1108,A,A,13.090000000,100,0,578191949,130,165247,465257024,ARL
2025-07-17T19:39:34.385465534Z,2025-07-17T19:39:34.385300173Z,160,2,1108,C,A,13.090000000,100,0,578191949,130,165361,465263829,ARL
2025-07-17T19:39:34.392916394Z,2025-07-17T19:39:34.392750821Z,160,2,1108,A,A,13.120000000,100,0,578203717,130,165573,465264129,ARL
2025-07-17T19:39:34.393488934Z,2025-07-17T19:39:34.393323757Z,160,2,1108,A,A,13.120000000,1,0,578203725,130,165177,465264153,ARL
2025-07-17T19:39:34.393984478Z,2025-07-17T19:39:34.393818822Z,160,2,1108,A,A,13.120000000,4,0,578203737,130,165656,465264168,ARL
2025-07-17T19:39:34.410157753Z,2025-07-17T19:39:34.409992511Z,160,2,1108,C,A,13.120000000,100,0,578203717,0,165242,465264614,ARL
2025-07-17T19:39:34.410157753Z,2025-07-17T19:39:34.409992511Z,160,2,1108,A,A,13.090000000,100,0,578204409,130,165242,465264614,ARL
2025-07-17T19:39:34.443962714Z,2025-07-17T19:39:34.443797949Z,160,2,1108,C,A,13.090000000,100,0,578204409,130,164765,465265447,ARL
2025-07-17T19:39:34.451538441Z,2025-07-17T19:39:34.451373388Z,160,2,1108,A,A,13.130000000,100,0,578206033,130,165053,465265729,ARL
2025-07-17T19:39:35.092133353Z,2025-07-17T19:39:35.091967797Z,160,2,1108,C,A,13.080000000,27,0,575873457,130,165556,465280304,ARL
2025-07-17T19:39:35.092255760Z,2025-07-17T19:39:35.092089765Z,160,2,1108,C,A,13.100000000,30,0,574299189,130,165995,465280328,ARL
2025-07-17T19:39:36.277294395Z,2025-07-17T19:39:36.277128232Z,160,2,1108,A,A,13.090000000,30,0,578274153,130,166163,465319203,ARL
2025-07-17T19:39:37.195520368Z,2025-07-17T19:39:37.195354198Z,160,2,1108,C,A,13.090000000,30,0,578274153,128,166170,465340384,ARL
2025-07-17T19:39:47.195838211Z,2025-07-17T19:39:47.195672803Z,160,2,1108,A,A,13.090000000,30,0,578600789,130,165408,465572878,ARL
2025-07-17T19:39:47.196077812Z,2025-07-17T19:39:47.195912039Z,160,2,1108,C,A,13.130000000,100,0,578206033,0,165773,465572888,ARL
2025-07-17T19:39:47.196077812Z,2025-07-17T19:39:47.195912039Z,160,2,1108,A,A,13.100000000,100,0,578600797,130,165773,465572888,ARL
2025-07-17T19:39:50.090755927Z,2025-07-17T19:39:50.090590729Z,160,2,1108,C,A,13.100000000,100,0,578600797,130,165198,465642836,ARL
2025-07-17T19:39:50.099054949Z,2025-07-17T19:39:50.098889758Z,160,2,1108,A,A,13.100000000,100,0,578673861,130,165191,465643182,ARL
2025-07-17T19:39:50.468845729Z,2025-07-17T19:39:50.468680453Z,160,2,1108,C,A,13.100000000,100,0,578673861,130,165276,465653680,ARL
2025-07-17T19:39:50.477131055Z,2025-07-17T19:39:50.476964893Z,160,2,1108,A,A,13.100000000,100,0,578687473,130,166162,465654108,ARL
2025-07-17T19:39:50.649797268Z,2025-07-17T19:39:50.649632320Z,160,2,1108,C,A,13.100000000,100,0,578687473,130,164948,465660767,ARL
2025-07-17T19:39:50.663687757Z,2025-07-17T19:39:50.663522673Z,160,2,1108,A,A,13.100000000,100,0,578696105,130,165084,465661158,ARL
2025-07-17T19:39:52.833688085Z,2025-07-17T19:39:52.833523000Z,160,2,1108,C,A,13.100000000,100,0,578696105,130,165085,465700576,ARL
2025-07-17T19:39:52.841694062Z,2025-07-17T19:39:52.841528831Z,160,2,1108,A,A,13.100000000,100,0,578750501,130,165231,465700749,ARL
2025-07-17T19:39:53.298473954Z,2025-07-17T19:39:53.298308979Z,160,2,1108,C,A,13.100000000,100,0,578750501,130,164975,465708442,ARL
2025-07-17T19:39:53.306467070Z,2025-07-17T19:39:53.306301866Z,160,2,1108,A,A,13.100000000,100,0,578764425,130,165204,465708663,ARL
2025-07-17T19:39:54.299590516Z,2025-07-17T19:39:54.299425521Z,160,2,1108,C,A,13.100000000,100,0,578764425,130,164995,465732111,ARL
2025-07-17T19:39:54.307345125Z,2025-07-17T19:39:54.307179955Z,160,2,1108,A,A,13.100000000,100,0,578795501,130,165170,465732316,ARL
2025-07-17T19:39:55.361904816Z,2025-07-17T19:39:55.361734829Z,160,2,1108,C,A,13.100000000,100,0,578795501,128,169987,465762877,ARL
2025-07-17T19:39:55.371695188Z,2025-07-17T19:39:55.371522724Z,160,2,1108,C,A,13.090000000,30,0,578600789,128,172464,465769150,ARL
2025-07-17T19:39:55.390146158Z,2025-07-17T19:39:55.389980425Z,160,2,1108,A,A,13.130000000,100,0,578852797,130,165733,465773816,ARL
2025-07-17T19:40:07.197281401Z,2025-07-17T19:40:07.197115320Z,160,2,1108,A,A,13.090000000,30,0,579304505,130,166081,466140815,ARL
2025-07-17T19:40:07.197515351Z,2025-07-17T19:40:07.197349970Z,160,2,1108,C,A,13.130000000,100,0,578852797,0,165381,466140818,ARL
2025-07-17T19:40:07.197515351Z,2025-07-17T19:40:07.197349970Z,160,2,1108,A,A,13.100000000,100,0,579304509,130,165381,466140818,ARL
2025-07-17T19:40:07.393402203Z,2025-07-17T19:40:07.393237190Z,160,2,1108,C,A,13.100000000,100,0,579304509,130,165013,466144406,ARL
2025-07-17T19:40:07.401544466Z,2025-07-17T19:40:07.401378962Z,160,2,1108,A,A,13.100000000,100,0,579310429,130,165504,466144570,ARL
2025-07-17T19:40:08.041041309Z,2025-07-17T19:40:08.040876435Z,160,2,1108,C,A,13.100000000,100,0,579310429,130,164874,466155307,ARL
2025-07-17T19:40:08.053745610Z,2025-07-17T19:40:08.053580452Z,160,2,1108,A,A,13.100000000,100,0,579325289,130,165158,466155625,ARL
2025-07-17T19:40:08.318353947Z,2025-07-17T19:40:08.318188899Z,160,2,1108,C,A,13.100000000,100,0,579325289,130,165048,466166322,ARL
2025-07-17T19:40:08.335290670Z,2025-07-17T19:40:08.335125561Z,160,2,1108,A,A,13.100000000,100,0,579341045,130,165109,466168384,ARL
2025-07-17T19:40:09.061982530Z,2025-07-17T19:40:09.061812921Z,160,2,1108,C,A,13.100000000,100,0,579341045,128,169609,466191057,ARL
2025-07-17T19:40:09.069533850Z,2025-07-17T19:40:09.069368342Z,160,2,1108,A,A,13.100000000,100,0,579366525,130,165508,466191493,ARL
2025-07-17T19:40:09.111624502Z,2025-07-17T19:40:09.111459404Z,160,2,1108,C,A,13.100000000,100,0,579366525,130,165098,466193896,ARL
2025-07-17T19:40:09.118998293Z,2025-07-17T19:40:09.118833158Z,160,2,1108,A,A,13.100000000,100,0,579368805,130,165135,466194475,ARL
2025-07-17T19:40:10.633398388Z,2025-07-17T19:40:10.633233239Z,160,2,1108,C,A,13.100000000,100,0,579368805,130,165149,466230908,ARL
2025-07-17T19:40:10.641277158Z,2025-07-17T19:40:10.641111920Z,160,2,1108,A,A,13.100000000,100,0,579418085,130,165238,466231533,ARL
2025-07-17T19:40:10.653422423Z,2025-07-17T19:40:10.653257053Z,160,2,1108,C,A,13.100000000,100,0,579418085,130,165370,466232429,ARL
2025-07-17T19:40:10.678628061Z,2025-07-17T19:40:10.678462773Z,160,2,1108,A,A,13.100000000,100,0,579420513,130,165288,466233409,ARL
2025-07-17T19:40:11.196607278Z,2025-07-17T19:40:11.196442233Z,160,2,1108,C,A,13.090000000,30,0,579304505,130,165045,466245683,ARL
2025-07-17T19:40:14.010339999Z,2025-07-17T19:40:14.010174116Z,160,2,1108,C,A,13.100000000,100,0,579420513,128,165883,466299900,ARL
2025-07-17T19:40:14.018345581Z,2025-07-17T19:40:14.018180412Z,160,2,1108,A,A,13.130000000,100,0,579508785,130,165169,466300128,ARL
2025-07-17T19:40:17.197628842Z,2025-07-17T19:40:17.197463448Z,160,2,1108,A,A,13.090000000,30,0,579611909,130,165394,466377917,ARL
2025-07-17T19:40:17.254413118Z,2025-07-17T19:40:17.254247334Z,160,2,1108,C,A,13.130000000,100,0,579508785,0,165784,466380016,ARL
2025-07-17T19:40:17.254413118Z,2025-07-17T19:40:17.254247334Z,160,2,1108,A,A,13.100000000,100,0,579615097,130,165784,466380016,ARL
2025-07-17T19:40:19.197222016Z,2025-07-17T19:40:19.197056255Z,160,2,1108,C,A,13.100000000,100,0,579615097,130,165761,466414118,ARL
2025-07-17T19:40:19.207703071Z,2025-07-17T19:40:19.207537660Z,160,2,1108,A,A,13.100000000,100,0,579666805,130,165411,466414579,ARL
2025-07-17T19:40:21.270608141Z,2025-07-17T19:40:21.270442450Z,160,2,1108,C,A,13.100000000,100,0,579666805,130,165691,466447231,ARL
2025-07-17T19:40:21.281643153Z,2025-07-17T19:40:21.281476875Z,160,2,1108,A,A,13.100000000,100,0,579718873,128,166278,466449484,ARL
2025-07-17T19:40:23.122513034Z,2025-07-17T19:40:23.122347889Z,160,2,1108,C,A,13.100000000,100,0,579718873,130,165145,466490459,ARL
2025-07-17T19:40:23.130174178Z,2025-07-17T19:40:23.130008776Z,160,2,1108,A,A,13.100000000,100,0,579775609,130,165402,466490758,ARL
2025-07-17T19:40:25.222013075Z,2025-07-17T19:40:25.221847698Z,160,2,1108,C,A,13.100000000,100,0,579775609,130,165377,466542257,ARL
2025-07-17T19:40:25.226706128Z,2025-07-17T19:40:25.226540807Z,160,2,1108,A,A,13.100000000,100,0,579843005,130,165321,466543337,ARL
2025-07-17T19:40:25.737372268Z,2025-07-17T19:40:25.737207119Z,160,2,1108,C,A,13.100000000,100,0,579843005,130,165149,466554779,ARL
2025-07-17T19:40:25.758839749Z,2025-07-17T19:40:25.758674397Z,160,2,1108,A,A,13.100000000,100,0,579858073,130,165352,466555692,ARL
2025-07-17T19:40:26.292009303Z,2025-07-17T19:40:26.291844262Z,160,2,1108,C,A,13.100000000,100,0,579858073,130,165041,466563588,ARL
2025-07-17T19:40:26.298986279Z,2025-07-17T19:40:26.298821172Z,160,2,1108,A,A,13.100000000,100,0,579870369,130,165107,466563849,ARL
2025-07-17T19:40:26.700408711Z,2025-07-17T19:40:26.700243399Z,160,2,1108,C,A,13.100000000,100,0,579870369,130,165312,466569124,ARL
2025-07-17T19:40:26.707489499Z,2025-07-17T19:40:26.707324159Z,160,2,1108,A,A,13.100000000,100,0,579879045,130,165340,466569793,ARL
2025-07-17T19:40:32.489235936Z,2025-07-17T19:40:32.489070519Z,160,2,1108,C,A,13.100000000,100,0,579879045,130,165417,466655337,ARL
2025-07-17T19:40:32.496920284Z,2025-07-17T19:40:32.496754881Z,160,2,1108,A,A,13.100000000,100,0,579999521,130,165403,466655462,ARL
2025-07-17T19:40:34.152691190Z,2025-07-17T19:40:34.152525612Z,160,2,1108,C,A,13.100000000,100,0,579999521,130,165578,466685882,ARL
2025-07-17T19:40:34.165287696Z,2025-07-17T19:40:34.165122475Z,160,2,1108,A,A,13.100000000,100,0,580042641,130,165221,466687098,ARL
2025-07-17T19:40:34.785608390Z,2025-07-17T19:40:34.785443424Z,160,2,1108,C,A,13.100000000,100,0,580042641,130,164966,466698686,ARL
2025-07-17T19:40:34.792963804Z,2025-07-17T19:40:34.792798593Z,160,2,1108,A,A,13.100000000,100,0,580059909,130,165211,466699266,ARL
2025-07-17T19:40:34.973093713Z,2025-07-17T19:40:34.972928355Z,160,2,1108,C,A,13.100000000,100,0,580059909,130,165358,466702807,ARL
2025-07-17T19:40:34.980106926Z,2025-07-17T19:40:34.979941752Z,160,2,1108,A,A,13.100000000,100,0,580063721,130,165174,466702905,ARL
2025-07-17T19:40:35.045413833Z,2025-07-17T19:40:35.045248836Z,160,2,1108,C,A,13.100000000,100,0,580063721,130,164997,466704339,ARL
2025-07-17T19:40:35.052274128Z,2025-07-17T19:40:35.052108978Z,160,2,1108,A,A,13.100000000,100,0,580067177,130,165150,466704534,ARL
2025-07-17T19:40:35.947277131Z,2025-07-17T19:40:35.947111826Z,160,2,1108,C,A,13.100000000,100,0,580067177,130,165305,466716794,ARL
2025-07-17T19:40:35.954785478Z,2025-07-17T19:40:35.954619989Z,160,2,1108,A,A,13.100000000,100,0,580085549,130,165489,466717110,ARL
2025-07-17T19:40:40.042546500Z,2025-07-17T19:40:40.042379170Z,160,2,1108,C,A,13.100000000,100,0,580085549,128,167330,466778339,ARL
2025-07-17T19:40:40.051012679Z,2025-07-17T19:40:40.050846788Z,160,2,1108,A,A,13.100000000,100,0,580176121,130,165891,466779737,ARL
2025-07-17T19:40:41.466139766Z,2025-07-17T19:40:41.465974767Z,160,2,1108,C,A,13.100000000,100,0,580176121,130,164999,466808564,ARL
2025-07-17T19:40:41.474620777Z,2025-07-17T19:40:41.474455353Z,160,2,1108,A,A,13.100000000,100,0,580217777,130,165424,466809327,ARL
2025-07-17T19:40:41.553362656Z,2025-07-17T19:40:41.553197641Z,160,2,1108,C,A,13.100000000,100,0,580217777,130,165015,466811174,ARL
2025-07-17T19:40:41.560647339Z,2025-07-17T19:40:41.560481986Z,160,2,1108,A,A,13.100000000,100,0,580220701,130,165353,466811295,ARL
2025-07-17T19:40:41.840714530Z,2025-07-17T19:40:41.840549597Z,160,2,1108,C,A,13.100000000,100,0,580220701,130,164933,466815098,ARL
2025-07-17T19:40:41.847726962Z,2025-07-17T19:40:41.847561836Z,160,2,1108,A,A,13.100000000,100,0,580225981,130,165126,466815210,ARL
2025-07-17T19:40:43.062170859Z,2025-07-17T19:40:43.062005677Z,160,2,1108,C,A,13.100000000,100,0,580225981,130,165182,466835131,ARL
2025-07-17T19:40:43.069462079Z,2025-07-17T19:40:43.069296789Z,160,2,1108,A,A,13.100000000,100,0,580254737,130,165290,466835256,ARL
2025-07-17T19:40:43.204175557Z,2025-07-17T19:40:43.204010666Z,160,2,1108,C,A,13.100000000,100,0,580254737,130,164891,466836883,ARL
2025-07-17T19:40:43.211285034Z,2025-07-17T19:40:43.211119846Z,160,2,1108,A,A,13.100000000,100,0,580257773,130,165188,466836960,ARL
2025-07-17T19:40:43.432306931Z,2025-07-17T19:40:43.432142003Z,160,2,1108,C,A,13.100000000,100,0,580257773,130,164928,466839289,ARL
2025-07-17T19:40:43.439645248Z,2025-07-17T19:40:43.439479934Z,160,2,1108,A,A,13.100000000,100,0,580260385,130,165314,466839393,ARL
2025-07-17T19:40:44.152745599Z,2025-07-17T19:40:44.152580522Z,160,2,1108,C,A,13.100000000,100,0,580260385,130,165077,466850470,ARL
2025-07-17T19:40:44.160020559Z,2025-07-17T19:40:44.159855303Z,160,2,1108,A,A,13.100000000,100,0,580276949,130,165256,466850569,ARL
2025-07-17T19:40:44.495966315Z,2025-07-17T19:40:44.495798676Z,160,2,1108,C,A,13.100000000,100,0,580276949,130,167639,466853714,ARL
2025-07-17T19:40:44.503909537Z,2025-07-17T19:40:44.503744232Z,160,2,1108,A,A,13.100000000,100,0,580282469,130,165305,466854418,ARL
2025-07-17T19:40:44.930341122Z,2025-07-17T19:40:44.930171750Z,160,2,1108,C,A,13.100000000,100,0,580282469,128,169372,466861652,ARL
2025-07-17T19:40:44.938674645Z,2025-07-17T19:40:44.938509499Z,160,2,1108,A,A,13.100000000,100,0,580295013,130,165146,466862316,ARL
2025-07-17T19:40:48.046474265Z,2025-07-17T19:40:48.046309136Z,160,2,1108,C,A,13.100000000,100,0,580295013,130,165129,466924790,ARL
2025-07-17T19:40:48.054339221Z,2025-07-17T19:40:48.054173771Z,160,2,1108,A,A,13.100000000,100,0,580370097,130,165450,466925097,ARL
2025-07-17T19:40:48.145807273Z,2025-07-17T19:40:48.145631878Z,160,2,1108,C,A,13.100000000,100,0,580370097,128,175395,466929460,ARL
2025-07-17T19:40:48.165434092Z,2025-07-17T19:40:48.165268983Z,160,2,1108,A,A,13.100000000,100,0,580379853,130,165109,466932518,ARL
2025-07-17T19:40:48.190699086Z,2025-07-17T19:40:48.190534160Z,160,2,1108,C,A,13.100000000,100,0,580379853,130,164926,466933823,ARL
2025-07-17T19:40:48.210300315Z,2025-07-17T19:40:48.210135125Z,160,2,1108,A,A,13.100000000,100,0,580382181,130,165190,466934559,ARL
2025-07-17T19:40:48.364806195Z,2025-07-17T19:40:48.364641284Z,160,2,1108,C,A,13.100000000,100,0,580382181,130,164911,466936861,ARL
2025-07-17T19:40:48.375990498Z,2025-07-17T19:40:48.375825217Z,160,2,1108,A,A,13.100000000,100,0,580385517,130,165281,466936997,ARL
2025-07-17T19:40:48.481478581Z,2025-07-17T19:40:48.481313574Z,160,2,1108,C,A,13.100000000,100,0,580385517,130,165007,466938907,ARL
2025-07-17T19:40:48.488336515Z,2025-07-17T19:40:48.488171313Z,160,2,1108,A,A,13.100000000,100,0,580388161,130,165202,466938998,ARL
2025-07-17T19:40:48.758794817Z,2025-07-17T19:40:48.758629399Z,160,2,1108,C,A,13.100000000,100,0,580388161,130,165418,466943353,ARL
2025-07-17T19:40:48.765767382Z,2025-07-17T19:40:48.765602114Z,160,2,1108,A,A,13.100000000,100,0,580394809,130,165268,466943456,ARL
2025-07-17T19:40:49.348979409Z,2025-07-17T19:40:49.348814419Z,160,2,1108,C,A,13.100000000,100,0,580394809,130,164990,466951602,ARL
2025-07-17T19:40:49.356233188Z,2025-07-17T19:40:49.356067817Z,160,2,1108,A,A,13.100000000,100,0,580406893,130,165371,466951774,ARL
2025-07-17T19:40:49.532887095Z,2025-07-17T19:40:49.532722152Z,160,2,1108,C,A,13.100000000,100,0,580406893,130,164943,466954068,ARL
2025-07-17T19:40:49.539882470Z,2025-07-17T19:40:49.539717298Z,160,2,1108,A,A,13.100000000,100,0,580409321,130,165172,466954241,ARL
2025-07-17T19:40:49.696747419Z,2025-07-17T19:40:49.696582171Z,160,2,1108,C,A,13.100000000,100,0,580409321,130,165248,466956602,ARL
2025-07-17T19:40:49.703848972Z,2025-07-17T19:40:49.703683742Z,160,2,1108,A,A,13.100000000,100,0,580412057,130,165230,466956671,ARL
2025-07-17T19:40:50.578143611Z,2025-07-17T19:40:50.577977600Z,160,2,1108,C,A,13.100000000,100,0,580412057,130,166011,466973915,ARL
2025-07-17T19:40:50.592657988Z,2025-07-17T19:40:50.592488009Z,160,2,1108,A,A,13.100000000,100,0,580435481,128,169979,466977046,ARL
2025-07-17T19:40:50.612012474Z,2025-07-17T19:40:50.611847396Z,160,2,1108,C,A,13.100000000,100,0,580435481,130,165078,466978546,ARL
2025-07-17T19:40:50.631610372Z,2025-07-17T19:40:50.631445217Z,160,2,1108,A,A,13.100000000,100,0,580437789,130,165155,466979347,ARL
2025-07-17T19:40:54.524306706Z,2025-07-17T19:40:54.524141465Z,160,2,1108,C,A,13.100000000,100,0,580437789,130,165241,467042651,ARL
2025-07-17T19:40:54.531610102Z,2025-07-17T19:40:54.531443852Z,160,2,1108,A,A,13.100000000,100,0,580536465,128,166250,467044507,ARL
2025-07-17T19:40:55.752244249Z,2025-07-17T19:40:55.752079269Z,160,2,1108,C,A,13.100000000,100,0,580536465,130,164980,467065346,ARL
2025-07-17T19:40:55.760280694Z,2025-07-17T19:40:55.760115474Z,160,2,1108,A,A,13.100000000,100,0,580565789,130,165220,467065577,ARL
2025-07-17T19:40:56.040162956Z,2025-07-17T19:40:56.039997860Z,160,2,1108,C,A,13.100000000,100,0,580565789,130,165096,467070457,ARL
2025-07-17T19:40:56.047470253Z,2025-07-17T19:40:56.047305110Z,160,2,1108,A,A,13.100000000,100,0,580571865,130,165143,467070617,ARL
2025-07-17T19:40:59.481343079Z,2025-07-17T19:40:59.481176871Z,160,2,1108,C,A,13.100000000,100,0,580571865,130,166208,467118712,ARL
2025-07-17T19:40:59.488228195Z,2025-07-17T19:40:59.488063064Z,160,2,1108,A,A,13.100000000,100,0,580641329,130,165131,467119727,ARL
2025-07-17T19:40:59.509056349Z,2025-07-17T19:40:59.508891217Z,160,2,1108,C,A,13.100000000,100,0,580641329,130,165132,467122272,ARL
2025-07-17T19:40:59.516705684Z,2025-07-17T19:40:59.516540487Z,160,2,1108,A,A,13.100000000,100,0,580643261,130,165197,467122756,ARL
2025-07-17T19:40:59.580974278Z,2025-07-17T19:40:59.580808372Z,160,2,1108,C,A,13.100000000,100,0,580643261,130,165906,467124151,ARL
2025-07-17T19:40:59.588026488Z,2025-07-17T19:40:59.587860203Z,160,2,1108,A,A,13.100000000,100,0,580646197,130,166285,467124624,ARL
2025-07-17T19:41:00.176633069Z,2025-07-17T19:41:00.176468015Z,160,2,1108,C,A,13.100000000,100,0,580646197,130,165054,467131853,ARL
2025-07-17T19:41:00.188054685Z,2025-07-17T19:41:00.187889417Z,160,2,1108,A,A,13.100000000,100,0,580656613,130,165268,467132079,ARL
2025-07-17T19:41:00.199872905Z,2025-07-17T19:41:00.199707978Z,160,2,1108,C,A,13.100000000,100,0,580656613,130,164927,467132411,ARL
2025-07-17T19:41:00.223837044Z,2025-07-17T19:41:00.223668408Z,160,2,1108,A,A,13.100000000,100,0,580657245,130,168636,467132779,ARL
2025-07-17T19:41:00.547668741Z,2025-07-17T19:41:00.547503425Z,160,2,1108,C,A,13.100000000,100,0,580657245,130,165316,467139748,ARL
2025-07-17T19:41:00.554999211Z,2025-07-17T19:41:00.554834098Z,160,2,1108,A,A,13.100000000,100,0,580666549,130,165113,467139922,ARL
2025-07-17T19:41:00.723855980Z,2025-07-17T19:41:00.723691092Z,160,2,1108,C,A,13.100000000,100,0,580666549,130,164888,467142873,ARL
2025-07-17T19:41:00.731047796Z,2025-07-17T19:41:00.730882645Z,160,2,1108,A,A,13.100000000,100,0,580670909,130,165151,467142975,ARL
2025-07-17T19:41:00.861043505Z,2025-07-17T19:41:00.860878355Z,160,2,1108,C,A,13.100000000,100,0,580670909,130,165150,467145004,ARL
2025-07-17T19:41:00.869821202Z,2025-07-17T19:41:00.869654416Z,160,2,1108,A,A,13.100000000,100,0,580673317,128,166786,467145218,ARL
2025-07-17T19:41:00.879454235Z,2025-07-17T19:41:00.879289250Z,160,2,1108,C,A,13.100000000,100,0,580673317,130,164985,467145842,ARL
2025-07-17T19:41:00.903204903Z,2025-07-17T19:41:00.903039724Z,160,2,1108,A,A,13.100000000,100,0,580673933,130,165179,467146189,ARL
2025-07-17T19:41:01.067198702Z,2025-07-17T19:41:01.067031449Z,160,2,1108,C,A,13.100000000,100,0,580673933,130,167253,467150117,ARL
2025-07-17T19:41:01.074554358Z,2025-07-17T19:41:01.074388789Z,160,2,1108,A,A,13.100000000,100,0,580680873,130,165569,467151008,ARL
2025-07-17T19:41:01.453632762Z,2025-07-17T19:41:01.453467544Z,160,2,1108,C,A,13.100000000,100,0,580680873,130,165218,467162666,ARL
2025-07-17T19:41:01.464705652Z,2025-07-17T19:41:01.464540051Z,160,2,1108,A,A,13.130000000,100,0,580694573,130,165601,467163007,ARL
2025-07-17T19:41:01.497668086Z,2025-07-17T19:41:01.497502774Z,160,2,1108,C,A,13.130000000,100,0,580694573,0,165312,467163727,ARL
2025-07-17T19:41:01.497668086Z,2025-07-17T19:41:01.497502774Z,160,2,1108,A,A,13.100000000,100,0,580695769,130,165312,467163727,ARL
2025-07-17T19:41:01.500907195Z,2025-07-17T19:41:01.500742194Z,160,2,1108,C,A,13.100000000,100,0,580695769,130,165001,467163813,ARL
2025-07-17T19:41:01.508118792Z,2025-07-17T19:41:01.507953468Z,160,2,1108,A,A,13.130000000,100,0,580695897,130,165324,467163929,ARL
2025-07-17T19:41:07.393682058Z,2025-07-17T19:41:07.393516527Z,160,2,1108,C,A,13.130000000,100,0,580695897,0,165531,467296216,ARL
2025-07-17T19:41:07.393682058Z,2025-07-17T19:41:07.393516527Z,160,2,1108,A,A,13.100000000,100,0,580854473,130,165531,467296216,ARL
2025-07-17T19:41:07.889706053Z,2025-07-17T19:41:07.889540915Z,160,2,1108,C,A,13.100000000,100,0,580854473,130,165138,467306111,ARL
2025-07-17T19:41:07.897204126Z,2025-07-17T19:41:07.897038923Z,160,2,1108,A,A,13.100000000,100,0,580865269,130,165203,467306190,ARL
2025-07-17T19:41:09.400098985Z,2025-07-17T19:41:09.399932474Z,160,2,1108,C,A,13.100000000,100,0,580865269,130,166511,467329951,ARL
2025-07-17T19:41:09.410810521Z,2025-07-17T19:41:09.410645174Z,160,2,1108,A,A,13.100000000,100,0,580895461,130,165347,467331048,ARL
2025-07-17T19:41:09.698042071Z,2025-07-17T19:41:09.697876695Z,160,2,1108,C,A,13.100000000,100,0,580895461,130,165376,467335335,ARL
2025-07-17T19:41:09.705139586Z,2025-07-17T19:41:09.704974402Z,160,2,1108,A,A,13.100000000,100,0,580901053,130,165184,467335659,ARL
2025-07-17T19:41:12.017025623Z,2025-07-17T19:41:12.016860432Z,160,2,1108,C,A,13.100000000,100,0,580901053,130,165191,467377798,ARL
2025-07-17T19:41:12.024570628Z,2025-07-17T19:41:12.024405477Z,160,2,1108,A,A,13.100000000,100,0,580960489,130,165151,467378024,ARL
2025-07-17T19:41:14.093995651Z,2025-07-17T19:41:14.093830321Z,160,2,1108,C,A,13.100000000,100,0,580960489,130,165330,467408650,ARL
2025-07-17T19:41:14.101881072Z,2025-07-17T19:41:14.101715797Z,160,2,1108,A,A,13.100000000,100,0,580999761,130,165275,467408833,ARL
2025-07-17T19:41:14.120360307Z,2025-07-17T19:41:14.120194925Z,160,2,1108,C,A,13.100000000,100,0,580999761,130,165382,467409256,ARL
2025-07-17T19:41:14.144307615Z,2025-07-17T19:41:14.144142067Z,160,2,1108,A,A,13.100000000,100,0,581000557,130,165548,467409791,ARL
2025-07-17T19:41:14.682379383Z,2025-07-17T19:41:14.682210915Z,160,2,1108,C,A,13.100000000,100,0,581000557,128,168468,467420137,ARL
2025-07-17T19:41:14.689621338Z,2025-07-17T19:41:14.689456085Z,160,2,1108,A,A,13.130000000,100,0,581014009,130,165253,467420707,ARL
2025-07-17T19:41:14.706616451Z,2025-07-17T19:41:14.706451163Z,160,2,1108,C,A,13.130000000,100,0,581014009,0,165288,467421035,ARL
2025-07-17T19:41:14.706616451Z,2025-07-17T19:41:14.706451163Z,160,2,1108,A,A,13.100000000,100,0,581014457,130,165288,467421035,ARL
2025-07-17T19:41:15.095178138Z,2025-07-17T19:41:15.095012331Z,160,2,1108,C,A,13.100000000,100,0,581014457,128,165807,467432362,ARL
2025-07-17T19:41:15.100300325Z,2025-07-17T19:41:15.100134775Z,160,2,1108,A,A,13.130000000,100,0,581028721,130,165550,467433966,ARL
2025-07-17T19:41:18.396910901Z,2025-07-17T19:41:18.396745254Z,160,2,1108,C,A,16.900000000,100,0,494070617,0,165647,467498454,ARL
2025-07-17T19:41:18.396910901Z,2025-07-17T19:41:18.396745254Z,160,2,1108,A,A,16.610000000,100,0,581122177,130,165647,467498454,ARL
2025-07-17T19:41:18.396911993Z,2025-07-17T19:41:18.396746523Z,160,2,1108,C,A,16.900000000,100,0,494070621,0,165470,467498455,ARL
2025-07-17T19:41:18.396911993Z,2025-07-17T19:41:18.396746523Z,160,2,1108,A,A,16.610000000,100,0,581122181,130,165470,467498455,ARL
2025-07-17T19:41:18.396915912Z,2025-07-17T19:41:18.396747892Z,160,2,1108,C,A,16.900000000,100,0,494070625,0,168020,467498456,ARL
2025-07-17T19:41:18.396915912Z,2025-07-17T19:41:18.396747892Z,160,2,1108,A,A,16.610000000,100,0,581122185,0,168020,467498456,ARL
2025-07-17T19:41:18.396915912Z,2025-07-17T19:41:18.396748506Z,160,2,1108,C,A,16.900000000,100,0,494070629,0,167406,467498457,ARL
2025-07-17T19:41:18.396915912Z,2025-07-17T19:41:18.396748506Z,160,2,1108,A,A,16.610000000,100,0,581122189,0,167406,467498457,ARL
2025-07-17T19:41:18.396915912Z,2025-07-17T19:41:18.396748863Z,160,2,1108,C,A,16.900000000,100,0,494070633,0,167049,467498458,ARL
2025-07-17T19:41:18.396915912Z,2025-07-17T19:41:18.396748863Z,160,2,1108,A,A,16.610000000,100,0,581122193,130,167049,467498458,ARL
2025-07-17T19:41:18.396917001Z,2025-07-17T19:41:18.396750232Z,160,2,1108,C,A,16.900000000,100,0,494070637,0,166769,467498459,ARL
2025-07-17T19:41:18.396917001Z,2025-07-17T19:41:18.396750232Z,160,2,1108,A,A,16.610000000,100,0,581122197,0,166769,467498459,ARL
2025-07-17T19:41:18.396917001Z,2025-07-17T19:41:18.396750661Z,160,2,1108,C,A,16.900000000,100,0,494070641,0,166340,467498460,ARL
2025-07-17T19:41:18.396917001Z,2025-07-17T19:41:18.396750661Z,160,2,1108,A,A,16.610000000,100,0,581122201,130,166340,467498460,ARL
2025-07-17T19:41:18.396919270Z,2025-07-17T19:41:18.396751907Z,160,2,1108,C,A,16.900000000,100,0,494070645,0,167363,467498461,ARL
2025-07-17T19:41:18.396919270Z,2025-07-17T19:41:18.396751907Z,160,2,1108,A,A,16.610000000,100,0,581122205,0,167363,467498461,ARL
2025-07-17T19:41:18.396919270Z,2025-07-17T19:41:18.396752280Z,160,2,1108,C,A,16.900000000,100,0,494070653,0,166990,467498462,ARL
2025-07-17T19:41:18.396919270Z,2025-07-17T19:41:18.396752280Z,160,2,1108,A,A,16.610000000,100,0,581122209,0,166990,467498462,ARL
2025-07-17T19:41:18.396919270Z,2025-07-17T19:41:18.396752732Z,160,2,1108,C,A,16.900000000,100,0,494070657,0,166538,467498463,ARL
2025-07-17T19:41:18.396919270Z,2025-07-17T19:41:18.396752732Z,160,2,1108,A,A,16.610000000,100,0,581122213,130,166538,467498463,ARL
2025-07-17T19:41:18.396924480Z,2025-07-17T19:41:18.396754112Z,160,2,1108,C,A,16.900000000,100,0,494070661,0,170368,467498464,ARL
2025-07-17T19:41:18.396924480Z,2025-07-17T19:41:18.396754112Z,160,2,1108,A,A,16.610000000,100,0,581122217,0,170368,467498464,ARL
2025-07-17T19:41:18.396924480Z,2025-07-17T19:41:18.396754536Z,160,2,1108,C,A,16.900000000,100,0,494070665,0,169944,467498465,ARL
2025-07-17T19:41:18.396924480Z,2025-07-17T19:41:18.396754536Z,160,2,1108,A,A,16.610000000,100,0,581122221,0,169944,467498465,ARL
2025-07-17T19:41:18.396924480Z,2025-07-17T19:41:18.396754934Z,160,2,1108,C,A,16.900000000,100,0,494070669,0,169546,467498466,ARL
2025-07-17T19:41:18.396924480Z,2025-07-17T19:41:18.396754934Z,160,2,1108,A,A,16.610000000,100,0,581122225,0,169546,467498466,ARL
2025-07-17T19:41:18.396924480Z,2025-07-17T19:41:18.396755869Z,160,2,1108,C,A,16.900000000,100,0,494070673,0,168611,467498467,ARL
2025-07-17T19:41:18.396924480Z,2025-07-17T19:41:18.396755869Z,160,2,1108,A,A,16.610000000,100,0,581122229,0,168611,467498467,ARL
2025-07-17T19:41:18.396924480Z,2025-07-17T19:41:18.396756304Z,160,2,1108,C,A,16.900000000,100,0,494070677,0,168176,467498468,ARL
2025-07-17T19:41:18.396924480Z,2025-07-17T19:41:18.396756304Z,160,2,1108,A,A,16.610000000,100,0,581122233,130,168176,467498468,ARL
2025-07-17T19:41:18.396925178Z,2025-07-17T19:41:18.396757443Z,160,2,1108,C,A,16.900000000,100,0,494070681,0,167735,467498469,ARL
2025-07-17T19:41:18.396925178Z,2025-07-17T19:41:18.396757443Z,160,2,1108,A,A,16.610000000,100,0,581122237,0,167735,467498469,ARL
2025-07-17T19:41:18.396925178Z,2025-07-17T19:41:18.396757955Z,160,2,1108,C,A,16.900000000,100,0,494159697,0,167223,467498470,ARL
2025-07-17T19:41:18.396925178Z,2025-07-17T19:41:18.396757955Z,160,2,1108,A,A,16.610000000,100,0,581122241,130,167223,467498470,ARL
2025-07-17T19:41:18.397465584Z,2025-07-17T19:41:18.397299899Z,160,2,1108,C,A,13.820000000,100,0,556663353,130,165685,467498474,ARL
2025-07-17T19:41:18.397495384Z,2025-07-17T19:41:18.397329786Z,160,2,1108,C,A,14.110000000,100,0,578069633,0,165598,467498475,ARL
2025-07-17T19:41:18.397495384Z,2025-07-17T19:41:18.397329786Z,160,2,1108,A,A,13.990000000,100,0,581122265,130,165598,467498475,ARL
2025-07-17T19:41:18.397639089Z,2025-07-17T19:41:18.397473587Z,160,2,1108,C,A,14.040000000,100,0,556764757,0,165502,467498477,ARL
2025-07-17T19:41:18.397639089Z,2025-07-17T19:41:18.397473587Z,160,2,1108,A,A,13.890000000,100,0,581122269,130,165502,467498477,ARL
2025-07-17T19:41:18.397825664Z,2025-07-17T19:41:18.397660496Z,160,2,1108,A,A,13.560000000,100,0,581122273,130,165168,467498479,ARL
2025-07-17T19:41:18.398286031Z,2025-07-17T19:41:18.398120508Z,160,2,1108,C,A,15.090000000,100,0,556764825,0,165523,467498484,ARL
2025-07-17T19:41:18.398286031Z,2025-07-17T19:41:18.398120508Z,160,2,1108,A,A,14.930000000,100,0,581122281,130,165523,467498484,ARL
2025-07-17T19:41:18.398791341Z,2025-07-17T19:41:18.398625385Z,160,2,1108,C,A,16.670000000,100,0,556764837,0,165956,467498486,ARL
2025-07-17T19:41:18.398791341Z,2025-07-17T19:41:18.398625385Z,160,2,1108,A,A,16.490000000,100,0,581122285,130,165956,467498486,ARL
2025-07-17T19:41:18.400543381Z,2025-07-17T19:41:18.400377644Z,160,2,1108,C,A,13.890000000,100,0,556764873,0,165737,467498492,ARL
2025-07-17T19:41:18.400543381Z,2025-07-17T19:41:18.400377644Z,160,2,1108,A,A,13.760000000,100,0,581122293,130,165737,467498492,ARL
2025-07-17T19:41:18.417700451Z,2025-07-17T19:41:18.417535321Z,160,2,1108,C,A,13.380000000,100,0,556765741,130,165130,467498717,ARL
2025-07-17T19:41:18.417751838Z,2025-07-17T19:41:18.417586604Z,160,2,1108,A,A,13.240000000,100,0,581122369,130,165234,467498718,ARL
2025-07-17T19:41:18.441799866Z,2025-07-17T19:41:18.441634285Z,160,2,1108,C,A,14.040000000,100,0,556765445,0,165581,467498959,ARL
2025-07-17T19:41:18.441799866Z,2025-07-17T19:41:18.441634285Z,160,2,1108,A,A,13.890000000,100,0,581122749,130,165581,467498959,ARL
2025-07-17T19:41:18.441879409Z,2025-07-17T19:41:18.441714057Z,160,2,1108,A,A,14.800000000,100,0,581122761,130,165352,467498963,ARL
2025-07-17T19:41:18.441892202Z,2025-07-17T19:41:18.441726683Z,160,2,1108,C,A,15.060000000,100,0,494073769,130,165519,467498964,ARL
2025-07-17T19:41:18.598444691Z,2025-07-17T19:41:18.598279232Z,160,2,1108,C,A,13.130000000,100,0,581028721,0,165459,467501435,ARL
2025-07-17T19:41:18.598444691Z,2025-07-17T19:41:18.598279232Z,160,2,1108,A,A,13.100000000,100,0,581125233,130,165459,467501435,ARL
2025-07-17T19:41:18.617904311Z,2025-07-17T19:41:18.617739138Z,160,2,1108,C,A,13.100000000,100,0,581125233,130,165173,467501776,ARL
2025-07-17T19:41:18.625557605Z,2025-07-17T19:41:18.625392418Z,160,2,1108,A,A,13.100000000,100,0,581125497,130,165187,467501892,ARL
2025-07-17T19:41:18.689491807Z,2025-07-17T19:41:18.689326481Z,160,2,1108,A,A,12.980000000,30,0,581128953,130,165326,467505046,ARL
2025-07-17T19:41:18.690641287Z,2025-07-17T19:41:18.690475762Z,160,2,1108,C,A,13.990000000,100,0,556764857,0,165525,467505166,ARL
2025-07-17T19:41:18.690641287Z,2025-07-17T19:41:18.690475762Z,160,2,1108,A,A,13.860000000,100,0,581129065,130,165525,467505166,ARL
2025-07-17T19:41:18.716402939Z,2025-07-17T19:41:18.716237240Z,160,2,1108,C,A,13.990000000,100,0,556764829,0,165699,467505965,ARL
2025-07-17T19:41:18.716402939Z,2025-07-17T19:41:18.716237240Z,160,2,1108,A,A,13.860000000,100,0,581130221,130,165699,467505965,ARL
2025-07-17T19:41:19.133290052Z,2025-07-17T19:41:19.133124673Z,160,2,1108,C,A,13.100000000,100,0,581125497,130,165379,467513702,ARL
2025-07-17T19:41:19.153985475Z,2025-07-17T19:41:19.153820114Z,160,2,1108,A,A,13.100000000,100,0,581138337,130,165361,467515608,ARL
2025-07-17T19:41:19.175924955Z,2025-07-17T19:41:19.175759885Z,160,2,1108,C,A,13.100000000,100,0,581138337,130,165070,467516004,ARL
2025-07-17T19:41:19.182810924Z,2025-07-17T19:41:19.182645367Z,160,2,1108,A,A,13.100000000,100,0,581139805,130,165557,467516337,ARL
2025-07-17T19:41:19.199474559Z,2025-07-17T19:41:19.199309738Z,160,2,1108,C,A,13.100000000,100,0,581139805,130,164821,467516811,ARL
2025-07-17T19:41:19.222409841Z,2025-07-17T19:41:19.222244700Z,160,2,1108,A,A,13.100000000,100,0,581140805,130,165141,467517232,ARL
2025-07-17T19:41:20.222202089Z,2025-07-17T19:41:20.222036509Z,160,2,1108,C,A,13.100000000,100,0,581140805,130,165580,467531492,ARL
2025-07-17T19:41:20.229655943Z,2025-07-17T19:41:20.229490726Z,160,2,1108,A,A,13.100000000,100,0,581160513,130,165217,467531715,ARL
2025-07-17T19:41:20.236491549Z,2025-07-17T19:41:20.236326567Z,160,2,1108,C,A,13.100000000,100,0,581160513,130,164982,467531923,ARL
2025-07-17T19:41:20.260170478Z,2025-07-17T19:41:20.260004714Z,160,2,1108,A,A,13.100000000,100,0,581161049,130,165764,467532528,ARL
2025-07-17T19:41:21.727026895Z,2025-07-17T19:41:21.726861847Z,160,2,1108,C,A,13.100000000,100,0,581161049,130,165048,467554326,ARL
2025-07-17T19:41:21.735063950Z,2025-07-17T19:41:21.734897862Z,160,2,1108,A,A,13.100000000,100,0,581191705,130,166088,467554535,ARL
2025-07-17T19:41:24.104217020Z,2025-07-17T19:41:24.104052058Z,160,2,1108,C,A,13.100000000,100,0,581191705,130,164962,467591604,ARL
2025-07-17T19:41:24.115088978Z,2025-07-17T19:41:24.114923898Z,160,2,1108,A,A,13.100000000,100,0,581248801,130,165080,467592666,ARL
2025-07-17T19:41:24.368882415Z,2025-07-17T19:41:24.368717476Z,160,2,1108,C,A,13.100000000,100,0,581248801,130,164939,467596636,ARL
2025-07-17T19:41:24.376074973Z,2025-07-17T19:41:24.375909406Z,160,2,1108,A,A,13.100000000,100,0,581255101,130,165567,467596769,ARL
2025-07-17T19:41:24.516027220Z,2025-07-17T19:41:24.515862375Z,160,2,1108,C,A,13.100000000,100,0,581255101,130,164845,467599578,ARL
2025-07-17T19:41:24.523324669Z,2025-07-17T19:41:24.523159457Z,160,2,1108,A,A,13.100000000,100,0,581258177,130,165212,467599871,ARL
2025-07-17T19:41:25.057707353Z,2025-07-17T19:41:25.057542327Z,160,2,1108,C,A,13.100000000,100,0,581258177,130,165026,467606921,ARL
2025-07-17T19:41:25.065046434Z,2025-07-17T19:41:25.064880881Z,160,2,1108,A,A,13.130000000,100,0,581269229,130,165553,467607031,ARL
2025-07-17T19:41:25.082331007Z,2025-07-17T19:41:25.082165852Z,160,2,1108,C,A,13.130000000,100,0,581269229,0,165155,467607305,ARL
2025-07-17T19:41:25.082331007Z,2025-07-17T19:41:25.082165852Z,160,2,1108,A,A,13.100000000,100,0,581269549,130,165155,467607305,ARL
2025-07-17T19:41:27.371575345Z,2025-07-17T19:41:27.371409765Z,160,2,1108,C,A,13.100000000,100,0,581269549,130,165580,467641623,ARL
2025-07-17T19:41:27.385140882Z,2025-07-17T19:41:27.384975702Z,160,2,1108,A,A,13.130000000,100,0,581322305,130,165180,467643689,ARL
2025-07-17T19:41:27.402545829Z,2025-07-17T19:41:27.402380533Z,160,2,1108,C,A,13.130000000,100,0,581322305,0,165296,467644247,ARL
2025-07-17T19:41:27.402545829Z,2025-07-17T19:41:27.402380533Z,160,2,1108,A,A,13.100000000,100,0,581322905,130,165296,467644247,ARL
2025-07-17T19:41:27.521777331Z,2025-07-17T19:41:27.521612366Z,160,2,1108,C,A,13.100000000,100,0,581322905,130,164965,467648256,ARL
2025-07-17T19:41:27.529331720Z,2025-07-17T19:41:27.529166516Z,160,2,1108,A,A,13.130000000,100,0,581328397,130,165204,467648391,ARL
2025-07-17T19:41:28.361065971Z,2025-07-17T19:41:28.360900654Z,160,2,1108,C,A,13.130000000,100,0,581328397,0,165317,467659553,ARL
2025-07-17T19:41:28.361065971Z,2025-07-17T19:41:28.360900654Z,160,2,1108,A,A,13.100000000,100,0,581347621,130,165317,467659553,ARL
2025-07-17T19:41:29.523124001Z,2025-07-17T19:41:29.522958235Z,160,2,1108,T,N,12.785000000,100,0,0,130,165766,467677167,ARL
2025-07-17T19:41:29.523379733Z,2025-07-17T19:41:29.523214481Z,160,2,1108,C,A,13.100000000,100,0,581347621,0,165252,467677183,ARL
2025-07-17T19:41:29.523379733Z,2025-07-17T19:41:29.523214481Z,160,2,1108,A,A,12.990000000,100,0,581373745,130,165252,467677183,ARL
2025-07-17T19:41:29.523570680Z,2025-07-17T19:41:29.523405171Z,160,2,1108,C,A,13.990000000,100,0,581122265,0,165509,467677192,ARL
2025-07-17T19:41:29.523570680Z,2025-07-17T19:41:29.523405171Z,160,2,1108,A,A,14.110000000,100,0,581373765,130,165509,467677192,ARL
2025-07-17T19:41:29.523714407Z,2025-07-17T19:41:29.523547055Z,160,2,1108,C,A,13.110000000,20,0,561122437,130,167352,467677196,ARL
2025-07-17T19:41:29.525201441Z,2025-07-17T19:41:29.525036228Z,160,2,1108,A,A,12.940000000,20,0,581373845,130,165213,467677220,ARL
2025-07-17T19:41:29.525241382Z,2025-07-17T19:41:29.525076211Z,160,2,1108,C,A,12.990000000,100,0,581373745,130,165171,467677221,ARL
2025-07-17T19:41:29.526699977Z,2025-07-17T19:41:29.526534539Z,160,2,1108,C,A,14.540000000,100,0,494071325,0,165438,467677231,ARL
2025-07-17T19:41:29.526699977Z,2025-07-17T19:41:29.526534539Z,160,2,1108,A,A,14.250000000,100,0,581373869,130,165438,467677231,ARL
2025-07-17T19:41:29.526952883Z,2025-07-17T19:41:29.526787245Z,160,2,1108,A,A,13.100000000,100,0,581373873,130,165638,467677232,ARL
2025-07-17T19:41:29.531631610Z,2025-07-17T19:41:29.531466353Z,160,2,1108,C,A,13.240000000,100,0,581122369,130,165257,467677339,ARL
2025-07-17T19:41:29.531680130Z,2025-07-17T19:41:29.531514968Z,160,2,1108,A,A,13.350000000,100,0,581374009,130,165162,467677340,ARL
2025-07-17T19:41:29.532502331Z,2025-07-17T19:41:29.532337327Z,160,2,1108,C,A,13.350000000,100,0,581374009,130,165004,467677344,ARL
2025-07-17T19:41:29.532550032Z,2025-07-17T19:41:29.532384780Z,160,2,1108,A,A,13.210000000,100,0,581374021,130,165252,467677345,ARL
2025-07-17T19:41:29.574167155Z,2025-07-17T19:41:29.574001989Z,160,2,1108,C,A,14.110000000,100,0,581373765,0,165166,467677969,ARL
2025-07-17T19:41:29.574167155Z,2025-07-17T19:41:29.574001989Z,160,2,1108,A,A,13.960000000,100,0,581375673,130,165166,467677969,ARL
2025-07-17T19:41:29.574233064Z,2025-07-17T19:41:29.574067427Z,160,2,1108,C,A,14.540000000,100,0,494077585,0,165637,467677970,ARL
2025-07-17T19:41:29.574233064Z,2025-07-17T19:41:29.574067427Z,160,2,1108,A,A,14.250000000,100,0,581375677,130,165637,467677970,ARL
2025-07-17T19:41:32.639040006Z,2025-07-17T19:41:32.638874642Z,160,2,1108,C,A,13.090000000,30,0,579611909,130,165364,467723572,ARL
2025-07-17T19:41:33.643528521Z,2025-07-17T19:41:33.643363155Z,160,2,1108,A,A,12.940000000,30,0,581483661,130,165366,467758785,ARL
2025-07-17T19:41:34.884171397Z,2025-07-17T19:41:34.884006090Z,160,2,1108,A,A,12.950000000,82,0,581514745,130,165307,467781772,ARL
2025-07-17T19:41:35.215150964Z,2025-07-17T19:41:35.214985131Z,160,2,1108,C,B,11.770000000,100,0,569617137,0,165833,467786714,ARL
2025-07-17T19:41:35.215150964Z,2025-07-17T19:41:35.214985131Z,160,2,1108,A,B,11.630000000,100,0,581520293,130,165833,467786714,ARL
2025-07-17T19:41:35.215175217Z,2025-07-17T19:41:35.215008052Z,160,2,1108,C,B,11.770000000,100,0,569616941,0,167165,467786718,ARL
2025-07-17T19:41:35.215175217Z,2025-07-17T19:41:35.215008052Z,160,2,1108,A,B,11.630000000,100,0,581520297,130,167165,467786718,ARL
2025-07-17T19:41:35.861258162Z,2025-07-17T19:41:35.861092849Z,160,2,1108,A,A,13.630000000,700,0,581536501,130,165313,467801231,ARL
2025-07-17T19:41:35.861653777Z,2025-07-17T19:41:35.861488355Z,160,2,1108,C,A,14.010000000,700,0,493339833,130,165422,467801271,ARL
2025-07-17T19:41:37.387232142Z,2025-07-17T19:41:37.387066294Z,160,2,1108,C,A,13.270000000,2,0,557659805,0,165848,467836360,ARL
2025-07-17T19:41:37.387232142Z,2025-07-17T19:41:37.387066294Z,160,2,1108,A,A,13.190000000,2,0,581593793,130,165848,467836360,ARL
2025-07-17T19:41:39.989946168Z,2025-07-17T19:41:39.989779992Z,160,2,1108,A,A,13.670000000,700,0,581645413,128,166176,467868909,ARL
2025-07-17T19:41:39.989998067Z,2025-07-17T19:41:39.989832759Z,160,2,1108,C,A,14.050000000,700,0,493307877,130,165308,467868911,ARL
2025-07-17T19:41:43.140957239Z,2025-07-17T19:41:43.140791802Z,160,2,1108,C,B,12.430000000,3,0,569978205,130,165437,467943834,ARL
2025-07-17T19:42:28.769823825Z,2025-07-17T19:42:28.769658366Z,160,2,1108,C,A,16.610000000,100,0,581122177,0,165459,468745160,ARL
2025-07-17T19:42:28.769823825Z,2025-07-17T19:42:28.769658366Z,160,2,1108,A,A,16.250000000,100,0,582827033,130,165459,468745160,ARL
2025-07-17T19:42:28.769825178Z,2025-07-17T19:42:28.769659559Z,160,2,1108,C,A,16.610000000,100,0,581122181,0,165619,468745161,ARL
2025-07-17T19:42:28.769825178Z,2025-07-17T19:42:28.769659559Z,160,2,1108,A,A,16.250000000,100,0,582827037,130,165619,468745161,ARL
2025-07-17T19:42:28.769826307Z,2025-07-17T19:42:28.769660741Z,160,2,1108,C,A,16.610000000,100,0,581122185,0,165566,468745162,ARL
2025-07-17T19:42:28.769826307Z,2025-07-17T19:42:28.769660741Z,160,2,1108,A,A,16.250000000,100,0,582827041,130,165566,468745162,ARL
2025-07-17T19:42:28.769827486Z,2025-07-17T19:42:28.769662013Z,160,2,1108,C,A,16.610000000,100,0,581122189,0,165473,468745163,ARL
2025-07-17T19:42:28.769827486Z,2025-07-17T19:42:28.769662013Z,160,2,1108,A,A,16.250000000,100,0,582827045,130,165473,468745163,ARL
2025-07-17T19:42:28.769828557Z,2025-07-17T19:42:28.769663111Z,160,2,1108,C,A,16.610000000,100,0,581122193,0,165446,468745164,ARL
2025-07-17T19:42:28.769828557Z,2025-07-17T19:42:28.769663111Z,160,2,1108,A,A,16.250000000,100,0,582827049,130,165446,468745164,ARL
2025-07-17T19:42:28.769830387Z,2025-07-17T19:42:28.769664315Z,160,2,1108,C,A,16.610000000,100,0,581122197,0,166072,468745165,ARL
2025-07-17T19:42:28.769830387Z,2025-07-17T19:42:28.769664315Z,160,2,1108,A,A,16.250000000,100,0,582827053,0,166072,468745165,ARL
2025-07-17T19:42:28.769830387Z,2025-07-17T19:42:28.769664574Z,160,2,1108,C,A,16.610000000,100,0,581122201,0,165813,468745166,ARL
2025-07-17T19:42:28.769830387Z,2025-07-17T19:42:28.769664574Z,160,2,1108,A,A,16.250000000,100,0,582827057,130,165813,468745166,ARL
2025-07-17T19:42:28.769831961Z,2025-07-17T19:42:28.769665762Z,160,2,1108,C,A,16.610000000,100,0,581122205,0,166199,468745167,ARL
2025-07-17T19:42:28.769831961Z,2025-07-17T19:42:28.769665762Z,160,2,1108,A,A,16.250000000,100,0,582827061,0,166199,468745167,ARL
2025-07-17T19:42:28.769831961Z,2025-07-17T19:42:28.769666090Z,160,2,1108,C,A,16.610000000,100,0,581122209,0,165871,468745168,ARL
2025-07-17T19:42:28.769831961Z,2025-07-17T19:42:28.769666090Z,160,2,1108,A,A,16.250000000,100,0,582827065,130,165871,468745168,ARL
2025-07-17T19:42:28.769832848Z,2025-07-17T19:42:28.769667148Z,160,2,1108,C,A,16.610000000,100,0,581122213,0,165700,468745169,ARL
2025-07-17T19:42:28.769832848Z,2025-07-17T19:42:28.769667148Z,160,2,1108,A,A,16.250000000,100,0,582827069,130,165700,468745169,ARL
2025-07-17T19:42:28.769834493Z,2025-07-17T19:42:28.769668262Z,160,2,1108,C,A,16.610000000,100,0,581122217,0,166231,468745170,ARL
2025-07-17T19:42:28.769834493Z,2025-07-17T19:42:28.769668262Z,160,2,1108,A,A,16.250000000,100,0,582827073,130,166231,468745170,ARL
2025-07-17T19:42:28.769838374Z,2025-07-17T19:42:28.769669604Z,160,2,1108,C,A,16.610000000,100,0,581122221,0,168770,468745171,ARL
2025-07-17T19:42:28.769838374Z,2025-07-17T19:42:28.769669604Z,160,2,1108,A,A,16.250000000,100,0,582827077,0,168770,468745171,ARL
2025-07-17T19:42:28.769838374Z,2025-07-17T19:42:28.769669956Z,160,2,1108,C,A,16.610000000,100,0,581122225,0,168418,468745172,ARL
2025-07-17T19:42:28.769838374Z,2025-07-17T19:42:28.769669956Z,160,2,1108,A,A,16.250000000,100,0,582827081,0,168418,468745172,ARL
2025-07-17T19:42:28.769838374Z,2025-07-17T19:42:28.769670555Z,160,2,1108,C,A,16.610000000,100,0,581122229,0,167819,468745173,ARL
2025-07-17T19:42:28.769838374Z,2025-07-17T19:42:28.769670555Z,160,2,1108,A,A,16.250000000,100,0,582827085,130,167819,468745173,ARL
2025-07-17T19:42:28.769839904Z,2025-07-17T19:42:28.769672021Z,160,2,1108,C,A,16.610000000,100,0,581122233,0,167883,468745174,ARL
2025-07-17T19:42:28.769839904Z,2025-07-17T19:42:28.769672021Z,160,2,1108,A,A,16.250000000,100,0,582827089,0,167883,468745174,ARL
2025-07-17T19:42:28.769839904Z,2025-07-17T19:42:28.769672387Z,160,2,1108,C,A,16.610000000,100,0,581122237,0,167517,468745175,ARL
2025-07-17T19:42:28.769839904Z,2025-07-17T19:42:28.769672387Z,160,2,1108,A,A,16.250000000,100,0,582827093,0,167517,468745175,ARL
2025-07-17T19:42:28.769839904Z,2025-07-17T19:42:28.769673639Z,160,2,1108,C,A,16.610000000,100,0,581122241,0,166265,468745176,ARL
2025-07-17T19:42:28.769839904Z,2025-07-17T19:42:28.769673639Z,160,2,1108,A,A,16.250000000,100,0,582827097,130,166265,468745176,ARL
2025-07-17T19:42:28.769981822Z,2025-07-17T19:42:28.769816552Z,160,2,1108,C,A,13.120000000,4,0,578203737,130,165270,468745178,ARL
2025-07-17T19:42:28.770020391Z,2025-07-17T19:42:28.769854584Z,160,2,1108,C,A,13.100000000,100,0,581373873,0,165807,468745179,ARL
2025-07-17T19:42:28.770020391Z,2025-07-17T19:42:28.769854584Z,160,2,1108,A,A,12.960000000,100,0,582827105,130,165807,468745179,ARL
2025-07-17T19:42:28.770201837Z,2025-07-17T19:42:28.770036137Z,160,2,1108,C,A,13.960000000,100,0,581375673,0,165700,468745180,ARL
2025-07-17T19:42:28.770201837Z,2025-07-17T19:42:28.770036137Z,160,2,1108,A,A,13.690000000,100,0,582827117,130,165700,468745180,ARL
2025-07-17T19:42:28.770205393Z,2025-07-17T19:42:28.770040082Z,160,2,1108,C,A,13.560000000,100,0,581122273,130,165311,468745181,ARL
2025-07-17T19:42:28.770462786Z,2025-07-17T19:42:28.770297262Z,160,2,1108,A,A,13.120000000,3,0,582827121,130,165524,468745184,ARL
2025-07-17T19:42:28.770573417Z,2025-07-17T19:42:28.770407088Z,160,2,1108,A,A,13.270000000,100,0,582827125,130,166329,468745188,ARL
2025-07-17T19:42:28.770908528Z,2025-07-17T19:42:28.770743315Z,160,2,1108,C,A,13.120000000,1,0,578203725,130,165213,468745197,ARL
2025-07-17T19:42:28.770909648Z,2025-07-17T19:42:28.770744200Z,160,2,1108,C,A,13.890000000,100,0,581122269,0,165448,468745198,ARL
2025-07-17T19:42:28.770909648Z,2025-07-17T19:42:28.770744200Z,160,2,1108,A,A,13.590000000,100,0,582827161,130,165448,468745198,ARL
2025-07-17T19:42:28.770944240Z,2025-07-17T19:42:28.770778497Z,160,2,1108,C,A,14.250000000,100,0,581375677,0,165743,468745199,ARL
2025-07-17T19:42:28.770944240Z,2025-07-17T19:42:28.770778497Z,160,2,1108,A,A,13.970000000,100,0,582827165,130,165743,468745199,ARL
2025-07-17T19:42:28.771340863Z,2025-07-17T19:42:28.771175933Z,160,2,1108,C,A,13.120000000,3,0,582827121,130,164930,468745201,ARL
2025-07-17T19:42:28.771553028Z,2025-07-17T19:42:28.771387448Z,160,2,1108,C,A,14.930000000,100,0,581122281,0,165580,468745210,ARL
2025-07-17T19:42:28.771553028Z,2025-07-17T19:42:28.771387448Z,160,2,1108,A,A,14.610000000,100,0,582827185,130,165580,468745210,ARL
2025-07-17T19:42:28.771690999Z,2025-07-17T19:42:28.771525690Z,160,2,1108,C,A,13.760000000,100,0,581122293,130,165309,468745212,ARL
2025-07-17T19:42:28.771799964Z,2025-07-17T19:42:28.771634742Z,160,2,1108,A,A,13.000000000,4,0,582827197,130,165222,468745213,ARL
2025-07-17T19:42:28.771819863Z,2025-07-17T19:42:28.771654380Z,160,2,1108,A,A,13.460000000,100,0,582827201,130,165483,468745214,ARL
2025-07-17T19:42:28.772038376Z,2025-07-17T19:42:28.771872856Z,160,2,1108,C,A,14.250000000,100,0,581373869,0,165520,468745217,ARL
2025-07-17T19:42:28.772038376Z,2025-07-17T19:42:28.771872856Z,160,2,1108,A,A,13.970000000,100,0,582827217,130,165520,468745217,ARL
2025-07-17T19:42:28.772039521Z,2025-07-17T19:42:28.771874215Z,160,2,1108,C,A,16.490000000,100,0,581122285,0,165306,468745218,ARL
2025-07-17T19:42:28.772039521Z,2025-07-17T19:42:28.771874215Z,160,2,1108,A,A,16.130000000,100,0,582827221,130,165306,468745218,ARL
2025-07-17T19:42:28.784136117Z,2025-07-17T19:42:28.783970787Z,160,2,1108,C,A,13.210000000,100,0,581374021,130,165330,468745361,ARL
2025-07-17T19:42:28.784185463Z,2025-07-17T19:42:28.784020169Z,160,2,1108,A,A,12.950000000,100,0,582827417,130,165294,468745363,ARL
2025-07-17T19:42:28.810959501Z,2025-07-17T19:42:28.810794102Z,160,2,1108,A,A,14.480000000,100,0,582827997,130,165399,468745572,ARL
2025-07-17T19:42:28.810972757Z,2025-07-17T19:42:28.810807424Z,160,2,1108,C,A,14.800000000,100,0,581122761,130,165333,468745573,ARL
2025-07-17T19:42:28.824356417Z,2025-07-17T19:42:28.824190979Z,160,2,1108,C,A,13.890000000,100,0,581122749,0,165438,468745755,ARL
2025-07-17T19:42:28.824356417Z,2025-07-17T19:42:28.824190979Z,160,2,1108,A,A,13.590000000,100,0,582828173,130,165438,468745755,ARL
2025-07-17T19:42:28.872031459Z,2025-07-17T19:42:28.871865713Z,160,2,1108,C,B,11.760000000,100,0,41376297,130,165746,468747367,ARL
2025-07-17T19:42:28.872476658Z,2025-07-17T19:42:28.872311455Z,160,2,1108,A,B,10.990000000,100,0,582832953,130,165203,468747381,ARL
2025-07-17T19:42:28.873089226Z,2025-07-17T19:42:28.872923380Z,160,2,1108,C,A,13.860000000,100,0,581130221,0,165846,468747397,ARL
2025-07-17T19:42:28.873089226Z,2025-07-17T19:42:28.872923380Z,160,2,1108,A,A,13.610000000,100,0,582833021,130,165846,468747397,ARL
2025-07-17T19:42:28.873274932Z,2025-07-17T19:42:28.873109554Z,160,2,1108,C,A,13.860000000,100,0,581129065,0,165378,468747407,ARL
2025-07-17T19:42:28.873274932Z,2025-07-17T19:42:28.873109554Z,160,2,1108,A,A,13.610000000,100,0,582833065,130,165378,468747407,ARL
2025-07-17T19:42:28.878783269Z,2025-07-17T19:42:28.878617589Z,160,2,1108,C,B,12.360000000,2,0,556764729,0,165680,468747563,ARL
2025-07-17T19:42:28.878783269Z,2025-07-17T19:42:28.878617589Z,160,2,1108,A,B,12.260000000,2,0,582833341,130,165680,468747563,ARL
2025-07-17T19:42:29.040409172Z,2025-07-17T19:42:29.040244182Z,160,2,1108,C,A,12.960000000,100,0,582827105,130,164990,468750656,ARL
2025-07-17T19:42:29.119821408Z,2025-07-17T19:42:29.119656077Z,160,2,1108,A,A,12.700000000,1,0,582839573,130,165331,468751905,ARL
2025-07-17T19:42:29.120083381Z,2025-07-17T19:42:29.119918140Z,160,2,1108,A,A,12.990000000,100,0,582839577,130,165241,468751906,ARL
2025-07-17T19:42:29.284682757Z,2025-07-17T19:42:29.284517321Z,160,2,1108,C,A,13.640000000,100,0,556769701,130,165436,468754044,ARL
2025-07-17T19:42:29.284683623Z,2025-07-17T19:42:29.284518344Z,160,2,1108,A,A,13.210000000,100,0,582842741,130,165279,468754045,ARL
2025-07-17T19:42:29.284919377Z,2025-07-17T19:42:29.284753592Z,160,2,1108,T,B,12.700000000,1,0,0,130,165785,468754049,ARL
2025-07-17T19:42:29.284919377Z,2025-07-17T19:42:29.284753592Z,160,2,1108,F,A,12.700000000,1,0,582839573,130,165785,468754049,ARL
2025-07-17T19:42:29.284919377Z,2025-07-17T19:42:29.284753592Z,160,2,1108,C,A,12.700000000,1,0,582839573,130,165785,468754049,ARL
2025-07-17T19:42:29.284947045Z,2025-07-17T19:42:29.284781718Z,160,2,1108,A,B,12.340000000,4,0,582842749,130,165327,468754050,ARL
2025-07-17T19:42:29.285178671Z,2025-07-17T19:42:29.285013313Z,160,2,1108,C,A,12.990000000,100,0,582839577,0,165358,468754051,ARL
2025-07-17T19:42:29.285178671Z,2025-07-17T19:42:29.285013313Z,160,2,1108,A,A,12.960000000,100,0,582842753,130,165358,468754051,ARL
2025-07-17T19:42:29.285487213Z,2025-07-17T19:42:29.285321903Z,160,2,1108,C,A,12.940000000,20,0,581373845,130,165310,468754053,ARL
2025-07-17T19:42:29.286906764Z,2025-07-17T19:42:29.286741571Z,160,2,1108,A,A,12.740000000,20,0,582842773,130,165193,468754074,ARL
2025-07-17T19:42:29.373789407Z,2025-07-17T19:42:29.373623949Z,160,2,1108,A,A,13.510000000,100,0,582844037,130,165458,468755560,ARL
2025-07-17T19:42:29.373811689Z,2025-07-17T19:42:29.373645914Z,160,2,1108,C,A,13.900000000,100,0,556767661,130,165775,468755561,ARL
2025-07-17T19:42:29.373812514Z,2025-07-17T19:42:29.373647555Z,160,2,1108,C,B,12.340000000,4,0,582842749,130,164959,468755562,ARL
2025-07-17T19:42:34.990668360Z,2025-07-17T19:42:34.990503028Z,160,2,1108,C,A,12.950000000,82,0,581514745,130,165332,468852430,ARL
2025-07-17T19:42:35.110572254Z,2025-07-17T19:42:35.110406826Z,160,2,1108,A,A,13.630000000,700,0,582971645,130,165428,468853807,ARL
2025-07-17T19:42:35.111359395Z,2025-07-17T19:42:35.111194157Z,160,2,1108,C,A,13.980000000,700,0,556936717,130,165238,468853811,ARL
2025-07-17T19:42:37.152360380Z,2025-07-17T19:42:37.152183390Z,160,2,1108,C,A,12.980000000,30,0,581128953,128,176990,468904049,ARL
2025-07-17T19:42:38.156424309Z,2025-07-17T19:42:38.156258693Z,160,2,1108,A,A,12.700000000,30,0,583083897,130,165616,468946091,ARL
2025-07-17T19:42:39.786138594Z,2025-07-17T19:42:39.785972913Z,160,2,1108,C,A,13.190000000,2,0,581593793,0,165681,469015939,ARL
2025-07-17T19:42:39.786138594Z,2025-07-17T19:42:39.785972913Z,160,2,1108,A,A,13.100000000,2,0,583172413,130,165681,469015939,ARL
2025-07-17T19:42:42.122846773Z,2025-07-17T19:42:42.122679728Z,160,2,1108,T,N,12.590000000,1,0,0,130,167045,469089521,ARL
2025-07-17T19:42:42.123417632Z,2025-07-17T19:42:42.123252044Z,160,2,1108,C,A,12.740000000,20,0,582842773,130,165588,469089533,ARL
2025-07-17T19:42:42.584671336Z,2025-07-17T19:42:42.584505995Z,160,2,1108,A,A,14.760000000,100,0,583270237,130,165341,469097953,ARL
2025-07-17T19:42:42.584676347Z,2025-07-17T19:42:42.584510722Z,160,2,1108,C,A,16.080000000,100,0,43788313,130,165625,469097954,ARL
2025-07-17T19:42:42.584679468Z,2025-07-17T19:42:42.584514097Z,160,2,1108,C,A,13.690000000,100,0,582827117,0,165371,469097955,ARL
2025-07-17T19:42:42.584679468Z,2025-07-17T19:42:42.584514097Z,160,2,1108,A,A,13.620000000,100,0,583270241,130,165371,469097955,ARL
2025-07-17T19:42:42.584684324Z,2025-07-17T19:42:42.584518645Z,160,2,1108,C,A,14.480000000,100,0,582827997,130,165679,469097956,ARL
2025-07-17T19:42:42.584712834Z,2025-07-17T19:42:42.584547477Z,160,2,1108,C,A,16.080000000,100,0,43826261,130,165357,469097957,ARL
2025-07-17T19:42:42.584735330Z,2025-07-17T19:42:42.584570057Z,160,2,1108,A,A,15.160000000,100,0,583270249,130,165273,469097958,ARL
2025-07-17T19:42:42.585477900Z,2025-07-17T19:42:42.585312176Z,160,2,1108,C,A,13.610000000,100,0,582833021,0,165724,469097995,ARL
2025-07-17T19:42:42.585477900Z,2025-07-17T19:42:42.585312176Z,160,2,1108,A,A,13.490000000,100,0,583270261,130,165724,469097995,ARL
2025-07-17T19:42:42.585529508Z,2025-07-17T19:42:42.585364090Z,160,2,1108,A,A,15.160000000,100,0,583270265,130,165418,469097997,ARL
2025-07-17T19:42:42.588382245Z,2025-07-17T19:42:42.588216592Z,160,2,1108,C,A,12.940000000,30,0,581483661,130,165653,469098089,ARL
2025-07-17T19:42:42.589063782Z,2025-07-17T19:42:42.588898330Z,160,2,1108,C,A,13.610000000,100,0,582833065,0,165452,469098114,ARL
2025-07-17T19:42:42.589063782Z,2025-07-17T19:42:42.588898330Z,160,2,1108,A,A,13.490000000,100,0,583270445,130,165452,469098114,ARL
2025-07-17T19:42:42.615044777Z,2025-07-17T19:42:42.614879458Z,160,2,1108,A,A,14.410000000,100,0,583271389,130,165319,469099048,ARL
2025-07-17T19:42:42.615057607Z,2025-07-17T19:42:42.614892323Z,160,2,1108,C,A,14.760000000,100,0,583270237,130,165284,469099049,ARL
2025-07-17T19:42:43.497329767Z,2025-07-17T19:42:43.497164502Z,160,2,1108,C,A,13.000000000,4,0,582827197,130,165265,469119630,ARL
2025-07-17T19:42:43.593330702Z,2025-07-17T19:42:43.593165481Z,160,2,1108,A,A,12.640000000,30,0,583305389,130,165221,469120986,ARL
2025-07-17T19:43:02.585960715Z,2025-07-17T19:43:02.585795199Z,160,2,1108,C,A,13.100000000,2,0,583172413,0,165516,469450738,ARL
2025-07-17T19:43:02.585960715Z,2025-07-17T19:43:02.585795199Z,160,2,1108,A,A,13.020000000,2,0,583722693,130,165516,469450738,ARL
2025-07-17T19:43:42.752343400Z,2025-07-17T19:43:42.752176920Z,160,2,1108,T,N,12.560000000,7,0,0,130,166480,470223591,ARL
2025-07-17T19:43:42.753659634Z,2025-07-17T19:43:42.753493791Z,160,2,1108,T,N,12.560000000,6,0,0,130,165843,470223599,ARL
2025-07-17T19:43:42.754334518Z,2025-07-17T19:43:42.754169111Z,160,2,1108,A,A,12.940000000,1,0,584762021,130,165407,470223603,ARL
2025-07-17T19:43:42.754891757Z,2025-07-17T19:43:42.754726143Z,160,2,1108,T,N,12.560000000,1,0,0,130,165614,470223608,ARL
2025-07-17T19:43:42.755373813Z,2025-07-17T19:43:42.755208761Z,160,2,1108,C,A,12.940000000,1,0,584762021,130,165052,470223615,ARL
2025-07-17T19:43:42.756447018Z,2025-07-17T19:43:42.756281139Z,160,2,1108,T,N,12.560000000,1,0,0,130,165879,470223620,ARL
2025-07-17T19:43:48.774480301Z,2025-07-17T19:43:48.774314350Z,160,2,1108,T,B,12.640000000,17,0,0,130,165951,470314618,ARL
2025-07-17T19:43:48.774480301Z,2025-07-17T19:43:48.774314350Z,160,2,1108,F,A,12.640000000,17,0,583305389,130,165951,470314618,ARL
2025-07-17T19:43:48.774480301Z,2025-07-17T19:43:48.774314350Z,160,2,1108,C,A,12.640000000,17,0,583305389,130,165951,470314618,ARL
2025-07-17T19:43:48.774483673Z,2025-07-17T19:43:48.774317607Z,160,2,1108,T,B,12.640000000,13,0,0,130,166066,470314619,ARL
2025-07-17T19:43:48.774483673Z,2025-07-17T19:43:48.774317607Z,160,2,1108,F,A,12.640000000,13,0,583305389,130,166066,470314619,ARL
2025-07-17T19:43:48.774483673Z,2025-07-17T19:43:48.774317607Z,160,2,1108,C,A,12.640000000,13,0,583305389,130,166066,470314619,ARL
2025-07-17T19:43:48.774510604Z,2025-07-17T19:43:48.774345312Z,160,2,1108,A,B,12.450000000,1,0,584890953,130,165292,470314620,ARL
2025-07-17T19:43:48.774523915Z,2025-07-17T19:43:48.774358775Z,160,2,1108,A,B,12.330000000,3,0,584890957,130,165140,470314621,ARL
2025-07-17T19:43:48.774666655Z,2025-07-17T19:43:48.774501316Z,160,2,1108,C,A,12.700000000,30,0,583083897,130,165339,470314626,ARL
2025-07-17T19:43:48.774734007Z,2025-07-17T19:43:48.774568601Z,160,2,1108,C,A,13.620000000,100,0,583270241,0,165406,470314628,ARL
2025-07-17T19:43:48.774734007Z,2025-07-17T19:43:48.774568601Z,160,2,1108,A,A,13.680000000,100,0,584890973,130,165406,470314628,ARL
2025-07-17T19:43:48.774739512Z,2025-07-17T19:43:48.774574181Z,160,2,1108,A,A,14.770000000,100,0,584890977,130,165331,470314629,ARL
2025-07-17T19:43:48.774753295Z,2025-07-17T19:43:48.774588050Z,160,2,1108,C,A,14.410000000,100,0,583271389,130,165245,470314630,ARL
2025-07-17T19:43:48.775104470Z,2025-07-17T19:43:48.774939027Z,160,2,1108,C,A,13.270000000,100,0,582827125,130,165443,470314635,ARL
2025-07-17T19:43:48.775265210Z,2025-07-17T19:43:48.775099596Z,160,2,1108,C,A,13.490000000,100,0,583270445,0,165614,470314636,ARL
2025-07-17T19:43:48.775265210Z,2025-07-17T19:43:48.775099596Z,160,2,1108,A,A,13.790000000,100,0,584891005,130,165614,470314636,ARL
2025-07-17T19:43:48.775442371Z,2025-07-17T19:43:48.775276714Z,160,2,1108,C,A,16.130000000,100,0,582827221,0,165657,470314637,ARL
2025-07-17T19:43:48.775442371Z,2025-07-17T19:43:48.775276714Z,160,2,1108,A,A,16.450000000,100,0,584891013,130,165657,470314637,ARL
2025-07-17T19:43:48.775461274Z,2025-07-17T19:43:48.775296089Z,160,2,1108,A,A,13.530000000,100,0,584891017,130,165185,470314638,ARL
2025-07-17T19:43:48.775559242Z,2025-07-17T19:43:48.775394260Z,160,2,1108,C,B,12.450000000,1,0,584890953,130,164982,470314639,ARL
2025-07-17T19:43:48.775892421Z,2025-07-17T19:43:48.775726967Z,160,2,1108,C,A,14.610000000,100,0,582827185,0,165454,470314642,ARL
2025-07-17T19:43:48.775892421Z,2025-07-17T19:43:48.775726967Z,160,2,1108,A,A,14.900000000,100,0,584891021,130,165454,470314642,ARL
2025-07-17T19:43:48.776646261Z,2025-07-17T19:43:48.776480676Z,160,2,1108,C,A,13.590000000,100,0,582827161,0,165585,470314645,ARL
2025-07-17T19:43:48.776646261Z,2025-07-17T19:43:48.776480676Z,160,2,1108,A,A,13.860000000,100,0,584891101,130,165585,470314645,ARL
2025-07-17T19:43:48.776754767Z,2025-07-17T19:43:48.776589415Z,160,2,1108,C,A,13.970000000,100,0,582827217,0,165352,470314646,ARL
2025-07-17T19:43:48.776754767Z,2025-07-17T19:43:48.776589415Z,160,2,1108,A,A,14.250000000,100,0,584891105,130,165352,470314646,ARL
2025-07-17T19:43:48.777416760Z,2025-07-17T19:43:48.777251281Z,160,2,1108,C,A,13.490000000,100,0,583270261,0,165479,470314652,ARL
2025-07-17T19:43:48.777416760Z,2025-07-17T19:43:48.777251281Z,160,2,1108,A,A,13.790000000,100,0,584891113,130,165479,470314652,ARL
2025-07-17T19:43:48.778536025Z,2025-07-17T19:43:48.778370475Z,160,2,1108,C,A,13.460000000,100,0,582827201,0,165550,470314665,ARL
2025-07-17T19:43:48.778536025Z,2025-07-17T19:43:48.778370475Z,160,2,1108,A,A,13.710000000,100,0,584891121,130,165550,470314665,ARL
2025-07-17T19:43:48.778995994Z,2025-07-17T19:43:48.778830352Z,160,2,1108,C,B,12.260000000,2,0,582833341,0,165642,470314666,ARL
2025-07-17T19:43:48.778995994Z,2025-07-17T19:43:48.778830352Z,160,2,1108,A,B,12.150000000,2,0,584891125,130,165642,470314666,ARL
2025-07-17T19:43:48.780662283Z,2025-07-17T19:43:48.780496721Z,160,2,1108,C,A,13.590000000,100,0,582828173,0,165562,470314789,ARL
2025-07-17T19:43:48.780662283Z,2025-07-17T19:43:48.780496721Z,160,2,1108,A,A,13.860000000,100,0,584891221,130,165562,470314789,ARL
2025-07-17T19:43:48.784580629Z,2025-07-17T19:43:48.784415049Z,160,2,1108,C,A,13.970000000,100,0,582827165,0,165580,470314940,ARL
2025-07-17T19:43:48.784580629Z,2025-07-17T19:43:48.784415049Z,160,2,1108,A,A,14.250000000,100,0,584891401,130,165580,470314940,ARL
2025-07-17T19:43:48.784603112Z,2025-07-17T19:43:48.784438037Z,160,2,1108,C,B,12.330000000,3,0,584890957,130,165075,470314941,ARL
2025-07-17T19:43:48.785539434Z,2025-07-17T19:43:48.785374027Z,160,2,1108,C,A,12.950000000,100,0,582827417,130,165407,470314953,ARL
2025-07-17T19:43:48.785592407Z,2025-07-17T19:43:48.785427231Z,160,2,1108,A,A,13.210000000,100,0,584891417,130,165176,470314954,ARL
2025-07-17T19:43:48.825155669Z,2025-07-17T19:43:48.824990369Z,160,2,1108,C,A,13.680000000,100,0,584890973,0,165300,470315228,ARL
2025-07-17T19:43:48.825155669Z,2025-07-17T19:43:48.824990369Z,160,2,1108,A,A,13.960000000,100,0,584891821,130,165300,470315228,ARL
2025-07-17T19:43:49.708000474Z,2025-07-17T19:43:49.707833803Z,160,2,1108,A,A,13.470000000,100,0,584905345,0,166671,470324254,ARL
2025-07-17T19:43:49.708000474Z,2025-07-17T19:43:49.707834944Z,160,2,1108,C,A,13.210000000,100,0,582842741,130,165530,470324255,ARL
2025-07-17T19:43:57.204023662Z,2025-07-17T19:43:57.203858090Z,160,2,1108,A,B,12.480000000,30,0,585076333,130,165572,470447624,ARL
2025-07-17T19:43:57.204024503Z,2025-07-17T19:43:57.203859368Z,160,2,1108,A,A,12.940000000,25,0,585076337,130,165135,470447625,ARL
2025-07-17T19:43:57.515279877Z,2025-07-17T19:43:57.515113793Z,160,2,1108,C,A,12.960000000,100,0,582842753,0,166084,470455953,ARL
2025-07-17T19:43:57.515279877Z,2025-07-17T19:43:57.515113793Z,160,2,1108,A,A,12.950000000,100,0,585088165,130,166084,470455953,ARL
2025-07-17T19:43:57.786131013Z,2025-07-17T19:43:57.785965578Z,160,2,1108,C,B,12.150000000,2,0,584891125,0,165435,470459422,ARL
2025-07-17T19:43:57.786131013Z,2025-07-17T19:43:57.785965578Z,160,2,1108,A,B,12.230000000,2,0,585093729,130,165435,470459422,ARL
2025-07-17T19:44:11.204263598Z,2025-07-17T19:44:11.204090298Z,160,2,1108,C,B,12.480000000,30,0,585076333,128,173300,470796203,ARL
2025-07-17T19:44:30.946908599Z,2025-07-17T19:44:30.946733921Z,160,2,1108,C,A,12.940000000,25,0,585076337,128,174678,471184916,ARL
2025-07-17T19:44:32.061005792Z,2025-07-17T19:44:32.060840313Z,160,2,1108,A,A,12.950000000,25,0,586294129,130,165479,471227393,ARL
2025-07-17T19:44:38.536934900Z,2025-07-17T19:44:38.536769493Z,160,2,1108,C,A,12.950000000,100,0,585088165,130,165407,471336357,ARL
2025-07-17T19:44:38.537663551Z,2025-07-17T19:44:38.537498092Z,160,2,1108,C,A,13.960000000,100,0,584891821,0,165459,471336388,ARL
2025-07-17T19:44:38.537663551Z,2025-07-17T19:44:38.537498092Z,160,2,1108,A,A,14.020000000,100,0,586482037,130,165459,471336388,ARL
2025-07-17T19:44:38.538079031Z,2025-07-17T19:44:38.537913521Z,160,2,1108,C,A,13.860000000,100,0,584891101,0,165510,471336401,ARL
2025-07-17T19:44:38.538079031Z,2025-07-17T19:44:38.537913521Z,160,2,1108,A,A,14.040000000,100,0,586482053,130,165510,471336401,ARL
2025-07-17T19:44:38.538333610Z,2025-07-17T19:44:38.538167998Z,160,2,1108,A,A,13.030000000,100,0,586482061,130,165612,471336412,ARL
2025-07-17T19:44:38.538673264Z,2025-07-17T19:44:38.538507307Z,160,2,1108,C,A,13.710000000,100,0,584891121,130,165957,471336415,ARL
2025-07-17T19:44:38.538776150Z,2025-07-17T19:44:38.538610835Z,160,2,1108,A,A,13.880000000,100,0,586482085,130,165315,471336417,ARL
2025-07-17T19:44:38.543021999Z,2025-07-17T19:44:38.542856440Z,160,2,1108,C,A,13.020000000,2,0,583722693,0,165559,471336457,ARL
2025-07-17T19:44:38.543021999Z,2025-07-17T19:44:38.542856440Z,160,2,1108,A,A,13.100000000,2,0,586482137,130,165559,471336457,ARL
2025-07-17T19:44:38.546295132Z,2025-07-17T19:44:38.546129917Z,160,2,1108,C,A,13.210000000,100,0,584891417,130,165215,471336521,ARL
2025-07-17T19:44:38.546347468Z,2025-07-17T19:44:38.546182295Z,160,2,1108,A,A,13.380000000,100,0,586482177,130,165173,471336523,ARL
2025-07-17T19:44:38.547181209Z,2025-07-17T19:44:38.547016068Z,160,2,1108,C,A,13.380000000,100,0,586482177,130,165141,471336531,ARL
2025-07-17T19:44:38.547227762Z,2025-07-17T19:44:38.547062293Z,160,2,1108,A,A,13.290000000,100,0,586482205,130,165469,471336532,ARL
2025-07-17T19:44:38.803863361Z,2025-07-17T19:44:38.803698195Z,160,2,1108,A,A,13.810000000,100,0,586489245,130,165166,471340096,ARL
2025-07-17T19:44:38.803877476Z,2025-07-17T19:44:38.803712150Z,160,2,1108,C,A,13.510000000,100,0,582844037,130,165326,471340097,ARL
2025-07-17T19:44:45.186118145Z,2025-07-17T19:44:45.185952552Z,160,2,1108,C,B,12.230000000,2,0,585093729,0,165593,471457369,ARL
2025-07-17T19:44:45.186118145Z,2025-07-17T19:44:45.185952552Z,160,2,1108,A,B,12.310000000,2,0,586704165,130,165593,471457369,ARL
2025-07-17T19:46:00.512915984Z,2025-07-17T19:46:00.512750403Z,160,2,1108,C,A,13.030000000,100,0,586482061,0,165581,473169979,ARL
2025-07-17T19:46:00.512915984Z,2025-07-17T19:46:00.512750403Z,160,2,1108,A,A,12.960000000,100,0,589486561,130,165581,473169979,ARL
2025-07-17T19:46:00.513681016Z,2025-07-17T19:46:00.513515318Z,160,2,1108,C,A,14.020000000,100,0,586482037,0,165698,473170029,ARL
2025-07-17T19:46:00.513681016Z,2025-07-17T19:46:00.513515318Z,160,2,1108,A,A,13.970000000,100,0,589486693,130,165698,473170029,ARL
2025-07-17T19:46:00.518002539Z,2025-07-17T19:46:00.517836953Z,160,2,1108,C,A,14.040000000,100,0,586482053,0,165586,473170268,ARL
2025-07-17T19:46:00.518002539Z,2025-07-17T19:46:00.517836953Z,160,2,1108,A,A,13.870000000,100,0,589487221,130,165586,473170268,ARL
2025-07-17T19:46:00.522493733Z,2025-07-17T19:46:00.522324018Z,160,2,1108,C,A,13.880000000,100,0,586482085,0,169715,473171174,ARL
2025-07-17T19:46:00.522493733Z,2025-07-17T19:46:00.522324018Z,160,2,1108,A,A,13.720000000,100,0,589488113,128,169715,473171174,ARL
2025-07-17T19:46:00.526367540Z,2025-07-17T19:46:00.526201523Z,160,2,1108,C,A,13.290000000,100,0,586482205,130,166017,473171823,ARL
2025-07-17T19:46:00.526420439Z,2025-07-17T19:46:00.526255049Z,160,2,1108,A,A,13.220000000,100,0,589488781,130,165390,473171842,ARL
2025-07-17T19:46:10.862690916Z,2025-07-17T19:46:10.862525721Z,160,2,1108,C,A,12.960000000,100,0,589486561,130,165195,473425231,ARL
2025-07-17T19:46:10.863438311Z,2025-07-17T19:46:10.863272802Z,160,2,1108,C,A,13.970000000,100,0,589486693,0,165509,473425312,ARL
2025-07-17T19:46:10.863438311Z,2025-07-17T19:46:10.863272802Z,160,2,1108,A,A,14.140000000,100,0,589877157,130,165509,473425312,ARL
2025-07-17T19:46:10.864124114Z,2025-07-17T19:46:10.863958875Z,160,2,1108,A,A,13.110000000,100,0,589877189,130,165239,473425361,ARL
2025-07-17T19:46:10.866868129Z,2025-07-17T19:46:10.866701869Z,160,2,1108,C,A,13.870000000,100,0,589487221,0,166260,473425552,ARL
2025-07-17T19:46:10.866868129Z,2025-07-17T19:46:10.866701869Z,160,2,1108,A,A,14.030000000,100,0,589877581,130,166260,473425552,ARL
2025-07-17T19:46:10.867680682Z,2025-07-17T19:46:10.867515454Z,160,2,1108,C,A,13.220000000,100,0,589488781,130,165228,473425652,ARL
2025-07-17T19:46:10.867731120Z,2025-07-17T19:46:10.867565831Z,160,2,1108,A,A,13.380000000,100,0,589877609,130,165289,473425662,ARL
2025-07-17T19:46:10.875429011Z,2025-07-17T19:46:10.875263821Z,160,2,1108,C,A,13.720000000,100,0,589488113,130,165190,473426026,ARL
2025-07-17T19:46:10.875532956Z,2025-07-17T19:46:10.875366907Z,160,2,1108,A,A,13.870000000,100,0,589878029,130,166049,473426027,ARL
2025-07-17T19:46:10.887778293Z,2025-07-17T19:46:10.887612583Z,160,2,1108,C,A,16.450000000,100,0,584891013,0,165710,473426473,ARL
2025-07-17T19:46:10.887778293Z,2025-07-17T19:46:10.887612583Z,160,2,1108,A,A,16.650000000,100,0,589879309,130,165710,473426473,ARL
2025-07-17T19:46:10.889100475Z,2025-07-17T19:46:10.888934891Z,160,2,1108,C,A,14.900000000,100,0,584891021,0,165584,473426516,ARL
2025-07-17T19:46:10.889100475Z,2025-07-17T19:46:10.888934891Z,160,2,1108,A,A,15.080000000,100,0,589879417,130,165584,473426516,ARL
2025-07-17T19:46:11.013580218Z,2025-07-17T19:46:11.013414750Z,160,2,1108,C,A,13.860000000,100,0,584891221,0,165468,473431650,ARL
2025-07-17T19:46:11.013580218Z,2025-07-17T19:46:11.013414750Z,160,2,1108,A,A,14.030000000,100,0,589889285,130,165468,473431650,ARL
2025-07-17T19:46:49.331593769Z,2025-07-17T19:46:49.331428262Z,160,2,1108,C,A,13.110000000,100,0,589877189,0,165507,474286110,ARL
2025-07-17T19:46:49.331593769Z,2025-07-17T19:46:49.331428262Z,160,2,1108,A,A,12.960000000,100,0,591202341,130,165507,474286110,ARL
2025-07-17T19:46:49.332337044Z,2025-07-17T19:46:49.332171434Z,160,2,1108,C,A,14.140000000,100,0,589877157,0,165610,474286118,ARL
2025-07-17T19:46:49.332337044Z,2025-07-17T19:46:49.332171434Z,160,2,1108,A,A,13.970000000,100,0,591202393,130,165610,474286118,ARL
2025-07-17T19:46:49.333066939Z,2025-07-17T19:46:49.332901137Z,160,2,1108,C,A,15.080000000,100,0,589879417,0,165802,474286134,ARL
2025-07-17T19:46:49.333066939Z,2025-07-17T19:46:49.332901137Z,160,2,1108,A,A,14.910000000,100,0,591202405,130,165802,474286134,ARL
2025-07-17T19:46:49.334377566Z,2025-07-17T19:46:49.334211902Z,160,2,1108,C,A,14.030000000,100,0,589877581,0,165664,474286200,ARL
2025-07-17T19:46:49.334377566Z,2025-07-17T19:46:49.334211902Z,160,2,1108,A,A,13.870000000,100,0,591202441,130,165664,474286200,ARL
2025-07-17T19:46:49.334388355Z,2025-07-17T19:46:49.334222786Z,160,2,1108,C,A,16.650000000,100,0,589879309,0,165569,474286202,ARL
2025-07-17T19:46:49.334388355Z,2025-07-17T19:46:49.334222786Z,160,2,1108,A,A,16.460000000,100,0,591202445,130,165569,474286202,ARL
2025-07-17T19:46:49.338150782Z,2025-07-17T19:46:49.337985419Z,160,2,1108,C,A,13.380000000,100,0,589877609,130,165363,474286351,ARL
2025-07-17T19:46:49.338206036Z,2025-07-17T19:46:49.338040696Z,160,2,1108,A,A,13.220000000,100,0,591202525,130,165340,474286355,ARL
2025-07-17T19:46:49.345150069Z,2025-07-17T19:46:49.344984399Z,160,2,1108,C,A,14.030000000,100,0,589889285,0,165670,474286571,ARL
2025-07-17T19:46:49.345150069Z,2025-07-17T19:46:49.344984399Z,160,2,1108,A,A,13.870000000,100,0,591202837,130,165670,474286571,ARL
2025-07-17T19:46:49.375338353Z,2025-07-17T19:46:49.375172775Z,160,2,1108,C,A,13.870000000,100,0,589878029,0,165578,474287210,ARL
2025-07-17T19:46:49.375338353Z,2025-07-17T19:46:49.375172775Z,160,2,1108,A,A,13.720000000,100,0,591203377,130,165578,474287210,ARL
2025-07-17T19:47:43.153923339Z,2025-07-17T19:47:43.153756054Z,160,2,1108,C,A,12.950000000,25,0,586294129,128,167285,475417373,ARL
2025-07-17T19:47:59.497636373Z,2025-07-17T19:47:59.497470564Z,160,2,1108,C,A,12.960000000,100,0,591202341,130,165809,475832011,ARL
2025-07-17T19:47:59.498380294Z,2025-07-17T19:47:59.498212373Z,160,2,1108,C,A,13.970000000,100,0,591202393,0,167921,475832140,ARL
2025-07-17T19:47:59.498380294Z,2025-07-17T19:47:59.498212373Z,160,2,1108,A,A,14.020000000,100,0,593712945,130,167921,475832140,ARL
2025-07-17T19:47:59.498584549Z,2025-07-17T19:47:59.498419094Z,160,2,1108,C,B,11.630000000,100,0,581520297,0,165455,475832164,ARL
2025-07-17T19:47:59.498584549Z,2025-07-17T19:47:59.498419094Z,160,2,1108,A,B,11.760000000,100,0,593712965,130,165455,475832164,ARL
2025-07-17T19:47:59.498662296Z,2025-07-17T19:47:59.498496785Z,160,2,1108,C,A,13.790000000,100,0,584891005,0,165511,475832172,ARL
2025-07-17T19:47:59.498662296Z,2025-07-17T19:47:59.498496785Z,160,2,1108,A,A,13.970000000,100,0,593712989,130,165511,475832172,ARL
2025-07-17T19:47:59.498800986Z,2025-07-17T19:47:59.498635653Z,160,2,1108,C,B,11.630000000,100,0,581520293,0,165333,475832186,ARL
2025-07-17T19:47:59.498800986Z,2025-07-17T19:47:59.498635653Z,160,2,1108,A,B,11.760000000,100,0,593713033,130,165333,475832186,ARL
2025-07-17T19:47:59.498870141Z,2025-07-17T19:47:59.498704693Z,160,2,1108,C,A,13.790000000,100,0,584891113,0,165448,475832189,ARL
2025-07-17T19:47:59.498870141Z,2025-07-17T19:47:59.498704693Z,160,2,1108,A,A,13.970000000,100,0,593713041,130,165448,475832189,ARL
2025-07-17T19:47:59.499610123Z,2025-07-17T19:47:59.499444245Z,160,2,1108,C,A,13.870000000,100,0,591202441,0,165878,475832296,ARL
2025-07-17T19:47:59.499610123Z,2025-07-17T19:47:59.499444245Z,160,2,1108,A,A,14.040000000,100,0,593713165,130,165878,475832296,ARL
2025-07-17T19:47:59.502504139Z,2025-07-17T19:47:59.502338784Z,160,2,1108,C,A,13.220000000,100,0,591202525,130,165355,475832389,ARL
2025-07-17T19:47:59.502553909Z,2025-07-17T19:47:59.502388144Z,160,2,1108,A,A,13.380000000,100,0,593713349,130,165765,475832391,ARL
2025-07-17T19:47:59.505316160Z,2025-07-17T19:47:59.505150761Z,160,2,1108,A,A,13.110000000,100,0,593713625,130,165399,475832604,ARL
2025-07-17T19:47:59.508244835Z,2025-07-17T19:47:59.508079541Z,160,2,1108,C,A,16.460000000,100,0,591202445,0,165294,475832711,ARL
2025-07-17T19:47:59.508244835Z,2025-07-17T19:47:59.508079541Z,160,2,1108,A,A,16.650000000,100,0,593713853,130,165294,475832711,ARL
2025-07-17T19:47:59.512496442Z,2025-07-17T19:47:59.512330890Z,160,2,1108,C,A,14.910000000,100,0,591202405,0,165552,475832795,ARL
2025-07-17T19:47:59.512496442Z,2025-07-17T19:47:59.512330890Z,160,2,1108,A,A,15.080000000,100,0,593714177,130,165552,475832795,ARL
2025-07-17T19:47:59.548510827Z,2025-07-17T19:47:59.548345490Z,160,2,1108,C,A,14.020000000,100,0,593712945,0,165337,475834979,ARL
2025-07-17T19:47:59.548510827Z,2025-07-17T19:47:59.548345490Z,160,2,1108,A,A,14.140000000,100,0,593716653,130,165337,475834979,ARL
2025-07-17T19:47:59.550945996Z,2025-07-17T19:47:59.550780795Z,160,2,1108,C,A,13.720000000,100,0,591203377,130,165201,475835018,ARL
2025-07-17T19:47:59.551051876Z,2025-07-17T19:47:59.550886681Z,160,2,1108,A,A,13.870000000,100,0,593716733,130,165195,475835020,ARL
2025-07-17T19:47:59.563396482Z,2025-07-17T19:47:59.563230864Z,160,2,1108,C,A,13.870000000,100,0,591202837,0,165618,475835362,ARL
2025-07-17T19:47:59.563396482Z,2025-07-17T19:47:59.563230864Z,160,2,1108,A,A,14.030000000,100,0,593717405,130,165618,475835362,ARL
2025-07-17T19:48:00.580791047Z,2025-07-17T19:48:00.580625421Z,160,2,1108,C,B,11.760000000,100,0,593713033,0,165626,475874768,ARL
2025-07-17T19:48:00.580791047Z,2025-07-17T19:48:00.580625421Z,160,2,1108,A,B,11.600000000,100,0,593785005,130,165626,475874768,ARL
2025-07-17T19:48:00.581558450Z,2025-07-17T19:48:00.581393098Z,160,2,1108,C,B,11.760000000,100,0,593712965,0,165352,475874784,ARL
2025-07-17T19:48:00.581558450Z,2025-07-17T19:48:00.581393098Z,160,2,1108,A,B,11.600000000,100,0,593785037,130,165352,475874784,ARL
2025-07-17T19:48:31.385992709Z,2025-07-17T19:48:31.385827035Z,160,2,1108,C,B,12.310000000,2,0,586704165,0,165674,476597995,ARL
2025-07-17T19:48:31.385992709Z,2025-07-17T19:48:31.385827035Z,160,2,1108,A,B,12.380000000,2,0,595050509,130,165674,476597995,ARL
2025-07-17T19:49:09.741413096Z,2025-07-17T19:49:09.741246975Z,160,2,1108,C,B,11.600000000,100,0,593785005,0,166121,477426282,ARL
2025-07-17T19:49:09.741413096Z,2025-07-17T19:49:09.741246975Z,160,2,1108,A,B,11.760000000,100,0,596570517,130,166121,477426282,ARL
2025-07-17T19:49:09.769937557Z,2025-07-17T19:49:09.769772064Z,160,2,1108,C,B,11.600000000,100,0,593785037,0,165493,477426983,ARL
2025-07-17T19:49:09.769937557Z,2025-07-17T19:49:09.769772064Z,160,2,1108,A,B,11.760000000,100,0,596571797,130,165493,477426983,ARL
2025-07-17T19:49:13.496960906Z,2025-07-17T19:49:13.496795363Z,160,2,1108,C,B,11.760000000,100,0,596570517,0,165543,477518807,ARL
2025-07-17T19:49:13.496960906Z,2025-07-17T19:49:13.496795363Z,160,2,1108,A,B,11.600000000,100,0,596735461,130,165543,477518807,ARL
2025-07-17T19:49:13.497323943Z,2025-07-17T19:49:13.497158448Z,160,2,1108,C,B,11.760000000,100,0,596571797,0,165495,477518814,ARL
2025-07-17T19:49:13.497323943Z,2025-07-17T19:49:13.497158448Z,160,2,1108,A,B,11.600000000,100,0,596735469,130,165495,477518814,ARL
2025-07-17T19:49:27.188301652Z,2025-07-17T19:49:27.188136127Z,160,2,1108,C,A,13.100000000,2,0,586482137,0,165525,477840569,ARL
2025-07-17T19:49:27.188301652Z,2025-07-17T19:49:27.188136127Z,160,2,1108,A,A,13.190000000,2,0,597302181,130,165525,477840569,ARL
2025-07-17T19:49:35.503074664Z,2025-07-17T19:49:35.502908780Z,160,2,1108,C,B,11.600000000,100,0,596735461,0,165884,478055433,ARL
2025-07-17T19:49:35.503074664Z,2025-07-17T19:49:35.502908780Z,160,2,1108,A,B,11.760000000,100,0,597661841,130,165884,478055433,ARL
2025-07-17T19:49:35.503075594Z,2025-07-17T19:49:35.502910124Z,160,2,1108,C,B,11.600000000,100,0,596735469,0,165470,478055434,ARL
2025-07-17T19:49:35.503075594Z,2025-07-17T19:49:35.502910124Z,160,2,1108,A,B,11.760000000,100,0,597661845,130,165470,478055434,ARL
2025-07-17T19:49:43.199322720Z,2025-07-17T19:49:43.199155701Z,160,2,1108,C,B,11.760000000,100,0,597661845,0,167019,478280955,ARL
2025-07-17T19:49:43.199322720Z,2025-07-17T19:49:43.199155701Z,160,2,1108,A,B,11.600000000,100,0,598007121,128,167019,478280955,ARL
2025-07-17T19:49:43.199404609Z,2025-07-17T19:49:43.199238646Z,160,2,1108,C,B,11.760000000,100,0,597661841,0,165963,478280969,ARL
2025-07-17T19:49:43.199404609Z,2025-07-17T19:49:43.199238646Z,160,2,1108,A,B,11.600000000,100,0,598007125,130,165963,478280969,ARL
2025-07-17T19:54:12.915124171Z,2025-07-17T19:54:12.914958243Z,160,2,1108,C,B,11.600000000,100,0,598007125,0,165928,489224310,ARL
2025-07-17T19:54:12.915124171Z,2025-07-17T19:54:12.914958243Z,160,2,1108,A,B,11.760000000,100,0,612972365,130,165928,489224310,ARL
2025-07-17T19:54:12.919488390Z,2025-07-17T19:54:12.919323017Z,160,2,1108,C,B,11.600000000,100,0,598007121,0,165373,489224652,ARL
2025-07-17T19:54:12.919488390Z,2025-07-17T19:54:12.919323017Z,160,2,1108,A,B,11.760000000,100,0,612972993,130,165373,489224652,ARL
2025-07-17T19:54:14.056944002Z,2025-07-17T19:54:14.056776996Z,160,2,1108,C,B,11.760000000,100,0,612972993,0,167006,489267193,ARL
2025-07-17T19:54:14.056944002Z,2025-07-17T19:54:14.056776996Z,160,2,1108,A,B,11.600000000,100,0,613029677,130,167006,489267193,ARL
2025-07-17T19:54:14.057448278Z,2025-07-17T19:54:14.057282694Z,160,2,1108,C,B,11.760000000,100,0,612972365,0,165584,489267217,ARL
2025-07-17T19:54:14.057448278Z,2025-07-17T19:54:14.057282694Z,160,2,1108,A,B,11.600000000,100,0,613029693,130,165584,489267217,ARL
2025-07-17T19:54:23.593969113Z,2025-07-17T19:54:23.593803645Z,160,2,1108,C,B,11.600000000,100,0,613029693,0,165468,489633620,ARL
2025-07-17T19:54:23.593969113Z,2025-07-17T19:54:23.593803645Z,160,2,1108,A,B,11.760000000,100,0,613607213,130,165468,489633620,ARL
2025-07-17T19:54:23.594313778Z,2025-07-17T19:54:23.594148215Z,160,2,1108,C,B,11.600000000,100,0,613029677,0,165563,489633625,ARL
2025-07-17T19:54:23.594313778Z,2025-07-17T19:54:23.594148215Z,160,2,1108,A,B,11.760000000,100,0,613607261,130,165563,489633625,ARL
2025-07-17T19:54:24.596972479Z,2025-07-17T19:54:24.596806913Z,160,2,1108,C,B,11.760000000,100,0,613607213,0,165566,489670419,ARL
2025-07-17T19:54:24.596972479Z,2025-07-17T19:54:24.596806913Z,160,2,1108,A,B,11.600000000,100,0,613658345,130,165566,489670419,ARL
2025-07-17T19:54:24.604435763Z,2025-07-17T19:54:24.604270260Z,160,2,1108,C,B,11.760000000,100,0,613607261,0,165503,489670744,ARL
2025-07-17T19:54:24.604435763Z,2025-07-17T19:54:24.604270260Z,160,2,1108,A,B,11.600000000,100,0,613658605,130,165503,489670744,ARL
2025-07-17T19:54:37.606825094Z,2025-07-17T19:54:37.606659629Z,160,2,1108,C,B,11.600000000,100,0,613658605,0,165465,490141024,ARL
2025-07-17T19:54:37.606825094Z,2025-07-17T19:54:37.606659629Z,160,2,1108,A,B,11.430000000,100,0,614408777,130,165465,490141024,ARL
2025-07-17T19:54:37.607484550Z,2025-07-17T19:54:37.607318901Z,160,2,1108,C,B,11.600000000,100,0,613658345,0,165649,490141029,ARL
2025-07-17T19:54:37.607484550Z,2025-07-17T19:54:37.607318901Z,160,2,1108,A,B,11.430000000,100,0,614408789,130,165649,490141029,ARL
2025-07-17T19:55:57.644432455Z,2025-07-17T19:55:57.644266461Z,160,2,1108,T,N,12.795000000,14,0,0,130,165994,496158194,ARL
2025-07-17T19:55:57.644594983Z,2025-07-17T19:55:57.644429856Z,160,2,1108,C,A,13.530000000,100,0,584891017,130,165127,496158204,ARL
2025-07-17T19:55:57.644599078Z,2025-07-17T19:55:57.644433652Z,160,2,1108,C,A,14.140000000,100,0,593716653,0,165426,496158205,ARL
2025-07-17T19:55:57.644599078Z,2025-07-17T19:55:57.644433652Z,160,2,1108,A,A,13.690000000,100,0,621057185,130,165426,496158205,ARL
2025-07-17T19:55:57.644973734Z,2025-07-17T19:55:57.644808599Z,160,2,1108,A,A,13.270000000,100,0,621057205,130,165135,496158232,ARL
2025-07-17T19:55:57.645208786Z,2025-07-17T19:55:57.645042265Z,160,2,1108,C,A,14.040000000,100,0,593713165,0,166521,496158261,ARL
2025-07-17T19:55:57.645208786Z,2025-07-17T19:55:57.645042265Z,160,2,1108,A,A,13.590000000,100,0,621057221,130,166521,496158261,ARL
2025-07-17T19:55:57.645462765Z,2025-07-17T19:55:57.645297277Z,160,2,1108,C,A,14.250000000,100,0,584891105,0,165488,496158274,ARL
2025-07-17T19:55:57.645462765Z,2025-07-17T19:55:57.645297277Z,160,2,1108,A,A,13.970000000,100,0,621057233,130,165488,496158274,ARL
2025-07-17T19:55:57.645572422Z,2025-07-17T19:55:57.645406944Z,160,2,1108,C,A,13.970000000,100,0,593713041,0,165478,496158277,ARL
2025-07-17T19:55:57.645572422Z,2025-07-17T19:55:57.645406944Z,160,2,1108,A,A,13.560000000,100,0,621057237,130,165478,496158277,ARL
2025-07-17T19:55:57.646712740Z,2025-07-17T19:55:57.646547439Z,160,2,1108,C,A,13.970000000,100,0,593712989,0,165301,496158325,ARL
2025-07-17T19:55:57.646712740Z,2025-07-17T19:55:57.646547439Z,160,2,1108,A,A,13.560000000,100,0,621057277,130,165301,496158325,ARL
2025-07-17T19:55:57.647781829Z,2025-07-17T19:55:57.647616439Z,160,2,1108,C,A,16.650000000,100,0,593713853,0,165390,496158363,ARL
2025-07-17T19:55:57.647781829Z,2025-07-17T19:55:57.647616439Z,160,2,1108,A,A,16.130000000,100,0,621057285,130,165390,496158363,ARL
2025-07-17T19:55:57.650577430Z,2025-07-17T19:55:57.650412038Z,160,2,1108,C,A,13.380000000,100,0,593713349,130,165392,496158522,ARL
2025-07-17T19:55:57.650629006Z,2025-07-17T19:55:57.650463556Z,160,2,1108,A,A,12.950000000,100,0,621057465,130,165450,496158525,ARL
2025-07-17T19:55:57.661036344Z,2025-07-17T19:55:57.660870778Z,160,2,1108,C,A,15.080000000,100,0,593714177,0,165566,496159192,ARL
2025-07-17T19:55:57.661036344Z,2025-07-17T19:55:57.660870778Z,160,2,1108,A,A,14.610000000,100,0,621058509,130,165566,496159192,ARL
2025-07-17T19:55:57.686324905Z,2025-07-17T19:55:57.686159670Z,160,2,1108,A,A,14.480000000,100,0,621059209,130,165235,496159717,ARL
2025-07-17T19:55:57.686339166Z,2025-07-17T19:55:57.686173960Z,160,2,1108,C,A,14.770000000,100,0,584890977,130,165206,496159722,ARL
2025-07-17T19:55:57.779036085Z,2025-07-17T19:55:57.778870707Z,160,2,1108,C,A,14.250000000,100,0,584891401,0,165378,496161694,ARL
2025-07-17T19:55:57.779036085Z,2025-07-17T19:55:57.778870707Z,160,2,1108,A,A,13.970000000,100,0,621063265,130,165378,496161694,ARL
2025-07-17T19:55:57.811636757Z,2025-07-17T19:55:57.811471411Z,160,2,1108,C,A,14.030000000,100,0,593717405,0,165346,496162532,ARL
2025-07-17T19:55:57.811636757Z,2025-07-17T19:55:57.811471411Z,160,2,1108,A,A,13.590000000,100,0,621064777,130,165346,496162532,ARL
2025-07-17T19:55:57.845732928Z,2025-07-17T19:55:57.845567439Z,160,2,1108,C,A,13.870000000,100,0,593716733,0,165489,496163260,ARL
2025-07-17T19:55:57.845732928Z,2025-07-17T19:55:57.845567439Z,160,2,1108,A,A,13.460000000,100,0,621066397,130,165489,496163260,ARL
2025-07-17T19:55:58.026826908Z,2025-07-17T19:55:58.026661698Z,160,2,1108,A,A,13.460000000,100,0,621075997,130,165210,496173267,ARL
2025-07-17T19:55:58.026874410Z,2025-07-17T19:55:58.026704665Z,160,2,1108,C,A,13.810000000,100,0,586489245,128,169745,496173283,ARL
2025-07-17T19:55:58.389584944Z,2025-07-17T19:55:58.389418752Z,160,2,1108,C,B,12.380000000,2,0,595050509,0,166192,496193655,ARL
2025-07-17T19:55:58.389584944Z,2025-07-17T19:55:58.389418752Z,160,2,1108,A,B,12.300000000,2,0,621093733,130,166192,496193655,ARL
2025-07-17T19:55:58.482152682Z,2025-07-17T19:55:58.481987426Z,160,2,1108,A,A,13.210000000,100,0,621099429,130,165256,496197106,ARL
2025-07-17T19:55:58.482153700Z,2025-07-17T19:55:58.481988407Z,160,2,1108,C,A,13.470000000,100,0,584905345,130,165293,496197107,ARL
2025-07-17T19:55:58.487990838Z,2025-07-17T19:55:58.487825694Z,160,2,1108,A,B,12.480000000,71,0,621099613,130,165144,496197202,ARL
2025-07-17T19:55:58.488715433Z,2025-07-17T19:55:58.488549937Z,160,2,1108,C,B,11.430000000,100,0,614408789,0,165496,496197213,ARL
2025-07-17T19:55:58.488715433Z,2025-07-17T19:55:58.488549937Z,160,2,1108,A,B,11.630000000,100,0,621099641,130,165496,496197213,ARL
2025-07-17T19:55:58.488999325Z,2025-07-17T19:55:58.488834036Z,160,2,1108,C,B,11.430000000,100,0,614408777,0,165289,496197217,ARL
2025-07-17T19:55:58.488999325Z,2025-07-17T19:55:58.488834036Z,160,2,1108,A,B,11.630000000,100,0,621099645,130,165289,496197217,ARL
2025-07-17T19:55:58.933082244Z,2025-07-17T19:55:58.932916725Z,160,2,1108,C,A,13.110000000,100,0,593713625,0,165519,496208167,ARL
2025-07-17T19:55:58.933082244Z,2025-07-17T19:55:58.932916725Z,160,2,1108,A,A,12.960000000,100,0,621115469,130,165519,496208167,ARL
2025-07-17T19:56:00.823121949Z,2025-07-17T19:56:00.822955209Z,160,2,1108,T,N,12.610000000,100,0,0,130,166740,496339617,ARL
2025-07-17T19:56:00.823287691Z,2025-07-17T19:56:00.823119090Z,160,2,1108,C,A,13.560000000,100,0,621057277,0,168601,496339713,ARL
2025-07-17T19:56:00.823287691Z,2025-07-17T19:56:00.823119090Z,160,2,1108,A,A,13.460000000,100,0,621242257,128,168601,496339713,ARL
2025-07-17T19:56:00.823809697Z,2025-07-17T19:56:00.823641294Z,160,2,1108,C,A,13.690000000,100,0,621057185,0,168403,496340010,ARL
2025-07-17T19:56:00.823809697Z,2025-07-17T19:56:00.823641294Z,160,2,1108,A,A,13.590000000,100,0,621242545,128,168403,496340010,ARL
2025-07-17T19:56:00.824282314Z,2025-07-17T19:56:00.824104052Z,160,2,1108,C,A,13.560000000,100,0,621057237,0,178262,496340365,ARL
2025-07-17T19:56:00.824282314Z,2025-07-17T19:56:00.824104052Z,160,2,1108,A,A,13.460000000,100,0,621242953,128,178262,496340365,ARL
2025-07-17T19:56:00.842670141Z,2025-07-17T19:56:00.842504854Z,160,2,1108,C,A,12.950000000,100,0,621057465,130,165287,496343529,ARL
2025-07-17T19:56:00.842725999Z,2025-07-17T19:56:00.842560775Z,160,2,1108,A,A,12.860000000,100,0,621248357,130,165224,496343531,ARL
2025-07-17T19:56:00.853786095Z,2025-07-17T19:56:00.853621062Z,160,2,1108,C,A,12.860000000,100,0,621248357,130,165033,496344599,ARL
2025-07-17T19:56:00.853835335Z,2025-07-17T19:56:00.853670111Z,160,2,1108,A,A,12.950000000,100,0,621249105,130,165224,496344600,ARL
2025-07-17T19:56:00.875204227Z,2025-07-17T19:56:00.875035723Z,160,2,1108,C,A,13.590000000,100,0,621242545,0,168504,496350729,ARL
2025-07-17T19:56:00.875204227Z,2025-07-17T19:56:00.875035723Z,160,2,1108,A,A,13.690000000,100,0,621254469,130,168504,496350729,ARL
2025-07-17T19:56:09.191094783Z,2025-07-17T19:56:09.190929073Z,160,2,1108,C,A,13.190000000,2,0,597302181,0,165710,496927134,ARL
2025-07-17T19:56:09.191094783Z,2025-07-17T19:56:09.190929073Z,160,2,1108,A,A,13.110000000,2,0,621837137,130,165710,496927134,ARL
2025-07-17T19:56:14.393765687Z,2025-07-17T19:56:14.393599613Z,160,2,1108,C,A,13.690000000,100,0,621254469,0,166074,497250076,ARL
2025-07-17T19:56:14.393765687Z,2025-07-17T19:56:14.393599613Z,160,2,1108,A,A,13.590000000,100,0,622176709,130,166074,497250076,ARL
2025-07-17T19:56:14.398799492Z,2025-07-17T19:56:14.398634103Z,160,2,1108,C,A,12.950000000,100,0,621249105,130,165389,497250639,ARL
2025-07-17T19:56:14.398850485Z,2025-07-17T19:56:14.398685273Z,160,2,1108,A,A,12.860000000,100,0,622177121,130,165212,497250640,ARL
2025-07-17T19:56:14.399680955Z,2025-07-17T19:56:14.399515970Z,160,2,1108,C,A,12.860000000,100,0,622177121,130,164985,497250678,ARL
2025-07-17T19:56:14.399731172Z,2025-07-17T19:56:14.399565998Z,160,2,1108,A,A,12.950000000,100,0,622177249,130,165174,497250681,ARL
2025-07-17T19:56:14.444198928Z,2025-07-17T19:56:14.444033617Z,160,2,1108,C,A,13.590000000,100,0,622176709,0,165311,497253059,ARL
2025-07-17T19:56:14.444198928Z,2025-07-17T19:56:14.444033617Z,160,2,1108,A,A,13.690000000,100,0,622180433,130,165311,497253059,ARL
2025-07-17T19:56:22.824764413Z,2025-07-17T19:56:22.824599042Z,160,2,1108,C,A,13.460000000,100,0,621242953,0,165371,497643841,ARL
2025-07-17T19:56:22.824764413Z,2025-07-17T19:56:22.824599042Z,160,2,1108,A,A,13.560000000,100,0,622602541,130,165371,497643841,ARL
2025-07-17T19:56:22.825767308Z,2025-07-17T19:56:22.825600862Z,160,2,1108,C,A,13.460000000,100,0,621242257,0,166446,497643962,ARL
2025-07-17T19:56:22.825767308Z,2025-07-17T19:56:22.825600862Z,160,2,1108,A,A,13.560000000,100,0,622602553,128,166446,497643962,ARL
2025-07-17T19:56:24.393144680Z,2025-07-17T19:56:24.392979011Z,160,2,1108,C,A,13.690000000,100,0,622180433,0,165669,497750003,ARL
2025-07-17T19:56:24.393144680Z,2025-07-17T19:56:24.392979011Z,160,2,1108,A,A,13.590000000,100,0,622715221,130,165669,497750003,ARL
2025-07-17T19:56:24.398262257Z,2025-07-17T19:56:24.398097144Z,160,2,1108,C,A,12.950000000,100,0,622177249,130,165113,497750207,ARL
2025-07-17T19:56:24.398315506Z,2025-07-17T19:56:24.398150345Z,160,2,1108,A,A,12.860000000,100,0,622715565,130,165161,497750214,ARL
2025-07-17T19:56:24.399143627Z,2025-07-17T19:56:24.398978675Z,160,2,1108,C,A,12.860000000,100,0,622715565,130,164952,497750239,ARL
2025-07-17T19:56:24.399190838Z,2025-07-17T19:56:24.399025467Z,160,2,1108,A,A,12.950000000,100,0,622715585,130,165371,497750241,ARL
2025-07-17T19:56:24.443549830Z,2025-07-17T19:56:24.443384651Z,160,2,1108,C,A,13.590000000,100,0,622715221,0,165179,497751765,ARL
2025-07-17T19:56:24.443549830Z,2025-07-17T19:56:24.443384651Z,160,2,1108,A,A,13.690000000,100,0,622719429,130,165179,497751765,ARL
2025-07-17T19:56:28.986186504Z,2025-07-17T19:56:28.986020828Z,160,2,1108,C,A,13.110000000,2,0,621837137,0,165676,498010483,ARL
2025-07-17T19:56:28.986186504Z,2025-07-17T19:56:28.986020828Z,160,2,1108,A,A,13.040000000,2,0,622997593,130,165676,498010483,ARL
2025-07-17T19:56:34.393155264Z,2025-07-17T19:56:34.392989696Z,160,2,1108,C,A,13.690000000,100,0,622719429,0,165568,498321802,ARL
2025-07-17T19:56:34.393155264Z,2025-07-17T19:56:34.392989696Z,160,2,1108,A,A,13.590000000,100,0,623300433,130,165568,498321802,ARL
2025-07-17T19:56:34.402528273Z,2025-07-17T19:56:34.402362577Z,160,2,1108,C,A,12.950000000,100,0,622715585,130,165696,498322069,ARL
2025-07-17T19:56:34.402577680Z,2025-07-17T19:56:34.402412428Z,160,2,1108,A,A,12.860000000,100,0,623300921,130,165252,498322071,ARL
2025-07-17T19:56:34.403402935Z,2025-07-17T19:56:34.403237959Z,160,2,1108,C,A,12.860000000,100,0,623300921,130,164976,498322086,ARL
2025-07-17T19:56:34.403449370Z,2025-07-17T19:56:34.403284345Z,160,2,1108,A,A,12.950000000,100,0,623301001,130,165025,498322087,ARL
2025-07-17T19:56:34.443580514Z,2025-07-17T19:56:34.443415386Z,160,2,1108,C,A,13.590000000,100,0,623300433,0,165128,498323689,ARL
2025-07-17T19:56:34.443580514Z,2025-07-17T19:56:34.443415386Z,160,2,1108,A,A,13.690000000,100,0,623302369,130,165128,498323689,ARL
2025-07-17T19:56:44.393190712Z,2025-07-17T19:56:44.393025365Z,160,2,1108,C,A,13.690000000,100,0,623302369,0,165347,498861771,ARL
2025-07-17T19:56:44.393190712Z,2025-07-17T19:56:44.393025365Z,160,2,1108,A,A,13.590000000,100,0,623848301,130,165347,498861771,ARL
2025-07-17T19:56:44.396466193Z,2025-07-17T19:56:44.396301009Z,160,2,1108,C,A,12.950000000,100,0,623301001,130,165184,498861939,ARL
2025-07-17T19:56:44.396521143Z,2025-07-17T19:56:44.396355734Z,160,2,1108,A,A,12.860000000,100,0,623848497,130,165409,498861941,ARL
2025-07-17T19:56:44.397349245Z,2025-07-17T19:56:44.397183394Z,160,2,1108,C,A,12.860000000,100,0,623848497,130,165851,498862045,ARL
2025-07-17T19:56:44.397402131Z,2025-07-17T19:56:44.397236789Z,160,2,1108,A,A,12.950000000,100,0,623848565,130,165342,498862050,ARL
2025-07-17T19:56:44.443579051Z,2025-07-17T19:56:44.443413997Z,160,2,1108,C,A,13.590000000,100,0,623848301,0,165054,498863939,ARL
2025-07-17T19:56:44.443579051Z,2025-07-17T19:56:44.443413997Z,160,2,1108,A,A,13.690000000,100,0,623851933,130,165054,498863939,ARL
2025-07-17T19:57:07.533354082Z,2025-07-17T19:57:07.533188590Z,160,2,1108,C,A,13.690000000,100,0,623851933,0,165492,500323175,ARL
2025-07-17T19:57:07.533354082Z,2025-07-17T19:57:07.533188590Z,160,2,1108,A,A,13.590000000,100,0,625331997,130,165492,500323175,ARL
2025-07-17T19:57:07.533965170Z,2025-07-17T19:57:07.533799849Z,160,2,1108,C,A,13.560000000,100,0,622602541,0,165321,500323368,ARL
2025-07-17T19:57:07.533965170Z,2025-07-17T19:57:07.533799849Z,160,2,1108,A,A,13.460000000,100,0,625332197,130,165321,500323368,ARL
2025-07-17T19:57:07.534073344Z,2025-07-17T19:57:07.533907909Z,160,2,1108,C,A,13.560000000,100,0,622602553,0,165435,500323380,ARL
2025-07-17T19:57:07.534073344Z,2025-07-17T19:57:07.533907909Z,160,2,1108,A,A,13.460000000,100,0,625332217,130,165435,500323380,ARL
2025-07-17T19:57:07.541685366Z,2025-07-17T19:57:07.541520132Z,160,2,1108,C,A,12.950000000,100,0,623848565,130,165234,500324890,ARL
2025-07-17T19:57:07.541734147Z,2025-07-17T19:57:07.541568893Z,160,2,1108,A,A,12.860000000,100,0,625333701,130,165254,500324895,ARL
2025-07-17T19:57:07.548107028Z,2025-07-17T19:57:07.547941925Z,160,2,1108,C,A,12.860000000,100,0,625333701,130,165103,500325274,ARL
2025-07-17T19:57:07.548155641Z,2025-07-17T19:57:07.547990482Z,160,2,1108,A,A,12.950000000,100,0,625334061,130,165159,500325276,ARL
2025-07-17T19:57:07.583931795Z,2025-07-17T19:57:07.583766514Z,160,2,1108,C,A,13.590000000,100,0,625331997,0,165281,500327600,ARL
2025-07-17T19:57:07.583931795Z,2025-07-17T19:57:07.583766514Z,160,2,1108,A,A,13.690000000,100,0,625336977,130,165281,500327600,ARL
2025-07-17T19:57:26.246582693Z,2025-07-17T19:57:26.246417429Z,160,2,1108,A,B,12.480000000,45,0,626523677,130,165264,501474830,ARL
2025-07-17T19:57:26.246583602Z,2025-07-17T19:57:26.246418448Z,160,2,1108,A,A,12.700000000,40,0,626523681,130,165154,501474831,ARL
2025-07-17T19:57:33.787356102Z,2025-07-17T19:57:33.787190653Z,160,2,1108,C,A,13.040000000,2,0,622997593,0,165449,501965414,ARL
2025-07-17T19:57:33.787356102Z,2025-07-17T19:57:33.787190653Z,160,2,1108,A,A,12.970000000,2,0,627078489,130,165449,501965414,ARL
2025-07-17T19:57:41.015578234Z,2025-07-17T19:57:41.015412783Z,160,2,1108,C,B,12.480000000,45,0,626523677,130,165451,502513502,ARL
2025-07-17T19:57:42.171646852Z,2025-07-17T19:57:42.171481732Z,160,2,1108,C,A,12.700000000,40,0,626523681,130,165120,502583147,ARL
2025-07-17T19:57:43.489496564Z,2025-07-17T19:57:43.489330673Z,160,2,1108,A,A,12.700000000,40,0,627886757,130,165891,502655820,ARL
2025-07-17T19:57:44.175326244Z,2025-07-17T19:57:44.175160587Z,160,2,1108,C,A,13.460000000,100,0,625332197,0,165657,502698200,ARL
2025-07-17T19:57:44.175326244Z,2025-07-17T19:57:44.175160587Z,160,2,1108,A,A,13.560000000,100,0,627933429,130,165657,502698200,ARL
2025-07-17T19:57:44.175640259Z,2025-07-17T19:57:44.175474787Z,160,2,1108,C,A,13.460000000,100,0,625332217,0,165472,502698216,ARL
2025-07-17T19:57:44.175640259Z,2025-07-17T19:57:44.175474787Z,160,2,1108,A,A,13.560000000,100,0,627933441,130,165472,502698216,ARL
2025-07-17T19:57:47.227751269Z,2025-07-17T19:57:47.227586157Z,160,2,1108,C,A,12.700000000,40,0,627886757,130,165112,502891976,ARL
2025-07-17T19:58:01.025839177Z,2025-07-17T19:58:01.025672411Z,160,2,1108,A,A,12.700000000,40,0,629223841,128,166766,503818190,ARL
2025-07-17T19:58:01.775253863Z,2025-07-17T19:58:01.775088734Z,160,2,1108,C,A,12.700000000,40,0,629223841,130,165129,503894802,ARL
2025-07-17T19:59:59.795012229Z,2025-07-17T19:59:59.794844333Z,160,2,1108,C,B,12.480000000,71,0,621099613,130,167896,515342968,ARL
2025-07-17T20:00:00.028080732Z,2025-07-17T20:00:00.027898140Z,160,2,1108,C,B,9.550000000,100,0,43314173,0,182592,515433487,ARL
2025-07-17T20:00:00.028080732Z,2025-07-17T20:00:00.027898550Z,160,2,1108,C,A,16.250000000,100,0,582827061,128,182182,515433488,ARL
2025-07-17T20:00:00.041258508Z,2025-07-17T20:00:00.041073936Z,160,2,1108,C,A,12.950000000,100,0,625334061,128,184572,515441924,ARL
2025-07-17T20:00:00.050279680Z,2025-07-17T20:00:00.050103263Z,160,2,1108,C,B,11.510000000,100,0,387225161,0,176417,515447954,ARL
2025-07-17T20:00:00.050279680Z,2025-07-17T20:00:00.050103263Z,160,2,1108,A,B,11.280000000,100,0,641851049,128,176417,515447954,ARL
2025-07-17T20:00:00.050457564Z,2025-07-17T20:00:00.050279197Z,160,2,1108,C,A,13.690000000,100,0,625336977,0,178367,515448063,ARL
2025-07-17T20:00:00.050457564Z,2025-07-17T20:00:00.050279197Z,160,2,1108,A,A,13.960000000,100,0,641851221,128,178367,515448063,ARL
2025-07-17T20:00:00.065475000Z,2025-07-17T20:00:00.065295807Z,160,2,1108,A,A,14.770000000,100,0,641863189,128,179193,515461512,ARL
2025-07-17T20:00:00.065556529Z,2025-07-17T20:00:00.065375272Z,160,2,1108,C,A,14.480000000,100,0,621059209,128,181257,515461601,ARL
2025-07-17T20:00:00.067747887Z,2025-07-17T20:00:00.067565677Z,160,2,1108,C,B,12.300000000,2,0,621093733,0,182210,515464299,ARL
2025-07-17T20:00:00.067747887Z,2025-07-17T20:00:00.067565953Z,160,2,1108,C,A,12.960000000,100,0,621115469,128,181934,515464300,ARL
2025-07-17T20:00:00.078274112Z,2025-07-17T20:00:00.078096089Z,160,2,1108,C,B,12.230000000,100,0,387224537,128,178023,515480381,ARL
2025-07-17T20:00:00.087977100Z,2025-07-17T20:00:00.087793542Z,160,2,1108,C,B,12.220000000,100,0,387224049,0,183558,515496392,ARL
2025-07-17T20:00:00.087977100Z,2025-07-17T20:00:00.087793760Z,160,2,1108,C,A,12.970000000,2,0,627078489,128,183340,515496393,ARL
2025-07-17T20:00:00.094364139Z,2025-07-17T20:00:00.094182218Z,160,2,1108,A,A,15.060000000,100,0,641887245,128,181921,515506872,ARL
2025-07-17T20:00:00.094399531Z,2025-07-17T20:00:00.094218024Z,160,2,1108,C,A,14.770000000,100,0,641863189,128,181507,515506933,ARL
2025-07-17T20:00:00.099416407Z,2025-07-17T20:00:00.099239600Z,160,2,1108,C,A,16.250000000,100,0,582827033,0,176807,515515108,ARL
2025-07-17T20:00:00.099416407Z,2025-07-17T20:00:00.099240114Z,160,2,1108,C,B,9.550000000,100,0,43314145,0,176293,515515109,ARL
2025-07-17T20:00:00.099416407Z,2025-07-17T20:00:00.099240658Z,160,2,1108,C,A,16.250000000,100,0,582827037,128,175749,515515110,ARL
2025-07-17T20:00:00.099426969Z,2025-07-17T20:00:00.099244603Z,160,2,1108,C,B,9.550000000,100,0,43314149,0,182366,515515116,ARL
2025-07-17T20:00:00.099426969Z,2025-07-17T20:00:00.099245074Z,160,2,1108,C,A,16.250000000,100,0,582827041,0,181895,515515117,ARL
2025-07-17T20:00:00.099426969Z,2025-07-17T20:00:00.099245679Z,160,2,1108,C,B,9.550000000,100,0,43314153,0,181290,515515118,ARL
2025-07-17T20:00:00.099426969Z,2025-07-17T20:00:00.099246205Z,160,2,1108,C,B,9.550000000,100,0,43690797,0,180764,515515119,ARL
2025-07-17T20:00:00.099426969Z,2025-07-17T20:00:00.099246722Z,160,2,1108,C,A,16.250000000,100,0,582827065,0,180247,515515120,ARL
2025-07-17T20:00:00.099426969Z,2025-07-17T20:00:00.099247261Z,160,2,1108,C,B,9.550000000,100,0,43314157,0,179708,515515121,ARL
2025-07-17T20:00:00.099426969Z,2025-07-17T20:00:00.099247927Z,160,2,1108,C,A,16.250000000,100,0,582827045,0,179042,515515122,ARL
2025-07-17T20:00:00.099426969Z,2025-07-17T20:00:00.099248441Z,160,2,1108,C,B,9.550000000,100,0,43314161,0,178528,515515123,ARL
2025-07-17T20:00:00.099426969Z,2025-07-17T20:00:00.099249077Z,160,2,1108,C,A,16.250000000,100,0,582827049,128,177892,515515124,ARL
2025-07-17T20:00:00.099441972Z,2025-07-17T20:00:00.099259306Z,160,2,1108,C,B,9.550000000,100,0,43314165,0,182666,515515147,ARL
2025-07-17T20:00:00.099441972Z,2025-07-17T20:00:00.099260004Z,160,2,1108,C,A,16.250000000,100,0,582827053,0,181968,515515148,ARL
2025-07-17T20:00:00.099441972Z,2025-07-17T20:00:00.099260610Z,160,2,1108,C,A,16.250000000,100,0,582827069,0,181362,515515149,ARL
2025-07-17T20:00:00.099441972Z,2025-07-17T20:00:00.099261280Z,160,2,1108,C,B,9.550000000,100,0,43690801,0,180692,515515150,ARL
2025-07-17T20:00:00.099441972Z,2025-07-17T20:00:00.099261941Z,160,2,1108,C,B,9.550000000,100,0,43690805,130,180031,515515151,ARL
2025-07-17T20:00:00.099443346Z,2025-07-17T20:00:00.099262493Z,160,2,1108,C,A,16.250000000,100,0,582827073,0,180853,515515152,ARL
2025-07-17T20:00:00.099443346Z,2025-07-17T20:00:00.099264792Z,160,2,1108,C,B,9.550000000,100,0,43690809,0,178554,515515154,ARL
2025-07-17T20:00:00.099443346Z,2025-07-17T20:00:00.099265257Z,160,2,1108,C,A,16.250000000,100,0,582827077,130,178089,515515155,ARL
2025-07-17T20:00:00.099449114Z,2025-07-17T20:00:00.099266337Z,160,2,1108,C,A,16.250000000,100,0,582827081,0,182777,515515156,ARL
2025-07-17T20:00:00.099449114Z,2025-07-17T20:00:00.099266848Z,160,2,1108,C,B,9.550000000,100,0,43690813,0,182266,515515157,ARL
2025-07-17T20:00:00.099449114Z,2025-07-17T20:00:00.099267334Z,160,2,1108,C,B,9.550000000,100,0,43690817,0,181780,515515158,ARL
2025-07-17T20:00:00.099449114Z,2025-07-17T20:00:00.099267891Z,160,2,1108,C,A,16.250000000,100,0,582827085,128,181223,515515159,ARL
2025-07-17T20:00:00.099460586Z,2025-07-17T20:00:00.099283688Z,160,2,1108,C,A,16.250000000,100,0,582827089,0,176898,515515175,ARL
2025-07-17T20:00:00.099460586Z,2025-07-17T20:00:00.099284071Z,160,2,1108,C,B,9.550000000,100,0,43690821,0,176515,515515176,ARL
2025-07-17T20:00:00.099460586Z,2025-07-17T20:00:00.099284587Z,160,2,1108,C,B,9.550000000,100,0,43314169,0,175999,515515177,ARL
2025-07-17T20:00:00.099460586Z,2025-07-17T20:00:00.099285045Z,160,2,1108,C,A,16.250000000,100,0,582827057,0,175541,515515178,ARL
2025-07-17T20:00:00.099460586Z,2025-07-17T20:00:00.099285364Z,160,2,1108,C,A,16.250000000,100,0,582827093,128,175222,515515179,ARL
2025-07-17T20:00:00.099461538Z,2025-07-17T20:00:00.099286719Z,160,2,1108,C,B,9.550000000,100,0,44040369,0,174819,515515182,ARL
2025-07-17T20:00:00.099461538Z,2025-07-17T20:00:00.099287246Z,160,2,1108,C,B,8.990000000,100,0,494159689,130,174292,515515183,ARL
2025-07-17T20:00:00.099472712Z,2025-07-17T20:00:00.099287666Z,160,2,1108,C,A,16.250000000,100,0,582827097,128,185046,515515184,ARL
2025-07-17T20:00:00.100787925Z,2025-07-17T20:00:00.100606334Z,160,2,1108,C,A,13.960000000,100,0,641851221,0,181591,515517464,ARL
2025-07-17T20:00:00.100787925Z,2025-07-17T20:00:00.100606334Z,160,2,1108,A,A,14.240000000,100,0,641890685,128,181591,515517464,ARL
2025-07-17T20:00:00.100821431Z,2025-07-17T20:00:00.100633837Z,160,2,1108,C,B,11.280000000,100,0,641851049,0,187594,515517515,ARL
2025-07-17T20:00:00.100821431Z,2025-07-17T20:00:00.100633837Z,160,2,1108,A,B,11.040000000,100,0,641890709,128,187594,515517515,ARL
2025-07-17T20:00:00.106937863Z,2025-07-17T20:00:00.106751877Z,160,2,1108,A,B,10.290000000,100,0,641892873,128,185986,515528247,ARL
2025-07-17T20:00:00.106966714Z,2025-07-17T20:00:00.106784949Z,160,2,1108,C,B,10.730000000,100,0,387224453,128,181765,515528312,ARL
2025-07-17T20:00:00.117101341Z,2025-07-17T20:00:00.116916533Z,160,2,1108,C,B,11.720000000,100,0,387229905,128,184808,515533101,ARL
2025-07-17T20:00:00.117253266Z,2025-07-17T20:00:00.117057598Z,160,2,1108,C,A,13.460000000,100,0,621066397,128,195668,515533356,ARL
2025-07-17T20:00:00.119101475Z,2025-07-17T20:00:00.118923800Z,160,2,1108,C,B,11.970000000,100,0,387211505,0,177675,515536699,ARL
2025-07-17T20:00:00.119101475Z,2025-07-17T20:00:00.118924134Z,160,2,1108,C,A,13.210000000,100,0,621099429,128,177341,515536700,ARL
2025-07-17T20:00:00.145127660Z,2025-07-17T20:00:00.144940425Z,160,2,1108,C,B,11.920000000,100,0,387224477,0,187235,515583726,ARL
2025-07-17T20:00:00.145127660Z,2025-07-17T20:00:00.144940679Z,160,2,1108,C,A,13.270000000,100,0,621057205,128,186981,515583727,ARL
2025-07-17T20:00:00.149545385Z,2025-07-17T20:00:00.149353369Z,160,2,1108,A,A,15.350000000,100,0,641906529,128,192016,515591823,ARL
2025-07-17T20:00:00.149563683Z,2025-07-17T20:00:00.149377566Z,160,2,1108,C,A,15.060000000,100,0,641887245,128,186117,515591867,ARL
2025-07-17T20:00:00.153569726Z,2025-07-17T20:00:00.153381977Z,160,2,1108,C,B,11.040000000,100,0,641890709,0,187749,515599206,ARL
2025-07-17T20:00:00.153569726Z,2025-07-17T20:00:00.153381977Z,160,2,1108,A,B,10.990000000,100,0,641907537,128,187749,515599206,ARL
2025-07-17T20:00:00.153593705Z,2025-07-17T20:00:00.153415539Z,160,2,1108,C,A,14.240000000,100,0,641890685,0,178166,515599268,ARL
2025-07-17T20:00:00.153593705Z,2025-07-17T20:00:00.153415539Z,160,2,1108,A,A,14.500000000,100,0,641907549,128,178166,515599268,ARL
2025-07-17T20:00:00.177217448Z,2025-07-17T20:00:00.177026948Z,160,2,1108,C,B,11.900000000,700,0,387208453,0,190500,515638794,ARL
2025-07-17T20:00:00.177217448Z,2025-07-17T20:00:00.177027665Z,160,2,1108,C,A,13.460000000,100,0,621075997,128,189783,515638795,ARL
2025-07-17T20:00:00.183239205Z,2025-07-17T20:00:00.183055412Z,160,2,1108,C,B,11.600000000,100,0,387224957,128,183793,515649177,ARL
2025-07-17T20:00:00.183277312Z,2025-07-17T20:00:00.183088588Z,160,2,1108,C,A,13.590000000,100,0,621064777,128,188724,515649244,ARL
2025-07-17T20:00:00.194020302Z,2025-07-17T20:00:00.193832742Z,160,2,1108,C,A,13.560000000,100,0,627933429,0,187560,515668107,ARL
2025-07-17T20:00:00.194020302Z,2025-07-17T20:00:00.193833141Z,160,2,1108,C,B,11.630000000,100,0,621099641,128,187161,515668108,ARL
2025-07-17T20:00:00.206400590Z,2025-07-17T20:00:00.206212054Z,160,2,1108,C,B,10.990000000,100,0,641907537,0,188536,515690012,ARL
2025-07-17T20:00:00.206400590Z,2025-07-17T20:00:00.206212054Z,160,2,1108,A,B,10.930000000,100,0,641914449,128,188536,515690012,ARL
2025-07-17T20:00:00.206432386Z,2025-07-17T20:00:00.206245015Z,160,2,1108,C,A,14.500000000,100,0,641907549,0,187371,515690068,ARL
2025-07-17T20:00:00.206432386Z,2025-07-17T20:00:00.206245015Z,160,2,1108,A,A,14.590000000,100,0,641914469,128,187371,515690068,ARL
2025-07-17T20:00:00.211091163Z,2025-07-17T20:00:00.210896898Z,160,2,1108,C,B,11.850000000,700,0,387224445,0,194265,515698462,ARL
2025-07-17T20:00:00.211091163Z,2025-07-17T20:00:00.210897191Z,160,2,1108,C,A,13.560000000,100,0,627933441,128,193972,515698463,ARL
2025-07-17T20:00:00.230049579Z,2025-07-17T20:00:00.229863686Z,160,2,1108,C,B,11.600000000,100,0,387224493,128,185893,515733609,ARL
2025-07-17T20:00:00.230073741Z,2025-07-17T20:00:00.229889272Z,160,2,1108,C,A,13.590000000,100,0,621057221,128,184469,515733655,ARL
2025-07-17T20:00:00.247034207Z,2025-07-17T20:00:00.246847549Z,160,2,1108,C,B,11.820000000,700,0,387224481,0,186658,515765364,ARL
2025-07-17T20:00:00.247034207Z,2025-07-17T20:00:00.246847945Z,160,2,1108,C,A,13.630000000,700,0,581536501,0,186262,515765365,ARL
2025-07-17T20:00:00.247034207Z,2025-07-17T20:00:00.246848306Z,160,2,1108,C,A,13.630000000,700,0,582971645,128,185901,515765366,ARL
2025-07-17T20:00:00.257926037Z,2025-07-17T20:00:00.257739505Z,160,2,1108,C,B,10.930000000,100,0,641914449,0,186532,515785455,ARL
2025-07-17T20:00:00.257926037Z,2025-07-17T20:00:00.257739505Z,160,2,1108,A,B,10.870000000,100,0,641920089,128,186532,515785455,ARL
2025-07-17T20:00:00.259687380Z,2025-07-17T20:00:00.259505093Z,160,2,1108,C,B,11.230000000,100,0,387224501,128,182287,515788784,ARL
2025-07-17T20:00:00.259730728Z,2025-07-17T20:00:00.259544079Z,160,2,1108,C,A,13.970000000,100,0,621057233,128,186649,515788863,ARL
2025-07-17T20:00:00.260098994Z,2025-07-17T20:00:00.259909786Z,160,2,1108,C,B,10.600000000,100,0,387224485,128,189208,515789541,ARL
2025-07-17T20:00:00.260121648Z,2025-07-17T20:00:00.259931493Z,160,2,1108,C,A,14.610000000,100,0,621058509,128,190155,515789581,ARL
2025-07-17T20:00:00.261489769Z,2025-07-17T20:00:00.261300714Z,160,2,1108,C,B,11.630000000,100,0,621099645,128,189055,515792088,ARL
2025-07-17T20:00:00.292753723Z,2025-07-17T20:00:00.292485549Z,160,2,1108,C,B,11.790000000,700,0,387224449,128,268174,515837879,ARL
2025-07-17T20:00:00.292769328Z,2025-07-17T20:00:00.292503341Z,160,2,1108,C,A,13.670000000,700,0,581645413,128,265987,515837916,ARL
2025-07-17T20:00:00.292884319Z,2025-07-17T20:00:00.292608449Z,160,2,1108,A,B,10.020000000,100,0,641923197,128,275870,515838117,ARL
2025-07-17T20:00:00.292912692Z,2025-07-17T20:00:00.292639023Z,160,2,1108,C,B,10.290000000,100,0,641892873,128,273669,515838177,ARL
2025-07-17T20:00:00.303895629Z,2025-07-17T20:00:00.303711969Z,160,2,1108,A,A,15.680000000,100,0,641924161,128,183660,515858567,ARL
2025-07-17T20:00:00.303945341Z,2025-07-17T20:00:00.303762787Z,160,2,1108,C,A,15.350000000,100,0,641906529,128,182554,515858656,ARL
2025-07-17T20:00:00.305400024Z,2025-07-17T20:00:00.305165497Z,160,2,1108,A,B,9.680000000,100,0,641924313,128,234527,515861430,ARL
2025-07-17T20:00:00.305436161Z,2025-07-17T20:00:00.305197889Z,160,2,1108,C,B,10.020000000,100,0,641923197,128,238272,515861493,ARL
2025-07-17T20:00:00.310630466Z,2025-07-17T20:00:00.310123354Z,160,2,1108,C,B,10.870000000,100,0,641920089,0,507112,515871285,ARL
2025-07-17T20:00:00.310630466Z,2025-07-17T20:00:00.310123354Z,160,2,1108,A,B,10.360000000,100,0,641924981,128,507112,515871285,ARL
2025-07-17T20:00:00.314838723Z,2025-07-17T20:00:00.314207706Z,160,2,1108,C,A,14.590000000,100,0,641914469,0,631017,515879335,ARL
2025-07-17T20:00:00.314838723Z,2025-07-17T20:00:00.314207706Z,160,2,1108,A,A,14.820000000,100,0,641925469,128,631017,515879335,ARL
2025-07-17T20:00:00.344697539Z,2025-07-17T20:00:00.344388812Z,160,2,1108,C,B,11.230000000,100,0,387224517,128,308727,515933448,ARL
2025-07-17T20:00:00.344704213Z,2025-07-17T20:00:00.344397152Z,160,2,1108,C,A,13.750000000,700,0,576804577,128,307061,515933463,ARL
2025-07-17T20:00:00.344802576Z,2025-07-17T20:00:00.344506866Z,160,2,1108,A,B,9.450000000,100,0,641928513,130,295710,515933648,ARL
2025-07-17T20:00:00.344829506Z,2025-07-17T20:00:00.344536907Z,160,2,1108,C,B,9.680000000,100,0,641924313,128,292599,515933698,ARL
2025-07-17T20:00:00.361329767Z,2025-07-17T20:00:00.360623123Z,160,2,1108,C,B,10.360000000,100,0,641924981,0,706644,515964386,ARL
2025-07-17T20:00:00.361329767Z,2025-07-17T20:00:00.360623123Z,160,2,1108,A,B,10.140000000,100,0,641930305,128,706644,515964386,ARL
2025-07-17T20:00:00.365678591Z,2025-07-17T20:00:00.364795471Z,160,2,1108,C,A,14.820000000,100,0,641925469,0,883120,515972591,ARL
2025-07-17T20:00:00.365678591Z,2025-07-17T20:00:00.364795471Z,160,2,1108,A,A,15.050000000,100,0,641930753,128,883120,515972591,ARL
2025-07-17T20:00:00.409426172Z,2025-07-17T20:00:00.408645190Z,160,2,1108,C,B,9.110000000,100,0,387224489,128,780982,516052743,ARL
2025-07-17T20:00:00.409439316Z,2025-07-17T20:00:00.408661347Z,160,2,1108,C,A,16.130000000,100,0,621057285,128,777969,516052776,ARL
2025-07-17T20:00:00.428400040Z,2025-07-17T20:00:00.427789605Z,160,2,1108,C,B,10.990000000,100,0,582832953,128,610435,516089219,ARL
2025-07-17T20:00:00.428430675Z,2025-07-17T20:00:00.427816425Z,160,2,1108,C,A,13.970000000,100,0,621063265,128,614250,516089278,ARL
2025-07-17T20:00:00.428601031Z,2025-07-17T20:00:00.427985044Z,160,2,1108,A,A,17.160000000,100,0,641936717,128,615987,516089600,ARL
2025-07-17T20:00:00.428620384Z,2025-07-17T20:00:00.428005858Z,160,2,1108,C,A,15.680000000,100,0,641924161,128,614526,516089641,ARL
2025-07-17T20:00:00.433695049Z,2025-07-17T20:00:00.433054512Z,160,2,1108,C,B,10.140000000,100,0,641930305,0,640537,516099755,ARL
2025-07-17T20:00:00.433695049Z,2025-07-17T20:00:00.433054512Z,160,2,1108,A,B,9.910000000,100,0,641937121,128,640537,516099755,ARL
2025-07-17T20:00:00.433722212Z,2025-07-17T20:00:00.433082020Z,160,2,1108,C,A,15.050000000,100,0,641930753,0,640192,516099812,ARL
2025-07-17T20:00:00.433722212Z,2025-07-17T20:00:00.433082020Z,160,2,1108,A,A,16.220000000,100,0,641937125,128,640192,516099812,ARL
2025-07-17T20:00:00.485582306Z,2025-07-17T20:00:00.483816751Z,160,2,1108,C,A,16.220000000,100,0,641937125,0,1765555,516203058,ARL
2025-07-17T20:00:00.485582306Z,2025-07-17T20:00:00.483816751Z,160,2,1108,A,A,16.340000000,100,0,641942049,130,1765555,516203058,ARL
2025-07-17T20:00:00.492177767Z,2025-07-17T20:00:00.490757466Z,160,2,1108,C,B,9.910000000,100,0,641937121,128,1420301,516215355,ARL
2025-07-17T20:00:00.496875731Z,2025-07-17T20:00:00.495745095Z,160,2,1108,C,B,10.610000000,100,0,43314465,0,1130636,516223907,ARL
2025-07-17T20:00:00.496875731Z,2025-07-17T20:00:00.495745414Z,160,2,1108,C,B,10.610000000,100,0,43317177,128,1130317,516223908,ARL
2025-07-17T20:00:00.496883849Z,2025-07-17T20:00:00.495750829Z,160,2,1108,C,A,15.160000000,100,0,583270249,128,1133020,516223920,ARL
2025-07-17T20:00:00.496890979Z,2025-07-17T20:00:00.495757703Z,160,2,1108,C,A,15.160000000,100,0,583270265,128,1133276,516223931,ARL
2025-07-17T20:00:00.535333680Z,2025-07-17T20:00:00.535161046Z,160,2,1108,C,A,16.340000000,100,0,641942049,128,172634,516286757,ARL
2025-07-17T20:00:00.539322480Z,2025-07-17T20:00:00.539145340Z,160,2,1108,C,A,15.300000000,100,0,41370837,130,177140,516292391,ARL
2025-07-17T20:00:00.539503296Z,2025-07-17T20:00:00.539320579Z,160,2,1108,A,A,2147.480000000,100,0,641950225,128,182717,516292597,ARL
2025-07-17T20:00:00.539526881Z,2025-07-17T20:00:00.539344608Z,160,2,1108,C,A,17.160000000,100,0,641936717,128,182273,516292637,ARL
2025-07-17T20:00:01.396367769Z,2025-07-17T20:00:01.396195152Z,160,2,1108,C,B,9.450000000,100,0,641928513,128,172617,517331392,ARL
2025-07-17T20:00:01.396387653Z,2025-07-17T20:00:01.396218628Z,160,2,1108,C,A,2147.480000000,100,0,641950225,128,169025,517331426,ARL
2025-07-17T20:00:48.778523852Z,2025-07-17T20:00:48.778357981Z,160,2,1108,A,B,9.850000000,400,0,642254625,130,165871,520459712,ARL
2025-07-17T20:20:15.948563568Z,2025-07-17T20:20:15.948398144Z,160,2,1108,A,B,9.790000000,100,0,643709105,130,165424,521758914,ARL
2025-07-17T20:20:15.948567677Z,2025-07-17T20:20:15.948402141Z,160,2,1108,A,A,17.930000000,100,0,643709109,130,165536,521758915,ARL
2025-07-17T20:21:08.113805239Z,2025-07-17T20:21:08.113639819Z,160,2,1108,A,B,9.840000000,100,0,643783525,130,165420,521811738,ARL
2025-07-17T20:21:08.113810712Z,2025-07-17T20:21:08.113645227Z,160,2,1108,A,A,17.850000000,100,0,643783529,130,165485,521811739,ARL
2025-07-17T20:47:59.252220825Z,2025-07-17T20:47:59.252055411Z,160,2,1108,A,A,16.250000000,60,0,644971685,130,165414,522588931,ARL
