,ts_recv,ts_event,rtype,publisher_id,instrument_id,action,side,depth,price,size,flags,ts_in_delta,sequence,bid_px_00,bid_sz_00,bid_ct_00,ask_px_00,ask_sz_00,ask_ct_00,bid_px_01,bid_sz_01,bid_ct_01,ask_px_01,ask_sz_01,ask_ct_01,bid_px_02,bid_sz_02,bid_ct_02,ask_px_02,ask_sz_02,ask_ct_02,bid_px_03,bid_sz_03,bid_ct_03,ask_px_03,ask_sz_03,ask_ct_03,bid_px_04,bid_sz_04,bid_ct_04,ask_px_04,ask_sz_04,ask_ct_04,bid_px_05,bid_sz_05,bid_ct_05,ask_px_05,ask_sz_05,ask_ct_05,bid_px_06,bid_sz_06,bid_ct_06,ask_px_06,ask_sz_06,ask_ct_06,bid_px_07,bid_sz_07,bid_ct_07,ask_px_07,ask_sz_07,ask_ct_07,bid_px_08,bid_sz_08,bid_ct_08,ask_px_08,ask_sz_08,ask_ct_08,bid_px_09,bid_sz_09,bid_ct_09,ask_px_09,ask_sz_09,ask_ct_09,symbol,order_id
1699,2025-07-17T16:02:20.956923753Z,2025-07-17T16:02:20.956923753Z,10,2,1108,A,B,2,13.12,100,130,165390,271679686,13.27,10,1,13.83,15,1,13.26,100,1,13.84,100,1,13.12,100,1,13.92,2,1,13.03,100,1,14.12,100,1,12.91,2,1,14.28,100,1,12.73,100,1,14.45,100,1,12.71,100,1,14.56,800,2,12.5,700,1,14.6,700,1,12.46,200,2,14.63,100,1,12.43,700,1,14.68,1400,2,ARL,325718833
1700,2025-07-17T16:02:20.956925447Z,2025-07-17T16:02:20.956925447Z,10,2,1108,A,B,2,13.12,100,130,165037,271679687,13.27,10,1,13.83,15,1,13.26,100,1,13.84,100,1,13.12,200,2,13.92,2,1,13.03,100,1,14.12,100,1,12.91,2,1,14.28,100,1,12.73,100,1,14.45,100,1,12.71,100,1,14.56,800,2,12.5,700,1,14.6,700,1,12.46,200,2,14.63,100,1,12.43,700,1,14.68,1400,2,ARL,325718837
1701,2025-07-17T16:02:20.988490644Z,2025-07-17T16:02:20.988490644Z,10,2,1108,A,A,3,13.98,100,130,165226,271679923,13.27,10,1,13.83,15,1,13.26,100,1,13.84,100,1,13.12,200,2,13.92,2,1,13.03,100,1,13.98,100,1,12.91,2,1,14.12,100,1,12.73,100,1,14.28,100,1,12.71,100,1,14.45,100,1,12.5,700,1,14.56,800,2,12.46,200,2,14.6,700,1,12.43,700,1,14.63,100,1,ARL,325719353
1702,2025-07-17T16:02:20.988491826Z,2025-07-17T16:02:20.988491826Z,10,2,1108,A,A,3,13.98,100,130,165118,271679924,13.27,10,1,13.83,15,1,13.26,100,1,13.84,100,1,13.12,200,2,13.92,2,1,13.03,100,1,13.98,200,2,12.91,2,1,14.12,100,1,12.73,100,1,14.28,100,1,12.71,100,1,14.45,100,1,12.5,700,1,14.56,800,2,12.46,200,2,14.6,700,1,12.43,700,1,14.63,100,1,ARL,325719357
1703,2025-07-17T16:02:30.805028316Z,2025-07-17T16:02:30.805028316Z,10,2,1108,C,B,0,13.27,10,130,165379,271818376,13.26,100,1,13.83,15,1,13.12,200,2,13.84,100,1,13.03,100,1,13.92,2,1,12.91,2,1,13.98,200,2,12.73,100,1,14.12,100,1,12.71,100,1,14.28,100,1,12.5,700,1,14.45,100,1,12.46,200,2,14.56,800,2,12.43,700,1,14.6,700,1,12.42,700,1,14.63,100,1,ARL,325714717
1704,2025-07-17T16:02:34.987005787Z,2025-07-17T16:02:34.987005787Z,10,2,1108,C,B,0,12.91,2,0,165610,271871706,13.26,100,1,13.83,15,1,13.12,200,2,13.84,100,1,13.03,100,1,13.92,2,1,12.73,100,1,13.98,200,2,12.71,100,1,14.12,100,1,12.5,700,1,14.28,100,1,12.46,200,2,14.45,100,1,12.43,700,1,14.56,800,2,12.42,700,1,14.6,700,1,12.37,700,1,14.63,100,1,ARL,325714741
1705,2025-07-17T16:02:34.987005787Z,2025-07-17T16:02:34.987005787Z,10,2,1108,A,B,3,13,2,130,165610,271871706,13.26,100,1,13.83,15,1,13.12,200,2,13.84,100,1,13.03,100,1,13.92,2,1,13,2,1,13.98,200,2,12.73,100,1,14.12,100,1,12.71,100,1,14.28,100,1,12.5,700,1,14.45,100,1,12.46,200,2,14.56,800,2,12.43,700,1,14.6,700,1,12.42,700,1,14.63,100,1,ARL,325967705
1706,2025-07-17T16:02:39.809299504Z,2025-07-17T16:02:39.809299504Z,10,2,1108,A,A,0,13.79,15,130,165457,271952021,13.26,100,1,13.79,15,1,13.12,200,2,13.83,15,1,13.03,100,1,13.84,100,1,13,2,1,13.92,2,1,12.73,100,1,13.98,200,2,12.71,100,1,14.12,100,1,12.5,700,1,14.28,100,1,12.46,200,2,14.45,100,1,12.43,700,1,14.56,800,2,12.42,700,1,14.6,700,1,ARL,326077141
1707,2025-07-17T16:02:40.007306432Z,2025-07-17T16:02:40.007306432Z,10,2,1108,C,A,0,13.84,100,0,165588,271957331,13.26,100,1,13.79,15,1,13.12,200,2,13.83,15,1,13.03,100,1,13.92,2,1,13,2,1,13.98,200,2,12.73,100,1,14.12,100,1,12.71,100,1,14.28,100,1,12.5,700,1,14.45,100,1,12.46,200,2,14.56,800,2,12.43,700,1,14.6,700,1,12.42,700,1,14.63,100,1,ARL,325718485
1708,2025-07-17T16:02:40.007306432Z,2025-07-17T16:02:40.007306432Z,10,2,1108,A,A,1,13.8,100,130,165588,271957331,13.26,100,1,13.79,15,1,13.12,200,2,13.8,100,1,13.03,100,1,13.83,15,1,13,2,1,13.92,2,1,12.73,100,1,13.98,200,2,12.71,100,1,14.12,100,1,12.5,700,1,14.28,100,1,12.46,200,2,14.45,100,1,12.43,700,1,14.56,800,2,12.42,700,1,14.6,700,1,ARL,326082329
1709,2025-07-17T16:02:40.008048023Z,2025-07-17T16:02:40.008048023Z,10,2,1108,C,A,0,14.91,100,0,165631,271957349,13.26,100,1,13.79,15,1,13.12,200,2,13.8,100,1,13.03,100,1,13.83,15,1,13,2,1,13.92,2,1,12.73,100,1,13.98,200,2,12.71,100,1,14.12,100,1,12.5,700,1,14.28,100,1,12.46,200,2,14.45,100,1,12.43,700,1,14.56,800,2,12.42,700,1,14.6,700,1,ARL,325718509
1710,2025-07-17T16:02:40.008048023Z,2025-07-17T16:02:40.008048023Z,10,2,1108,A,A,14,14.87,100,130,165631,271957349,13.26,100,1,13.79,15,1,13.12,200,2,13.8,100,1,13.03,100,1,13.83,15,1,13,2,1,13.92,2,1,12.73,100,1,13.98,200,2,12.71,100,1,14.12,100,1,12.5,700,1,14.28,100,1,12.46,200,2,14.45,100,1,12.43,700,1,14.56,800,2,12.42,700,1,14.6,700,1,ARL,326082353
1711,2025-07-17T16:02:40.794847674Z,2025-07-17T16:02:40.794847674Z,10,2,1108,C,A,0,13.79,15,130,166797,271972417,13.26,100,1,13.8,100,1,13.12,200,2,13.83,15,1,13.03,100,1,13.92,2,1,13,2,1,13.98,200,2,12.73,100,1,14.12,100,1,12.71,100,1,14.28,100,1,12.5,700,1,14.45,100,1,12.46,200,2,14.56,800,2,12.43,700,1,14.6,700,1,12.42,700,1,14.63,100,1,ARL,326077141
1712,2025-07-17T16:02:40.806140621Z,2025-07-17T16:02:40.806140621Z,10,2,1108,C,A,0,13.83,15,130,165274,271973288,13.26,100,1,13.8,100,1,13.12,200,2,13.92,2,1,13.03,100,1,13.98,200,2,13,2,1,14.12,100,1,12.73,100,1,14.28,100,1,12.71,100,1,14.45,100,1,12.5,700,1,14.56,800,2,12.46,200,2,14.6,700,1,12.43,700,1,14.63,100,1,12.42,700,1,14.68,1400,2,ARL,325714721
1713,2025-07-17T16:02:43.841686908Z,2025-07-17T16:02:43.841686908Z,10,2,1108,C,B,0,13.26,100,130,165522,272014658,13.12,200,2,13.8,100,1,13.03,100,1,13.92,2,1,13,2,1,13.98,200,2,12.73,100,1,14.12,100,1,12.71,100,1,14.28,100,1,12.5,700,1,14.45,100,1,12.46,200,2,14.56,800,2,12.43,700,1,14.6,700,1,12.42,700,1,14.63,100,1,12.37,700,1,14.68,1400,2,ARL,325718821
1714,2025-07-17T16:02:43.841746626Z,2025-07-17T16:02:43.841746626Z,10,2,1108,A,A,1,13.9,4,130,165427,272014659,13.12,200,2,13.8,100,1,13.03,100,1,13.9,4,1,13,2,1,13.92,2,1,12.73,100,1,13.98,200,2,12.71,100,1,14.12,100,1,12.5,700,1,14.28,100,1,12.46,200,2,14.45,100,1,12.43,700,1,14.56,800,2,12.42,700,1,14.6,700,1,12.37,700,1,14.63,100,1,ARL,326158809
1715,2025-07-17T16:02:43.842130114Z,2025-07-17T16:02:43.842130114Z,10,2,1108,C,A,0,13.8,100,130,165313,272014661,13.12,200,2,13.9,4,1,13.03,100,1,13.92,2,1,13,2,1,13.98,200,2,12.73,100,1,14.12,100,1,12.71,100,1,14.28,100,1,12.5,700,1,14.45,100,1,12.46,200,2,14.56,800,2,12.43,700,1,14.6,700,1,12.42,700,1,14.63,100,1,12.37,700,1,14.68,1400,2,ARL,326082329
1716,2025-07-17T16:02:43.842871428Z,2025-07-17T16:02:43.842871428Z,10,2,1108,C,A,0,14.87,100,0,165508,272014673,13.12,200,2,13.9,4,1,13.03,100,1,13.92,2,1,13,2,1,13.98,200,2,12.73,100,1,14.12,100,1,12.71,100,1,14.28,100,1,12.5,700,1,14.45,100,1,12.46,200,2,14.56,800,2,12.43,700,1,14.6,700,1,12.42,700,1,14.63,100,1,12.37,700,1,14.68,1400,2,ARL,326082353
1717,2025-07-17T16:02:43.842871428Z,2025-07-17T16:02:43.842871428Z,10,2,1108,A,A,12,14.92,100,130,165508,272014673,13.12,200,2,13.9,4,1,13.03,100,1,13.92,2,1,13,2,1,13.98,200,2,12.73,100,1,14.12,100,1,12.71,100,1,14.28,100,1,12.5,700,1,14.45,100,1,12.46,200,2,14.56,800,2,12.43,700,1,14.6,700,1,12.42,700,1,14.63,100,1,12.37,700,1,14.68,1400,2,ARL,326158869
1718,2025-07-17T16:02:43.842941514Z,2025-07-17T16:02:43.842941514Z,10,2,1108,A,B,1,13.11,100,130,165235,272014674,13.12,200,2,13.9,4,1,13.11,100,1,13.92,2,1,13.03,100,1,13.98,200,2,13,2,1,14.12,100,1,12.73,100,1,14.28,100,1,12.71,100,1,14.45,100,1,12.5,700,1,14.56,800,2,12.46,200,2,14.6,700,1,12.43,700,1,14.63,100,1,12.42,700,1,14.68,1400,2,ARL,326158877
1719,2025-07-17T16:02:43.842943173Z,2025-07-17T16:02:43.842943173Z,10,2,1108,C,A,11,14.81,100,0,165853,272014675,13.12,200,2,13.9,4,1,13.11,100,1,13.92,2,1,13.03,100,1,13.98,200,2,13,2,1,14.12,100,1,12.73,100,1,14.28,100,1,12.71,100,1,14.45,100,1,12.5,700,1,14.56,800,2,12.46,200,2,14.6,700,1,12.43,700,1,14.63,100,1,12.42,700,1,14.68,1400,2,ARL,325718549
1720,2025-07-17T16:02:43.842943173Z,2025-07-17T16:02:43.842943173Z,10,2,1108,A,A,13,14.96,100,130,165853,272014675,13.12,200,2,13.9,4,1,13.11,100,1,13.92,2,1,13.03,100,1,13.98,200,2,13,2,1,14.12,100,1,12.73,100,1,14.28,100,1,12.71,100,1,14.45,100,1,12.5,700,1,14.56,800,2,12.46,200,2,14.6,700,1,12.43,700,1,14.63,100,1,12.42,700,1,14.68,1400,2,ARL,326158881
1721,2025-07-17T16:02:43.843039530Z,2025-07-17T16:02:43.843039530Z,10,2,1108,C,A,0,13.9,4,130,165162,272014681,13.12,200,2,13.92,2,1,13.11,100,1,13.98,200,2,13.03,100,1,14.12,100,1,13,2,1,14.28,100,1,12.73,100,1,14.45,100,1,12.71,100,1,14.56,800,2,12.5,700,1,14.6,700,1,12.46,200,2,14.63,100,1,12.43,700,1,14.68,1400,2,12.42,700,1,14.73,200,2,ARL,326158809
1722,2025-07-17T16:02:43.843791297Z,2025-07-17T16:02:43.843791297Z,10,2,1108,C,A,0,17.58,100,0,165523,272014689,13.12,200,2,13.92,2,1,13.11,100,1,13.98,200,2,13.03,100,1,14.12,100,1,13,2,1,14.28,100,1,12.73,100,1,14.45,100,1,12.71,100,1,14.56,800,2,12.5,700,1,14.6,700,1,12.46,200,2,14.63,100,1,12.43,700,1,14.68,1400,2,12.42,700,1,14.73,200,2,ARL,325718557
1723,2025-07-17T16:02:43.843791297Z,2025-07-17T16:02:43.843791297Z,10,2,1108,A,A,20,17.76,100,130,165523,272014689,13.12,200,2,13.92,2,1,13.11,100,1,13.98,200,2,13.03,100,1,14.12,100,1,13,2,1,14.28,100,1,12.73,100,1,14.45,100,1,12.71,100,1,14.56,800,2,12.5,700,1,14.6,700,1,12.46,200,2,14.63,100,1,12.43,700,1,14.68,1400,2,12.42,700,1,14.73,200,2,ARL,326158953
1724,2025-07-17T16:02:43.844487204Z,2025-07-17T16:02:43.844487204Z,10,2,1108,C,A,0,15.92,100,0,165810,272014697,13.12,200,2,13.92,2,1,13.11,100,1,13.98,200,2,13.03,100,1,14.12,100,1,13,2,1,14.28,100,1,12.73,100,1,14.45,100,1,12.71,100,1,14.56,800,2,12.5,700,1,14.6,700,1,12.46,200,2,14.63,100,1,12.43,700,1,14.68,1400,2,12.42,700,1,14.73,200,2,ARL,325718525
1725,2025-07-17T16:02:43.844487204Z,2025-07-17T16:02:43.844487204Z,10,2,1108,A,A,17,16.08,100,130,165810,272014697,13.12,200,2,13.92,2,1,13.11,100,1,13.98,200,2,13.03,100,1,14.12,100,1,13,2,1,14.28,100,1,12.73,100,1,14.45,100,1,12.71,100,1,14.56,800,2,12.5,700,1,14.6,700,1,12.46,200,2,14.63,100,1,12.43,700,1,14.68,1400,2,12.42,700,1,14.73,200,2,ARL,326158989
1726,2025-07-17T16:02:43.844636465Z,2025-07-17T16:02:43.844636465Z,10,2,1108,C,A,0,14.81,100,0,165486,272014698,13.12,200,2,13.92,2,1,13.11,100,1,13.98,200,2,13.03,100,1,14.12,100,1,13,2,1,14.28,100,1,12.73,100,1,14.45,100,1,12.71,100,1,14.56,800,2,12.5,700,1,14.6,700,1,12.46,200,2,14.63,100,1,12.43,700,1,14.68,1400,2,12.42,700,1,14.73,200,2,ARL,325718517
1727,2025-07-17T16:02:43.844636465Z,2025-07-17T16:02:43.844636465Z,10,2,1108,A,A,11,14.96,100,130,165486,272014698,13.12,200,2,13.92,2,1,13.11,100,1,13.98,200,2,13.03,100,1,14.12,100,1,13,2,1,14.28,100,1,12.73,100,1,14.45,100,1,12.71,100,1,14.56,800,2,12.5,700,1,14.6,700,1,12.46,200,2,14.63,100,1,12.43,700,1,14.68,1400,2,12.42,700,1,14.73,200,2,ARL,326158997
1728,2025-07-17T16:02:43.846861336Z,2025-07-17T16:02:43.846861336Z,10,2,1108,C,A,0,13.92,2,0,165459,272014713,13.12,200,2,13.98,200,2,13.11,100,1,14.12,100,1,13.03,100,1,14.28,100,1,13,2,1,14.45,100,1,12.73,100,1,14.56,800,2,12.71,100,1,14.6,700,1,12.5,700,1,14.63,100,1,12.46,200,2,14.68,1400,2,12.43,700,1,14.73,200,2,12.42,700,1,14.92,100,1,ARL,325297093
1729,2025-07-17T16:02:43.846861336Z,2025-07-17T16:02:43.846861336Z,10,2,1108,A,A,1,14.03,2,130,165459,272014713,13.12,200,2,13.98,200,2,13.11,100,1,14.03,2,1,13.03,100,1,14.12,100,1,13,2,1,14.28,100,1,12.73,100,1,14.45,100,1,12.71,100,1,14.56,800,2,12.5,700,1,14.6,700,1,12.46,200,2,14.63,100,1,12.43,700,1,14.68,1400,2,12.42,700,1,14.73,200,2,ARL,326159041
1730,2025-07-17T16:02:43.847666979Z,2025-07-17T16:02:43.847666979Z,10,2,1108,C,A,9,14.73,100,0,165279,272014721,13.12,200,2,13.98,200,2,13.11,100,1,14.03,2,1,13.03,100,1,14.12,100,1,13,2,1,14.28,100,1,12.73,100,1,14.45,100,1,12.71,100,1,14.56,800,2,12.5,700,1,14.6,700,1,12.46,200,2,14.63,100,1,12.43,700,1,14.68,1400,2,12.42,700,1,14.73,100,1,ARL,325714613
1731,2025-07-17T16:02:43.847666979Z,2025-07-17T16:02:43.847666979Z,10,2,1108,A,A,10,14.87,100,130,165279,272014721,13.12,200,2,13.98,200,2,13.11,100,1,14.03,2,1,13.03,100,1,14.12,100,1,13,2,1,14.28,100,1,12.73,100,1,14.45,100,1,12.71,100,1,14.56,800,2,12.5,700,1,14.6,700,1,12.46,200,2,14.63,100,1,12.43,700,1,14.68,1400,2,12.42,700,1,14.73,100,1,ARL,326159049
1732,2025-07-17T16:02:43.847981726Z,2025-07-17T16:02:43.847981726Z,10,2,1108,C,A,0,14.73,100,0,165472,272014724,13.12,200,2,13.98,200,2,13.11,100,1,14.03,2,1,13.03,100,1,14.12,100,1,13,2,1,14.28,100,1,12.73,100,1,14.45,100,1,12.71,100,1,14.56,800,2,12.5,700,1,14.6,700,1,12.46,200,2,14.63,100,1,12.43,700,1,14.68,1400,2,12.42,700,1,14.87,100,1,ARL,325714577
1733,2025-07-17T16:02:43.847981726Z,2025-07-17T16:02:43.847981726Z,10,2,1108,A,A,9,14.87,100,130,165472,272014724,13.12,200,2,13.98,200,2,13.11,100,1,14.03,2,1,13.03,100,1,14.12,100,1,13,2,1,14.28,100,1,12.73,100,1,14.45,100,1,12.71,100,1,14.56,800,2,12.5,700,1,14.6,700,1,12.46,200,2,14.63,100,1,12.43,700,1,14.68,1400,2,12.42,700,1,14.87,200,2,ARL,326159061
1734,2025-07-17T16:02:43.860034354Z,2025-07-17T16:02:43.860034354Z,10,2,1108,C,A,0,14.12,100,130,165293,272014788,13.12,200,2,13.98,200,2,13.11,100,1,14.03,2,1,13.03,100,1,14.28,100,1,13,2,1,14.45,100,1,12.73,100,1,14.56,800,2,12.71,100,1,14.6,700,1,12.5,700,1,14.63,100,1,12.46,200,2,14.68,1400,2,12.43,700,1,14.87,200,2,12.42,700,1,14.92,100,1,ARL,325718637
1735,2025-07-17T16:02:43.860087215Z,2025-07-17T16:02:43.860087215Z,10,2,1108,A,A,2,14.26,100,130,165231,272014789,13.12,200,2,13.98,200,2,13.11,100,1,14.03,2,1,13.03,100,1,14.26,100,1,13,2,1,14.28,100,1,12.73,100,1,14.45,100,1,12.71,100,1,14.56,800,2,12.5,700,1,14.6,700,1,12.46,200,2,14.63,100,1,12.43,700,1,14.68,1400,2,12.42,700,1,14.87,200,2,ARL,326159201
1736,2025-07-17T16:02:43.893011012Z,2025-07-17T16:02:43.893011012Z,10,2,1108,C,A,0,14.92,100,0,165300,272014986,13.12,200,2,13.98,200,2,13.11,100,1,14.03,2,1,13.03,100,1,14.26,100,1,13,2,1,14.28,100,1,12.73,100,1,14.45,100,1,12.71,100,1,14.56,800,2,12.5,700,1,14.6,700,1,12.46,200,2,14.63,100,1,12.43,700,1,14.68,1400,2,12.42,700,1,14.87,200,2,ARL,326158869
1737,2025-07-17T16:02:43.893011012Z,2025-07-17T16:02:43.893011012Z,10,2,1108,A,A,11,15.06,100,130,165300,272014986,13.12,200,2,13.98,200,2,13.11,100,1,14.03,2,1,13.03,100,1,14.26,100,1,13,2,1,14.28,100,1,12.73,100,1,14.45,100,1,12.71,100,1,14.56,800,2,12.5,700,1,14.6,700,1,12.46,200,2,14.63,100,1,12.43,700,1,14.68,1400,2,12.42,700,1,14.87,200,2,ARL,326159425
1738,2025-07-17T16:02:43.946801538Z,2025-07-17T16:02:43.946801538Z,10,2,1108,C,A,0,14.63,100,0,165599,272015584,13.12,200,2,13.98,200,2,13.11,100,1,14.03,2,1,13.03,100,1,14.26,100,1,13,2,1,14.28,100,1,12.73,100,1,14.45,100,1,12.71,100,1,14.56,800,2,12.5,700,1,14.6,700,1,12.46,200,2,14.68,1400,2,12.43,700,1,14.87,200,2,12.42,700,1,14.96,200,2,ARL,325714653
1739,2025-07-17T16:02:43.946801538Z,2025-07-17T16:02:43.946801538Z,10,2,1108,A,A,8,14.77,100,130,165599,272015584,13.12,200,2,13.98,200,2,13.11,100,1,14.03,2,1,13.03,100,1,14.26,100,1,13,2,1,14.28,100,1,12.73,100,1,14.45,100,1,12.71,100,1,14.56,800,2,12.5,700,1,14.6,700,1,12.46,200,2,14.68,1400,2,12.43,700,1,14.77,100,1,12.42,700,1,14.87,200,2,ARL,326160141
1740,2025-07-17T16:02:44.664054457Z,2025-07-17T16:02:44.664054457Z,10,2,1108,A,A,1,13.99,100,130,165327,272021808,13.12,200,2,13.98,200,2,13.11,100,1,13.99,100,1,13.03,100,1,14.03,2,1,13,2,1,14.26,100,1,12.73,100,1,14.28,100,1,12.71,100,1,14.45,100,1,12.5,700,1,14.56,800,2,12.46,200,2,14.6,700,1,12.43,700,1,14.68,1400,2,12.42,700,1,14.77,100,1,ARL,326167529
1741,2025-07-17T16:03:02.985818199Z,2025-07-17T16:03:02.985818199Z,10,2,1108,C,A,10,14.87,100,0,169399,272331833,13.12,200,2,13.98,200,2,13.11,100,1,13.99,100,1,13.03,100,1,14.03,2,1,13,2,1,14.26,100,1,12.73,100,1,14.28,100,1,12.71,100,1,14.45,100,1,12.5,700,1,14.56,800,2,12.46,200,2,14.6,700,1,12.43,700,1,14.68,1400,2,12.42,700,1,14.77,100,1,ARL,326159049
1742,2025-07-17T16:03:02.985818199Z,2025-07-17T16:03:02.985818199Z,10,2,1108,A,A,9,14.7,100,128,169399,272331833,13.12,200,2,13.98,200,2,13.11,100,1,13.99,100,1,13.03,100,1,14.03,2,1,13,2,1,14.26,100,1,12.73,100,1,14.28,100,1,12.71,100,1,14.45,100,1,12.5,700,1,14.56,800,2,12.46,200,2,14.6,700,1,12.43,700,1,14.68,1400,2,12.42,700,1,14.7,100,1,ARL,326551237
1743,2025-07-17T16:03:02.987797728Z,2025-07-17T16:03:02.987797728Z,10,2,1108,C,A,0,14.87,100,0,172001,272332718,13.12,200,2,13.98,200,2,13.11,100,1,13.99,100,1,13.03,100,1,14.03,2,1,13,2,1,14.26,100,1,12.73,100,1,14.28,100,1,12.71,100,1,14.45,100,1,12.5,700,1,14.56,800,2,12.46,200,2,14.6,700,1,12.43,700,1,14.68,1400,2,12.42,700,1,14.7,100,1,ARL,326159061
1744,2025-07-17T16:03:02.987797728Z,2025-07-17T16:03:02.987797728Z,10,2,1108,A,A,9,14.7,100,128,172001,272332718,13.12,200,2,13.98,200,2,13.11,100,1,13.99,100,1,13.03,100,1,14.03,2,1,13,2,1,14.26,100,1,12.73,100,1,14.28,100,1,12.71,100,1,14.45,100,1,12.5,700,1,14.56,800,2,12.46,200,2,14.6,700,1,12.43,700,1,14.68,1400,2,12.42,700,1,14.7,200,2,ARL,326551829
1745,2025-07-17T16:03:10.807281669Z,2025-07-17T16:03:10.807281669Z,10,2,1108,A,A,0,13.72,15,130,165306,272474575,13.12,200,2,13.72,15,1,13.11,100,1,13.98,200,2,13.03,100,1,13.99,100,1,13,2,1,14.03,2,1,12.73,100,1,14.26,100,1,12.71,100,1,14.28,100,1,12.5,700,1,14.45,100,1,12.46,200,2,14.56,800,2,12.43,700,1,14.6,700,1,12.42,700,1,14.68,1400,2,ARL,326729677
1746,2025-07-17T16:03:10.807548848Z,2025-07-17T16:03:10.807548848Z,10,2,1108,C,A,0,13.99,100,0,165573,272474576,13.12,200,2,13.72,15,1,13.11,100,1,13.98,200,2,13.03,100,1,14.03,2,1,13,2,1,14.26,100,1,12.73,100,1,14.28,100,1,12.71,100,1,14.45,100,1,12.5,700,1,14.56,800,2,12.46,200,2,14.6,700,1,12.43,700,1,14.68,1400,2,12.42,700,1,14.7,200,2,ARL,326167529
1747,2025-07-17T16:03:10.807548848Z,2025-07-17T16:03:10.807548848Z,10,2,1108,A,A,1,13.73,100,130,165573,272474576,13.12,200,2,13.72,15,1,13.11,100,1,13.73,100,1,13.03,100,1,13.98,200,2,13,2,1,14.03,2,1,12.73,100,1,14.26,100,1,12.71,100,1,14.28,100,1,12.5,700,1,14.45,100,1,12.46,200,2,14.56,800,2,12.43,700,1,14.6,700,1,12.42,700,1,14.68,1400,2,ARL,326729685
1748,2025-07-17T16:03:10.808290914Z,2025-07-17T16:03:10.808290914Z,10,2,1108,C,A,0,15.06,100,0,166364,272474580,13.12,200,2,13.72,15,1,13.11,100,1,13.73,100,1,13.03,100,1,13.98,200,2,13,2,1,14.03,2,1,12.73,100,1,14.26,100,1,12.71,100,1,14.28,100,1,12.5,700,1,14.45,100,1,12.46,200,2,14.56,800,2,12.43,700,1,14.6,700,1,12.42,700,1,14.68,1400,2,ARL,326159425
1749,2025-07-17T16:03:10.808290914Z,2025-07-17T16:03:10.808290914Z,10,2,1108,A,A,12,14.79,100,128,166364,272474580,13.12,200,2,13.72,15,1,13.11,100,1,13.73,100,1,13.03,100,1,13.98,200,2,13,2,1,14.03,2,1,12.73,100,1,14.26,100,1,12.71,100,1,14.28,100,1,12.5,700,1,14.45,100,1,12.46,200,2,14.56,800,2,12.43,700,1,14.6,700,1,12.42,700,1,14.68,1400,2,ARL,326729705
1750,2025-07-17T16:03:10.809541651Z,2025-07-17T16:03:10.809541651Z,10,2,1108,C,A,13,14.96,100,0,165623,272474585,13.12,200,2,13.72,15,1,13.11,100,1,13.73,100,1,13.03,100,1,13.98,200,2,13,2,1,14.03,2,1,12.73,100,1,14.26,100,1,12.71,100,1,14.28,100,1,12.5,700,1,14.45,100,1,12.46,200,2,14.56,800,2,12.43,700,1,14.6,700,1,12.42,700,1,14.68,1400,2,ARL,326158881
1751,2025-07-17T16:03:10.809541651Z,2025-07-17T16:03:10.809541651Z,10,2,1108,A,A,10,14.7,100,130,165623,272474585,13.12,200,2,13.72,15,1,13.11,100,1,13.73,100,1,13.03,100,1,13.98,200,2,13,2,1,14.03,2,1,12.73,100,1,14.26,100,1,12.71,100,1,14.28,100,1,12.5,700,1,14.45,100,1,12.46,200,2,14.56,800,2,12.43,700,1,14.6,700,1,12.42,700,1,14.68,1400,2,ARL,326729721
1752,2025-07-17T16:03:10.809771527Z,2025-07-17T16:03:10.809771527Z,10,2,1108,C,A,0,14.77,100,130,165294,272474594,13.12,200,2,13.72,15,1,13.11,100,1,13.73,100,1,13.03,100,1,13.98,200,2,13,2,1,14.03,2,1,12.73,100,1,14.26,100,1,12.71,100,1,14.28,100,1,12.5,700,1,14.45,100,1,12.46,200,2,14.56,800,2,12.43,700,1,14.6,700,1,12.42,700,1,14.68,1400,2,ARL,326160141
1753,2025-07-17T16:03:10.809798084Z,2025-07-17T16:03:10.809798084Z,10,2,1108,C,A,0,17.76,100,0,165493,272474595,13.12,200,2,13.72,15,1,13.11,100,1,13.73,100,1,13.03,100,1,13.98,200,2,13,2,1,14.03,2,1,12.73,100,1,14.26,100,1,12.71,100,1,14.28,100,1,12.5,700,1,14.45,100,1,12.46,200,2,14.56,800,2,12.43,700,1,14.6,700,1,12.42,700,1,14.68,1400,2,ARL,326158953
1754,2025-07-17T16:03:10.809798084Z,2025-07-17T16:03:10.809798084Z,10,2,1108,A,A,19,17.44,100,130,165493,272474595,13.12,200,2,13.72,15,1,13.11,100,1,13.73,100,1,13.03,100,1,13.98,200,2,13,2,1,14.03,2,1,12.73,100,1,14.26,100,1,12.71,100,1,14.28,100,1,12.5,700,1,14.45,100,1,12.46,200,2,14.56,800,2,12.43,700,1,14.6,700,1,12.42,700,1,14.68,1400,2,ARL,326729725
1755,2025-07-17T16:03:10.809894317Z,2025-07-17T16:03:10.809894317Z,10,2,1108,A,A,7,14.52,100,130,165125,272474597,13.12,200,2,13.72,15,1,13.11,100,1,13.73,100,1,13.03,100,1,13.98,200,2,13,2,1,14.03,2,1,12.73,100,1,14.26,100,1,12.71,100,1,14.28,100,1,12.5,700,1,14.45,100,1,12.46,200,2,14.52,100,1,12.43,700,1,14.56,800,2,12.42,700,1,14.6,700,1,ARL,326729729
1756,2025-07-17T16:03:10.810312923Z,2025-07-17T16:03:10.810312923Z,10,2,1108,C,A,18,16.08,100,0,165601,272474600,13.12,200,2,13.72,15,1,13.11,100,1,13.73,100,1,13.03,100,1,13.98,200,2,13,2,1,14.03,2,1,12.73,100,1,14.26,100,1,12.71,100,1,14.28,100,1,12.5,700,1,14.45,100,1,12.46,200,2,14.52,100,1,12.43,700,1,14.56,800,2,12.42,700,1,14.6,700,1,ARL,326158989
1757,2025-07-17T16:03:10.810312923Z,2025-07-17T16:03:10.810312923Z,10,2,1108,A,A,17,15.79,100,130,165601,272474600,13.12,200,2,13.72,15,1,13.11,100,1,13.73,100,1,13.03,100,1,13.98,200,2,13,2,1,14.03,2,1,12.73,100,1,14.26,100,1,12.71,100,1,14.28,100,1,12.5,700,1,14.45,100,1,12.46,200,2,14.52,100,1,12.43,700,1,14.56,800,2,12.42,700,1,14.6,700,1,ARL,326729733
1758,2025-07-17T16:03:10.814480532Z,2025-07-17T16:03:10.814480532Z,10,2,1108,C,A,0,14.96,100,0,165738,272474635,13.12,200,2,13.72,15,1,13.11,100,1,13.73,100,1,13.03,100,1,13.98,200,2,13,2,1,14.03,2,1,12.73,100,1,14.26,100,1,12.71,100,1,14.28,100,1,12.5,700,1,14.45,100,1,12.46,200,2,14.52,100,1,12.43,700,1,14.56,800,2,12.42,700,1,14.6,700,1,ARL,326158997
1759,2025-07-17T16:03:10.814480532Z,2025-07-17T16:03:10.814480532Z,10,2,1108,A,A,11,14.7,100,130,165738,272474635,13.12,200,2,13.72,15,1,13.11,100,1,13.73,100,1,13.03,100,1,13.98,200,2,13,2,1,14.03,2,1,12.73,100,1,14.26,100,1,12.71,100,1,14.28,100,1,12.5,700,1,14.45,100,1,12.46,200,2,14.52,100,1,12.43,700,1,14.56,800,2,12.42,700,1,14.6,700,1,ARL,326729821
1760,2025-07-17T16:03:10.817700664Z,2025-07-17T16:03:10.817700664Z,10,2,1108,C,A,0,14.26,100,130,165402,272474675,13.12,200,2,13.72,15,1,13.11,100,1,13.73,100,1,13.03,100,1,13.98,200,2,13,2,1,14.03,2,1,12.73,100,1,14.28,100,1,12.71,100,1,14.45,100,1,12.5,700,1,14.52,100,1,12.46,200,2,14.56,800,2,12.43,700,1,14.6,700,1,12.42,700,1,14.68,1400,2,ARL,326159201
1761,2025-07-17T16:03:10.817754737Z,2025-07-17T16:03:10.817754737Z,10,2,1108,A,A,3,14,100,130,165233,272474676,13.12,200,2,13.72,15,1,13.11,100,1,13.73,100,1,13.03,100,1,13.98,200,2,13,2,1,14,100,1,12.73,100,1,14.03,2,1,12.71,100,1,14.28,100,1,12.5,700,1,14.45,100,1,12.46,200,2,14.52,100,1,12.43,700,1,14.56,800,2,12.42,700,1,14.6,700,1,ARL,326729929
1762,2025-07-17T16:03:10.843172549Z,2025-07-17T16:03:10.843172549Z,10,2,1108,A,A,16,15.66,100,130,165296,272474826,13.12,200,2,13.72,15,1,13.11,100,1,13.73,100,1,13.03,100,1,13.98,200,2,13,2,1,14,100,1,12.73,100,1,14.03,2,1,12.71,100,1,14.28,100,1,12.5,700,1,14.45,100,1,12.46,200,2,14.52,100,1,12.43,700,1,14.56,800,2,12.42,700,1,14.6,700,1,ARL,326730513
1763,2025-07-17T16:03:10.843184785Z,2025-07-17T16:03:10.843184785Z,10,2,1108,C,A,0,15.94,100,130,165375,272474827,13.12,200,2,13.72,15,1,13.11,100,1,13.73,100,1,13.03,100,1,13.98,200,2,13,2,1,14,100,1,12.73,100,1,14.03,2,1,12.71,100,1,14.28,100,1,12.5,700,1,14.45,100,1,12.46,200,2,14.52,100,1,12.43,700,1,14.56,800,2,12.42,700,1,14.6,700,1,ARL,325714909
1764,2025-07-17T16:03:10.843448998Z,2025-07-17T16:03:10.843448998Z,10,2,1108,C,A,2,13.98,100,0,166539,272474828,13.12,200,2,13.72,15,1,13.11,100,1,13.73,100,1,13.03,100,1,13.98,100,1,13,2,1,14,100,1,12.73,100,1,14.03,2,1,12.71,100,1,14.28,100,1,12.5,700,1,14.45,100,1,12.46,200,2,14.52,100,1,12.43,700,1,14.56,800,2,12.42,700,1,14.6,700,1,ARL,325719357
1765,2025-07-17T16:03:10.843449402Z,2025-07-17T16:03:10.843449402Z,10,2,1108,C,A,0,13.98,100,130,166135,272474829,13.12,200,2,13.72,15,1,13.11,100,1,13.73,100,1,13.03,100,1,14,100,1,13,2,1,14.03,2,1,12.73,100,1,14.28,100,1,12.71,100,1,14.45,100,1,12.5,700,1,14.52,100,1,12.46,200,2,14.56,800,2,12.43,700,1,14.6,700,1,12.42,700,1,14.68,1400,2,ARL,325719353
1766,2025-07-17T16:03:10.843462898Z,2025-07-17T16:03:10.843462898Z,10,2,1108,A,A,2,13.87,100,130,165348,272474830,13.12,200,2,13.72,15,1,13.11,100,1,13.73,100,1,13.03,100,1,13.87,100,1,13,2,1,14,100,1,12.73,100,1,14.03,2,1,12.71,100,1,14.28,100,1,12.5,700,1,14.45,100,1,12.46,200,2,14.52,100,1,12.43,700,1,14.56,800,2,12.42,700,1,14.6,700,1,ARL,326730517
1767,2025-07-17T16:03:10.843464369Z,2025-07-17T16:03:10.843464369Z,10,2,1108,A,A,2,13.87,100,130,165264,272474831,13.12,200,2,13.72,15,1,13.11,100,1,13.73,100,1,13.03,100,1,13.87,200,2,13,2,1,14,100,1,12.73,100,1,14.03,2,1,12.71,100,1,14.28,100,1,12.5,700,1,14.45,100,1,12.46,200,2,14.52,100,1,12.43,700,1,14.56,800,2,12.42,700,1,14.6,700,1,ARL,326730521
1768,2025-07-17T16:03:16.348023740Z,2025-07-17T16:03:16.348023740Z,10,2,1108,A,A,0,13.69,15,130,165337,272557172,13.12,200,2,13.69,15,1,13.11,100,1,13.72,15,1,13.03,100,1,13.73,100,1,13,2,1,13.87,200,2,12.73,100,1,14,100,1,12.71,100,1,14.03,2,1,12.5,700,1,14.28,100,1,12.46,200,2,14.45,100,1,12.43,700,1,14.52,100,1,12.42,700,1,14.56,800,2,ARL,326835877
1769,2025-07-17T16:03:16.348302787Z,2025-07-17T16:03:16.348302787Z,10,2,1108,C,A,12,14.7,100,0,166037,272557230,13.12,200,2,13.69,15,1,13.11,100,1,13.72,15,1,13.03,100,1,13.73,100,1,13,2,1,13.87,200,2,12.73,100,1,14,100,1,12.71,100,1,14.03,2,1,12.5,700,1,14.28,100,1,12.46,200,2,14.45,100,1,12.43,700,1,14.52,100,1,12.42,700,1,14.56,800,2,ARL,326551829
1770,2025-07-17T16:03:16.348302787Z,2025-07-17T16:03:16.348302787Z,10,2,1108,A,A,10,14.58,100,130,166037,272557230,13.12,200,2,13.69,15,1,13.11,100,1,13.72,15,1,13.03,100,1,13.73,100,1,13,2,1,13.87,200,2,12.73,100,1,14,100,1,12.71,100,1,14.03,2,1,12.5,700,1,14.28,100,1,12.46,200,2,14.45,100,1,12.43,700,1,14.52,100,1,12.42,700,1,14.56,800,2,ARL,326835885
1771,2025-07-17T16:03:16.349513354Z,2025-07-17T16:03:16.349513354Z,10,2,1108,C,A,13,14.7,100,0,166595,272557430,13.12,200,2,13.69,15,1,13.11,100,1,13.72,15,1,13.03,100,1,13.73,100,1,13,2,1,13.87,200,2,12.73,100,1,14,100,1,12.71,100,1,14.03,2,1,12.5,700,1,14.28,100,1,12.46,200,2,14.45,100,1,12.43,700,1,14.52,100,1,12.42,700,1,14.56,800,2,ARL,326551237
1772,2025-07-17T16:03:16.349513354Z,2025-07-17T16:03:16.349513354Z,10,2,1108,A,A,10,14.58,100,130,166595,272557430,13.12,200,2,13.69,15,1,13.11,100,1,13.72,15,1,13.03,100,1,13.73,100,1,13,2,1,13.87,200,2,12.73,100,1,14,100,1,12.71,100,1,14.03,2,1,12.5,700,1,14.28,100,1,12.46,200,2,14.45,100,1,12.43,700,1,14.52,100,1,12.42,700,1,14.56,800,2,ARL,326836085
1773,2025-07-17T16:03:16.351845457Z,2025-07-17T16:03:16.351845457Z,10,2,1108,C,A,0,13.73,100,0,166374,272557789,13.12,200,2,13.69,15,1,13.11,100,1,13.72,15,1,13.03,100,1,13.87,200,2,13,2,1,14,100,1,12.73,100,1,14.03,2,1,12.71,100,1,14.28,100,1,12.5,700,1,14.45,100,1,12.46,200,2,14.52,100,1,12.43,700,1,14.56,800,2,12.42,700,1,14.58,200,2,ARL,326729685
1774,2025-07-17T16:03:16.351845457Z,2025-07-17T16:03:16.351845457Z,10,2,1108,A,A,1,13.7,100,130,166374,272557789,13.12,200,2,13.69,15,1,13.11,100,1,13.7,100,1,13.03,100,1,13.72,15,1,13,2,1,13.87,200,2,12.73,100,1,14,100,1,12.71,100,1,14.03,2,1,12.5,700,1,14.28,100,1,12.46,200,2,14.45,100,1,12.43,700,1,14.52,100,1,12.42,700,1,14.56,800,2,ARL,326836533
1775,2025-07-17T16:03:16.365819243Z,2025-07-17T16:03:16.365819243Z,10,2,1108,C,A,0,15.38,100,0,165919,272559024,13.12,200,2,13.69,15,1,13.11,100,1,13.7,100,1,13.03,100,1,13.72,15,1,13,2,1,13.87,200,2,12.73,100,1,14,100,1,12.71,100,1,14.03,2,1,12.5,700,1,14.28,100,1,12.46,200,2,14.45,100,1,12.43,700,1,14.52,100,1,12.42,700,1,14.56,800,2,ARL,325714965
1776,2025-07-17T16:03:16.365819243Z,2025-07-17T16:03:16.365819243Z,10,2,1108,A,A,15,15.07,100,130,165919,272559024,13.12,200,2,13.69,15,1,13.11,100,1,13.7,100,1,13.03,100,1,13.72,15,1,13,2,1,13.87,200,2,12.73,100,1,14,100,1,12.71,100,1,14.03,2,1,12.5,700,1,14.28,100,1,12.46,200,2,14.45,100,1,12.43,700,1,14.52,100,1,12.42,700,1,14.56,800,2,ARL,326837501
1777,2025-07-17T16:03:18.804159952Z,2025-07-17T16:03:18.804159952Z,10,2,1108,C,A,0,13.69,15,130,165126,272609485,13.12,200,2,13.7,100,1,13.11,100,1,13.72,15,1,13.03,100,1,13.87,200,2,13,2,1,14,100,1,12.73,100,1,14.03,2,1,12.71,100,1,14.28,100,1,12.5,700,1,14.45,100,1,12.46,200,2,14.52,100,1,12.43,700,1,14.56,800,2,12.42,700,1,14.58,200,2,ARL,326835877
1778,2025-07-17T16:03:18.804202246Z,2025-07-17T16:03:18.804202246Z,10,2,1108,C,A,0,13.7,100,130,165314,272609486,13.12,200,2,13.72,15,1,13.11,100,1,13.87,200,2,13.03,100,1,14,100,1,13,2,1,14.03,2,1,12.73,100,1,14.28,100,1,12.71,100,1,14.45,100,1,12.5,700,1,14.52,100,1,12.46,200,2,14.56,800,2,12.43,700,1,14.58,200,2,12.42,700,1,14.6,700,1,ARL,326836533
1779,2025-07-17T16:03:18.804933488Z,2025-07-17T16:03:18.804933488Z,10,2,1108,C,A,0,14.79,100,0,165630,272609510,13.12,200,2,13.72,15,1,13.11,100,1,13.87,200,2,13.03,100,1,14,100,1,13,2,1,14.03,2,1,12.73,100,1,14.28,100,1,12.71,100,1,14.45,100,1,12.5,700,1,14.52,100,1,12.46,200,2,14.56,800,2,12.43,700,1,14.58,200,2,12.42,700,1,14.6,700,1,ARL,326729705
1780,2025-07-17T16:03:18.804933488Z,2025-07-17T16:03:18.804933488Z,10,2,1108,A,A,12,14.95,100,130,165630,272609510,13.12,200,2,13.72,15,1,13.11,100,1,13.87,200,2,13.03,100,1,14,100,1,13,2,1,14.03,2,1,12.73,100,1,14.28,100,1,12.71,100,1,14.45,100,1,12.5,700,1,14.52,100,1,12.46,200,2,14.56,800,2,12.43,700,1,14.58,200,2,12.42,700,1,14.6,700,1,ARL,326892717
1781,2025-07-17T16:03:18.805126035Z,2025-07-17T16:03:18.805126035Z,10,2,1108,C,A,11,14.7,100,0,165594,272609526,13.12,200,2,13.72,15,1,13.11,100,1,13.87,200,2,13.03,100,1,14,100,1,13,2,1,14.03,2,1,12.73,100,1,14.28,100,1,12.71,100,1,14.45,100,1,12.5,700,1,14.52,100,1,12.46,200,2,14.56,800,2,12.43,700,1,14.58,200,2,12.42,700,1,14.6,700,1,ARL,326729721
1782,2025-07-17T16:03:18.805126035Z,2025-07-17T16:03:18.805126035Z,10,2,1108,A,A,12,14.85,100,130,165594,272609526,13.12,200,2,13.72,15,1,13.11,100,1,13.87,200,2,13.03,100,1,14,100,1,13,2,1,14.03,2,1,12.73,100,1,14.28,100,1,12.71,100,1,14.45,100,1,12.5,700,1,14.52,100,1,12.46,200,2,14.56,800,2,12.43,700,1,14.58,200,2,12.42,700,1,14.6,700,1,ARL,326892721
1783,2025-07-17T16:03:18.805283236Z,2025-07-17T16:03:18.805283236Z,10,2,1108,C,A,0,13.72,15,130,165853,272609541,13.12,200,2,13.87,200,2,13.11,100,1,14,100,1,13.03,100,1,14.03,2,1,13,2,1,14.28,100,1,12.73,100,1,14.45,100,1,12.71,100,1,14.52,100,1,12.5,700,1,14.56,800,2,12.46,200,2,14.58,200,2,12.43,700,1,14.6,700,1,12.42,700,1,14.68,1400,2,ARL,326729677
1784,2025-07-17T16:03:18.806370373Z,2025-07-17T16:03:18.806370373Z,10,2,1108,C,A,7,14.58,100,0,165530,272609577,13.12,200,2,13.87,200,2,13.11,100,1,14,100,1,13.03,100,1,14.03,2,1,13,2,1,14.28,100,1,12.73,100,1,14.45,100,1,12.71,100,1,14.52,100,1,12.5,700,1,14.56,800,2,12.46,200,2,14.58,100,1,12.43,700,1,14.6,700,1,12.42,700,1,14.68,1400,2,ARL,326835885
1785,2025-07-17T16:03:18.806370373Z,2025-07-17T16:03:18.806370373Z,10,2,1108,A,A,11,14.76,100,130,165530,272609577,13.12,200,2,13.87,200,2,13.11,100,1,14,100,1,13.03,100,1,14.03,2,1,13,2,1,14.28,100,1,12.73,100,1,14.45,100,1,12.71,100,1,14.52,100,1,12.5,700,1,14.56,800,2,12.46,200,2,14.58,100,1,12.43,700,1,14.6,700,1,12.42,700,1,14.68,1400,2,ARL,326892817
1786,2025-07-17T16:03:18.806637004Z,2025-07-17T16:03:18.806637004Z,10,2,1108,C,A,0,14.58,100,0,165585,272609583,13.12,200,2,13.87,200,2,13.11,100,1,14,100,1,13.03,100,1,14.03,2,1,13,2,1,14.28,100,1,12.73,100,1,14.45,100,1,12.71,100,1,14.52,100,1,12.5,700,1,14.56,800,2,12.46,200,2,14.6,700,1,12.43,700,1,14.68,1400,2,12.42,700,1,14.7,100,1,ARL,326836085
1787,2025-07-17T16:03:18.806637004Z,2025-07-17T16:03:18.806637004Z,10,2,1108,A,A,10,14.76,100,130,165585,272609583,13.12,200,2,13.87,200,2,13.11,100,1,14,100,1,13.03,100,1,14.03,2,1,13,2,1,14.28,100,1,12.73,100,1,14.45,100,1,12.71,100,1,14.52,100,1,12.5,700,1,14.56,800,2,12.46,200,2,14.6,700,1,12.43,700,1,14.68,1400,2,12.42,700,1,14.7,100,1,ARL,326892825
1788,2025-07-17T16:03:18.809540733Z,2025-07-17T16:03:18.809540733Z,10,2,1108,C,A,0,14.52,100,0,165601,272609656,13.12,200,2,13.87,200,2,13.11,100,1,14,100,1,13.03,100,1,14.03,2,1,13,2,1,14.28,100,1,12.73,100,1,14.45,100,1,12.71,100,1,14.56,800,2,12.5,700,1,14.6,700,1,12.46,200,2,14.68,1400,2,12.43,700,1,14.7,100,1,12.42,700,1,14.76,200,2,ARL,326729729
1789,2025-07-17T16:03:18.809540733Z,2025-07-17T16:03:18.809540733Z,10,2,1108,A,A,7,14.66,100,130,165601,272609656,13.12,200,2,13.87,200,2,13.11,100,1,14,100,1,13.03,100,1,14.03,2,1,13,2,1,14.28,100,1,12.73,100,1,14.45,100,1,12.71,100,1,14.56,800,2,12.5,700,1,14.6,700,1,12.46,200,2,14.66,100,1,12.43,700,1,14.68,1400,2,12.42,700,1,14.7,100,1,ARL,326892885
1790,2025-07-17T16:03:18.809683187Z,2025-07-17T16:03:18.809683187Z,10,2,1108,C,A,0,15.79,100,0,165478,272609658,13.12,200,2,13.87,200,2,13.11,100,1,14,100,1,13.03,100,1,14.03,2,1,13,2,1,14.28,100,1,12.73,100,1,14.45,100,1,12.71,100,1,14.56,800,2,12.5,700,1,14.6,700,1,12.46,200,2,14.66,100,1,12.43,700,1,14.68,1400,2,12.42,700,1,14.7,100,1,ARL,326729733
1791,2025-07-17T16:03:18.809683187Z,2025-07-17T16:03:18.809683187Z,10,2,1108,A,A,17,15.96,100,130,165478,272609658,13.12,200,2,13.87,200,2,13.11,100,1,14,100,1,13.03,100,1,14.03,2,1,13,2,1,14.28,100,1,12.73,100,1,14.45,100,1,12.71,100,1,14.56,800,2,12.5,700,1,14.6,700,1,12.46,200,2,14.66,100,1,12.43,700,1,14.68,1400,2,12.42,700,1,14.7,100,1,ARL,326892889
1792,2025-07-17T16:03:18.811941680Z,2025-07-17T16:03:18.811941680Z,10,2,1108,C,A,0,17.44,100,0,165526,272609679,13.12,200,2,13.87,200,2,13.11,100,1,14,100,1,13.03,100,1,14.03,2,1,13,2,1,14.28,100,1,12.73,100,1,14.45,100,1,12.71,100,1,14.56,800,2,12.5,700,1,14.6,700,1,12.46,200,2,14.66,100,1,12.43,700,1,14.68,1400,2,12.42,700,1,14.7,100,1,ARL,326729725
1793,2025-07-17T16:03:18.811941680Z,2025-07-17T16:03:18.811941680Z,10,2,1108,A,A,20,17.62,100,130,165526,272609679,13.12,200,2,13.87,200,2,13.11,100,1,14,100,1,13.03,100,1,14.03,2,1,13,2,1,14.28,100,1,12.73,100,1,14.45,100,1,12.71,100,1,14.56,800,2,12.5,700,1,14.6,700,1,12.46,200,2,14.66,100,1,12.43,700,1,14.68,1400,2,12.42,700,1,14.7,100,1,ARL,326892921
1794,2025-07-17T16:03:18.818080239Z,2025-07-17T16:03:18.818080239Z,10,2,1108,C,A,0,14,100,130,165390,272609768,13.12,200,2,13.87,200,2,13.11,100,1,14.03,2,1,13.03,100,1,14.28,100,1,13,2,1,14.45,100,1,12.73,100,1,14.56,800,2,12.71,100,1,14.6,700,1,12.5,700,1,14.66,100,1,12.46,200,2,14.68,1400,2,12.43,700,1,14.7,100,1,12.42,700,1,14.76,200,2,ARL,326729929
1795,2025-07-17T16:03:18.818135688Z,2025-07-17T16:03:18.818135688Z,10,2,1108,A,A,2,14.15,100,130,165455,272609769,13.12,200,2,13.87,200,2,13.11,100,1,14.03,2,1,13.03,100,1,14.15,100,1,13,2,1,14.28,100,1,12.73,100,1,14.45,100,1,12.71,100,1,14.56,800,2,12.5,700,1,14.6,700,1,12.46,200,2,14.66,100,1,12.43,700,1,14.68,1400,2,12.42,700,1,14.7,100,1,ARL,326893213
1796,2025-07-17T16:03:18.868254768Z,2025-07-17T16:03:18.868254768Z,10,2,1108,C,A,0,14.7,100,0,165735,272610397,13.12,200,2,13.87,200,2,13.11,100,1,14.03,2,1,13.03,100,1,14.15,100,1,13,2,1,14.28,100,1,12.73,100,1,14.45,100,1,12.71,100,1,14.56,800,2,12.5,700,1,14.6,700,1,12.46,200,2,14.66,100,1,12.43,700,1,14.68,1400,2,12.42,700,1,14.76,200,2,ARL,326729821
1797,2025-07-17T16:03:18.868254768Z,2025-07-17T16:03:18.868254768Z,10,2,1108,A,A,10,14.85,100,130,165735,272610397,13.12,200,2,13.87,200,2,13.11,100,1,14.03,2,1,13.03,100,1,14.15,100,1,13,2,1,14.28,100,1,12.73,100,1,14.45,100,1,12.71,100,1,14.56,800,2,12.5,700,1,14.6,700,1,12.46,200,2,14.66,100,1,12.43,700,1,14.68,1400,2,12.42,700,1,14.76,200,2,ARL,326893961
1798,2025-07-17T16:03:19.191054306Z,2025-07-17T16:03:19.191054306Z,10,2,1108,A,A,1,13.88,100,130,165201,272614303,13.12,200,2,13.87,200,2,13.11,100,1,13.88,100,1,13.03,100,1,14.03,2,1,13,2,1,14.15,100,1,12.73,100,1,14.28,100,1,12.71,100,1,14.45,100,1,12.5,700,1,14.56,800,2,12.46,200,2,14.6,700,1,12.43,700,1,14.66,100,1,12.42,700,1,14.68,1400,2,ARL,326899125
1799,2025-07-17T16:03:27.436158395Z,2025-07-17T16:03:27.436158395Z,10,2,1108,A,A,4,14.25,53,130,165556,272788767,13.12,200,2,13.87,200,2,13.11,100,1,13.88,100,1,13.03,100,1,14.03,2,1,13,2,1,14.15,100,1,12.73,100,1,14.25,53,1,12.71,100,1,14.28,100,1,12.5,700,1,14.45,100,1,12.46,200,2,14.56,800,2,12.43,700,1,14.6,700,1,12.42,700,1,14.66,100,1,ARL,327112281
1800,2025-07-17T16:03:27.436715001Z,2025-07-17T16:03:27.436715001Z,10,2,1108,C,B,0,12.23,100,0,165767,272788774,13.12,200,2,13.87,200,2,13.11,100,1,13.88,100,1,13.03,100,1,14.03,2,1,13,2,1,14.15,100,1,12.73,100,1,14.25,53,1,12.71,100,1,14.28,100,1,12.5,700,1,14.45,100,1,12.46,200,2,14.56,800,2,12.43,700,1,14.6,700,1,12.42,700,1,14.66,100,1,ARL,291964745
1801,2025-07-17T16:03:27.436715001Z,2025-07-17T16:03:27.436715001Z,10,2,1108,A,B,13,12.1,100,130,165767,272788774,13.12,200,2,13.87,200,2,13.11,100,1,13.88,100,1,13.03,100,1,14.03,2,1,13,2,1,14.15,100,1,12.73,100,1,14.25,53,1,12.71,100,1,14.28,100,1,12.5,700,1,14.45,100,1,12.46,200,2,14.56,800,2,12.43,700,1,14.6,700,1,12.42,700,1,14.66,100,1,ARL,327112289
1802,2025-07-17T16:03:27.438400828Z,2025-07-17T16:03:27.438400828Z,10,2,1108,C,B,12,12.34,100,0,166143,272788792,13.12,200,2,13.87,200,2,13.11,100,1,13.88,100,1,13.03,100,1,14.03,2,1,13,2,1,14.15,100,1,12.73,100,1,14.25,53,1,12.71,100,1,14.28,100,1,12.5,700,1,14.45,100,1,12.46,200,2,14.56,800,2,12.43,700,1,14.6,700,1,12.42,700,1,14.66,100,1,ARL,285586113
1803,2025-07-17T16:03:27.438400828Z,2025-07-17T16:03:27.438400828Z,10,2,1108,A,B,13,12.2,100,130,166143,272788792,13.12,200,2,13.87,200,2,13.11,100,1,13.88,100,1,13.03,100,1,14.03,2,1,13,2,1,14.15,100,1,12.73,100,1,14.25,53,1,12.71,100,1,14.28,100,1,12.5,700,1,14.45,100,1,12.46,200,2,14.56,800,2,12.43,700,1,14.6,700,1,12.42,700,1,14.66,100,1,ARL,327112385
1804,2025-07-17T16:03:27.438437969Z,2025-07-17T16:03:27.438437969Z,10,2,1108,C,B,0,12.34,100,0,165595,272788793,13.12,200,2,13.87,200,2,13.11,100,1,13.88,100,1,13.03,100,1,14.03,2,1,13,2,1,14.15,100,1,12.73,100,1,14.25,53,1,12.71,100,1,14.28,100,1,12.5,700,1,14.45,100,1,12.46,200,2,14.56,800,2,12.43,700,1,14.6,700,1,12.42,700,1,14.66,100,1,ARL,285586189
1805,2025-07-17T16:03:27.438437969Z,2025-07-17T16:03:27.438437969Z,10,2,1108,A,B,12,12.2,100,130,165595,272788793,13.12,200,2,13.87,200,2,13.11,100,1,13.88,100,1,13.03,100,1,14.03,2,1,13,2,1,14.15,100,1,12.73,100,1,14.25,53,1,12.71,100,1,14.28,100,1,12.5,700,1,14.45,100,1,12.46,200,2,14.56,800,2,12.43,700,1,14.6,700,1,12.42,700,1,14.66,100,1,ARL,327112393
1806,2025-07-17T16:03:27.453845141Z,2025-07-17T16:03:27.453845141Z,10,2,1108,C,B,0,13.03,100,130,165214,272788897,13.12,200,2,13.87,200,2,13.11,100,1,13.88,100,1,13,2,1,14.03,2,1,12.73,100,1,14.15,100,1,12.71,100,1,14.25,53,1,12.5,700,1,14.28,100,1,12.46,200,2,14.45,100,1,12.43,700,1,14.56,800,2,12.42,700,1,14.6,700,1,12.37,700,1,14.66,100,1,ARL,285586293
1807,2025-07-17T16:03:27.453894425Z,2025-07-17T16:03:27.453894425Z,10,2,1108,A,B,3,12.95,100,130,165294,272788898,13.12,200,2,13.87,200,2,13.11,100,1,13.88,100,1,13,2,1,14.03,2,1,12.95,100,1,14.15,100,1,12.73,100,1,14.25,53,1,12.71,100,1,14.28,100,1,12.5,700,1,14.45,100,1,12.46,200,2,14.56,800,2,12.43,700,1,14.6,700,1,12.42,700,1,14.66,100,1,ARL,327112565
1808,2025-07-17T16:03:27.454726901Z,2025-07-17T16:03:27.454726901Z,10,2,1108,C,B,0,12.95,100,130,165420,272788942,13.12,200,2,13.87,200,2,13.11,100,1,13.88,100,1,13,2,1,14.03,2,1,12.73,100,1,14.15,100,1,12.71,100,1,14.25,53,1,12.5,700,1,14.28,100,1,12.46,200,2,14.45,100,1,12.43,700,1,14.56,800,2,12.42,700,1,14.6,700,1,12.37,700,1,14.66,100,1,ARL,327112565
1809,2025-07-17T16:03:27.454773691Z,2025-07-17T16:03:27.454773691Z,10,2,1108,A,B,3,12.86,100,130,165909,272788943,13.12,200,2,13.87,200,2,13.11,100,1,13.88,100,1,13,2,1,14.03,2,1,12.86,100,1,14.15,100,1,12.73,100,1,14.25,53,1,12.71,100,1,14.28,100,1,12.5,700,1,14.45,100,1,12.46,200,2,14.56,800,2,12.43,700,1,14.6,700,1,12.42,700,1,14.66,100,1,ARL,327112577
1810,2025-07-17T16:03:27.517585374Z,2025-07-17T16:03:27.517585374Z,10,2,1108,C,B,7,12.46,100,130,165896,272790695,13.12,200,2,13.87,200,2,13.11,100,1,13.88,100,1,13,2,1,14.03,2,1,12.86,100,1,14.15,100,1,12.73,100,1,14.25,53,1,12.71,100,1,14.28,100,1,12.5,700,1,14.45,100,1,12.46,100,1,14.56,800,2,12.43,700,1,14.6,700,1,12.42,700,1,14.66,100,1,ARL,285587281
1811,2025-07-17T16:03:27.517699408Z,2025-07-17T16:03:27.517699408Z,10,2,1108,A,B,12,12.33,100,130,165267,272790696,13.12,200,2,13.87,200,2,13.11,100,1,13.88,100,1,13,2,1,14.03,2,1,12.86,100,1,14.15,100,1,12.73,100,1,14.25,53,1,12.71,100,1,14.28,100,1,12.5,700,1,14.45,100,1,12.46,100,1,14.56,800,2,12.43,700,1,14.6,700,1,12.42,700,1,14.66,100,1,ARL,327114465
1812,2025-07-17T16:03:27.536178718Z,2025-07-17T16:03:27.536178718Z,10,2,1108,C,A,0,14.25,53,130,165225,272791410,13.12,200,2,13.87,200,2,13.11,100,1,13.88,100,1,13,2,1,14.03,2,1,12.86,100,1,14.15,100,1,12.73,100,1,14.28,100,1,12.71,100,1,14.45,100,1,12.5,700,1,14.56,800,2,12.46,100,1,14.6,700,1,12.43,700,1,14.66,100,1,12.42,700,1,14.68,1400,2,ARL,327112281
1813,2025-07-17T16:03:56.548182793Z,2025-07-17T16:03:56.548182793Z,10,2,1108,A,A,0,13.8,15,130,165254,273208310,13.12,200,2,13.8,15,1,13.11,100,1,13.87,200,2,13,2,1,13.88,100,1,12.86,100,1,14.03,2,1,12.73,100,1,14.15,100,1,12.71,100,1,14.28,100,1,12.5,700,1,14.45,100,1,12.46,100,1,14.56,800,2,12.43,700,1,14.6,700,1,12.42,700,1,14.66,100,1,ARL,327675057
1814,2025-07-17T16:03:56.548446336Z,2025-07-17T16:03:56.548446336Z,10,2,1108,C,A,0,13.88,100,0,165380,273208316,13.12,200,2,13.8,15,1,13.11,100,1,13.87,200,2,13,2,1,14.03,2,1,12.86,100,1,14.15,100,1,12.73,100,1,14.28,100,1,12.71,100,1,14.45,100,1,12.5,700,1,14.56,800,2,12.46,100,1,14.6,700,1,12.43,700,1,14.66,100,1,12.42,700,1,14.68,1400,2,ARL,326899125
1815,2025-07-17T16:03:56.548446336Z,2025-07-17T16:03:56.548446336Z,10,2,1108,A,A,1,13.81,100,130,165380,273208316,13.12,200,2,13.8,15,1,13.11,100,1,13.81,100,1,13,2,1,13.87,200,2,12.86,100,1,14.03,2,1,12.73,100,1,14.15,100,1,12.71,100,1,14.28,100,1,12.5,700,1,14.45,100,1,12.46,100,1,14.56,800,2,12.43,700,1,14.6,700,1,12.42,700,1,14.66,100,1,ARL,327675065
1816,2025-07-17T16:03:56.549188993Z,2025-07-17T16:03:56.549188993Z,10,2,1108,C,A,0,14.95,100,0,165412,273208325,13.12,200,2,13.8,15,1,13.11,100,1,13.81,100,1,13,2,1,13.87,200,2,12.86,100,1,14.03,2,1,12.73,100,1,14.15,100,1,12.71,100,1,14.28,100,1,12.5,700,1,14.45,100,1,12.46,100,1,14.56,800,2,12.43,700,1,14.6,700,1,12.42,700,1,14.66,100,1,ARL,326892717
1817,2025-07-17T16:03:56.549188993Z,2025-07-17T16:03:56.549188993Z,10,2,1108,A,A,13,14.88,100,130,165412,273208325,13.12,200,2,13.8,15,1,13.11,100,1,13.81,100,1,13,2,1,13.87,200,2,12.86,100,1,14.03,2,1,12.73,100,1,14.15,100,1,12.71,100,1,14.28,100,1,12.5,700,1,14.45,100,1,12.46,100,1,14.56,800,2,12.43,700,1,14.6,700,1,12.42,700,1,14.66,100,1,ARL,327675093
1818,2025-07-17T16:04:06.233692491Z,2025-07-17T16:04:06.233692491Z,10,2,1108,C,A,11,14.76,100,0,166120,273345719,13.12,200,2,13.8,15,1,13.11,100,1,13.81,100,1,13,2,1,13.87,200,2,12.86,100,1,14.03,2,1,12.73,100,1,14.15,100,1,12.71,100,1,14.28,100,1,12.5,700,1,14.45,100,1,12.46,100,1,14.56,800,2,12.43,700,1,14.6,700,1,12.42,700,1,14.66,100,1,ARL,326892825
1819,2025-07-17T16:04:06.233692491Z,2025-07-17T16:04:06.233692491Z,10,2,1108,A,A,9,14.64,100,130,166120,273345719,13.12,200,2,13.8,15,1,13.11,100,1,13.81,100,1,13,2,1,13.87,200,2,12.86,100,1,14.03,2,1,12.73,100,1,14.15,100,1,12.71,100,1,14.28,100,1,12.5,700,1,14.45,100,1,12.46,100,1,14.56,800,2,12.43,700,1,14.6,700,1,12.42,700,1,14.64,100,1,ARL,327856297
1820,2025-07-17T16:04:06.234433294Z,2025-07-17T16:04:06.234433294Z,10,2,1108,C,A,0,14.76,100,0,166904,273345721,13.12,200,2,13.8,15,1,13.11,100,1,13.81,100,1,13,2,1,13.87,200,2,12.86,100,1,14.03,2,1,12.73,100,1,14.15,100,1,12.71,100,1,14.28,100,1,12.5,700,1,14.45,100,1,12.46,100,1,14.56,800,2,12.43,700,1,14.6,700,1,12.42,700,1,14.64,100,1,ARL,326892817
1821,2025-07-17T16:04:06.234433294Z,2025-07-17T16:04:06.234433294Z,10,2,1108,A,A,9,14.64,100,130,166904,273345721,13.12,200,2,13.8,15,1,13.11,100,1,13.81,100,1,13,2,1,13.87,200,2,12.86,100,1,14.03,2,1,12.73,100,1,14.15,100,1,12.71,100,1,14.28,100,1,12.5,700,1,14.45,100,1,12.46,100,1,14.56,800,2,12.43,700,1,14.6,700,1,12.42,700,1,14.64,200,2,ARL,327856309
1822,2025-07-17T16:04:06.510748731Z,2025-07-17T16:04:06.510748731Z,10,2,1108,A,A,0,13.72,15,130,165370,273352664,13.12,200,2,13.72,15,1,13.11,100,1,13.8,15,1,13,2,1,13.81,100,1,12.86,100,1,13.87,200,2,12.73,100,1,14.03,2,1,12.71,100,1,14.15,100,1,12.5,700,1,14.28,100,1,12.46,100,1,14.45,100,1,12.43,700,1,14.56,800,2,12.42,700,1,14.6,700,1,ARL,327863853
1823,2025-07-17T16:04:06.512244746Z,2025-07-17T16:04:06.512244746Z,10,2,1108,C,A,0,13.81,100,0,168356,273352888,13.12,200,2,13.72,15,1,13.11,100,1,13.8,15,1,13,2,1,13.87,200,2,12.86,100,1,14.03,2,1,12.73,100,1,14.15,100,1,12.71,100,1,14.28,100,1,12.5,700,1,14.45,100,1,12.46,100,1,14.56,800,2,12.43,700,1,14.6,700,1,12.42,700,1,14.64,200,2,ARL,327675065
1824,2025-07-17T16:04:06.512244746Z,2025-07-17T16:04:06.512244746Z,10,2,1108,A,A,1,13.73,100,128,168356,273352888,13.12,200,2,13.72,15,1,13.11,100,1,13.73,100,1,13,2,1,13.8,15,1,12.86,100,1,13.87,200,2,12.73,100,1,14.03,2,1,12.71,100,1,14.15,100,1,12.5,700,1,14.28,100,1,12.46,100,1,14.45,100,1,12.43,700,1,14.56,800,2,12.42,700,1,14.6,700,1,ARL,327864137
1825,2025-07-17T16:04:06.513497276Z,2025-07-17T16:04:06.513497276Z,10,2,1108,C,A,0,14.88,100,0,178023,273353923,13.12,200,2,13.72,15,1,13.11,100,1,13.73,100,1,13,2,1,13.8,15,1,12.86,100,1,13.87,200,2,12.73,100,1,14.03,2,1,12.71,100,1,14.15,100,1,12.5,700,1,14.28,100,1,12.46,100,1,14.45,100,1,12.43,700,1,14.56,800,2,12.42,700,1,14.6,700,1,ARL,327675093
1826,2025-07-17T16:04:06.513497276Z,2025-07-17T16:04:06.513497276Z,10,2,1108,A,A,13,14.79,100,128,178023,273353923,13.12,200,2,13.72,15,1,13.11,100,1,13.73,100,1,13,2,1,13.8,15,1,12.86,100,1,13.87,200,2,12.73,100,1,14.03,2,1,12.71,100,1,14.15,100,1,12.5,700,1,14.28,100,1,12.46,100,1,14.45,100,1,12.43,700,1,14.56,800,2,12.42,700,1,14.6,700,1,ARL,327864893
1827,2025-07-17T16:04:06.522687474Z,2025-07-17T16:04:06.522687474Z,10,2,1108,C,A,14,14.85,100,0,165687,273357758,13.12,200,2,13.72,15,1,13.11,100,1,13.73,100,1,13,2,1,13.8,15,1,12.86,100,1,13.87,200,2,12.73,100,1,14.03,2,1,12.71,100,1,14.15,100,1,12.5,700,1,14.28,100,1,12.46,100,1,14.45,100,1,12.43,700,1,14.56,800,2,12.42,700,1,14.6,700,1,ARL,326892721
1828,2025-07-17T16:04:06.522687474Z,2025-07-17T16:04:06.522687474Z,10,2,1108,A,A,13,14.7,100,130,165687,273357758,13.12,200,2,13.72,15,1,13.11,100,1,13.73,100,1,13,2,1,13.8,15,1,12.86,100,1,13.87,200,2,12.73,100,1,14.03,2,1,12.71,100,1,14.15,100,1,12.5,700,1,14.28,100,1,12.46,100,1,14.45,100,1,12.43,700,1,14.56,800,2,12.42,700,1,14.6,700,1,ARL,327868421
1829,2025-07-17T16:04:06.525385108Z,2025-07-17T16:04:06.525385108Z,10,2,1108,C,A,0,14.15,100,130,165707,273358260,13.12,200,2,13.72,15,1,13.11,100,1,13.73,100,1,13,2,1,13.8,15,1,12.86,100,1,13.87,200,2,12.73,100,1,14.03,2,1,12.71,100,1,14.28,100,1,12.5,700,1,14.45,100,1,12.46,100,1,14.56,800,2,12.43,700,1,14.6,700,1,12.42,700,1,14.64,200,2,ARL,326893213
1830,2025-07-17T16:04:06.525442486Z,2025-07-17T16:04:06.525442486Z,10,2,1108,A,A,4,14,100,128,166260,273358273,13.12,200,2,13.72,15,1,13.11,100,1,13.73,100,1,13,2,1,13.8,15,1,12.86,100,1,13.87,200,2,12.73,100,1,14,100,1,12.71,100,1,14.03,2,1,12.5,700,1,14.28,100,1,12.46,100,1,14.45,100,1,12.43,700,1,14.56,800,2,12.42,700,1,14.6,700,1,ARL,327869193
1831,2025-07-17T16:04:06.528043934Z,2025-07-17T16:04:06.528043934Z,10,2,1108,C,A,0,14.66,100,130,166821,273358598,13.12,200,2,13.72,15,1,13.11,100,1,13.73,100,1,13,2,1,13.8,15,1,12.86,100,1,13.87,200,2,12.73,100,1,14,100,1,12.71,100,1,14.03,2,1,12.5,700,1,14.28,100,1,12.46,100,1,14.45,100,1,12.43,700,1,14.56,800,2,12.42,700,1,14.6,700,1,ARL,326892885
1832,2025-07-17T16:04:06.528161631Z,2025-07-17T16:04:06.528161631Z,10,2,1108,A,A,8,14.52,100,128,167417,273358642,13.12,200,2,13.72,15,1,13.11,100,1,13.73,100,1,13,2,1,13.8,15,1,12.86,100,1,13.87,200,2,12.73,100,1,14,100,1,12.71,100,1,14.03,2,1,12.5,700,1,14.28,100,1,12.46,100,1,14.45,100,1,12.43,700,1,14.52,100,1,12.42,700,1,14.56,800,2,ARL,327869529
1833,2025-07-17T16:04:06.543314706Z,2025-07-17T16:04:06.543314706Z,10,2,1108,C,A,0,17.62,100,0,165606,273359491,13.12,200,2,13.72,15,1,13.11,100,1,13.73,100,1,13,2,1,13.8,15,1,12.86,100,1,13.87,200,2,12.73,100,1,14,100,1,12.71,100,1,14.03,2,1,12.5,700,1,14.28,100,1,12.46,100,1,14.45,100,1,12.43,700,1,14.52,100,1,12.42,700,1,14.56,800,2,ARL,326892921
1834,2025-07-17T16:04:06.543314706Z,2025-07-17T16:04:06.543314706Z,10,2,1108,A,A,23,17.44,100,130,165606,273359491,13.12,200,2,13.72,15,1,13.11,100,1,13.73,100,1,13,2,1,13.8,15,1,12.86,100,1,13.87,200,2,12.73,100,1,14,100,1,12.71,100,1,14.03,2,1,12.5,700,1,14.28,100,1,12.46,100,1,14.45,100,1,12.43,700,1,14.52,100,1,12.42,700,1,14.56,800,2,ARL,327870217
1835,2025-07-17T16:04:06.548778200Z,2025-07-17T16:04:06.548778200Z,10,2,1108,C,A,0,15.96,100,0,167039,273359672,13.12,200,2,13.72,15,1,13.11,100,1,13.73,100,1,13,2,1,13.8,15,1,12.86,100,1,13.87,200,2,12.73,100,1,14,100,1,12.71,100,1,14.03,2,1,12.5,700,1,14.28,100,1,12.46,100,1,14.45,100,1,12.43,700,1,14.52,100,1,12.42,700,1,14.56,800,2,ARL,326892889
1836,2025-07-17T16:04:06.548778200Z,2025-07-17T16:04:06.548778200Z,10,2,1108,A,A,20,15.79,100,130,167039,273359672,13.12,200,2,13.72,15,1,13.11,100,1,13.73,100,1,13,2,1,13.8,15,1,12.86,100,1,13.87,200,2,12.73,100,1,14,100,1,12.71,100,1,14.03,2,1,12.5,700,1,14.28,100,1,12.46,100,1,14.45,100,1,12.43,700,1,14.52,100,1,12.42,700,1,14.56,800,2,ARL,327870361
1837,2025-07-17T16:04:06.647944313Z,2025-07-17T16:04:06.647944313Z,10,2,1108,C,A,0,14.85,100,0,165516,273361957,13.12,200,2,13.72,15,1,13.11,100,1,13.73,100,1,13,2,1,13.8,15,1,12.86,100,1,13.87,200,2,12.73,100,1,14,100,1,12.71,100,1,14.03,2,1,12.5,700,1,14.28,100,1,12.46,100,1,14.45,100,1,12.43,700,1,14.52,100,1,12.42,700,1,14.56,800,2,ARL,326893961
1838,2025-07-17T16:04:06.647944313Z,2025-07-17T16:04:06.647944313Z,10,2,1108,A,A,13,14.7,100,130,165516,273361957,13.12,200,2,13.72,15,1,13.11,100,1,13.73,100,1,13,2,1,13.8,15,1,12.86,100,1,13.87,200,2,12.73,100,1,14,100,1,12.71,100,1,14.03,2,1,12.5,700,1,14.28,100,1,12.46,100,1,14.45,100,1,12.43,700,1,14.52,100,1,12.42,700,1,14.56,800,2,ARL,327873009
1839,2025-07-17T16:04:06.805335354Z,2025-07-17T16:04:06.805335354Z,10,2,1108,C,A,0,13.72,15,130,165169,273364089,13.12,200,2,13.73,100,1,13.11,100,1,13.8,15,1,13,2,1,13.87,200,2,12.86,100,1,14,100,1,12.73,100,1,14.03,2,1,12.71,100,1,14.28,100,1,12.5,700,1,14.45,100,1,12.46,100,1,14.52,100,1,12.43,700,1,14.56,800,2,12.42,700,1,14.6,700,1,ARL,327863853
1840,2025-07-17T16:04:06.806052396Z,2025-07-17T16:04:06.806052396Z,10,2,1108,C,A,0,13.8,15,130,165188,273364090,13.12,200,2,13.73,100,1,13.11,100,1,13.87,200,2,13,2,1,14,100,1,12.86,100,1,14.03,2,1,12.73,100,1,14.28,100,1,12.71,100,1,14.45,100,1,12.5,700,1,14.52,100,1,12.46,100,1,14.56,800,2,12.43,700,1,14.6,700,1,12.42,700,1,14.64,200,2,ARL,327675057
1841,2025-07-17T16:04:21.276976977Z,2025-07-17T16:04:21.276976977Z,10,2,1108,A,A,1,13.77,100,130,165685,273687857,13.12,200,2,13.73,100,1,13.11,100,1,13.77,100,1,13,2,1,13.87,200,2,12.86,100,1,14,100,1,12.73,100,1,14.03,2,1,12.71,100,1,14.28,100,1,12.5,700,1,14.45,100,1,12.46,100,1,14.52,100,1,12.43,700,1,14.56,800,2,12.42,700,1,14.6,700,1,ARL,328239293
1842,2025-07-17T16:04:27.790889618Z,2025-07-17T16:04:27.790889618Z,10,2,1108,C,A,0,14.03,2,0,165528,273775264,13.12,200,2,13.73,100,1,13.11,100,1,13.77,100,1,13,2,1,13.87,200,2,12.86,100,1,14,100,1,12.73,100,1,14.28,100,1,12.71,100,1,14.45,100,1,12.5,700,1,14.52,100,1,12.46,100,1,14.56,800,2,12.43,700,1,14.6,700,1,12.42,700,1,14.64,200,2,ARL,326159041
1843,2025-07-17T16:04:27.790889618Z,2025-07-17T16:04:27.790889618Z,10,2,1108,A,A,3,13.94,2,130,165528,273775264,13.12,200,2,13.73,100,1,13.11,100,1,13.77,100,1,13,2,1,13.87,200,2,12.86,100,1,13.94,2,1,12.73,100,1,14,100,1,12.71,100,1,14.28,100,1,12.5,700,1,14.45,100,1,12.46,100,1,14.52,100,1,12.43,700,1,14.56,800,2,12.42,700,1,14.6,700,1,ARL,328351217
1844,2025-07-17T16:04:31.231887784Z,2025-07-17T16:04:31.231887784Z,10,2,1108,A,A,0,13.68,15,130,165370,273846737,13.12,200,2,13.68,15,1,13.11,100,1,13.73,100,1,13,2,1,13.77,100,1,12.86,100,1,13.87,200,2,12.73,100,1,13.94,2,1,12.71,100,1,14,100,1,12.5,700,1,14.28,100,1,12.46,100,1,14.45,100,1,12.43,700,1,14.52,100,1,12.42,700,1,14.56,800,2,ARL,328437797
1845,2025-07-17T16:04:31.232440773Z,2025-07-17T16:04:31.232440773Z,10,2,1108,A,A,1,13.72,100,130,165667,273846745,13.12,200,2,13.68,15,1,13.11,100,1,13.72,100,1,13,2,1,13.73,100,1,12.86,100,1,13.77,100,1,12.73,100,1,13.87,200,2,12.71,100,1,13.94,2,1,12.5,700,1,14,100,1,12.46,100,1,14.28,100,1,12.43,700,1,14.45,100,1,12.42,700,1,14.52,100,1,ARL,328437805
1846,2025-07-17T16:04:31.246515467Z,2025-07-17T16:04:31.246515467Z,10,2,1108,C,A,0,13.77,100,130,165695,273847000,13.12,200,2,13.68,15,1,13.11,100,1,13.72,100,1,13,2,1,13.73,100,1,12.86,100,1,13.87,200,2,12.73,100,1,13.94,2,1,12.71,100,1,14,100,1,12.5,700,1,14.28,100,1,12.46,100,1,14.45,100,1,12.43,700,1,14.52,100,1,12.42,700,1,14.56,800,2,ARL,328239293
1847,2025-07-17T16:04:32.836635838Z,2025-07-17T16:04:32.836635838Z,10,2,1108,C,A,0,13.73,100,0,166273,273882084,13.12,200,2,13.68,15,1,13.11,100,1,13.72,100,1,13,2,1,13.87,200,2,12.86,100,1,13.94,2,1,12.73,100,1,14,100,1,12.71,100,1,14.28,100,1,12.5,700,1,14.45,100,1,12.46,100,1,14.52,100,1,12.43,700,1,14.56,800,2,12.42,700,1,14.6,700,1,ARL,327864137
1848,2025-07-17T16:04:32.836635838Z,2025-07-17T16:04:32.836635838Z,10,2,1108,A,A,1,13.69,100,130,166273,273882084,13.12,200,2,13.68,15,1,13.11,100,1,13.69,100,1,13,2,1,13.72,100,1,12.86,100,1,13.87,200,2,12.73,100,1,13.94,2,1,12.71,100,1,14,100,1,12.5,700,1,14.28,100,1,12.46,100,1,14.45,100,1,12.43,700,1,14.52,100,1,12.42,700,1,14.56,800,2,ARL,328489153
1849,2025-07-17T16:04:32.837000154Z,2025-07-17T16:04:32.837000154Z,10,2,1108,C,B,0,13.12,100,130,165277,273882201,13.12,100,1,13.68,15,1,13.11,100,1,13.69,100,1,13,2,1,13.72,100,1,12.86,100,1,13.87,200,2,12.73,100,1,13.94,2,1,12.71,100,1,14,100,1,12.5,700,1,14.28,100,1,12.46,100,1,14.45,100,1,12.43,700,1,14.52,100,1,12.42,700,1,14.56,800,2,ARL,325718833
1850,2025-07-17T16:04:32.837002825Z,2025-07-17T16:04:32.837002825Z,10,2,1108,C,B,0,13.12,100,128,166258,273882202,13.11,100,1,13.68,15,1,13,2,1,13.69,100,1,12.86,100,1,13.72,100,1,12.73,100,1,13.87,200,2,12.71,100,1,13.94,2,1,12.5,700,1,14,100,1,12.46,100,1,14.28,100,1,12.43,700,1,14.45,100,1,12.42,700,1,14.52,100,1,12.37,700,1,14.56,800,2,ARL,325718837
1851,2025-07-17T16:04:32.837013456Z,2025-07-17T16:04:32.837013456Z,10,2,1108,A,B,2,12.98,100,130,166112,273882207,13.11,100,1,13.68,15,1,13,2,1,13.69,100,1,12.98,100,1,13.72,100,1,12.86,100,1,13.87,200,2,12.73,100,1,13.94,2,1,12.71,100,1,14,100,1,12.5,700,1,14.28,100,1,12.46,100,1,14.45,100,1,12.43,700,1,14.52,100,1,12.42,700,1,14.56,800,2,ARL,328489377
1852,2025-07-17T16:04:32.837016087Z,2025-07-17T16:04:32.837016087Z,10,2,1108,A,B,2,12.98,100,130,165495,273882208,13.11,100,1,13.68,15,1,13,2,1,13.69,100,1,12.98,200,2,13.72,100,1,12.86,100,1,13.87,200,2,12.73,100,1,13.94,2,1,12.71,100,1,14,100,1,12.5,700,1,14.28,100,1,12.46,100,1,14.45,100,1,12.43,700,1,14.52,100,1,12.42,700,1,14.56,800,2,ARL,328489385
1853,2025-07-17T16:04:32.837369811Z,2025-07-17T16:04:32.837369811Z,10,2,1108,C,A,0,14.79,100,0,166623,273882286,13.11,100,1,13.68,15,1,13,2,1,13.69,100,1,12.98,200,2,13.72,100,1,12.86,100,1,13.87,200,2,12.73,100,1,13.94,2,1,12.71,100,1,14,100,1,12.5,700,1,14.28,100,1,12.46,100,1,14.45,100,1,12.43,700,1,14.52,100,1,12.42,700,1,14.56,800,2,ARL,327864893
1854,2025-07-17T16:04:32.837369811Z,2025-07-17T16:04:32.837369811Z,10,2,1108,A,A,14,14.75,100,128,166623,273882286,13.11,100,1,13.68,15,1,13,2,1,13.69,100,1,12.98,200,2,13.72,100,1,12.86,100,1,13.87,200,2,12.73,100,1,13.94,2,1,12.71,100,1,14,100,1,12.5,700,1,14.28,100,1,12.46,100,1,14.45,100,1,12.43,700,1,14.52,100,1,12.42,700,1,14.56,800,2,ARL,328489481
1855,2025-07-17T16:04:36.810551890Z,2025-07-17T16:04:36.810551890Z,10,2,1108,A,A,0,13.65,15,130,165256,273963456,13.11,100,1,13.65,15,1,13,2,1,13.68,15,1,12.98,200,2,13.69,100,1,12.86,100,1,13.72,100,1,12.73,100,1,13.87,200,2,12.71,100,1,13.94,2,1,12.5,700,1,14,100,1,12.46,100,1,14.28,100,1,12.43,700,1,14.45,100,1,12.42,700,1,14.52,100,1,ARL,328603377
1856,2025-07-17T16:04:37.026771973Z,2025-07-17T16:04:37.026771973Z,10,2,1108,A,A,2,13.69,100,130,165520,273965417,13.11,100,1,13.65,15,1,13,2,1,13.68,15,1,12.98,200,2,13.69,200,2,12.86,100,1,13.72,100,1,12.73,100,1,13.87,200,2,12.71,100,1,13.94,2,1,12.5,700,1,14,100,1,12.46,100,1,14.28,100,1,12.43,700,1,14.45,100,1,12.42,700,1,14.52,100,1,ARL,328606289
1857,2025-07-17T16:04:37.033389265Z,2025-07-17T16:04:37.033389265Z,10,2,1108,C,A,0,13.72,100,130,165292,273965562,13.11,100,1,13.65,15,1,13,2,1,13.68,15,1,12.98,200,2,13.69,200,2,12.86,100,1,13.87,200,2,12.73,100,1,13.94,2,1,12.71,100,1,14,100,1,12.5,700,1,14.28,100,1,12.46,100,1,14.45,100,1,12.43,700,1,14.52,100,1,12.42,700,1,14.56,800,2,ARL,328437805
1858,2025-07-17T16:04:37.542795711Z,2025-07-17T16:04:37.542795711Z,10,2,1108,C,A,2,13.69,100,0,165450,273971021,13.11,100,1,13.65,15,1,13,2,1,13.68,15,1,12.98,200,2,13.69,100,1,12.86,100,1,13.87,200,2,12.73,100,1,13.94,2,1,12.71,100,1,14,100,1,12.5,700,1,14.28,100,1,12.46,100,1,14.45,100,1,12.43,700,1,14.52,100,1,12.42,700,1,14.56,800,2,ARL,328489153
1859,2025-07-17T16:04:37.542795711Z,2025-07-17T16:04:37.542795711Z,10,2,1108,A,A,1,13.66,100,130,165450,273971021,13.11,100,1,13.65,15,1,13,2,1,13.66,100,1,12.98,200,2,13.68,15,1,12.86,100,1,13.69,100,1,12.73,100,1,13.87,200,2,12.71,100,1,13.94,2,1,12.5,700,1,14,100,1,12.46,100,1,14.28,100,1,12.43,700,1,14.45,100,1,12.42,700,1,14.52,100,1,ARL,328614509
1860,2025-07-17T16:04:37.543063240Z,2025-07-17T16:04:37.543063240Z,10,2,1108,C,A,4,13.87,100,0,167440,273971035,13.11,100,1,13.65,15,1,13,2,1,13.66,100,1,12.98,200,2,13.68,15,1,12.86,100,1,13.69,100,1,12.73,100,1,13.87,100,1,12.71,100,1,13.94,2,1,12.5,700,1,14,100,1,12.46,100,1,14.28,100,1,12.43,700,1,14.45,100,1,12.42,700,1,14.52,100,1,ARL,326730517
1861,2025-07-17T16:04:37.543064690Z,2025-07-17T16:04:37.543064690Z,10,2,1108,C,A,0,13.87,100,130,165990,273971037,13.11,100,1,13.65,15,1,13,2,1,13.66,100,1,12.98,200,2,13.68,15,1,12.86,100,1,13.69,100,1,12.73,100,1,13.94,2,1,12.71,100,1,14,100,1,12.5,700,1,14.28,100,1,12.46,100,1,14.45,100,1,12.43,700,1,14.52,100,1,12.42,700,1,14.56,800,2,ARL,326730521
1862,2025-07-17T16:04:37.543077174Z,2025-07-17T16:04:37.543077174Z,10,2,1108,A,A,4,13.8,100,130,165216,273971040,13.11,100,1,13.65,15,1,13,2,1,13.66,100,1,12.98,200,2,13.68,15,1,12.86,100,1,13.69,100,1,12.73,100,1,13.8,100,1,12.71,100,1,13.94,2,1,12.5,700,1,14,100,1,12.46,100,1,14.28,100,1,12.43,700,1,14.45,100,1,12.42,700,1,14.52,100,1,ARL,328614525
1863,2025-07-17T16:04:37.543078532Z,2025-07-17T16:04:37.543078532Z,10,2,1108,A,A,4,13.8,100,130,165661,273971041,13.11,100,1,13.65,15,1,13,2,1,13.66,100,1,12.98,200,2,13.68,15,1,12.86,100,1,13.69,100,1,12.73,100,1,13.8,200,2,12.71,100,1,13.94,2,1,12.5,700,1,14,100,1,12.46,100,1,14.28,100,1,12.43,700,1,14.45,100,1,12.42,700,1,14.52,100,1,ARL,328614529
1864,2025-07-17T16:04:37.549519006Z,2025-07-17T16:04:37.549519006Z,10,2,1108,C,A,0,14,100,130,165707,273973481,13.11,100,1,13.65,15,1,13,2,1,13.66,100,1,12.98,200,2,13.68,15,1,12.86,100,1,13.69,100,1,12.73,100,1,13.8,200,2,12.71,100,1,13.94,2,1,12.5,700,1,14.28,100,1,12.46,100,1,14.45,100,1,12.43,700,1,14.52,100,1,12.42,700,1,14.56,800,2,ARL,327869193
1865,2025-07-17T16:04:37.549570649Z,2025-07-17T16:04:37.549570649Z,10,2,1108,A,A,5,13.93,100,130,165175,273973485,13.11,100,1,13.65,15,1,13,2,1,13.66,100,1,12.98,200,2,13.68,15,1,12.86,100,1,13.69,100,1,12.73,100,1,13.8,200,2,12.71,100,1,13.93,100,1,12.5,700,1,13.94,2,1,12.46,100,1,14.28,100,1,12.43,700,1,14.45,100,1,12.42,700,1,14.52,100,1,ARL,328616925
1866,2025-07-17T16:04:44.524360626Z,2025-07-17T16:04:44.524360626Z,10,2,1108,C,A,0,13.68,15,130,165919,274066152,13.11,100,1,13.65,15,1,13,2,1,13.66,100,1,12.98,200,2,13.69,100,1,12.86,100,1,13.8,200,2,12.73,100,1,13.93,100,1,12.71,100,1,13.94,2,1,12.5,700,1,14.28,100,1,12.46,100,1,14.45,100,1,12.43,700,1,14.52,100,1,12.42,700,1,14.56,800,2,ARL,328437797
1867,2025-07-17T16:04:45.527835033Z,2025-07-17T16:04:45.527835033Z,10,2,1108,A,A,0,13.63,15,130,165110,274088918,13.11,100,1,13.63,15,1,13,2,1,13.65,15,1,12.98,200,2,13.66,100,1,12.86,100,1,13.69,100,1,12.73,100,1,13.8,200,2,12.71,100,1,13.93,100,1,12.5,700,1,13.94,2,1,12.46,100,1,14.28,100,1,12.43,700,1,14.45,100,1,12.42,700,1,14.52,100,1,ARL,328780565
1868,2025-07-17T16:04:45.528464092Z,2025-07-17T16:04:45.528464092Z,10,2,1108,C,A,12,14.64,100,0,165521,274088922,13.11,100,1,13.63,15,1,13,2,1,13.65,15,1,12.98,200,2,13.66,100,1,12.86,100,1,13.69,100,1,12.73,100,1,13.8,200,2,12.71,100,1,13.93,100,1,12.5,700,1,13.94,2,1,12.46,100,1,14.28,100,1,12.43,700,1,14.45,100,1,12.42,700,1,14.52,100,1,ARL,327856309
1869,2025-07-17T16:04:45.528464092Z,2025-07-17T16:04:45.528464092Z,10,2,1108,A,A,9,14.52,100,130,165521,274088922,13.11,100,1,13.63,15,1,13,2,1,13.65,15,1,12.98,200,2,13.66,100,1,12.86,100,1,13.69,100,1,12.73,100,1,13.8,200,2,12.71,100,1,13.93,100,1,12.5,700,1,13.94,2,1,12.46,100,1,14.28,100,1,12.43,700,1,14.45,100,1,12.42,700,1,14.52,200,2,ARL,328780577
1870,2025-07-17T16:04:45.530252804Z,2025-07-17T16:04:45.530252804Z,10,2,1108,C,A,0,14.64,100,0,165474,274088937,13.11,100,1,13.63,15,1,13,2,1,13.65,15,1,12.98,200,2,13.66,100,1,12.86,100,1,13.69,100,1,12.73,100,1,13.8,200,2,12.71,100,1,13.93,100,1,12.5,700,1,13.94,2,1,12.46,100,1,14.28,100,1,12.43,700,1,14.45,100,1,12.42,700,1,14.52,200,2,ARL,327856297
1871,2025-07-17T16:04:45.530252804Z,2025-07-17T16:04:45.530252804Z,10,2,1108,A,A,9,14.52,100,130,165474,274088937,13.11,100,1,13.63,15,1,13,2,1,13.65,15,1,12.98,200,2,13.66,100,1,12.86,100,1,13.69,100,1,12.73,100,1,13.8,200,2,12.71,100,1,13.93,100,1,12.5,700,1,13.94,2,1,12.46,100,1,14.28,100,1,12.43,700,1,14.45,100,1,12.42,700,1,14.52,300,3,ARL,328780597
1872,2025-07-17T16:04:45.532901874Z,2025-07-17T16:04:45.532901874Z,10,2,1108,C,A,0,13.66,100,0,165155,274088955,13.11,100,1,13.63,15,1,13,2,1,13.65,15,1,12.98,200,2,13.69,100,1,12.86,100,1,13.8,200,2,12.73,100,1,13.93,100,1,12.71,100,1,13.94,2,1,12.5,700,1,14.28,100,1,12.46,100,1,14.45,100,1,12.43,700,1,14.52,300,3,12.42,700,1,14.56,800,2,ARL,328614509
1873,2025-07-17T16:04:45.532901874Z,2025-07-17T16:04:45.532901874Z,10,2,1108,A,A,1,13.64,100,130,165155,274088955,13.11,100,1,13.63,15,1,13,2,1,13.64,100,1,12.98,200,2,13.65,15,1,12.86,100,1,13.69,100,1,12.73,100,1,13.8,200,2,12.71,100,1,13.93,100,1,12.5,700,1,13.94,2,1,12.46,100,1,14.28,100,1,12.43,700,1,14.45,100,1,12.42,700,1,14.52,300,3,ARL,328780669
1874,2025-07-17T16:04:45.533639142Z,2025-07-17T16:04:45.533639142Z,10,2,1108,C,A,0,14.75,100,0,165626,274088957,13.11,100,1,13.63,15,1,13,2,1,13.64,100,1,12.98,200,2,13.65,15,1,12.86,100,1,13.69,100,1,12.73,100,1,13.8,200,2,12.71,100,1,13.93,100,1,12.5,700,1,13.94,2,1,12.46,100,1,14.28,100,1,12.43,700,1,14.45,100,1,12.42,700,1,14.52,300,3,ARL,328489481
1875,2025-07-17T16:04:45.533639142Z,2025-07-17T16:04:45.533639142Z,10,2,1108,A,A,13,14.7,100,130,165626,274088957,13.11,100,1,13.63,15,1,13,2,1,13.64,100,1,12.98,200,2,13.65,15,1,12.86,100,1,13.69,100,1,12.73,100,1,13.8,200,2,12.71,100,1,13.93,100,1,12.5,700,1,13.94,2,1,12.46,100,1,14.28,100,1,12.43,700,1,14.45,100,1,12.42,700,1,14.52,300,3,ARL,328780685
1876,2025-07-17T16:04:45.533705428Z,2025-07-17T16:04:45.533705428Z,10,2,1108,A,A,3,13.67,100,130,165283,274088959,13.11,100,1,13.63,15,1,13,2,1,13.64,100,1,12.98,200,2,13.65,15,1,12.86,100,1,13.67,100,1,12.73,100,1,13.69,100,1,12.71,100,1,13.8,200,2,12.5,700,1,13.93,100,1,12.46,100,1,13.94,2,1,12.43,700,1,14.28,100,1,12.42,700,1,14.45,100,1,ARL,328780689
1877,2025-07-17T16:04:45.562972204Z,2025-07-17T16:04:45.562972204Z,10,2,1108,C,A,0,13.69,100,130,165239,274089319,13.11,100,1,13.63,15,1,13,2,1,13.64,100,1,12.98,200,2,13.65,15,1,12.86,100,1,13.67,100,1,12.73,100,1,13.8,200,2,12.71,100,1,13.93,100,1,12.5,700,1,13.94,2,1,12.46,100,1,14.28,100,1,12.43,700,1,14.45,100,1,12.42,700,1,14.52,300,3,ARL,328606289
1878,2025-07-17T16:04:56.809584701Z,2025-07-17T16:04:56.809584701Z,10,2,1108,C,A,0,13.65,15,130,165272,274293432,13.11,100,1,13.63,15,1,13,2,1,13.64,100,1,12.98,200,2,13.67,100,1,12.86,100,1,13.8,200,2,12.73,100,1,13.93,100,1,12.71,100,1,13.94,2,1,12.5,700,1,14.28,100,1,12.46,100,1,14.45,100,1,12.43,700,1,14.52,300,3,12.42,700,1,14.56,800,2,ARL,328603377
1879,2025-07-17T16:04:57.826913717Z,2025-07-17T16:04:57.826913717Z,10,2,1108,A,A,0,13.61,15,130,165292,274310244,13.11,100,1,13.61,15,1,13,2,1,13.63,15,1,12.98,200,2,13.64,100,1,12.86,100,1,13.67,100,1,12.73,100,1,13.8,200,2,12.71,100,1,13.93,100,1,12.5,700,1,13.94,2,1,12.46,100,1,14.28,100,1,12.43,700,1,14.45,100,1,12.42,700,1,14.52,300,3,ARL,329068341
1880,2025-07-17T16:04:57.970451236Z,2025-07-17T16:04:57.970451236Z,10,2,1108,C,A,0,13.64,100,0,165374,274316281,13.11,100,1,13.61,15,1,13,2,1,13.63,15,1,12.98,200,2,13.67,100,1,12.86,100,1,13.8,200,2,12.73,100,1,13.93,100,1,12.71,100,1,13.94,2,1,12.5,700,1,14.28,100,1,12.46,100,1,14.45,100,1,12.43,700,1,14.52,300,3,12.42,700,1,14.56,800,2,ARL,328780669
1881,2025-07-17T16:04:57.970451236Z,2025-07-17T16:04:57.970451236Z,10,2,1108,A,A,1,13.62,100,130,165374,274316281,13.11,100,1,13.61,15,1,13,2,1,13.62,100,1,12.98,200,2,13.63,15,1,12.86,100,1,13.67,100,1,12.73,100,1,13.8,200,2,12.71,100,1,13.93,100,1,12.5,700,1,13.94,2,1,12.46,100,1,14.28,100,1,12.43,700,1,14.45,100,1,12.42,700,1,14.52,300,3,ARL,329074609
1882,2025-07-17T16:04:57.971193734Z,2025-07-17T16:04:57.971193734Z,10,2,1108,C,A,0,14.45,100,128,166610,274316507,13.11,100,1,13.61,15,1,13,2,1,13.62,100,1,12.98,200,2,13.63,15,1,12.86,100,1,13.67,100,1,12.73,100,1,13.8,200,2,12.71,100,1,13.93,100,1,12.5,700,1,13.94,2,1,12.46,100,1,14.28,100,1,12.43,700,1,14.52,300,3,12.42,700,1,14.56,800,2,ARL,325714601
1883,2025-07-17T16:04:57.971552262Z,2025-07-17T16:04:57.971552262Z,10,2,1108,A,A,7,14.23,100,130,165249,274316527,13.11,100,1,13.61,15,1,13,2,1,13.62,100,1,12.98,200,2,13.63,15,1,12.86,100,1,13.67,100,1,12.73,100,1,13.8,200,2,12.71,100,1,13.93,100,1,12.5,700,1,13.94,2,1,12.46,100,1,14.23,100,1,12.43,700,1,14.28,100,1,12.42,700,1,14.52,300,3,ARL,329074833
1884,2025-07-17T16:04:57.991966904Z,2025-07-17T16:04:57.991966904Z,10,2,1108,C,A,0,13.61,15,130,164974,274318490,13.11,100,1,13.62,100,1,13,2,1,13.63,15,1,12.98,200,2,13.67,100,1,12.86,100,1,13.8,200,2,12.73,100,1,13.93,100,1,12.71,100,1,13.94,2,1,12.5,700,1,14.23,100,1,12.46,100,1,14.28,100,1,12.43,700,1,14.52,300,3,12.42,700,1,14.56,800,2,ARL,329068341
1885,2025-07-17T16:04:57.992976406Z,2025-07-17T16:04:57.992976406Z,10,2,1108,C,A,0,13.62,100,130,165032,274318579,13.11,100,1,13.63,15,1,13,2,1,13.67,100,1,12.98,200,2,13.8,200,2,12.86,100,1,13.93,100,1,12.73,100,1,13.94,2,1,12.71,100,1,14.23,100,1,12.5,700,1,14.28,100,1,12.46,100,1,14.52,300,3,12.43,700,1,14.56,800,2,12.42,700,1,14.6,700,1,ARL,329074609
1886,2025-07-17T16:04:57.993143873Z,2025-07-17T16:04:57.993143873Z,10,2,1108,C,A,0,13.63,15,130,165688,274318603,13.11,100,1,13.67,100,1,13,2,1,13.8,200,2,12.98,200,2,13.93,100,1,12.86,100,1,13.94,2,1,12.73,100,1,14.23,100,1,12.71,100,1,14.28,100,1,12.5,700,1,14.52,300,3,12.46,100,1,14.56,800,2,12.43,700,1,14.6,700,1,12.42,700,1,14.68,1400,2,ARL,328780565
1887,2025-07-17T16:04:58.002094377Z,2025-07-17T16:04:58.002094377Z,10,2,1108,C,A,0,13.67,100,130,165338,274319058,13.11,100,1,13.8,200,2,13,2,1,13.93,100,1,12.98,200,2,13.94,2,1,12.86,100,1,14.23,100,1,12.73,100,1,14.28,100,1,12.71,100,1,14.52,300,3,12.5,700,1,14.56,800,2,12.46,100,1,14.6,700,1,12.43,700,1,14.68,1400,2,12.42,700,1,14.7,300,3,ARL,328780689
1888,2025-07-17T16:04:58.002823841Z,2025-07-17T16:04:58.002823841Z,10,2,1108,C,A,9,14.7,100,0,165589,274319069,13.11,100,1,13.8,200,2,13,2,1,13.93,100,1,12.98,200,2,13.94,2,1,12.86,100,1,14.23,100,1,12.73,100,1,14.28,100,1,12.71,100,1,14.52,300,3,12.5,700,1,14.56,800,2,12.46,100,1,14.6,700,1,12.43,700,1,14.68,1400,2,12.42,700,1,14.7,200,2,ARL,328780685
1889,2025-07-17T16:04:58.002823841Z,2025-07-17T16:04:58.002823841Z,10,2,1108,A,A,10,14.87,100,130,165589,274319069,13.11,100,1,13.8,200,2,13,2,1,13.93,100,1,12.98,200,2,13.94,2,1,12.86,100,1,14.23,100,1,12.73,100,1,14.28,100,1,12.71,100,1,14.52,300,3,12.5,700,1,14.56,800,2,12.46,100,1,14.6,700,1,12.43,700,1,14.68,1400,2,12.42,700,1,14.7,200,2,ARL,329078553
1890,2025-07-17T16:04:58.013739242Z,2025-07-17T16:04:58.013739242Z,10,2,1108,C,A,0,13.93,100,130,165455,274319298,13.11,100,1,13.8,200,2,13,2,1,13.94,2,1,12.98,200,2,14.23,100,1,12.86,100,1,14.28,100,1,12.73,100,1,14.52,300,3,12.71,100,1,14.56,800,2,12.5,700,1,14.6,700,1,12.46,100,1,14.68,1400,2,12.43,700,1,14.7,200,2,12.42,700,1,14.87,100,1,ARL,328616925
1891,2025-07-17T16:04:58.013793974Z,2025-07-17T16:04:58.013793974Z,10,2,1108,A,A,2,14.08,100,130,165259,274319304,13.11,100,1,13.8,200,2,13,2,1,13.94,2,1,12.98,200,2,14.08,100,1,12.86,100,1,14.23,100,1,12.73,100,1,14.28,100,1,12.71,100,1,14.52,300,3,12.5,700,1,14.56,800,2,12.46,100,1,14.6,700,1,12.43,700,1,14.68,1400,2,12.42,700,1,14.7,200,2,ARL,329078953
1892,2025-07-17T16:04:58.536452621Z,2025-07-17T16:04:58.536452621Z,10,2,1108,A,A,1,13.81,100,130,165296,274326535,13.11,100,1,13.8,200,2,13,2,1,13.81,100,1,12.98,200,2,13.94,2,1,12.86,100,1,14.08,100,1,12.73,100,1,14.23,100,1,12.71,100,1,14.28,100,1,12.5,700,1,14.52,300,3,12.46,100,1,14.56,800,2,12.43,700,1,14.6,700,1,12.42,700,1,14.68,1400,2,ARL,329088265
1893,2025-07-17T16:05:46.593966383Z,2025-07-17T16:05:46.593966383Z,10,2,1108,A,A,0,13.76,100,130,165281,275083968,13.11,100,1,13.76,100,1,13,2,1,13.8,200,2,12.98,200,2,13.81,100,1,12.86,100,1,13.94,2,1,12.73,100,1,14.08,100,1,12.71,100,1,14.23,100,1,12.5,700,1,14.28,100,1,12.46,100,1,14.52,300,3,12.43,700,1,14.56,800,2,12.42,700,1,14.6,700,1,ARL,330066537
1894,2025-07-17T16:05:46.594705962Z,2025-07-17T16:05:46.594705962Z,10,2,1108,C,A,0,14.87,100,0,165374,275083970,13.11,100,1,13.76,100,1,13,2,1,13.8,200,2,12.98,200,2,13.81,100,1,12.86,100,1,13.94,2,1,12.73,100,1,14.08,100,1,12.71,100,1,14.23,100,1,12.5,700,1,14.28,100,1,12.46,100,1,14.52,300,3,12.43,700,1,14.56,800,2,12.42,700,1,14.6,700,1,ARL,329078553
1895,2025-07-17T16:05:46.594705962Z,2025-07-17T16:05:46.594705962Z,10,2,1108,A,A,12,14.83,100,130,165374,275083970,13.11,100,1,13.76,100,1,13,2,1,13.8,200,2,12.98,200,2,13.81,100,1,12.86,100,1,13.94,2,1,12.73,100,1,14.08,100,1,12.71,100,1,14.23,100,1,12.5,700,1,14.28,100,1,12.46,100,1,14.52,300,3,12.43,700,1,14.56,800,2,12.42,700,1,14.6,700,1,ARL,330066553
1896,2025-07-17T16:05:46.995837526Z,2025-07-17T16:05:46.995837526Z,10,2,1108,C,A,0,13.81,100,0,166026,275092978,13.11,100,1,13.76,100,1,13,2,1,13.8,200,2,12.98,200,2,13.94,2,1,12.86,100,1,14.08,100,1,12.73,100,1,14.23,100,1,12.71,100,1,14.28,100,1,12.5,700,1,14.52,300,3,12.46,100,1,14.56,800,2,12.43,700,1,14.6,700,1,12.42,700,1,14.68,1400,2,ARL,329088265
1897,2025-07-17T16:05:46.995837526Z,2025-07-17T16:05:46.995837526Z,10,2,1108,A,A,1,13.77,100,130,166026,275092978,13.11,100,1,13.76,100,1,13,2,1,13.77,100,1,12.98,200,2,13.8,200,2,12.86,100,1,13.94,2,1,12.73,100,1,14.08,100,1,12.71,100,1,14.23,100,1,12.5,700,1,14.28,100,1,12.46,100,1,14.52,300,3,12.43,700,1,14.56,800,2,12.42,700,1,14.6,700,1,ARL,330075425
1898,2025-07-17T16:05:50.680167632Z,2025-07-17T16:05:50.680167632Z,10,2,1108,A,A,0,13.68,15,130,165519,275152014,13.11,100,1,13.68,15,1,13,2,1,13.76,100,1,12.98,200,2,13.77,100,1,12.86,100,1,13.8,200,2,12.73,100,1,13.94,2,1,12.71,100,1,14.08,100,1,12.5,700,1,14.23,100,1,12.46,100,1,14.28,100,1,12.43,700,1,14.52,300,3,12.42,700,1,14.56,800,2,ARL,330143813
1899,2025-07-17T16:05:50.697005084Z,2025-07-17T16:05:50.697005084Z,10,2,1108,A,A,1,13.72,100,130,165236,275152383,13.11,100,1,13.68,15,1,13,2,1,13.72,100,1,12.98,200,2,13.76,100,1,12.86,100,1,13.77,100,1,12.73,100,1,13.8,200,2,12.71,100,1,13.94,2,1,12.5,700,1,14.08,100,1,12.46,100,1,14.23,100,1,12.43,700,1,14.28,100,1,12.42,700,1,14.52,300,3,ARL,330144301
1900,2025-07-17T16:05:50.697739933Z,2025-07-17T16:05:50.697739933Z,10,2,1108,C,A,0,14.83,100,0,165439,275152385,13.11,100,1,13.68,15,1,13,2,1,13.72,100,1,12.98,200,2,13.76,100,1,12.86,100,1,13.77,100,1,12.73,100,1,13.8,200,2,12.71,100,1,13.94,2,1,12.5,700,1,14.08,100,1,12.46,100,1,14.23,100,1,12.43,700,1,14.28,100,1,12.42,700,1,14.52,300,3,ARL,330066553
1901,2025-07-17T16:05:50.697739933Z,2025-07-17T16:05:50.697739933Z,10,2,1108,A,A,14,14.78,100,130,165439,275152385,13.11,100,1,13.68,15,1,13,2,1,13.72,100,1,12.98,200,2,13.76,100,1,12.86,100,1,13.77,100,1,12.73,100,1,13.8,200,2,12.71,100,1,13.94,2,1,12.5,700,1,14.08,100,1,12.46,100,1,14.23,100,1,12.43,700,1,14.28,100,1,12.42,700,1,14.52,300,3,ARL,330144321
1902,2025-07-17T16:05:50.704366332Z,2025-07-17T16:05:50.704366332Z,10,2,1108,C,A,0,13.76,100,130,165416,275152443,13.11,100,1,13.68,15,1,13,2,1,13.72,100,1,12.98,200,2,13.77,100,1,12.86,100,1,13.8,200,2,12.73,100,1,13.94,2,1,12.71,100,1,14.08,100,1,12.5,700,1,14.23,100,1,12.46,100,1,14.28,100,1,12.43,700,1,14.52,300,3,12.42,700,1,14.56,800,2,ARL,330066537
1903,2025-07-17T16:05:50.708714027Z,2025-07-17T16:05:50.708714027Z,10,2,1108,C,A,0,14.08,100,130,165284,275152465,13.11,100,1,13.68,15,1,13,2,1,13.72,100,1,12.98,200,2,13.77,100,1,12.86,100,1,13.8,200,2,12.73,100,1,13.94,2,1,12.71,100,1,14.23,100,1,12.5,700,1,14.28,100,1,12.46,100,1,14.52,300,3,12.43,700,1,14.56,800,2,12.42,700,1,14.6,700,1,ARL,329078953
1904,2025-07-17T16:05:50.708766050Z,2025-07-17T16:05:50.708766050Z,10,2,1108,A,A,5,13.99,100,130,165139,275152466,13.11,100,1,13.68,15,1,13,2,1,13.72,100,1,12.98,200,2,13.77,100,1,12.86,100,1,13.8,200,2,12.73,100,1,13.94,2,1,12.71,100,1,13.99,100,1,12.5,700,1,14.23,100,1,12.46,100,1,14.28,100,1,12.43,700,1,14.52,300,3,12.42,700,1,14.56,800,2,ARL,330144513
1905,2025-07-17T16:05:50.913310799Z,2025-07-17T16:05:50.913310799Z,10,2,1108,C,A,0,13.77,100,0,165469,275159685,13.11,100,1,13.68,15,1,13,2,1,13.72,100,1,12.98,200,2,13.8,200,2,12.86,100,1,13.94,2,1,12.73,100,1,13.99,100,1,12.71,100,1,14.23,100,1,12.5,700,1,14.28,100,1,12.46,100,1,14.52,300,3,12.43,700,1,14.56,800,2,12.42,700,1,14.6,700,1,ARL,330075425
1906,2025-07-17T16:05:50.913310799Z,2025-07-17T16:05:50.913310799Z,10,2,1108,A,A,1,13.69,100,130,165469,275159685,13.11,100,1,13.68,15,1,13,2,1,13.69,100,1,12.98,200,2,13.72,100,1,12.86,100,1,13.8,200,2,12.73,100,1,13.94,2,1,12.71,100,1,13.99,100,1,12.5,700,1,14.23,100,1,12.46,100,1,14.28,100,1,12.43,700,1,14.52,300,3,12.42,700,1,14.56,800,2,ARL,330151389
1907,2025-07-17T16:05:59.704790753Z,2025-07-17T16:05:59.704790753Z,10,2,1108,A,A,0,13.64,15,130,165217,275325555,13.11,100,1,13.64,15,1,13,2,1,13.68,15,1,12.98,200,2,13.69,100,1,12.86,100,1,13.72,100,1,12.73,100,1,13.8,200,2,12.71,100,1,13.94,2,1,12.5,700,1,13.99,100,1,12.46,100,1,14.23,100,1,12.43,700,1,14.28,100,1,12.42,700,1,14.52,300,3,ARL,330357473
1908,2025-07-17T16:05:59.714925412Z,2025-07-17T16:05:59.714925412Z,10,2,1108,A,A,1,13.68,100,130,165250,275325807,13.11,100,1,13.64,15,1,13,2,1,13.68,115,2,12.98,200,2,13.69,100,1,12.86,100,1,13.72,100,1,12.73,100,1,13.8,200,2,12.71,100,1,13.94,2,1,12.5,700,1,13.99,100,1,12.46,100,1,14.23,100,1,12.43,700,1,14.28,100,1,12.42,700,1,14.52,300,3,ARL,330357633
1909,2025-07-17T16:05:59.722730507Z,2025-07-17T16:05:59.722730507Z,10,2,1108,C,A,0,13.72,100,130,165243,275325854,13.11,100,1,13.64,15,1,13,2,1,13.68,115,2,12.98,200,2,13.69,100,1,12.86,100,1,13.8,200,2,12.73,100,1,13.94,2,1,12.71,100,1,13.99,100,1,12.5,700,1,14.23,100,1,12.46,100,1,14.28,100,1,12.43,700,1,14.52,300,3,12.42,700,1,14.56,800,2,ARL,330144301
1910,2025-07-17T16:05:59.802596747Z,2025-07-17T16:05:59.802596747Z,10,2,1108,C,A,0,13.69,100,0,165340,275327082,13.11,100,1,13.64,15,1,13,2,1,13.68,115,2,12.98,200,2,13.8,200,2,12.86,100,1,13.94,2,1,12.73,100,1,13.99,100,1,12.71,100,1,14.23,100,1,12.5,700,1,14.28,100,1,12.46,100,1,14.52,300,3,12.43,700,1,14.56,800,2,12.42,700,1,14.6,700,1,ARL,330151389
1911,2025-07-17T16:05:59.802596747Z,2025-07-17T16:05:59.802596747Z,10,2,1108,A,A,1,13.65,100,130,165340,275327082,13.11,100,1,13.64,15,1,13,2,1,13.65,100,1,12.98,200,2,13.68,115,2,12.86,100,1,13.8,200,2,12.73,100,1,13.94,2,1,12.71,100,1,13.99,100,1,12.5,700,1,14.23,100,1,12.46,100,1,14.28,100,1,12.43,700,1,14.52,300,3,12.42,700,1,14.56,800,2,ARL,330359197
1912,2025-07-17T16:05:59.803338996Z,2025-07-17T16:05:59.803338996Z,10,2,1108,C,A,0,14.78,100,0,165662,275327093,13.11,100,1,13.64,15,1,13,2,1,13.65,100,1,12.98,200,2,13.68,115,2,12.86,100,1,13.8,200,2,12.73,100,1,13.94,2,1,12.71,100,1,13.99,100,1,12.5,700,1,14.23,100,1,12.46,100,1,14.28,100,1,12.43,700,1,14.52,300,3,12.42,700,1,14.56,800,2,ARL,330144321
1913,2025-07-17T16:05:59.803338996Z,2025-07-17T16:05:59.803338996Z,10,2,1108,A,A,13,14.71,100,130,165662,275327093,13.11,100,1,13.64,15,1,13,2,1,13.65,100,1,12.98,200,2,13.68,115,2,12.86,100,1,13.8,200,2,12.73,100,1,13.94,2,1,12.71,100,1,13.99,100,1,12.5,700,1,14.23,100,1,12.46,100,1,14.28,100,1,12.43,700,1,14.52,300,3,12.42,700,1,14.56,800,2,ARL,330359225
1914,2025-07-17T16:05:59.827622529Z,2025-07-17T16:05:59.827622529Z,10,2,1108,C,A,0,13.99,100,130,165308,275327416,13.11,100,1,13.64,15,1,13,2,1,13.65,100,1,12.98,200,2,13.68,115,2,12.86,100,1,13.8,200,2,12.73,100,1,13.94,2,1,12.71,100,1,14.23,100,1,12.5,700,1,14.28,100,1,12.46,100,1,14.52,300,3,12.43,700,1,14.56,800,2,12.42,700,1,14.6,700,1,ARL,330144513
1915,2025-07-17T16:05:59.827674437Z,2025-07-17T16:05:59.827674437Z,10,2,1108,A,A,4,13.92,100,130,165365,275327417,13.11,100,1,13.64,15,1,13,2,1,13.65,100,1,12.98,200,2,13.68,115,2,12.86,100,1,13.8,200,2,12.73,100,1,13.92,100,1,12.71,100,1,13.94,2,1,12.5,700,1,14.23,100,1,12.46,100,1,14.28,100,1,12.43,700,1,14.52,300,3,12.42,700,1,14.56,800,2,ARL,330359625
1916,2025-07-17T16:06:02.724280161Z,2025-07-17T16:06:02.724280161Z,10,2,1108,C,A,2,13.68,15,128,166176,275430576,13.11,100,1,13.64,15,1,13,2,1,13.65,100,1,12.98,200,2,13.68,100,1,12.86,100,1,13.8,200,2,12.73,100,1,13.92,100,1,12.71,100,1,13.94,2,1,12.5,700,1,14.23,100,1,12.46,100,1,14.28,100,1,12.43,700,1,14.52,300,3,12.42,700,1,14.56,800,2,ARL,330143813
1917,2025-07-17T16:06:03.729212428Z,2025-07-17T16:06:03.729212428Z,10,2,1108,A,A,0,13.62,15,130,165342,275517342,13.11,100,1,13.62,15,1,13,2,1,13.64,15,1,12.98,200,2,13.65,100,1,12.86,100,1,13.68,100,1,12.73,100,1,13.8,200,2,12.71,100,1,13.92,100,1,12.5,700,1,13.94,2,1,12.46,100,1,14.23,100,1,12.43,700,1,14.28,100,1,12.42,700,1,14.52,300,3,ARL,330577045
1918,2025-07-17T16:06:03.738332427Z,2025-07-17T16:06:03.738332427Z,10,2,1108,A,A,2,13.65,100,130,165218,275517997,13.11,100,1,13.62,15,1,13,2,1,13.64,15,1,12.98,200,2,13.65,200,2,12.86,100,1,13.68,100,1,12.73,100,1,13.8,200,2,12.71,100,1,13.92,100,1,12.5,700,1,13.94,2,1,12.46,100,1,14.23,100,1,12.43,700,1,14.28,100,1,12.42,700,1,14.52,300,3,ARL,330577773
1919,2025-07-17T16:06:03.747330178Z,2025-07-17T16:06:03.747330178Z,10,2,1108,C,A,0,13.68,100,130,165491,275518621,13.11,100,1,13.62,15,1,13,2,1,13.64,15,1,12.98,200,2,13.65,200,2,12.86,100,1,13.8,200,2,12.73,100,1,13.92,100,1,12.71,100,1,13.94,2,1,12.5,700,1,14.23,100,1,12.46,100,1,14.28,100,1,12.43,700,1,14.52,300,3,12.42,700,1,14.56,800,2,ARL,330357633
1920,2025-07-17T16:06:03.887107153Z,2025-07-17T16:06:03.887107153Z,10,2,1108,C,A,2,13.65,100,0,167517,275532429,13.11,100,1,13.62,15,1,13,2,1,13.64,15,1,12.98,200,2,13.65,100,1,12.86,100,1,13.8,200,2,12.73,100,1,13.92,100,1,12.71,100,1,13.94,2,1,12.5,700,1,14.23,100,1,12.46,100,1,14.28,100,1,12.43,700,1,14.52,300,3,12.42,700,1,14.56,800,2,ARL,330359197
1921,2025-07-17T16:06:03.887107153Z,2025-07-17T16:06:03.887107153Z,10,2,1108,A,A,1,13.63,100,130,167517,275532429,13.11,100,1,13.62,15,1,13,2,1,13.63,100,1,12.98,200,2,13.64,15,1,12.86,100,1,13.65,100,1,12.73,100,1,13.8,200,2,12.71,100,1,13.92,100,1,12.5,700,1,13.94,2,1,12.46,100,1,14.23,100,1,12.43,700,1,14.28,100,1,12.42,700,1,14.52,300,3,ARL,330592465
1922,2025-07-17T16:06:07.509885114Z,2025-07-17T16:06:07.509885114Z,10,2,1108,C,A,0,13.64,15,130,165644,275647392,13.11,100,1,13.62,15,1,13,2,1,13.63,100,1,12.98,200,2,13.65,100,1,12.86,100,1,13.8,200,2,12.73,100,1,13.92,100,1,12.71,100,1,13.94,2,1,12.5,700,1,14.23,100,1,12.46,100,1,14.28,100,1,12.43,700,1,14.52,300,3,12.42,700,1,14.56,800,2,ARL,330357473
1923,2025-07-17T16:06:09.884978592Z,2025-07-17T16:06:09.884978592Z,10,2,1108,A,A,0,13.6,15,130,165317,275699092,13.11,100,1,13.6,15,1,13,2,1,13.62,15,1,12.98,200,2,13.63,100,1,12.86,100,1,13.65,100,1,12.73,100,1,13.8,200,2,12.71,100,1,13.92,100,1,12.5,700,1,13.94,2,1,12.46,100,1,14.23,100,1,12.43,700,1,14.28,100,1,12.42,700,1,14.52,300,3,ARL,330788421
1924,2025-07-17T16:06:09.967442600Z,2025-07-17T16:06:09.967442600Z,10,2,1108,C,A,0,13.63,100,0,165461,275700261,13.11,100,1,13.6,15,1,13,2,1,13.62,15,1,12.98,200,2,13.65,100,1,12.86,100,1,13.8,200,2,12.73,100,1,13.92,100,1,12.71,100,1,13.94,2,1,12.5,700,1,14.23,100,1,12.46,100,1,14.28,100,1,12.43,700,1,14.52,300,3,12.42,700,1,14.56,800,2,ARL,330592465
1925,2025-07-17T16:06:09.967442600Z,2025-07-17T16:06:09.967442600Z,10,2,1108,A,A,1,13.61,100,130,165461,275700261,13.11,100,1,13.6,15,1,13,2,1,13.61,100,1,12.98,200,2,13.62,15,1,12.86,100,1,13.65,100,1,12.73,100,1,13.8,200,2,12.71,100,1,13.92,100,1,12.5,700,1,13.94,2,1,12.46,100,1,14.23,100,1,12.43,700,1,14.28,100,1,12.42,700,1,14.52,300,3,ARL,330789481
1926,2025-07-17T16:06:09.968186617Z,2025-07-17T16:06:09.968186617Z,10,2,1108,C,A,0,14.71,100,0,165449,275700270,13.11,100,1,13.6,15,1,13,2,1,13.61,100,1,12.98,200,2,13.62,15,1,12.86,100,1,13.65,100,1,12.73,100,1,13.8,200,2,12.71,100,1,13.92,100,1,12.5,700,1,13.94,2,1,12.46,100,1,14.23,100,1,12.43,700,1,14.28,100,1,12.42,700,1,14.52,300,3,ARL,330359225
1927,2025-07-17T16:06:09.968186617Z,2025-07-17T16:06:09.968186617Z,10,2,1108,A,A,12,14.67,100,130,165449,275700270,13.11,100,1,13.6,15,1,13,2,1,13.61,100,1,12.98,200,2,13.62,15,1,12.86,100,1,13.65,100,1,12.73,100,1,13.8,200,2,12.71,100,1,13.92,100,1,12.5,700,1,13.94,2,1,12.46,100,1,14.23,100,1,12.43,700,1,14.28,100,1,12.42,700,1,14.52,300,3,ARL,330789501
1928,2025-07-17T16:06:09.969875190Z,2025-07-17T16:06:09.969875190Z,10,2,1108,C,A,0,17.44,100,0,165496,275700282,13.11,100,1,13.6,15,1,13,2,1,13.61,100,1,12.98,200,2,13.62,15,1,12.86,100,1,13.65,100,1,12.73,100,1,13.8,200,2,12.71,100,1,13.92,100,1,12.5,700,1,13.94,2,1,12.46,100,1,14.23,100,1,12.43,700,1,14.28,100,1,12.42,700,1,14.52,300,3,ARL,327870217
1929,2025-07-17T16:06:09.969875190Z,2025-07-17T16:06:09.969875190Z,10,2,1108,A,A,22,17.29,100,130,165496,275700282,13.11,100,1,13.6,15,1,13,2,1,13.61,100,1,12.98,200,2,13.62,15,1,12.86,100,1,13.65,100,1,12.73,100,1,13.8,200,2,12.71,100,1,13.92,100,1,12.5,700,1,13.94,2,1,12.46,100,1,14.23,100,1,12.43,700,1,14.28,100,1,12.42,700,1,14.52,300,3,ARL,330789509
1930,2025-07-17T16:06:20.470724464Z,2025-07-17T16:06:20.470724464Z,10,2,1108,A,A,3,13.63,100,130,165387,275896138,13.11,100,1,13.6,15,1,13,2,1,13.61,100,1,12.98,200,2,13.62,15,1,12.86,100,1,13.63,100,1,12.73,100,1,13.65,100,1,12.71,100,1,13.8,200,2,12.5,700,1,13.92,100,1,12.46,100,1,13.94,2,1,12.43,700,1,14.23,100,1,12.42,700,1,14.28,100,1,ARL,331018065
1931,2025-07-17T16:06:20.477432988Z,2025-07-17T16:06:20.477432988Z,10,2,1108,C,A,0,13.65,100,130,165590,275896242,13.11,100,1,13.6,15,1,13,2,1,13.61,100,1,12.98,200,2,13.62,15,1,12.86,100,1,13.63,100,1,12.73,100,1,13.8,200,2,12.71,100,1,13.92,100,1,12.5,700,1,13.94,2,1,12.46,100,1,14.23,100,1,12.43,700,1,14.28,100,1,12.42,700,1,14.52,300,3,ARL,330577773
1932,2025-07-17T16:06:20.810998706Z,2025-07-17T16:06:20.810998706Z,10,2,1108,C,A,0,13.62,15,130,165472,275900161,13.11,100,1,13.6,15,1,13,2,1,13.61,100,1,12.98,200,2,13.63,100,1,12.86,100,1,13.8,200,2,12.73,100,1,13.92,100,1,12.71,100,1,13.94,2,1,12.5,700,1,14.23,100,1,12.46,100,1,14.28,100,1,12.43,700,1,14.52,300,3,12.42,700,1,14.56,800,2,ARL,330577045
1933,2025-07-17T16:06:22.151057292Z,2025-07-17T16:06:22.151057292Z,10,2,1108,A,A,0,13.58,15,130,165527,275926927,13.11,100,1,13.58,15,1,13,2,1,13.6,15,1,12.98,200,2,13.61,100,1,12.86,100,1,13.63,100,1,12.73,100,1,13.8,200,2,12.71,100,1,13.92,100,1,12.5,700,1,13.94,2,1,12.46,100,1,14.23,100,1,12.43,700,1,14.28,100,1,12.42,700,1,14.52,300,3,ARL,331050981
1934,2025-07-17T16:06:22.151326300Z,2025-07-17T16:06:22.151326300Z,10,2,1108,C,A,0,13.61,100,0,165532,275926940,13.11,100,1,13.58,15,1,13,2,1,13.6,15,1,12.98,200,2,13.63,100,1,12.86,100,1,13.8,200,2,12.73,100,1,13.92,100,1,12.71,100,1,13.94,2,1,12.5,700,1,14.23,100,1,12.46,100,1,14.28,100,1,12.43,700,1,14.52,300,3,12.42,700,1,14.56,800,2,ARL,330789481
1935,2025-07-17T16:06:22.151326300Z,2025-07-17T16:06:22.151326300Z,10,2,1108,A,A,1,13.59,100,130,165532,275926940,13.11,100,1,13.58,15,1,13,2,1,13.59,100,1,12.98,200,2,13.6,15,1,12.86,100,1,13.63,100,1,12.73,100,1,13.8,200,2,12.71,100,1,13.92,100,1,12.5,700,1,13.94,2,1,12.46,100,1,14.23,100,1,12.43,700,1,14.28,100,1,12.42,700,1,14.52,300,3,ARL,331050989
1936,2025-07-17T16:06:22.151595415Z,2025-07-17T16:06:22.151595415Z,10,2,1108,C,A,4,13.8,100,0,165914,275926966,13.11,100,1,13.58,15,1,13,2,1,13.59,100,1,12.98,200,2,13.6,15,1,12.86,100,1,13.63,100,1,12.73,100,1,13.8,100,1,12.71,100,1,13.92,100,1,12.5,700,1,13.94,2,1,12.46,100,1,14.23,100,1,12.43,700,1,14.28,100,1,12.42,700,1,14.52,300,3,ARL,328614525
1937,2025-07-17T16:06:22.151595781Z,2025-07-17T16:06:22.151595781Z,10,2,1108,C,A,0,13.8,100,130,165548,275926967,13.11,100,1,13.58,15,1,13,2,1,13.59,100,1,12.98,200,2,13.6,15,1,12.86,100,1,13.63,100,1,12.73,100,1,13.92,100,1,12.71,100,1,13.94,2,1,12.5,700,1,14.23,100,1,12.46,100,1,14.28,100,1,12.43,700,1,14.52,300,3,12.42,700,1,14.56,800,2,ARL,328614529
1938,2025-07-17T16:06:22.152983326Z,2025-07-17T16:06:22.152983326Z,10,2,1108,C,A,0,15.79,100,0,165567,275927034,13.11,100,1,13.58,15,1,13,2,1,13.59,100,1,12.98,200,2,13.6,15,1,12.86,100,1,13.63,100,1,12.73,100,1,13.92,100,1,12.71,100,1,13.94,2,1,12.5,700,1,14.23,100,1,12.46,100,1,14.28,100,1,12.43,700,1,14.52,300,3,12.42,700,1,14.56,800,2,ARL,327870361
1939,2025-07-17T16:06:22.152983326Z,2025-07-17T16:06:22.152983326Z,10,2,1108,A,A,17,15.63,100,130,165567,275927034,13.11,100,1,13.58,15,1,13,2,1,13.59,100,1,12.98,200,2,13.6,15,1,12.86,100,1,13.63,100,1,12.73,100,1,13.92,100,1,12.71,100,1,13.94,2,1,12.5,700,1,14.23,100,1,12.46,100,1,14.28,100,1,12.43,700,1,14.52,300,3,12.42,700,1,14.56,800,2,ARL,331051145
1940,2025-07-17T16:06:22.153749481Z,2025-07-17T16:06:22.153749481Z,10,2,1108,C,A,13,14.7,100,0,166688,275927046,13.11,100,1,13.58,15,1,13,2,1,13.59,100,1,12.98,200,2,13.6,15,1,12.86,100,1,13.63,100,1,12.73,100,1,13.92,100,1,12.71,100,1,13.94,2,1,12.5,700,1,14.23,100,1,12.46,100,1,14.28,100,1,12.43,700,1,14.52,300,3,12.42,700,1,14.56,800,2,ARL,327868421
1941,2025-07-17T16:06:22.153749481Z,2025-07-17T16:06:22.153749481Z,10,2,1108,A,A,9,14.55,100,130,166688,275927046,13.11,100,1,13.58,15,1,13,2,1,13.59,100,1,12.98,200,2,13.6,15,1,12.86,100,1,13.63,100,1,12.73,100,1,13.92,100,1,12.71,100,1,13.94,2,1,12.5,700,1,14.23,100,1,12.46,100,1,14.28,100,1,12.43,700,1,14.52,300,3,12.42,700,1,14.55,100,1,ARL,331051173
1942,2025-07-17T16:06:22.155905240Z,2025-07-17T16:06:22.155905240Z,10,2,1108,C,A,8,14.52,100,0,165458,275927117,13.11,100,1,13.58,15,1,13,2,1,13.59,100,1,12.98,200,2,13.6,15,1,12.86,100,1,13.63,100,1,12.73,100,1,13.92,100,1,12.71,100,1,13.94,2,1,12.5,700,1,14.23,100,1,12.46,100,1,14.28,100,1,12.43,700,1,14.52,200,2,12.42,700,1,14.55,100,1,ARL,327869529
1943,2025-07-17T16:06:22.155905240Z,2025-07-17T16:06:22.155905240Z,10,2,1108,A,A,8,14.38,100,130,165458,275927117,13.11,100,1,13.58,15,1,13,2,1,13.59,100,1,12.98,200,2,13.6,15,1,12.86,100,1,13.63,100,1,12.73,100,1,13.92,100,1,12.71,100,1,13.94,2,1,12.5,700,1,14.23,100,1,12.46,100,1,14.28,100,1,12.43,700,1,14.38,100,1,12.42,700,1,14.52,200,2,ARL,331051369
1944,2025-07-17T16:06:22.177879233Z,2025-07-17T16:06:22.177879233Z,10,2,1108,C,A,0,14.7,100,0,165442,275927444,13.11,100,1,13.58,15,1,13,2,1,13.59,100,1,12.98,200,2,13.6,15,1,12.86,100,1,13.63,100,1,12.73,100,1,13.92,100,1,12.71,100,1,13.94,2,1,12.5,700,1,14.23,100,1,12.46,100,1,14.28,100,1,12.43,700,1,14.38,100,1,12.42,700,1,14.52,200,2,ARL,327873009
1945,2025-07-17T16:06:22.177879233Z,2025-07-17T16:06:22.177879233Z,10,2,1108,A,A,10,14.55,100,130,165442,275927444,13.11,100,1,13.58,15,1,13,2,1,13.59,100,1,12.98,200,2,13.6,15,1,12.86,100,1,13.63,100,1,12.73,100,1,13.92,100,1,12.71,100,1,13.94,2,1,12.5,700,1,14.23,100,1,12.46,100,1,14.28,100,1,12.43,700,1,14.38,100,1,12.42,700,1,14.52,200,2,ARL,331052197
1946,2025-07-17T16:06:24.519345743Z,2025-07-17T16:06:24.519345743Z,10,2,1108,A,A,2,13.6,100,130,165385,275968354,13.11,100,1,13.58,15,1,13,2,1,13.59,100,1,12.98,200,2,13.6,115,2,12.86,100,1,13.63,100,1,12.73,100,1,13.92,100,1,12.71,100,1,13.94,2,1,12.5,700,1,14.23,100,1,12.46,100,1,14.28,100,1,12.43,700,1,14.38,100,1,12.42,700,1,14.52,200,2,ARL,331104725
1947,2025-07-17T16:06:24.526194457Z,2025-07-17T16:06:24.526194457Z,10,2,1108,C,A,0,13.63,100,130,165259,275968393,13.11,100,1,13.58,15,1,13,2,1,13.59,100,1,12.98,200,2,13.6,115,2,12.86,100,1,13.92,100,1,12.73,100,1,13.94,2,1,12.71,100,1,14.23,100,1,12.5,700,1,14.28,100,1,12.46,100,1,14.38,100,1,12.43,700,1,14.52,200,2,12.42,700,1,14.55,200,2,ARL,331018065
1948,2025-07-17T16:06:26.610180184Z,2025-07-17T16:06:26.610180184Z,10,2,1108,C,A,0,13.94,2,0,165616,276013080,13.11,100,1,13.58,15,1,13,2,1,13.59,100,1,12.98,200,2,13.6,115,2,12.86,100,1,13.92,100,1,12.73,100,1,14.23,100,1,12.71,100,1,14.28,100,1,12.5,700,1,14.38,100,1,12.46,100,1,14.52,200,2,12.43,700,1,14.55,200,2,12.42,700,1,14.56,800,2,ARL,328351217
1949,2025-07-17T16:06:26.610180184Z,2025-07-17T16:06:26.610180184Z,10,2,1108,A,A,3,13.85,2,130,165616,276013080,13.11,100,1,13.58,15,1,13,2,1,13.59,100,1,12.98,200,2,13.6,115,2,12.86,100,1,13.85,2,1,12.73,100,1,13.92,100,1,12.71,100,1,14.23,100,1,12.5,700,1,14.28,100,1,12.46,100,1,14.38,100,1,12.43,700,1,14.52,200,2,12.42,700,1,14.55,200,2,ARL,331155889
1950,2025-07-17T16:06:30.625711923Z,2025-07-17T16:06:30.625711923Z,10,2,1108,A,A,6,14.27,700,130,165291,276103282,13.11,100,1,13.58,15,1,13,2,1,13.59,100,1,12.98,200,2,13.6,115,2,12.86,100,1,13.85,2,1,12.73,100,1,13.92,100,1,12.71,100,1,14.23,100,1,12.5,700,1,14.27,700,1,12.46,100,1,14.28,100,1,12.43,700,1,14.38,100,1,12.42,700,1,14.52,200,2,ARL,331257169
1951,2025-07-17T16:06:30.625790910Z,2025-07-17T16:06:30.625790910Z,10,2,1108,C,A,14,14.68,700,130,165397,276103283,13.11,100,1,13.58,15,1,13,2,1,13.59,100,1,12.98,200,2,13.6,115,2,12.86,100,1,13.85,2,1,12.73,100,1,13.92,100,1,12.71,100,1,14.23,100,1,12.5,700,1,14.27,700,1,12.46,100,1,14.28,100,1,12.43,700,1,14.38,100,1,12.42,700,1,14.52,200,2,ARL,325716945
1952,2025-07-17T16:06:31.127662311Z,2025-07-17T16:06:31.127662311Z,10,2,1108,A,A,9,14.48,700,130,165494,276118990,13.11,100,1,13.58,15,1,13,2,1,13.59,100,1,12.98,200,2,13.6,115,2,12.86,100,1,13.85,2,1,12.73,100,1,13.92,100,1,12.71,100,1,14.23,100,1,12.5,700,1,14.27,700,1,12.46,100,1,14.28,100,1,12.43,700,1,14.38,100,1,12.42,700,1,14.48,700,1,ARL,331272997
1953,2025-07-17T16:06:31.128416336Z,2025-07-17T16:06:31.128416336Z,10,2,1108,C,A,0,14.68,700,130,165495,276119017,13.11,100,1,13.58,15,1,13,2,1,13.59,100,1,12.98,200,2,13.6,115,2,12.86,100,1,13.85,2,1,12.73,100,1,13.92,100,1,12.71,100,1,14.23,100,1,12.5,700,1,14.27,700,1,12.46,100,1,14.28,100,1,12.43,700,1,14.38,100,1,12.42,700,1,14.48,700,1,ARL,289932801
1954,2025-07-17T16:06:31.990483799Z,2025-07-17T16:06:31.990483799Z,10,2,1108,C,A,2,13.6,15,130,165430,276135226,13.11,100,1,13.58,15,1,13,2,1,13.59,100,1,12.98,200,2,13.6,100,1,12.86,100,1,13.85,2,1,12.73,100,1,13.92,100,1,12.71,100,1,14.23,100,1,12.5,700,1,14.27,700,1,12.46,100,1,14.28,100,1,12.43,700,1,14.38,100,1,12.42,700,1,14.48,700,1,ARL,330788421
1955,2025-07-17T16:06:42.812641697Z,2025-07-17T16:06:42.812641697Z,10,2,1108,A,A,0,13.56,15,130,165399,276276783,13.11,100,1,13.56,15,1,13,2,1,13.58,15,1,12.98,200,2,13.59,100,1,12.86,100,1,13.6,100,1,12.73,100,1,13.85,2,1,12.71,100,1,13.92,100,1,12.5,700,1,14.23,100,1,12.46,100,1,14.27,700,1,12.43,700,1,14.28,100,1,12.42,700,1,14.38,100,1,ARL,331488089
1956,2025-07-17T16:06:43.012799164Z,2025-07-17T16:06:43.012799164Z,10,2,1108,C,A,0,13.59,100,0,166793,276279311,13.11,100,1,13.56,15,1,13,2,1,13.58,15,1,12.98,200,2,13.6,100,1,12.86,100,1,13.85,2,1,12.73,100,1,13.92,100,1,12.71,100,1,14.23,100,1,12.5,700,1,14.27,700,1,12.46,100,1,14.28,100,1,12.43,700,1,14.38,100,1,12.42,700,1,14.48,700,1,ARL,331050989
1957,2025-07-17T16:06:43.012799164Z,2025-07-17T16:06:43.012799164Z,10,2,1108,A,A,1,13.57,100,128,166793,276279311,13.11,100,1,13.56,15,1,13,2,1,13.57,100,1,12.98,200,2,13.58,15,1,12.86,100,1,13.6,100,1,12.73,100,1,13.85,2,1,12.71,100,1,13.92,100,1,12.5,700,1,14.23,100,1,12.46,100,1,14.27,700,1,12.43,700,1,14.28,100,1,12.42,700,1,14.38,100,1,ARL,331491049
1958,2025-07-17T16:06:43.013550575Z,2025-07-17T16:06:43.013550575Z,10,2,1108,C,A,0,14.67,100,0,165630,276279331,13.11,100,1,13.56,15,1,13,2,1,13.57,100,1,12.98,200,2,13.58,15,1,12.86,100,1,13.6,100,1,12.73,100,1,13.85,2,1,12.71,100,1,13.92,100,1,12.5,700,1,14.23,100,1,12.46,100,1,14.27,700,1,12.43,700,1,14.28,100,1,12.42,700,1,14.38,100,1,ARL,330789501
1959,2025-07-17T16:06:43.013550575Z,2025-07-17T16:06:43.013550575Z,10,2,1108,A,A,15,14.62,100,130,165630,276279331,13.11,100,1,13.56,15,1,13,2,1,13.57,100,1,12.98,200,2,13.58,15,1,12.86,100,1,13.6,100,1,12.73,100,1,13.85,2,1,12.71,100,1,13.92,100,1,12.5,700,1,14.23,100,1,12.46,100,1,14.27,700,1,12.43,700,1,14.28,100,1,12.42,700,1,14.38,100,1,ARL,331491077
1960,2025-07-17T16:06:43.024490355Z,2025-07-17T16:06:43.024490355Z,10,2,1108,C,A,0,13.92,100,130,165668,276279620,13.11,100,1,13.56,15,1,13,2,1,13.57,100,1,12.98,200,2,13.58,15,1,12.86,100,1,13.6,100,1,12.73,100,1,13.85,2,1,12.71,100,1,14.23,100,1,12.5,700,1,14.27,700,1,12.46,100,1,14.28,100,1,12.43,700,1,14.38,100,1,12.42,700,1,14.48,700,1,ARL,330359625
1961,2025-07-17T16:06:43.024543099Z,2025-07-17T16:06:43.024543099Z,10,2,1108,A,A,4,13.84,100,130,165205,276279621,13.11,100,1,13.56,15,1,13,2,1,13.57,100,1,12.98,200,2,13.58,15,1,12.86,100,1,13.6,100,1,12.73,100,1,13.84,100,1,12.71,100,1,13.85,2,1,12.5,700,1,14.23,100,1,12.46,100,1,14.27,700,1,12.43,700,1,14.28,100,1,12.42,700,1,14.38,100,1,ARL,331491269
1962,2025-07-17T16:06:49.613776144Z,2025-07-17T16:06:49.613776144Z,10,2,1108,C,A,0,13.58,15,130,165677,276382302,13.11,100,1,13.56,15,1,13,2,1,13.57,100,1,12.98,200,2,13.6,100,1,12.86,100,1,13.84,100,1,12.73,100,1,13.85,2,1,12.71,100,1,14.23,100,1,12.5,700,1,14.27,700,1,12.46,100,1,14.28,100,1,12.43,700,1,14.38,100,1,12.42,700,1,14.48,700,1,ARL,331050981
1963,2025-07-17T16:06:50.618504506Z,2025-07-17T16:06:50.618504506Z,10,2,1108,A,A,0,13.54,15,130,165337,276408477,13.11,100,1,13.54,15,1,13,2,1,13.56,15,1,12.98,200,2,13.57,100,1,12.86,100,1,13.6,100,1,12.73,100,1,13.84,100,1,12.71,100,1,13.85,2,1,12.5,700,1,14.23,100,1,12.46,100,1,14.27,700,1,12.43,700,1,14.28,100,1,12.42,700,1,14.38,100,1,ARL,331666961
1964,2025-07-17T16:06:50.626272828Z,2025-07-17T16:06:50.626272828Z,10,2,1108,A,A,3,13.58,100,130,165377,276408566,13.11,100,1,13.54,15,1,13,2,1,13.56,15,1,12.98,200,2,13.57,100,1,12.86,100,1,13.58,100,1,12.73,100,1,13.6,100,1,12.71,100,1,13.84,100,1,12.5,700,1,13.85,2,1,12.46,100,1,14.23,100,1,12.43,700,1,14.27,700,1,12.42,700,1,14.28,100,1,ARL,331667121
1965,2025-07-17T16:06:50.632947998Z,2025-07-17T16:06:50.632947998Z,10,2,1108,C,A,0,13.6,100,130,165559,276408644,13.11,100,1,13.54,15,1,13,2,1,13.56,15,1,12.98,200,2,13.57,100,1,12.86,100,1,13.58,100,1,12.73,100,1,13.84,100,1,12.71,100,1,13.85,2,1,12.5,700,1,14.23,100,1,12.46,100,1,14.27,700,1,12.43,700,1,14.28,100,1,12.42,700,1,14.38,100,1,ARL,331104725
1966,2025-07-17T16:06:51.754410704Z,2025-07-17T16:06:51.754410704Z,10,2,1108,C,A,0,13.57,100,0,165618,276428315,13.11,100,1,13.54,15,1,13,2,1,13.56,15,1,12.98,200,2,13.58,100,1,12.86,100,1,13.84,100,1,12.73,100,1,13.85,2,1,12.71,100,1,14.23,100,1,12.5,700,1,14.27,700,1,12.46,100,1,14.28,100,1,12.43,700,1,14.38,100,1,12.42,700,1,14.48,700,1,ARL,331491049
1967,2025-07-17T16:06:51.754410704Z,2025-07-17T16:06:51.754410704Z,10,2,1108,A,A,1,13.55,100,130,165618,276428315,13.11,100,1,13.54,15,1,13,2,1,13.55,100,1,12.98,200,2,13.56,15,1,12.86,100,1,13.58,100,1,12.73,100,1,13.84,100,1,12.71,100,1,13.85,2,1,12.5,700,1,14.23,100,1,12.46,100,1,14.27,700,1,12.43,700,1,14.28,100,1,12.42,700,1,14.38,100,1,ARL,331694265
1968,2025-07-17T16:06:51.757237300Z,2025-07-17T16:06:51.757237300Z,10,2,1108,C,B,0,13,2,0,165809,276428333,13.11,100,1,13.54,15,1,12.98,200,2,13.55,100,1,12.86,100,1,13.56,15,1,12.73,100,1,13.58,100,1,12.71,100,1,13.84,100,1,12.5,700,1,13.85,2,1,12.46,100,1,14.23,100,1,12.43,700,1,14.27,700,1,12.42,700,1,14.28,100,1,12.37,700,1,14.38,100,1,ARL,325967705
1969,2025-07-17T16:06:51.757237300Z,2025-07-17T16:06:51.757237300Z,10,2,1108,A,B,2,12.9,2,130,165809,276428333,13.11,100,1,13.54,15,1,12.98,200,2,13.55,100,1,12.9,2,1,13.56,15,1,12.86,100,1,13.58,100,1,12.73,100,1,13.84,100,1,12.71,100,1,13.85,2,1,12.5,700,1,14.23,100,1,12.46,100,1,14.27,700,1,12.43,700,1,14.28,100,1,12.42,700,1,14.38,100,1,ARL,331694297
1970,2025-07-17T16:06:55.056135380Z,2025-07-17T16:06:55.056135380Z,10,2,1108,C,A,0,13.54,15,130,165481,276516227,13.11,100,1,13.55,100,1,12.98,200,2,13.56,15,1,12.9,2,1,13.58,100,1,12.86,100,1,13.84,100,1,12.73,100,1,13.85,2,1,12.71,100,1,14.23,100,1,12.5,700,1,14.27,700,1,12.46,100,1,14.28,100,1,12.43,700,1,14.38,100,1,12.42,700,1,14.48,700,1,ARL,331666961
1971,2025-07-17T16:06:55.056301001Z,2025-07-17T16:06:55.056301001Z,10,2,1108,C,A,0,13.56,15,130,165230,276516239,13.11,100,1,13.55,100,1,12.98,200,2,13.58,100,1,12.9,2,1,13.84,100,1,12.86,100,1,13.85,2,1,12.73,100,1,14.23,100,1,12.71,100,1,14.27,700,1,12.5,700,1,14.28,100,1,12.46,100,1,14.38,100,1,12.43,700,1,14.48,700,1,12.42,700,1,14.52,200,2,ARL,331488089
1972,2025-07-17T16:07:00.010829521Z,2025-07-17T16:07:00.010829521Z,10,2,1108,C,A,0,13.55,100,130,166037,276611719,13.11,100,1,13.58,100,1,12.98,200,2,13.84,100,1,12.9,2,1,13.85,2,1,12.86,100,1,14.23,100,1,12.73,100,1,14.27,700,1,12.71,100,1,14.28,100,1,12.5,700,1,14.38,100,1,12.46,100,1,14.48,700,1,12.43,700,1,14.52,200,2,12.42,700,1,14.55,200,2,ARL,331694265
1973,2025-07-17T16:07:00.023683961Z,2025-07-17T16:07:00.023683961Z,10,2,1108,C,A,0,13.58,100,130,165219,276613073,13.11,100,1,13.84,100,1,12.98,200,2,13.85,2,1,12.9,2,1,14.23,100,1,12.86,100,1,14.27,700,1,12.73,100,1,14.28,100,1,12.71,100,1,14.38,100,1,12.5,700,1,14.48,700,1,12.46,100,1,14.52,200,2,12.43,700,1,14.55,200,2,12.42,700,1,14.56,800,2,ARL,331667121
1974,2025-07-17T16:07:00.023752163Z,2025-07-17T16:07:00.023752163Z,10,2,1108,C,A,0,14.27,700,130,165380,276613077,13.11,100,1,13.84,100,1,12.98,200,2,13.85,2,1,12.9,2,1,14.23,100,1,12.86,100,1,14.28,100,1,12.73,100,1,14.38,100,1,12.71,100,1,14.48,700,1,12.5,700,1,14.52,200,2,12.46,100,1,14.55,200,2,12.43,700,1,14.56,800,2,12.42,700,1,14.6,700,1,ARL,331257169
1975,2025-07-17T16:07:00.023815326Z,2025-07-17T16:07:00.023815326Z,10,2,1108,A,A,6,14.51,700,130,165479,276613078,13.11,100,1,13.84,100,1,12.98,200,2,13.85,2,1,12.9,2,1,14.23,100,1,12.86,100,1,14.28,100,1,12.73,100,1,14.38,100,1,12.71,100,1,14.48,700,1,12.5,700,1,14.51,700,1,12.46,100,1,14.52,200,2,12.43,700,1,14.55,200,2,12.42,700,1,14.56,800,2,ARL,331926981
1976,2025-07-17T16:07:00.024424816Z,2025-07-17T16:07:00.024424816Z,10,2,1108,C,A,0,14.62,100,0,165467,276613110,13.11,100,1,13.84,100,1,12.98,200,2,13.85,2,1,12.9,2,1,14.23,100,1,12.86,100,1,14.28,100,1,12.73,100,1,14.38,100,1,12.71,100,1,14.48,700,1,12.5,700,1,14.51,700,1,12.46,100,1,14.52,200,2,12.43,700,1,14.55,200,2,12.42,700,1,14.56,800,2,ARL,331491077
1977,2025-07-17T16:07:00.024424816Z,2025-07-17T16:07:00.024424816Z,10,2,1108,A,A,11,14.88,100,130,165467,276613110,13.11,100,1,13.84,100,1,12.98,200,2,13.85,2,1,12.9,2,1,14.23,100,1,12.86,100,1,14.28,100,1,12.73,100,1,14.38,100,1,12.71,100,1,14.48,700,1,12.5,700,1,14.51,700,1,12.46,100,1,14.52,200,2,12.43,700,1,14.55,200,2,12.42,700,1,14.56,800,2,ARL,331927017
1978,2025-07-17T16:07:00.025064913Z,2025-07-17T16:07:00.025064913Z,10,2,1108,C,A,0,14.23,100,130,166251,276613157,13.11,100,1,13.84,100,1,12.98,200,2,13.85,2,1,12.9,2,1,14.28,100,1,12.86,100,1,14.38,100,1,12.73,100,1,14.48,700,1,12.71,100,1,14.51,700,1,12.5,700,1,14.52,200,2,12.46,100,1,14.55,200,2,12.43,700,1,14.56,800,2,12.42,700,1,14.6,700,1,ARL,329074833
1979,2025-07-17T16:07:00.025422082Z,2025-07-17T16:07:00.025422082Z,10,2,1108,A,A,4,14.46,100,130,165467,276613175,13.11,100,1,13.84,100,1,12.98,200,2,13.85,2,1,12.9,2,1,14.28,100,1,12.86,100,1,14.38,100,1,12.73,100,1,14.46,100,1,12.71,100,1,14.48,700,1,12.5,700,1,14.51,700,1,12.46,100,1,14.52,200,2,12.43,700,1,14.55,200,2,12.42,700,1,14.56,800,2,ARL,331927161
1980,2025-07-17T16:07:00.025628157Z,2025-07-17T16:07:00.025628157Z,10,2,1108,A,A,0,13.59,100,130,165103,276613194,13.11,100,1,13.59,100,1,12.98,200,2,13.84,100,1,12.9,2,1,13.85,2,1,12.86,100,1,14.28,100,1,12.73,100,1,14.38,100,1,12.71,100,1,14.46,100,1,12.5,700,1,14.48,700,1,12.46,100,1,14.51,700,1,12.43,700,1,14.52,200,2,12.42,700,1,14.55,200,2,ARL,331927177
1981,2025-07-17T16:07:00.026833761Z,2025-07-17T16:07:00.026833761Z,10,2,1108,C,A,0,13.59,100,130,164934,276613224,13.11,100,1,13.84,100,1,12.98,200,2,13.85,2,1,12.9,2,1,14.28,100,1,12.86,100,1,14.38,100,1,12.73,100,1,14.46,100,1,12.71,100,1,14.48,700,1,12.5,700,1,14.51,700,1,12.46,100,1,14.52,200,2,12.43,700,1,14.55,200,2,12.42,700,1,14.56,800,2,ARL,331927177
1982,2025-07-17T16:07:00.032596898Z,2025-07-17T16:07:00.032596898Z,10,2,1108,C,A,0,14.38,100,130,165284,276613329,13.11,100,1,13.84,100,1,12.98,200,2,13.85,2,1,12.9,2,1,14.28,100,1,12.86,100,1,14.46,100,1,12.73,100,1,14.48,700,1,12.71,100,1,14.51,700,1,12.5,700,1,14.52,200,2,12.46,100,1,14.55,200,2,12.43,700,1,14.56,800,2,12.42,700,1,14.6,700,1,ARL,331051369
1983,2025-07-17T16:07:00.032711777Z,2025-07-17T16:07:00.032711777Z,10,2,1108,A,A,10,14.63,100,130,165170,276613336,13.11,100,1,13.84,100,1,12.98,200,2,13.85,2,1,12.9,2,1,14.28,100,1,12.86,100,1,14.46,100,1,12.73,100,1,14.48,700,1,12.71,100,1,14.51,700,1,12.5,700,1,14.52,200,2,12.46,100,1,14.55,200,2,12.43,700,1,14.56,800,2,12.42,700,1,14.6,700,1,ARL,331927477
1984,2025-07-17T16:07:00.045359807Z,2025-07-17T16:07:00.045359807Z,10,2,1108,C,A,0,13.84,100,130,165240,276613663,13.11,100,1,13.85,2,1,12.98,200,2,14.28,100,1,12.9,2,1,14.46,100,1,12.86,100,1,14.48,700,1,12.73,100,1,14.51,700,1,12.71,100,1,14.52,200,2,12.5,700,1,14.55,200,2,12.46,100,1,14.56,800,2,12.43,700,1,14.6,700,1,12.42,700,1,14.63,100,1,ARL,331491269
1985,2025-07-17T16:07:00.045394317Z,2025-07-17T16:07:00.045394317Z,10,2,1108,C,A,0,14.51,700,130,164955,276613664,13.11,100,1,13.85,2,1,12.98,200,2,14.28,100,1,12.9,2,1,14.46,100,1,12.86,100,1,14.48,700,1,12.73,100,1,14.52,200,2,12.71,100,1,14.55,200,2,12.5,700,1,14.56,800,2,12.46,100,1,14.6,700,1,12.43,700,1,14.63,100,1,12.42,700,1,14.88,100,1,ARL,331926981
1986,2025-07-17T16:07:00.045409635Z,2025-07-17T16:07:00.045409635Z,10,2,1108,A,A,1,14.09,100,130,165151,276613665,13.11,100,1,13.85,2,1,12.98,200,2,14.09,100,1,12.9,2,1,14.28,100,1,12.86,100,1,14.46,100,1,12.73,100,1,14.48,700,1,12.71,100,1,14.52,200,2,12.5,700,1,14.55,200,2,12.46,100,1,14.56,800,2,12.43,700,1,14.6,700,1,12.42,700,1,14.63,100,1,ARL,331927857
1987,2025-07-17T16:07:00.046672908Z,2025-07-17T16:07:00.046672908Z,10,2,1108,C,A,0,14.09,100,130,165694,276613680,13.11,100,1,13.85,2,1,12.98,200,2,14.28,100,1,12.9,2,1,14.46,100,1,12.86,100,1,14.48,700,1,12.73,100,1,14.52,200,2,12.71,100,1,14.55,200,2,12.5,700,1,14.56,800,2,12.46,100,1,14.6,700,1,12.43,700,1,14.63,100,1,12.42,700,1,14.88,100,1,ARL,331927857
1988,2025-07-17T16:07:00.046721624Z,2025-07-17T16:07:00.046721624Z,10,2,1108,A,A,1,13.86,100,130,165381,276613681,13.11,100,1,13.85,2,1,12.98,200,2,13.86,100,1,12.9,2,1,14.28,100,1,12.86,100,1,14.46,100,1,12.73,100,1,14.48,700,1,12.71,100,1,14.52,200,2,12.5,700,1,14.55,200,2,12.46,100,1,14.56,800,2,12.43,700,1,14.6,700,1,12.42,700,1,14.63,100,1,ARL,331927877
1989,2025-07-17T16:07:00.047544064Z,2025-07-17T16:07:00.047544064Z,10,2,1108,C,A,0,13.86,100,130,164872,276613692,13.11,100,1,13.85,2,1,12.98,200,2,14.28,100,1,12.9,2,1,14.46,100,1,12.86,100,1,14.48,700,1,12.73,100,1,14.52,200,2,12.71,100,1,14.55,200,2,12.5,700,1,14.56,800,2,12.46,100,1,14.6,700,1,12.43,700,1,14.63,100,1,12.42,700,1,14.88,100,1,ARL,331927877
1990,2025-07-17T16:07:00.047590313Z,2025-07-17T16:07:00.047590313Z,10,2,1108,A,A,1,14.12,100,130,165185,276613693,13.11,100,1,13.85,2,1,12.98,200,2,14.12,100,1,12.9,2,1,14.28,100,1,12.86,100,1,14.46,100,1,12.73,100,1,14.48,700,1,12.71,100,1,14.52,200,2,12.5,700,1,14.55,200,2,12.46,100,1,14.56,800,2,12.43,700,1,14.6,700,1,12.42,700,1,14.63,100,1,ARL,331927921
1991,2025-07-17T16:07:00.053283700Z,2025-07-17T16:07:00.053283700Z,10,2,1108,C,A,0,14.12,100,130,164970,276613731,13.11,100,1,13.85,2,1,12.98,200,2,14.28,100,1,12.9,2,1,14.46,100,1,12.86,100,1,14.48,700,1,12.73,100,1,14.52,200,2,12.71,100,1,14.55,200,2,12.5,700,1,14.56,800,2,12.46,100,1,14.6,700,1,12.43,700,1,14.63,100,1,12.42,700,1,14.88,100,1,ARL,331927921
1992,2025-07-17T16:07:00.053329959Z,2025-07-17T16:07:00.053329959Z,10,2,1108,A,A,1,14.26,100,130,165136,276613732,13.11,100,1,13.85,2,1,12.98,200,2,14.26,100,1,12.9,2,1,14.28,100,1,12.86,100,1,14.46,100,1,12.73,100,1,14.48,700,1,12.71,100,1,14.52,200,2,12.5,700,1,14.55,200,2,12.46,100,1,14.56,800,2,12.43,700,1,14.6,700,1,12.42,700,1,14.63,100,1,ARL,331928009
1993,2025-07-17T16:07:00.057644427Z,2025-07-17T16:07:00.057644427Z,10,2,1108,C,A,6,14.55,100,0,165430,276613800,13.11,100,1,13.85,2,1,12.98,200,2,14.26,100,1,12.9,2,1,14.28,100,1,12.86,100,1,14.46,100,1,12.73,100,1,14.48,700,1,12.71,100,1,14.52,200,2,12.5,700,1,14.55,100,1,12.46,100,1,14.56,800,2,12.43,700,1,14.6,700,1,12.42,700,1,14.63,100,1,ARL,331052197
1994,2025-07-17T16:07:00.057644427Z,2025-07-17T16:07:00.057644427Z,10,2,1108,A,A,11,14.96,100,130,165430,276613800,13.11,100,1,13.85,2,1,12.98,200,2,14.26,100,1,12.9,2,1,14.28,100,1,12.86,100,1,14.46,100,1,12.73,100,1,14.48,700,1,12.71,100,1,14.52,200,2,12.5,700,1,14.55,100,1,12.46,100,1,14.56,800,2,12.43,700,1,14.6,700,1,12.42,700,1,14.63,100,1,ARL,331928129
1995,2025-07-17T16:07:00.070325784Z,2025-07-17T16:07:00.070325784Z,10,2,1108,C,A,0,14.26,100,130,165051,276614087,13.11,100,1,13.85,2,1,12.98,200,2,14.28,100,1,12.9,2,1,14.46,100,1,12.86,100,1,14.48,700,1,12.73,100,1,14.52,200,2,12.71,100,1,14.55,100,1,12.5,700,1,14.56,800,2,12.46,100,1,14.6,700,1,12.43,700,1,14.63,100,1,12.42,700,1,14.88,100,1,ARL,331928009
1996,2025-07-17T16:07:00.070373975Z,2025-07-17T16:07:00.070373975Z,10,2,1108,A,A,1,14.14,100,130,165247,276614089,13.11,100,1,13.85,2,1,12.98,200,2,14.14,100,1,12.9,2,1,14.28,100,1,12.86,100,1,14.46,100,1,12.73,100,1,14.48,700,1,12.71,100,1,14.52,200,2,12.5,700,1,14.55,100,1,12.46,100,1,14.56,800,2,12.43,700,1,14.6,700,1,12.42,700,1,14.63,100,1,ARL,331929033
1997,2025-07-17T16:07:00.071194493Z,2025-07-17T16:07:00.071194493Z,10,2,1108,C,A,0,14.14,100,130,164857,276614094,13.11,100,1,13.85,2,1,12.98,200,2,14.28,100,1,12.9,2,1,14.46,100,1,12.86,100,1,14.48,700,1,12.73,100,1,14.52,200,2,12.71,100,1,14.55,100,1,12.5,700,1,14.56,800,2,12.46,100,1,14.6,700,1,12.43,700,1,14.63,100,1,12.42,700,1,14.88,100,1,ARL,331929033
1998,2025-07-17T16:07:00.071239867Z,2025-07-17T16:07:00.071239867Z,10,2,1108,A,A,1,14.26,100,130,165238,276614095,13.11,100,1,13.85,2,1,12.98,200,2,14.26,100,1,12.9,2,1,14.28,100,1,12.86,100,1,14.46,100,1,12.73,100,1,14.48,700,1,12.71,100,1,14.52,200,2,12.5,700,1,14.55,100,1,12.46,100,1,14.56,800,2,12.43,700,1,14.6,700,1,12.42,700,1,14.63,100,1,ARL,331929041
1999,2025-07-17T16:07:00.074415631Z,2025-07-17T16:07:00.074415631Z,10,2,1108,C,A,0,14.88,100,0,165315,276614119,13.11,100,1,13.85,2,1,12.98,200,2,14.26,100,1,12.9,2,1,14.28,100,1,12.86,100,1,14.46,100,1,12.73,100,1,14.48,700,1,12.71,100,1,14.52,200,2,12.5,700,1,14.55,100,1,12.46,100,1,14.56,800,2,12.43,700,1,14.6,700,1,12.42,700,1,14.63,100,1,ARL,331927017
2000,2025-07-17T16:07:00.074415631Z,2025-07-17T16:07:00.074415631Z,10,2,1108,A,A,11,15.06,100,130,165315,276614119,13.11,100,1,13.85,2,1,12.98,200,2,14.26,100,1,12.9,2,1,14.28,100,1,12.86,100,1,14.46,100,1,12.73,100,1,14.48,700,1,12.71,100,1,14.52,200,2,12.5,700,1,14.55,100,1,12.46,100,1,14.56,800,2,12.43,700,1,14.6,700,1,12.42,700,1,14.63,100,1,ARL,331929065
2001,2025-07-17T16:07:00.084965637Z,2025-07-17T16:07:00.084965637Z,10,2,1108,C,A,0,15.07,100,0,165626,276614295,13.11,100,1,13.85,2,1,12.98,200,2,14.26,100,1,12.9,2,1,14.28,100,1,12.86,100,1,14.46,100,1,12.73,100,1,14.48,700,1,12.71,100,1,14.52,200,2,12.5,700,1,14.55,100,1,12.46,100,1,14.56,800,2,12.43,700,1,14.6,700,1,12.42,700,1,14.63,100,1,ARL,326837501
2002,2025-07-17T16:07:00.084965637Z,2025-07-17T16:07:00.084965637Z,10,2,1108,A,A,14,15.38,100,130,165626,276614295,13.11,100,1,13.85,2,1,12.98,200,2,14.26,100,1,12.9,2,1,14.28,100,1,12.86,100,1,14.46,100,1,12.73,100,1,14.48,700,1,12.71,100,1,14.52,200,2,12.5,700,1,14.55,100,1,12.46,100,1,14.56,800,2,12.43,700,1,14.6,700,1,12.42,700,1,14.63,100,1,ARL,331929445
2003,2025-07-17T16:07:00.090194106Z,2025-07-17T16:07:00.090194106Z,10,2,1108,C,A,0,14.55,100,0,165651,276614378,13.11,100,1,13.85,2,1,12.98,200,2,14.26,100,1,12.9,2,1,14.28,100,1,12.86,100,1,14.46,100,1,12.73,100,1,14.48,700,1,12.71,100,1,14.52,200,2,12.5,700,1,14.56,800,2,12.46,100,1,14.6,700,1,12.43,700,1,14.63,100,1,12.42,700,1,14.96,100,1,ARL,331051173
2004,2025-07-17T16:07:00.090194106Z,2025-07-17T16:07:00.090194106Z,10,2,1108,A,A,9,14.96,100,130,165651,276614378,13.11,100,1,13.85,2,1,12.98,200,2,14.26,100,1,12.9,2,1,14.28,100,1,12.86,100,1,14.46,100,1,12.73,100,1,14.48,700,1,12.71,100,1,14.52,200,2,12.5,700,1,14.56,800,2,12.46,100,1,14.6,700,1,12.43,700,1,14.63,100,1,12.42,700,1,14.96,200,2,ARL,331929633
2005,2025-07-17T16:07:00.101927028Z,2025-07-17T16:07:00.101927028Z,10,2,1108,A,A,9,14.68,700,130,165119,276614699,13.11,100,1,13.85,2,1,12.98,200,2,14.26,100,1,12.9,2,1,14.28,100,1,12.86,100,1,14.46,100,1,12.73,100,1,14.48,700,1,12.71,100,1,14.52,200,2,12.5,700,1,14.56,800,2,12.46,100,1,14.6,700,1,12.43,700,1,14.63,100,1,12.42,700,1,14.68,700,1,ARL,331929977
2006,2025-07-17T16:07:00.287416733Z,2025-07-17T16:07:00.287416733Z,10,2,1108,C,A,0,17.29,100,0,165715,276617288,13.11,100,1,13.85,2,1,12.98,200,2,14.26,100,1,12.9,2,1,14.28,100,1,12.86,100,1,14.46,100,1,12.73,100,1,14.48,700,1,12.71,100,1,14.52,200,2,12.5,700,1,14.56,800,2,12.46,100,1,14.6,700,1,12.43,700,1,14.63,100,1,12.42,700,1,14.68,700,1,ARL,330789509
2007,2025-07-17T16:07:00.287416733Z,2025-07-17T16:07:00.287416733Z,10,2,1108,A,A,19,17.76,100,130,165715,276617288,13.11,100,1,13.85,2,1,12.98,200,2,14.26,100,1,12.9,2,1,14.28,100,1,12.86,100,1,14.46,100,1,12.73,100,1,14.48,700,1,12.71,100,1,14.52,200,2,12.5,700,1,14.56,800,2,12.46,100,1,14.6,700,1,12.43,700,1,14.63,100,1,12.42,700,1,14.68,700,1,ARL,331934277
2008,2025-07-17T16:07:00.293454856Z,2025-07-17T16:07:00.293454856Z,10,2,1108,C,A,0,15.63,100,0,165578,276617317,13.11,100,1,13.85,2,1,12.98,200,2,14.26,100,1,12.9,2,1,14.28,100,1,12.86,100,1,14.46,100,1,12.73,100,1,14.48,700,1,12.71,100,1,14.52,200,2,12.5,700,1,14.56,800,2,12.46,100,1,14.6,700,1,12.43,700,1,14.63,100,1,12.42,700,1,14.68,700,1,ARL,331051145
2009,2025-07-17T16:07:00.293454856Z,2025-07-17T16:07:00.293454856Z,10,2,1108,A,A,16,16.08,100,130,165578,276617317,13.11,100,1,13.85,2,1,12.98,200,2,14.26,100,1,12.9,2,1,14.28,100,1,12.86,100,1,14.46,100,1,12.73,100,1,14.48,700,1,12.71,100,1,14.52,200,2,12.5,700,1,14.56,800,2,12.46,100,1,14.6,700,1,12.43,700,1,14.63,100,1,12.42,700,1,14.68,700,1,ARL,331934377
2010,2025-07-17T16:07:00.494492099Z,2025-07-17T16:07:00.494492099Z,10,2,1108,A,A,1,13.86,100,130,165396,276622423,13.11,100,1,13.85,2,1,12.98,200,2,13.86,100,1,12.9,2,1,14.26,100,1,12.86,100,1,14.28,100,1,12.73,100,1,14.46,100,1,12.71,100,1,14.48,700,1,12.5,700,1,14.52,200,2,12.46,100,1,14.56,800,2,12.43,700,1,14.6,700,1,12.42,700,1,14.63,100,1,ARL,331942821
2011,2025-07-17T16:07:00.495152219Z,2025-07-17T16:07:00.495152219Z,10,2,1108,C,B,11,12.36,100,0,166026,276622452,13.11,100,1,13.85,2,1,12.98,200,2,13.86,100,1,12.9,2,1,14.26,100,1,12.86,100,1,14.28,100,1,12.73,100,1,14.46,100,1,12.71,100,1,14.48,700,1,12.5,700,1,14.52,200,2,12.46,100,1,14.56,800,2,12.43,700,1,14.6,700,1,12.42,700,1,14.63,100,1,ARL,288723817
2012,2025-07-17T16:07:00.495152219Z,2025-07-17T16:07:00.495152219Z,10,2,1108,A,B,7,12.49,100,130,166026,276622452,13.11,100,1,13.85,2,1,12.98,200,2,13.86,100,1,12.9,2,1,14.26,100,1,12.86,100,1,14.28,100,1,12.73,100,1,14.46,100,1,12.71,100,1,14.48,700,1,12.5,700,1,14.52,200,2,12.49,100,1,14.56,800,2,12.46,100,1,14.6,700,1,12.43,700,1,14.63,100,1,ARL,331942901
2013,2025-07-17T16:07:00.495233001Z,2025-07-17T16:07:00.495233001Z,10,2,1108,C,A,0,15.06,100,0,165643,276622455,13.11,100,1,13.85,2,1,12.98,200,2,13.86,100,1,12.9,2,1,14.26,100,1,12.86,100,1,14.28,100,1,12.73,100,1,14.46,100,1,12.71,100,1,14.48,700,1,12.5,700,1,14.52,200,2,12.49,100,1,14.56,800,2,12.46,100,1,14.6,700,1,12.43,700,1,14.63,100,1,ARL,331929065
2014,2025-07-17T16:07:00.495233001Z,2025-07-17T16:07:00.495233001Z,10,2,1108,A,A,11,14.93,100,130,165643,276622455,13.11,100,1,13.85,2,1,12.98,200,2,13.86,100,1,12.9,2,1,14.26,100,1,12.86,100,1,14.28,100,1,12.73,100,1,14.46,100,1,12.71,100,1,14.48,700,1,12.5,700,1,14.52,200,2,12.49,100,1,14.56,800,2,12.46,100,1,14.6,700,1,12.43,700,1,14.63,100,1,ARL,331942913
2015,2025-07-17T16:07:00.495823953Z,2025-07-17T16:07:00.495823953Z,10,2,1108,C,B,0,12.36,100,0,165645,276622469,13.11,100,1,13.85,2,1,12.98,200,2,13.86,100,1,12.9,2,1,14.26,100,1,12.86,100,1,14.28,100,1,12.73,100,1,14.46,100,1,12.71,100,1,14.48,700,1,12.5,700,1,14.52,200,2,12.49,100,1,14.56,800,2,12.46,100,1,14.6,700,1,12.43,700,1,14.63,100,1,ARL,288723813
2016,2025-07-17T16:07:00.495823953Z,2025-07-17T16:07:00.495823953Z,10,2,1108,A,B,7,12.49,100,130,165645,276622469,13.11,100,1,13.85,2,1,12.98,200,2,13.86,100,1,12.9,2,1,14.26,100,1,12.86,100,1,14.28,100,1,12.73,100,1,14.46,100,1,12.71,100,1,14.48,700,1,12.5,700,1,14.52,200,2,12.49,200,2,14.56,800,2,12.46,100,1,14.6,700,1,12.43,700,1,14.63,100,1,ARL,331942945
2017,2025-07-17T16:07:00.496317847Z,2025-07-17T16:07:00.496317847Z,10,2,1108,C,A,0,17.76,100,0,165613,276622478,13.11,100,1,13.85,2,1,12.98,200,2,13.86,100,1,12.9,2,1,14.26,100,1,12.86,100,1,14.28,100,1,12.73,100,1,14.46,100,1,12.71,100,1,14.48,700,1,12.5,700,1,14.52,200,2,12.49,200,2,14.56,800,2,12.46,100,1,14.6,700,1,12.43,700,1,14.63,100,1,ARL,331934277
2018,2025-07-17T16:07:00.496317847Z,2025-07-17T16:07:00.496317847Z,10,2,1108,A,A,19,17.61,100,130,165613,276622478,13.11,100,1,13.85,2,1,12.98,200,2,13.86,100,1,12.9,2,1,14.26,100,1,12.86,100,1,14.28,100,1,12.73,100,1,14.46,100,1,12.71,100,1,14.48,700,1,12.5,700,1,14.52,200,2,12.49,200,2,14.56,800,2,12.46,100,1,14.6,700,1,12.43,700,1,14.63,100,1,ARL,331942981
2019,2025-07-17T16:07:00.499501052Z,2025-07-17T16:07:00.499501052Z,10,2,1108,C,A,0,14.26,100,130,165097,276622569,13.11,100,1,13.85,2,1,12.98,200,2,13.86,100,1,12.9,2,1,14.28,100,1,12.86,100,1,14.46,100,1,12.73,100,1,14.48,700,1,12.71,100,1,14.52,200,2,12.5,700,1,14.56,800,2,12.49,200,2,14.6,700,1,12.46,100,1,14.63,100,1,12.43,700,1,14.68,700,1,ARL,331929041
2020,2025-07-17T16:07:00.499549738Z,2025-07-17T16:07:00.499549738Z,10,2,1108,A,A,2,14.14,100,130,165180,276622571,13.11,100,1,13.85,2,1,12.98,200,2,13.86,100,1,12.9,2,1,14.14,100,1,12.86,100,1,14.28,100,1,12.73,100,1,14.46,100,1,12.71,100,1,14.48,700,1,12.5,700,1,14.52,200,2,12.49,200,2,14.56,800,2,12.46,100,1,14.6,700,1,12.43,700,1,14.63,100,1,ARL,331943133
2021,2025-07-17T16:07:22.814776694Z,2025-07-17T16:07:22.814776694Z,10,2,1108,A,A,0,13.69,15,130,165115,276946179,13.11,100,1,13.69,15,1,12.98,200,2,13.85,2,1,12.9,2,1,13.86,100,1,12.86,100,1,14.14,100,1,12.73,100,1,14.28,100,1,12.71,100,1,14.46,100,1,12.5,700,1,14.48,700,1,12.49,200,2,14.52,200,2,12.46,100,1,14.56,800,2,12.43,700,1,14.6,700,1,ARL,332385317
2022,2025-07-17T16:07:22.814891345Z,2025-07-17T16:07:22.814891345Z,10,2,1108,C,A,0,13.86,100,0,166162,276946183,13.11,100,1,13.69,15,1,12.98,200,2,13.85,2,1,12.9,2,1,14.14,100,1,12.86,100,1,14.28,100,1,12.73,100,1,14.46,100,1,12.71,100,1,14.48,700,1,12.5,700,1,14.52,200,2,12.49,200,2,14.56,800,2,12.46,100,1,14.6,700,1,12.43,700,1,14.63,100,1,ARL,331942821
2023,2025-07-17T16:07:22.814891345Z,2025-07-17T16:07:22.814891345Z,10,2,1108,A,A,1,13.7,100,130,166162,276946183,13.11,100,1,13.69,15,1,12.98,200,2,13.7,100,1,12.9,2,1,13.85,2,1,12.86,100,1,14.14,100,1,12.73,100,1,14.28,100,1,12.71,100,1,14.46,100,1,12.5,700,1,14.48,700,1,12.49,200,2,14.52,200,2,12.46,100,1,14.56,800,2,12.43,700,1,14.6,700,1,ARL,332385325
2024,2025-07-17T16:07:22.815625345Z,2025-07-17T16:07:22.815625345Z,10,2,1108,C,A,0,14.93,100,0,165545,276946264,13.11,100,1,13.69,15,1,12.98,200,2,13.7,100,1,12.9,2,1,13.85,2,1,12.86,100,1,14.14,100,1,12.73,100,1,14.28,100,1,12.71,100,1,14.46,100,1,12.5,700,1,14.48,700,1,12.49,200,2,14.52,200,2,12.46,100,1,14.56,800,2,12.43,700,1,14.6,700,1,ARL,331942913
2025,2025-07-17T16:07:22.815625345Z,2025-07-17T16:07:22.815625345Z,10,2,1108,A,A,12,14.76,100,130,165545,276946264,13.11,100,1,13.69,15,1,12.98,200,2,13.7,100,1,12.9,2,1,13.85,2,1,12.86,100,1,14.14,100,1,12.73,100,1,14.28,100,1,12.71,100,1,14.46,100,1,12.5,700,1,14.48,700,1,12.49,200,2,14.52,200,2,12.46,100,1,14.56,800,2,12.43,700,1,14.6,700,1,ARL,332385501
2026,2025-07-17T16:07:22.817341789Z,2025-07-17T16:07:22.817341789Z,10,2,1108,C,A,13,14.96,100,0,166020,276946309,13.11,100,1,13.69,15,1,12.98,200,2,13.7,100,1,12.9,2,1,13.85,2,1,12.86,100,1,14.14,100,1,12.73,100,1,14.28,100,1,12.71,100,1,14.46,100,1,12.5,700,1,14.48,700,1,12.49,200,2,14.52,200,2,12.46,100,1,14.56,800,2,12.43,700,1,14.6,700,1,ARL,331929633
2027,2025-07-17T16:07:22.817341789Z,2025-07-17T16:07:22.817341789Z,10,2,1108,A,A,11,14.66,100,130,166020,276946309,13.11,100,1,13.69,15,1,12.98,200,2,13.7,100,1,12.9,2,1,13.85,2,1,12.86,100,1,14.14,100,1,12.73,100,1,14.28,100,1,12.71,100,1,14.46,100,1,12.5,700,1,14.48,700,1,12.49,200,2,14.52,200,2,12.46,100,1,14.56,800,2,12.43,700,1,14.6,700,1,ARL,332385565
2028,2025-07-17T16:07:22.817459170Z,2025-07-17T16:07:22.817459170Z,10,2,1108,C,A,0,15.38,100,0,165529,276946313,13.11,100,1,13.69,15,1,12.98,200,2,13.7,100,1,12.9,2,1,13.85,2,1,12.86,100,1,14.14,100,1,12.73,100,1,14.28,100,1,12.71,100,1,14.46,100,1,12.5,700,1,14.48,700,1,12.49,200,2,14.52,200,2,12.46,100,1,14.56,800,2,12.43,700,1,14.6,700,1,ARL,331929445
2029,2025-07-17T16:07:22.817459170Z,2025-07-17T16:07:22.817459170Z,10,2,1108,A,A,15,15.07,100,130,165529,276946313,13.11,100,1,13.69,15,1,12.98,200,2,13.7,100,1,12.9,2,1,13.85,2,1,12.86,100,1,14.14,100,1,12.73,100,1,14.28,100,1,12.71,100,1,14.46,100,1,12.5,700,1,14.48,700,1,12.49,200,2,14.52,200,2,12.46,100,1,14.56,800,2,12.43,700,1,14.6,700,1,ARL,332385569
2030,2025-07-17T16:07:22.818400003Z,2025-07-17T16:07:22.818400003Z,10,2,1108,C,A,19,16.08,100,0,165763,276946327,13.11,100,1,13.69,15,1,12.98,200,2,13.7,100,1,12.9,2,1,13.85,2,1,12.86,100,1,14.14,100,1,12.73,100,1,14.28,100,1,12.71,100,1,14.46,100,1,12.5,700,1,14.48,700,1,12.49,200,2,14.52,200,2,12.46,100,1,14.56,800,2,12.43,700,1,14.6,700,1,ARL,331934377
2031,2025-07-17T16:07:22.818400003Z,2025-07-17T16:07:22.818400003Z,10,2,1108,A,A,19,15.76,100,130,165763,276946327,13.11,100,1,13.69,15,1,12.98,200,2,13.7,100,1,12.9,2,1,13.85,2,1,12.86,100,1,14.14,100,1,12.73,100,1,14.28,100,1,12.71,100,1,14.46,100,1,12.5,700,1,14.48,700,1,12.49,200,2,14.52,200,2,12.46,100,1,14.56,800,2,12.43,700,1,14.6,700,1,ARL,332385585
2032,2025-07-17T16:07:22.819545360Z,2025-07-17T16:07:22.819545360Z,10,2,1108,C,A,0,17.61,100,0,165623,276946336,13.11,100,1,13.69,15,1,12.98,200,2,13.7,100,1,12.9,2,1,13.85,2,1,12.86,100,1,14.14,100,1,12.73,100,1,14.28,100,1,12.71,100,1,14.46,100,1,12.5,700,1,14.48,700,1,12.49,200,2,14.52,200,2,12.46,100,1,14.56,800,2,12.43,700,1,14.6,700,1,ARL,331942981
2033,2025-07-17T16:07:22.819545360Z,2025-07-17T16:07:22.819545360Z,10,2,1108,A,A,22,17.4,100,130,165623,276946336,13.11,100,1,13.69,15,1,12.98,200,2,13.7,100,1,12.9,2,1,13.85,2,1,12.86,100,1,14.14,100,1,12.73,100,1,14.28,100,1,12.71,100,1,14.46,100,1,12.5,700,1,14.48,700,1,12.49,200,2,14.52,200,2,12.46,100,1,14.56,800,2,12.43,700,1,14.6,700,1,ARL,332385593
2034,2025-07-17T16:07:22.819606945Z,2025-07-17T16:07:22.819606945Z,10,2,1108,C,A,0,14.63,100,0,165463,276946337,13.11,100,1,13.69,15,1,12.98,200,2,13.7,100,1,12.9,2,1,13.85,2,1,12.86,100,1,14.14,100,1,12.73,100,1,14.28,100,1,12.71,100,1,14.46,100,1,12.5,700,1,14.48,700,1,12.49,200,2,14.52,200,2,12.46,100,1,14.56,800,2,12.43,700,1,14.6,700,1,ARL,331927477
2035,2025-07-17T16:07:22.819606945Z,2025-07-17T16:07:22.819606945Z,10,2,1108,A,A,7,14.49,100,130,165463,276946337,13.11,100,1,13.69,15,1,12.98,200,2,13.7,100,1,12.9,2,1,13.85,2,1,12.86,100,1,14.14,100,1,12.73,100,1,14.28,100,1,12.71,100,1,14.46,100,1,12.5,700,1,14.48,700,1,12.49,200,2,14.49,100,1,12.46,100,1,14.52,200,2,12.43,700,1,14.56,800,2,ARL,332385597
2036,2025-07-17T16:07:22.821000003Z,2025-07-17T16:07:22.821000003Z,10,2,1108,C,A,0,14.14,100,130,165448,276946343,13.11,100,1,13.69,15,1,12.98,200,2,13.7,100,1,12.9,2,1,13.85,2,1,12.86,100,1,14.28,100,1,12.73,100,1,14.46,100,1,12.71,100,1,14.48,700,1,12.5,700,1,14.49,100,1,12.49,200,2,14.52,200,2,12.46,100,1,14.56,800,2,12.43,700,1,14.6,700,1,ARL,331943133
2037,2025-07-17T16:07:22.821052982Z,2025-07-17T16:07:22.821052982Z,10,2,1108,A,A,3,13.97,100,130,165225,276946344,13.11,100,1,13.69,15,1,12.98,200,2,13.7,100,1,12.9,2,1,13.85,2,1,12.86,100,1,13.97,100,1,12.73,100,1,14.28,100,1,12.71,100,1,14.46,100,1,12.5,700,1,14.48,700,1,12.49,200,2,14.49,100,1,12.46,100,1,14.52,200,2,12.43,700,1,14.56,800,2,ARL,332385613
2038,2025-07-17T16:07:22.831949887Z,2025-07-17T16:07:22.831949887Z,10,2,1108,C,A,0,14.96,100,0,169333,276946801,13.11,100,1,13.69,15,1,12.98,200,2,13.7,100,1,12.9,2,1,13.85,2,1,12.86,100,1,13.97,100,1,12.73,100,1,14.28,100,1,12.71,100,1,14.46,100,1,12.5,700,1,14.48,700,1,12.49,200,2,14.49,100,1,12.46,100,1,14.52,200,2,12.43,700,1,14.56,800,2,ARL,331928129
2039,2025-07-17T16:07:22.831949887Z,2025-07-17T16:07:22.831949887Z,10,2,1108,A,A,11,14.66,100,128,169333,276946801,13.11,100,1,13.69,15,1,12.98,200,2,13.7,100,1,12.9,2,1,13.85,2,1,12.86,100,1,13.97,100,1,12.73,100,1,14.28,100,1,12.71,100,1,14.46,100,1,12.5,700,1,14.48,700,1,12.49,200,2,14.49,100,1,12.46,100,1,14.52,200,2,12.43,700,1,14.56,800,2,ARL,332386121
2040,2025-07-17T16:07:28.273658191Z,2025-07-17T16:07:28.273658191Z,10,2,1108,C,A,0,13.69,15,130,165417,277012951,13.11,100,1,13.7,100,1,12.98,200,2,13.85,2,1,12.9,2,1,13.97,100,1,12.86,100,1,14.28,100,1,12.73,100,1,14.46,100,1,12.71,100,1,14.48,700,1,12.5,700,1,14.49,100,1,12.49,200,2,14.52,200,2,12.46,100,1,14.56,800,2,12.43,700,1,14.6,700,1,ARL,332385317
2041,2025-07-17T16:07:28.700815737Z,2025-07-17T16:07:28.700815737Z,10,2,1108,C,A,0,13.7,100,130,165412,277019711,13.11,100,1,13.85,2,1,12.98,200,2,13.97,100,1,12.9,2,1,14.28,100,1,12.86,100,1,14.46,100,1,12.73,100,1,14.48,700,1,12.71,100,1,14.49,100,1,12.5,700,1,14.52,200,2,12.49,200,2,14.56,800,2,12.46,100,1,14.6,700,1,12.43,700,1,14.66,200,2,ARL,332385325
2042,2025-07-17T16:07:28.701230409Z,2025-07-17T16:07:28.701230409Z,10,2,1108,C,B,0,12.9,2,0,166260,277019718,13.11,100,1,13.85,2,1,12.98,200,2,13.97,100,1,12.86,100,1,14.28,100,1,12.73,100,1,14.46,100,1,12.71,100,1,14.48,700,1,12.5,700,1,14.49,100,1,12.49,200,2,14.52,200,2,12.46,100,1,14.56,800,2,12.43,700,1,14.6,700,1,12.42,700,1,14.66,200,2,ARL,331694297
2043,2025-07-17T16:07:28.701230409Z,2025-07-17T16:07:28.701230409Z,10,2,1108,A,B,1,13.01,2,130,166260,277019718,13.11,100,1,13.85,2,1,13.01,2,1,13.97,100,1,12.98,200,2,14.28,100,1,12.86,100,1,14.46,100,1,12.73,100,1,14.48,700,1,12.71,100,1,14.49,100,1,12.5,700,1,14.52,200,2,12.49,200,2,14.56,800,2,12.46,100,1,14.6,700,1,12.43,700,1,14.66,200,2,ARL,332494213
2044,2025-07-17T16:07:28.701547540Z,2025-07-17T16:07:28.701547540Z,10,2,1108,C,A,0,14.76,100,0,165692,277019720,13.11,100,1,13.85,2,1,13.01,2,1,13.97,100,1,12.98,200,2,14.28,100,1,12.86,100,1,14.46,100,1,12.73,100,1,14.48,700,1,12.71,100,1,14.49,100,1,12.5,700,1,14.52,200,2,12.49,200,2,14.56,800,2,12.46,100,1,14.6,700,1,12.43,700,1,14.66,200,2,ARL,332385501
2045,2025-07-17T16:07:28.701547540Z,2025-07-17T16:07:28.701547540Z,10,2,1108,A,A,11,14.82,100,130,165692,277019720,13.11,100,1,13.85,2,1,13.01,2,1,13.97,100,1,12.98,200,2,14.28,100,1,12.86,100,1,14.46,100,1,12.73,100,1,14.48,700,1,12.71,100,1,14.49,100,1,12.5,700,1,14.52,200,2,12.49,200,2,14.56,800,2,12.46,100,1,14.6,700,1,12.43,700,1,14.66,200,2,ARL,332494229
2046,2025-07-17T16:07:28.702000772Z,2025-07-17T16:07:28.702000772Z,10,2,1108,C,A,0,15.76,100,0,165525,277019722,13.11,100,1,13.85,2,1,13.01,2,1,13.97,100,1,12.98,200,2,14.28,100,1,12.86,100,1,14.46,100,1,12.73,100,1,14.48,700,1,12.71,100,1,14.49,100,1,12.5,700,1,14.52,200,2,12.49,200,2,14.56,800,2,12.46,100,1,14.6,700,1,12.43,700,1,14.66,200,2,ARL,332385585
2047,2025-07-17T16:07:28.702000772Z,2025-07-17T16:07:28.702000772Z,10,2,1108,A,A,16,16.01,100,130,165525,277019722,13.11,100,1,13.85,2,1,13.01,2,1,13.97,100,1,12.98,200,2,14.28,100,1,12.86,100,1,14.46,100,1,12.73,100,1,14.48,700,1,12.71,100,1,14.49,100,1,12.5,700,1,14.52,200,2,12.49,200,2,14.56,800,2,12.46,100,1,14.6,700,1,12.43,700,1,14.66,200,2,ARL,332494245
2048,2025-07-17T16:07:28.702476699Z,2025-07-17T16:07:28.702476699Z,10,2,1108,C,A,9,14.66,100,0,165321,277019729,13.11,100,1,13.85,2,1,13.01,2,1,13.97,100,1,12.98,200,2,14.28,100,1,12.86,100,1,14.46,100,1,12.73,100,1,14.48,700,1,12.71,100,1,14.49,100,1,12.5,700,1,14.52,200,2,12.49,200,2,14.56,800,2,12.46,100,1,14.6,700,1,12.43,700,1,14.66,100,1,ARL,332386121
2049,2025-07-17T16:07:28.702476699Z,2025-07-17T16:07:28.702476699Z,10,2,1108,A,A,12,14.95,100,130,165321,277019729,13.11,100,1,13.85,2,1,13.01,2,1,13.97,100,1,12.98,200,2,14.28,100,1,12.86,100,1,14.46,100,1,12.73,100,1,14.48,700,1,12.71,100,1,14.49,100,1,12.5,700,1,14.52,200,2,12.49,200,2,14.56,800,2,12.46,100,1,14.6,700,1,12.43,700,1,14.66,100,1,ARL,332494281
2050,2025-07-17T16:07:28.703357714Z,2025-07-17T16:07:28.703357714Z,10,2,1108,C,A,0,14.66,100,0,165378,277019733,13.11,100,1,13.85,2,1,13.01,2,1,13.97,100,1,12.98,200,2,14.28,100,1,12.86,100,1,14.46,100,1,12.73,100,1,14.48,700,1,12.71,100,1,14.49,100,1,12.5,700,1,14.52,200,2,12.49,200,2,14.56,800,2,12.46,100,1,14.6,700,1,12.43,700,1,14.68,700,1,ARL,332385565
2051,2025-07-17T16:07:28.703357714Z,2025-07-17T16:07:28.703357714Z,10,2,1108,A,A,11,14.95,100,130,165378,277019733,13.11,100,1,13.85,2,1,13.01,2,1,13.97,100,1,12.98,200,2,14.28,100,1,12.86,100,1,14.46,100,1,12.73,100,1,14.48,700,1,12.71,100,1,14.49,100,1,12.5,700,1,14.52,200,2,12.49,200,2,14.56,800,2,12.46,100,1,14.6,700,1,12.43,700,1,14.68,700,1,ARL,332494285
2052,2025-07-17T16:07:28.703754662Z,2025-07-17T16:07:28.703754662Z,10,2,1108,C,A,0,15.07,100,0,165674,277019735,13.11,100,1,13.85,2,1,13.01,2,1,13.97,100,1,12.98,200,2,14.28,100,1,12.86,100,1,14.46,100,1,12.73,100,1,14.48,700,1,12.71,100,1,14.49,100,1,12.5,700,1,14.52,200,2,12.49,200,2,14.56,800,2,12.46,100,1,14.6,700,1,12.43,700,1,14.68,700,1,ARL,332385569
2053,2025-07-17T16:07:28.703754662Z,2025-07-17T16:07:28.703754662Z,10,2,1108,A,A,14,15.37,100,130,165674,277019735,13.11,100,1,13.85,2,1,13.01,2,1,13.97,100,1,12.98,200,2,14.28,100,1,12.86,100,1,14.46,100,1,12.73,100,1,14.48,700,1,12.71,100,1,14.49,100,1,12.5,700,1,14.52,200,2,12.49,200,2,14.56,800,2,12.46,100,1,14.6,700,1,12.43,700,1,14.68,700,1,ARL,332494289
2054,2025-07-17T16:07:28.704032725Z,2025-07-17T16:07:28.704032725Z,10,2,1108,C,A,0,17.4,100,0,165378,277019738,13.11,100,1,13.85,2,1,13.01,2,1,13.97,100,1,12.98,200,2,14.28,100,1,12.86,100,1,14.46,100,1,12.73,100,1,14.48,700,1,12.71,100,1,14.49,100,1,12.5,700,1,14.52,200,2,12.49,200,2,14.56,800,2,12.46,100,1,14.6,700,1,12.43,700,1,14.68,700,1,ARL,332385593
2055,2025-07-17T16:07:28.704032725Z,2025-07-17T16:07:28.704032725Z,10,2,1108,A,A,19,17.75,100,130,165378,277019738,13.11,100,1,13.85,2,1,13.01,2,1,13.97,100,1,12.98,200,2,14.28,100,1,12.86,100,1,14.46,100,1,12.73,100,1,14.48,700,1,12.71,100,1,14.49,100,1,12.5,700,1,14.52,200,2,12.49,200,2,14.56,800,2,12.46,100,1,14.6,700,1,12.43,700,1,14.68,700,1,ARL,332494297
2056,2025-07-17T16:07:28.724036175Z,2025-07-17T16:07:28.724036175Z,10,2,1108,C,A,0,13.97,100,130,165665,277019926,13.11,100,1,13.85,2,1,13.01,2,1,14.28,100,1,12.98,200,2,14.46,100,1,12.86,100,1,14.48,700,1,12.73,100,1,14.49,100,1,12.71,100,1,14.52,200,2,12.5,700,1,14.56,800,2,12.49,200,2,14.6,700,1,12.46,100,1,14.68,700,1,12.43,700,1,14.82,100,1,ARL,332385613
2057,2025-07-17T16:07:28.724085453Z,2025-07-17T16:07:28.724085453Z,10,2,1108,A,A,1,14.2,100,130,165382,277019929,13.11,100,1,13.85,2,1,13.01,2,1,14.2,100,1,12.98,200,2,14.28,100,1,12.86,100,1,14.46,100,1,12.73,100,1,14.48,700,1,12.71,100,1,14.49,100,1,12.5,700,1,14.52,200,2,12.49,200,2,14.56,800,2,12.46,100,1,14.6,700,1,12.43,700,1,14.68,700,1,ARL,332494893
2058,2025-07-17T16:07:28.751662660Z,2025-07-17T16:07:28.751662660Z,10,2,1108,C,A,0,14.82,100,0,165460,277020284,13.11,100,1,13.85,2,1,13.01,2,1,14.2,100,1,12.98,200,2,14.28,100,1,12.86,100,1,14.46,100,1,12.73,100,1,14.48,700,1,12.71,100,1,14.49,100,1,12.5,700,1,14.52,200,2,12.49,200,2,14.56,800,2,12.46,100,1,14.6,700,1,12.43,700,1,14.68,700,1,ARL,332494229
2059,2025-07-17T16:07:28.751662660Z,2025-07-17T16:07:28.751662660Z,10,2,1108,A,A,11,15.05,100,130,165460,277020284,13.11,100,1,13.85,2,1,13.01,2,1,14.2,100,1,12.98,200,2,14.28,100,1,12.86,100,1,14.46,100,1,12.73,100,1,14.48,700,1,12.71,100,1,14.49,100,1,12.5,700,1,14.52,200,2,12.49,200,2,14.56,800,2,12.46,100,1,14.6,700,1,12.43,700,1,14.68,700,1,ARL,332495781
2060,2025-07-17T16:07:28.830995364Z,2025-07-17T16:07:28.830995364Z,10,2,1108,C,A,0,14.49,100,130,165623,277021007,13.11,100,1,13.85,2,1,13.01,2,1,14.2,100,1,12.98,200,2,14.28,100,1,12.86,100,1,14.46,100,1,12.73,100,1,14.48,700,1,12.71,100,1,14.52,200,2,12.5,700,1,14.56,800,2,12.49,200,2,14.6,700,1,12.46,100,1,14.68,700,1,12.43,700,1,14.95,200,2,ARL,332385597
2061,2025-07-17T16:07:28.831125667Z,2025-07-17T16:07:28.831125667Z,10,2,1108,A,A,9,14.77,100,130,165710,277021012,13.11,100,1,13.85,2,1,13.01,2,1,14.2,100,1,12.98,200,2,14.28,100,1,12.86,100,1,14.46,100,1,12.73,100,1,14.48,700,1,12.71,100,1,14.52,200,2,12.5,700,1,14.56,800,2,12.49,200,2,14.6,700,1,12.46,100,1,14.68,700,1,12.43,700,1,14.77,100,1,ARL,332497653
2062,2025-07-17T16:07:29.214500816Z,2025-07-17T16:07:29.214500816Z,10,2,1108,A,A,1,13.86,100,128,166454,277029015,13.11,100,1,13.85,2,1,13.01,2,1,13.86,100,1,12.98,200,2,14.2,100,1,12.86,100,1,14.28,100,1,12.73,100,1,14.46,100,1,12.71,100,1,14.48,700,1,12.5,700,1,14.52,200,2,12.49,200,2,14.56,800,2,12.46,100,1,14.6,700,1,12.43,700,1,14.68,700,1,ARL,332508813
2063,2025-07-17T16:07:29.215292291Z,2025-07-17T16:07:29.215292291Z,10,2,1108,C,A,0,15.05,100,0,166553,277029273,13.11,100,1,13.85,2,1,13.01,2,1,13.86,100,1,12.98,200,2,14.2,100,1,12.86,100,1,14.28,100,1,12.73,100,1,14.46,100,1,12.71,100,1,14.48,700,1,12.5,700,1,14.52,200,2,12.49,200,2,14.56,800,2,12.46,100,1,14.6,700,1,12.43,700,1,14.68,700,1,ARL,332495781
2064,2025-07-17T16:07:29.215292291Z,2025-07-17T16:07:29.215292291Z,10,2,1108,A,A,11,14.93,100,128,166553,277029273,13.11,100,1,13.85,2,1,13.01,2,1,13.86,100,1,12.98,200,2,14.2,100,1,12.86,100,1,14.28,100,1,12.73,100,1,14.46,100,1,12.71,100,1,14.48,700,1,12.5,700,1,14.52,200,2,12.49,200,2,14.56,800,2,12.46,100,1,14.6,700,1,12.43,700,1,14.68,700,1,ARL,332508997
2065,2025-07-17T16:08:20.816087447Z,2025-07-17T16:08:20.816087447Z,10,2,1108,A,A,0,13.68,15,130,165403,277732167,13.11,100,1,13.68,15,1,13.01,2,1,13.85,2,1,12.98,200,2,13.86,100,1,12.86,100,1,14.2,100,1,12.73,100,1,14.28,100,1,12.71,100,1,14.46,100,1,12.5,700,1,14.48,700,1,12.49,200,2,14.52,200,2,12.46,100,1,14.56,800,2,12.43,700,1,14.6,700,1,ARL,333436357
2066,2025-07-17T16:08:20.816200644Z,2025-07-17T16:08:20.816200644Z,10,2,1108,C,A,0,13.86,100,0,165561,277732170,13.11,100,1,13.68,15,1,13.01,2,1,13.85,2,1,12.98,200,2,14.2,100,1,12.86,100,1,14.28,100,1,12.73,100,1,14.46,100,1,12.71,100,1,14.48,700,1,12.5,700,1,14.52,200,2,12.49,200,2,14.56,800,2,12.46,100,1,14.6,700,1,12.43,700,1,14.68,700,1,ARL,332508813
2067,2025-07-17T16:08:20.816200644Z,2025-07-17T16:08:20.816200644Z,10,2,1108,A,A,1,13.69,100,130,165561,277732170,13.11,100,1,13.68,15,1,13.01,2,1,13.69,100,1,12.98,200,2,13.85,2,1,12.86,100,1,14.2,100,1,12.73,100,1,14.28,100,1,12.71,100,1,14.46,100,1,12.5,700,1,14.48,700,1,12.49,200,2,14.52,200,2,12.46,100,1,14.56,800,2,12.43,700,1,14.6,700,1,ARL,333436361
2068,2025-07-17T16:08:20.816932150Z,2025-07-17T16:08:20.816932150Z,10,2,1108,C,A,0,14.93,100,0,165437,277732194,13.11,100,1,13.68,15,1,13.01,2,1,13.69,100,1,12.98,200,2,13.85,2,1,12.86,100,1,14.2,100,1,12.73,100,1,14.28,100,1,12.71,100,1,14.46,100,1,12.5,700,1,14.48,700,1,12.49,200,2,14.52,200,2,12.46,100,1,14.56,800,2,12.43,700,1,14.6,700,1,ARL,332508997
2069,2025-07-17T16:08:20.816932150Z,2025-07-17T16:08:20.816932150Z,10,2,1108,A,A,11,14.75,100,130,165437,277732194,13.11,100,1,13.68,15,1,13.01,2,1,13.69,100,1,12.98,200,2,13.85,2,1,12.86,100,1,14.2,100,1,12.73,100,1,14.28,100,1,12.71,100,1,14.46,100,1,12.5,700,1,14.48,700,1,12.49,200,2,14.52,200,2,12.46,100,1,14.56,800,2,12.43,700,1,14.6,700,1,ARL,333436397
2070,2025-07-17T16:08:20.818559377Z,2025-07-17T16:08:20.818559377Z,10,2,1108,C,A,0,15.37,100,0,165725,277732213,13.11,100,1,13.68,15,1,13.01,2,1,13.69,100,1,12.98,200,2,13.85,2,1,12.86,100,1,14.2,100,1,12.73,100,1,14.28,100,1,12.71,100,1,14.46,100,1,12.5,700,1,14.48,700,1,12.49,200,2,14.52,200,2,12.46,100,1,14.56,800,2,12.43,700,1,14.6,700,1,ARL,332494289
2071,2025-07-17T16:08:20.818559377Z,2025-07-17T16:08:20.818559377Z,10,2,1108,A,A,14,15.06,100,130,165725,277732213,13.11,100,1,13.68,15,1,13.01,2,1,13.69,100,1,12.98,200,2,13.85,2,1,12.86,100,1,14.2,100,1,12.73,100,1,14.28,100,1,12.71,100,1,14.46,100,1,12.5,700,1,14.48,700,1,12.49,200,2,14.52,200,2,12.46,100,1,14.56,800,2,12.43,700,1,14.6,700,1,ARL,333436421
2072,2025-07-17T16:08:20.818965359Z,2025-07-17T16:08:20.818965359Z,10,2,1108,C,A,13,14.95,100,0,165461,277732216,13.11,100,1,13.68,15,1,13.01,2,1,13.69,100,1,12.98,200,2,13.85,2,1,12.86,100,1,14.2,100,1,12.73,100,1,14.28,100,1,12.71,100,1,14.46,100,1,12.5,700,1,14.48,700,1,12.49,200,2,14.52,200,2,12.46,100,1,14.56,800,2,12.43,700,1,14.6,700,1,ARL,332494285
2073,2025-07-17T16:08:20.818965359Z,2025-07-17T16:08:20.818965359Z,10,2,1108,A,A,10,14.65,100,130,165461,277732216,13.11,100,1,13.68,15,1,13.01,2,1,13.69,100,1,12.98,200,2,13.85,2,1,12.86,100,1,14.2,100,1,12.73,100,1,14.28,100,1,12.71,100,1,14.46,100,1,12.5,700,1,14.48,700,1,12.49,200,2,14.52,200,2,12.46,100,1,14.56,800,2,12.43,700,1,14.6,700,1,ARL,333436425
2074,2025-07-17T16:08:20.819601669Z,2025-07-17T16:08:20.819601669Z,10,2,1108,C,A,0,17.75,100,0,165422,277732221,13.11,100,1,13.68,15,1,13.01,2,1,13.69,100,1,12.98,200,2,13.85,2,1,12.86,100,1,14.2,100,1,12.73,100,1,14.28,100,1,12.71,100,1,14.46,100,1,12.5,700,1,14.48,700,1,12.49,200,2,14.52,200,2,12.46,100,1,14.56,800,2,12.43,700,1,14.6,700,1,ARL,332494297
2075,2025-07-17T16:08:20.819601669Z,2025-07-17T16:08:20.819601669Z,10,2,1108,A,A,22,17.39,100,130,165422,277732221,13.11,100,1,13.68,15,1,13.01,2,1,13.69,100,1,12.98,200,2,13.85,2,1,12.86,100,1,14.2,100,1,12.73,100,1,14.28,100,1,12.71,100,1,14.46,100,1,12.5,700,1,14.48,700,1,12.49,200,2,14.52,200,2,12.46,100,1,14.56,800,2,12.43,700,1,14.6,700,1,ARL,333436441
2076,2025-07-17T16:08:20.820500575Z,2025-07-17T16:08:20.820500575Z,10,2,1108,C,A,0,16.01,100,0,165594,277732228,13.11,100,1,13.68,15,1,13.01,2,1,13.69,100,1,12.98,200,2,13.85,2,1,12.86,100,1,14.2,100,1,12.73,100,1,14.28,100,1,12.71,100,1,14.46,100,1,12.5,700,1,14.48,700,1,12.49,200,2,14.52,200,2,12.46,100,1,14.56,800,2,12.43,700,1,14.6,700,1,ARL,332494245
2077,2025-07-17T16:08:20.820500575Z,2025-07-17T16:08:20.820500575Z,10,2,1108,A,A,19,15.75,100,130,165594,277732228,13.11,100,1,13.68,15,1,13.01,2,1,13.69,100,1,12.98,200,2,13.85,2,1,12.86,100,1,14.2,100,1,12.73,100,1,14.28,100,1,12.71,100,1,14.46,100,1,12.5,700,1,14.48,700,1,12.49,200,2,14.52,200,2,12.46,100,1,14.56,800,2,12.43,700,1,14.6,700,1,ARL,333436449
2078,2025-07-17T16:08:20.821924168Z,2025-07-17T16:08:20.821924168Z,10,2,1108,C,A,0,14.2,100,130,165376,277732239,13.11,100,1,13.68,15,1,13.01,2,1,13.69,100,1,12.98,200,2,13.85,2,1,12.86,100,1,14.28,100,1,12.73,100,1,14.46,100,1,12.71,100,1,14.48,700,1,12.5,700,1,14.52,200,2,12.49,200,2,14.56,800,2,12.46,100,1,14.6,700,1,12.43,700,1,14.65,100,1,ARL,332494893
2079,2025-07-17T16:08:20.821974299Z,2025-07-17T16:08:20.821974299Z,10,2,1108,A,A,3,13.96,100,130,165242,277732240,13.11,100,1,13.68,15,1,13.01,2,1,13.69,100,1,12.98,200,2,13.85,2,1,12.86,100,1,13.96,100,1,12.73,100,1,14.28,100,1,12.71,100,1,14.46,100,1,12.5,700,1,14.48,700,1,12.49,200,2,14.52,200,2,12.46,100,1,14.56,800,2,12.43,700,1,14.6,700,1,ARL,333436473
2080,2025-07-17T16:08:20.829945074Z,2025-07-17T16:08:20.829945074Z,10,2,1108,C,A,0,14.95,100,0,165425,277732299,13.11,100,1,13.68,15,1,13.01,2,1,13.69,100,1,12.98,200,2,13.85,2,1,12.86,100,1,13.96,100,1,12.73,100,1,14.28,100,1,12.71,100,1,14.46,100,1,12.5,700,1,14.48,700,1,12.49,200,2,14.52,200,2,12.46,100,1,14.56,800,2,12.43,700,1,14.6,700,1,ARL,332494281
2081,2025-07-17T16:08:20.829945074Z,2025-07-17T16:08:20.829945074Z,10,2,1108,A,A,10,14.65,100,130,165425,277732299,13.11,100,1,13.68,15,1,13.01,2,1,13.69,100,1,12.98,200,2,13.85,2,1,12.86,100,1,13.96,100,1,12.73,100,1,14.28,100,1,12.71,100,1,14.46,100,1,12.5,700,1,14.48,700,1,12.49,200,2,14.52,200,2,12.46,100,1,14.56,800,2,12.43,700,1,14.6,700,1,ARL,333436589
2082,2025-07-17T16:08:20.966063681Z,2025-07-17T16:08:20.966063681Z,10,2,1108,C,A,0,14.77,100,0,165585,277733304,13.11,100,1,13.68,15,1,13.01,2,1,13.69,100,1,12.98,200,2,13.85,2,1,12.86,100,1,13.96,100,1,12.73,100,1,14.28,100,1,12.71,100,1,14.46,100,1,12.5,700,1,14.48,700,1,12.49,200,2,14.52,200,2,12.46,100,1,14.56,800,2,12.43,700,1,14.6,700,1,ARL,332497653
2083,2025-07-17T16:08:20.966063681Z,2025-07-17T16:08:20.966063681Z,10,2,1108,A,A,6,14.48,100,130,165585,277733304,13.11,100,1,13.68,15,1,13.01,2,1,13.69,100,1,12.98,200,2,13.85,2,1,12.86,100,1,13.96,100,1,12.73,100,1,14.28,100,1,12.71,100,1,14.46,100,1,12.5,700,1,14.48,800,2,12.49,200,2,14.52,200,2,12.46,100,1,14.56,800,2,12.43,700,1,14.6,700,1,ARL,333438545
2084,2025-07-17T16:08:22.998002821Z,2025-07-17T16:08:22.998002821Z,10,2,1108,C,A,0,13.68,15,130,165365,277766492,13.11,100,1,13.69,100,1,13.01,2,1,13.85,2,1,12.98,200,2,13.96,100,1,12.86,100,1,14.28,100,1,12.73,100,1,14.46,100,1,12.71,100,1,14.48,800,2,12.5,700,1,14.52,200,2,12.49,200,2,14.56,800,2,12.46,100,1,14.6,700,1,12.43,700,1,14.65,200,2,ARL,333436357
2085,2025-07-17T16:08:27.482344236Z,2025-07-17T16:08:27.482344236Z,10,2,1108,C,A,0,13.69,100,130,165448,277841171,13.11,100,1,13.85,2,1,13.01,2,1,13.96,100,1,12.98,200,2,14.28,100,1,12.86,100,1,14.46,100,1,12.73,100,1,14.48,800,2,12.71,100,1,14.52,200,2,12.5,700,1,14.56,800,2,12.49,200,2,14.6,700,1,12.46,100,1,14.65,200,2,12.43,700,1,14.68,700,1,ARL,333436361
2086,2025-07-17T16:08:27.483075481Z,2025-07-17T16:08:27.483075481Z,10,2,1108,C,A,0,14.75,100,0,165526,277841175,13.11,100,1,13.85,2,1,13.01,2,1,13.96,100,1,12.98,200,2,14.28,100,1,12.86,100,1,14.46,100,1,12.73,100,1,14.48,800,2,12.71,100,1,14.52,200,2,12.5,700,1,14.56,800,2,12.49,200,2,14.6,700,1,12.46,100,1,14.65,200,2,12.43,700,1,14.68,700,1,ARL,333436397
2087,2025-07-17T16:08:27.483075481Z,2025-07-17T16:08:27.483075481Z,10,2,1108,A,A,10,14.99,100,130,165526,277841175,13.11,100,1,13.85,2,1,13.01,2,1,13.96,100,1,12.98,200,2,14.28,100,1,12.86,100,1,14.46,100,1,12.73,100,1,14.48,800,2,12.71,100,1,14.52,200,2,12.5,700,1,14.56,800,2,12.49,200,2,14.6,700,1,12.46,100,1,14.65,200,2,12.43,700,1,14.68,700,1,ARL,333581389
2088,2025-07-17T16:08:27.483420069Z,2025-07-17T16:08:27.483420069Z,10,2,1108,C,A,5,14.52,100,0,165823,277841178,13.11,100,1,13.85,2,1,13.01,2,1,13.96,100,1,12.98,200,2,14.28,100,1,12.86,100,1,14.46,100,1,12.73,100,1,14.48,800,2,12.71,100,1,14.52,100,1,12.5,700,1,14.56,800,2,12.49,200,2,14.6,700,1,12.46,100,1,14.65,200,2,12.43,700,1,14.68,700,1,ARL,328780577
2089,2025-07-17T16:08:27.483420069Z,2025-07-17T16:08:27.483420069Z,10,2,1108,A,A,10,14.74,100,130,165823,277841178,13.11,100,1,13.85,2,1,13.01,2,1,13.96,100,1,12.98,200,2,14.28,100,1,12.86,100,1,14.46,100,1,12.73,100,1,14.48,800,2,12.71,100,1,14.52,100,1,12.5,700,1,14.56,800,2,12.49,200,2,14.6,700,1,12.46,100,1,14.65,200,2,12.43,700,1,14.68,700,1,ARL,333581393
2090,2025-07-17T16:08:27.483913735Z,2025-07-17T16:08:27.483913735Z,10,2,1108,C,A,8,14.65,100,0,165489,277841218,13.11,100,1,13.85,2,1,13.01,2,1,13.96,100,1,12.98,200,2,14.28,100,1,12.86,100,1,14.46,100,1,12.73,100,1,14.48,800,2,12.71,100,1,14.52,100,1,12.5,700,1,14.56,800,2,12.49,200,2,14.6,700,1,12.46,100,1,14.65,100,1,12.43,700,1,14.68,700,1,ARL,333436589
2091,2025-07-17T16:08:27.483913735Z,2025-07-17T16:08:27.483913735Z,10,2,1108,A,A,11,14.94,100,130,165489,277841218,13.11,100,1,13.85,2,1,13.01,2,1,13.96,100,1,12.98,200,2,14.28,100,1,12.86,100,1,14.46,100,1,12.73,100,1,14.48,800,2,12.71,100,1,14.52,100,1,12.5,700,1,14.56,800,2,12.49,200,2,14.6,700,1,12.46,100,1,14.65,100,1,12.43,700,1,14.68,700,1,ARL,333581409
2092,2025-07-17T16:08:27.484693568Z,2025-07-17T16:08:27.484693568Z,10,2,1108,C,A,0,17.39,100,0,165620,277841226,13.11,100,1,13.85,2,1,13.01,2,1,13.96,100,1,12.98,200,2,14.28,100,1,12.86,100,1,14.46,100,1,12.73,100,1,14.48,800,2,12.71,100,1,14.52,100,1,12.5,700,1,14.56,800,2,12.49,200,2,14.6,700,1,12.46,100,1,14.65,100,1,12.43,700,1,14.68,700,1,ARL,333436441
2093,2025-07-17T16:08:27.484693568Z,2025-07-17T16:08:27.484693568Z,10,2,1108,A,A,20,17.73,100,130,165620,277841226,13.11,100,1,13.85,2,1,13.01,2,1,13.96,100,1,12.98,200,2,14.28,100,1,12.86,100,1,14.46,100,1,12.73,100,1,14.48,800,2,12.71,100,1,14.52,100,1,12.5,700,1,14.56,800,2,12.49,200,2,14.6,700,1,12.46,100,1,14.65,100,1,12.43,700,1,14.68,700,1,ARL,333581425
2094,2025-07-17T16:08:27.484800296Z,2025-07-17T16:08:27.484800296Z,10,2,1108,C,A,0,14.65,100,0,165661,277841228,13.11,100,1,13.85,2,1,13.01,2,1,13.96,100,1,12.98,200,2,14.28,100,1,12.86,100,1,14.46,100,1,12.73,100,1,14.48,800,2,12.71,100,1,14.52,100,1,12.5,700,1,14.56,800,2,12.49,200,2,14.6,700,1,12.46,100,1,14.68,700,1,12.43,700,1,14.74,100,1,ARL,333436425
2095,2025-07-17T16:08:27.484800296Z,2025-07-17T16:08:27.484800296Z,10,2,1108,A,A,10,14.94,100,130,165661,277841228,13.11,100,1,13.85,2,1,13.01,2,1,13.96,100,1,12.98,200,2,14.28,100,1,12.86,100,1,14.46,100,1,12.73,100,1,14.48,800,2,12.71,100,1,14.52,100,1,12.5,700,1,14.56,800,2,12.49,200,2,14.6,700,1,12.46,100,1,14.68,700,1,12.43,700,1,14.74,100,1,ARL,333581429
2096,2025-07-17T16:08:27.484813280Z,2025-07-17T16:08:27.484813280Z,10,2,1108,C,A,0,15.75,100,0,165579,277841229,13.11,100,1,13.85,2,1,13.01,2,1,13.96,100,1,12.98,200,2,14.28,100,1,12.86,100,1,14.46,100,1,12.73,100,1,14.48,800,2,12.71,100,1,14.52,100,1,12.5,700,1,14.56,800,2,12.49,200,2,14.6,700,1,12.46,100,1,14.68,700,1,12.43,700,1,14.74,100,1,ARL,333436449
2097,2025-07-17T16:08:27.484813280Z,2025-07-17T16:08:27.484813280Z,10,2,1108,A,A,16,16.06,100,130,165579,277841229,13.11,100,1,13.85,2,1,13.01,2,1,13.96,100,1,12.98,200,2,14.28,100,1,12.86,100,1,14.46,100,1,12.73,100,1,14.48,800,2,12.71,100,1,14.52,100,1,12.5,700,1,14.56,800,2,12.49,200,2,14.6,700,1,12.46,100,1,14.68,700,1,12.43,700,1,14.74,100,1,ARL,333581433
2098,2025-07-17T16:08:27.485186411Z,2025-07-17T16:08:27.485186411Z,10,2,1108,C,A,0,15.06,100,0,165793,277841231,13.11,100,1,13.85,2,1,13.01,2,1,13.96,100,1,12.98,200,2,14.28,100,1,12.86,100,1,14.46,100,1,12.73,100,1,14.48,800,2,12.71,100,1,14.52,100,1,12.5,700,1,14.56,800,2,12.49,200,2,14.6,700,1,12.46,100,1,14.68,700,1,12.43,700,1,14.74,100,1,ARL,333436421
2099,2025-07-17T16:08:27.485186411Z,2025-07-17T16:08:27.485186411Z,10,2,1108,A,A,14,15.36,100,130,165793,277841231,13.11,100,1,13.85,2,1,13.01,2,1,13.96,100,1,12.98,200,2,14.28,100,1,12.86,100,1,14.46,100,1,12.73,100,1,14.48,800,2,12.71,100,1,14.52,100,1,12.5,700,1,14.56,800,2,12.49,200,2,14.6,700,1,12.46,100,1,14.68,700,1,12.43,700,1,14.74,100,1,ARL,333581441
2100,2025-07-17T16:08:27.487097702Z,2025-07-17T16:08:27.487097702Z,10,2,1108,C,A,0,14.52,100,0,165574,277841319,13.11,100,1,13.85,2,1,13.01,2,1,13.96,100,1,12.98,200,2,14.28,100,1,12.86,100,1,14.46,100,1,12.73,100,1,14.48,800,2,12.71,100,1,14.56,800,2,12.5,700,1,14.6,700,1,12.49,200,2,14.68,700,1,12.46,100,1,14.74,100,1,12.43,700,1,14.94,200,2,ARL,328780597
2101,2025-07-17T16:08:27.487097702Z,2025-07-17T16:08:27.487097702Z,10,2,1108,A,A,8,14.74,100,130,165574,277841319,13.11,100,1,13.85,2,1,13.01,2,1,13.96,100,1,12.98,200,2,14.28,100,1,12.86,100,1,14.46,100,1,12.73,100,1,14.48,800,2,12.71,100,1,14.56,800,2,12.5,700,1,14.6,700,1,12.49,200,2,14.68,700,1,12.46,100,1,14.74,200,2,12.43,700,1,14.94,200,2,ARL,333581481
2102,2025-07-17T16:08:27.492093401Z,2025-07-17T16:08:27.492093401Z,10,2,1108,C,A,4,14.48,100,130,165505,277841396,13.11,100,1,13.85,2,1,13.01,2,1,13.96,100,1,12.98,200,2,14.28,100,1,12.86,100,1,14.46,100,1,12.73,100,1,14.48,700,1,12.71,100,1,14.56,800,2,12.5,700,1,14.6,700,1,12.49,200,2,14.68,700,1,12.46,100,1,14.74,200,2,12.43,700,1,14.94,200,2,ARL,333438545
2103,2025-07-17T16:08:27.492220454Z,2025-07-17T16:08:27.492220454Z,10,2,1108,A,A,9,14.75,100,130,165296,277841397,13.11,100,1,13.85,2,1,13.01,2,1,13.96,100,1,12.98,200,2,14.28,100,1,12.86,100,1,14.46,100,1,12.73,100,1,14.48,700,1,12.71,100,1,14.56,800,2,12.5,700,1,14.6,700,1,12.49,200,2,14.68,700,1,12.46,100,1,14.74,200,2,12.43,700,1,14.75,100,1,ARL,333581569
2104,2025-07-17T16:08:27.496770678Z,2025-07-17T16:08:27.496770678Z,10,2,1108,C,A,0,13.96,100,130,165444,277841427,13.11,100,1,13.85,2,1,13.01,2,1,14.28,100,1,12.98,200,2,14.46,100,1,12.86,100,1,14.48,700,1,12.73,100,1,14.56,800,2,12.71,100,1,14.6,700,1,12.5,700,1,14.68,700,1,12.49,200,2,14.74,200,2,12.46,100,1,14.75,100,1,12.43,700,1,14.94,200,2,ARL,333436473
2105,2025-07-17T16:08:27.496822540Z,2025-07-17T16:08:27.496822540Z,10,2,1108,A,A,1,14.19,100,130,165292,277841428,13.11,100,1,13.85,2,1,13.01,2,1,14.19,100,1,12.98,200,2,14.28,100,1,12.86,100,1,14.46,100,1,12.73,100,1,14.48,700,1,12.71,100,1,14.56,800,2,12.5,700,1,14.6,700,1,12.49,200,2,14.68,700,1,12.46,100,1,14.74,200,2,12.43,700,1,14.75,100,1,ARL,333581625
2106,2025-07-17T16:08:27.500928061Z,2025-07-17T16:08:27.500928061Z,10,2,1108,C,A,0,13.85,2,0,165557,277841469,13.11,100,1,14.19,100,1,13.01,2,1,14.28,100,1,12.98,200,2,14.46,100,1,12.86,100,1,14.48,700,1,12.73,100,1,14.56,800,2,12.71,100,1,14.6,700,1,12.5,700,1,14.68,700,1,12.49,200,2,14.74,200,2,12.46,100,1,14.75,100,1,12.43,700,1,14.94,200,2,ARL,331155889
2107,2025-07-17T16:08:27.500928061Z,2025-07-17T16:08:27.500928061Z,10,2,1108,A,A,0,13.98,2,130,165557,277841469,13.11,100,1,13.98,2,1,13.01,2,1,14.19,100,1,12.98,200,2,14.28,100,1,12.86,100,1,14.46,100,1,12.73,100,1,14.48,700,1,12.71,100,1,14.56,800,2,12.5,700,1,14.6,700,1,12.49,200,2,14.68,700,1,12.46,100,1,14.74,200,2,12.43,700,1,14.75,100,1,ARL,333581677
2108,2025-07-17T16:08:27.516449334Z,2025-07-17T16:08:27.516449334Z,10,2,1108,C,A,0,14.19,100,130,165039,277841551,13.11,100,1,13.98,2,1,13.01,2,1,14.28,100,1,12.98,200,2,14.46,100,1,12.86,100,1,14.48,700,1,12.73,100,1,14.56,800,2,12.71,100,1,14.6,700,1,12.5,700,1,14.68,700,1,12.49,200,2,14.74,200,2,12.46,100,1,14.75,100,1,12.43,700,1,14.94,200,2,ARL,333581625
2109,2025-07-17T16:08:27.516496962Z,2025-07-17T16:08:27.516496962Z,10,2,1108,A,A,1,14.26,100,130,165137,277841552,13.11,100,1,13.98,2,1,13.01,2,1,14.26,100,1,12.98,200,2,14.28,100,1,12.86,100,1,14.46,100,1,12.73,100,1,14.48,700,1,12.71,100,1,14.56,800,2,12.5,700,1,14.6,700,1,12.49,200,2,14.68,700,1,12.46,100,1,14.74,200,2,12.43,700,1,14.75,100,1,ARL,333581765
2110,2025-07-17T16:08:27.533773259Z,2025-07-17T16:08:27.533773259Z,10,2,1108,C,A,0,14.99,100,0,165191,277841588,13.11,100,1,13.98,2,1,13.01,2,1,14.26,100,1,12.98,200,2,14.28,100,1,12.86,100,1,14.46,100,1,12.73,100,1,14.48,700,1,12.71,100,1,14.56,800,2,12.5,700,1,14.6,700,1,12.49,200,2,14.68,700,1,12.46,100,1,14.74,200,2,12.43,700,1,14.75,100,1,ARL,333581389
2111,2025-07-17T16:08:27.533773259Z,2025-07-17T16:08:27.533773259Z,10,2,1108,A,A,11,15.04,100,130,165191,277841588,13.11,100,1,13.98,2,1,13.01,2,1,14.26,100,1,12.98,200,2,14.28,100,1,12.86,100,1,14.46,100,1,12.73,100,1,14.48,700,1,12.71,100,1,14.56,800,2,12.5,700,1,14.6,700,1,12.49,200,2,14.68,700,1,12.46,100,1,14.74,200,2,12.43,700,1,14.75,100,1,ARL,333581845
2112,2025-07-17T16:08:27.987513451Z,2025-07-17T16:08:27.987513451Z,10,2,1108,A,A,1,13.99,100,130,165288,277846288,13.11,100,1,13.98,2,1,13.01,2,1,13.99,100,1,12.98,200,2,14.26,100,1,12.86,100,1,14.28,100,1,12.73,100,1,14.46,100,1,12.71,100,1,14.48,700,1,12.5,700,1,14.56,800,2,12.49,200,2,14.6,700,1,12.46,100,1,14.68,700,1,12.43,700,1,14.74,200,2,ARL,333590057
2113,2025-07-17T16:08:58.024814068Z,2025-07-17T16:08:58.024814068Z,10,2,1108,A,A,0,13.81,15,130,165314,278261182,13.11,100,1,13.81,15,1,13.01,2,1,13.98,2,1,12.98,200,2,13.99,100,1,12.86,100,1,14.26,100,1,12.73,100,1,14.28,100,1,12.71,100,1,14.46,100,1,12.5,700,1,14.48,700,1,12.49,200,2,14.56,800,2,12.46,100,1,14.6,700,1,12.43,700,1,14.68,700,1,ARL,334141429
2114,2025-07-17T16:09:00.222509491Z,2025-07-17T16:09:00.222509491Z,10,2,1108,C,A,0,13.99,100,0,165743,278295684,13.11,100,1,13.81,15,1,13.01,2,1,13.98,2,1,12.98,200,2,14.26,100,1,12.86,100,1,14.28,100,1,12.73,100,1,14.46,100,1,12.71,100,1,14.48,700,1,12.5,700,1,14.56,800,2,12.49,200,2,14.6,700,1,12.46,100,1,14.68,700,1,12.43,700,1,14.74,200,2,ARL,333590057
2115,2025-07-17T16:09:00.222509491Z,2025-07-17T16:09:00.222509491Z,10,2,1108,A,A,1,13.82,100,130,165743,278295684,13.11,100,1,13.81,15,1,13.01,2,1,13.82,100,1,12.98,200,2,13.98,2,1,12.86,100,1,14.26,100,1,12.73,100,1,14.28,100,1,12.71,100,1,14.46,100,1,12.5,700,1,14.48,700,1,12.49,200,2,14.56,800,2,12.46,100,1,14.6,700,1,12.43,700,1,14.68,700,1,ARL,334189729
2116,2025-07-17T16:09:00.223269382Z,2025-07-17T16:09:00.223269382Z,10,2,1108,C,A,0,15.04,100,0,167375,278295848,13.11,100,1,13.81,15,1,13.01,2,1,13.82,100,1,12.98,200,2,13.98,2,1,12.86,100,1,14.26,100,1,12.73,100,1,14.28,100,1,12.71,100,1,14.46,100,1,12.5,700,1,14.48,700,1,12.49,200,2,14.56,800,2,12.46,100,1,14.6,700,1,12.43,700,1,14.68,700,1,ARL,333581845
2117,2025-07-17T16:09:00.223269382Z,2025-07-17T16:09:00.223269382Z,10,2,1108,A,A,12,14.89,100,128,167375,278295848,13.11,100,1,13.81,15,1,13.01,2,1,13.82,100,1,12.98,200,2,13.98,2,1,12.86,100,1,14.26,100,1,12.73,100,1,14.28,100,1,12.71,100,1,14.46,100,1,12.5,700,1,14.48,700,1,12.49,200,2,14.56,800,2,12.46,100,1,14.6,700,1,12.43,700,1,14.68,700,1,ARL,334189777
2118,2025-07-17T16:09:00.226338384Z,2025-07-17T16:09:00.226338384Z,10,2,1108,C,A,0,14.75,100,0,165962,278296281,13.11,100,1,13.81,15,1,13.01,2,1,13.82,100,1,12.98,200,2,13.98,2,1,12.86,100,1,14.26,100,1,12.73,100,1,14.28,100,1,12.71,100,1,14.46,100,1,12.5,700,1,14.48,700,1,12.49,200,2,14.56,800,2,12.46,100,1,14.6,700,1,12.43,700,1,14.68,700,1,ARL,333581569
2119,2025-07-17T16:09:00.226338384Z,2025-07-17T16:09:00.226338384Z,10,2,1108,A,A,9,14.61,100,130,165962,278296281,13.11,100,1,13.81,15,1,13.01,2,1,13.82,100,1,12.98,200,2,13.98,2,1,12.86,100,1,14.26,100,1,12.73,100,1,14.28,100,1,12.71,100,1,14.46,100,1,12.5,700,1,14.48,700,1,12.49,200,2,14.56,800,2,12.46,100,1,14.6,700,1,12.43,700,1,14.61,100,1,ARL,334190189
2120,2025-07-17T16:09:00.227763275Z,2025-07-17T16:09:00.227763275Z,10,2,1108,C,A,0,14.26,100,130,165786,278296402,13.11,100,1,13.81,15,1,13.01,2,1,13.82,100,1,12.98,200,2,13.98,2,1,12.86,100,1,14.28,100,1,12.73,100,1,14.46,100,1,12.71,100,1,14.48,700,1,12.5,700,1,14.56,800,2,12.49,200,2,14.6,700,1,12.46,100,1,14.61,100,1,12.43,700,1,14.68,700,1,ARL,333581765
2121,2025-07-17T16:09:00.227818153Z,2025-07-17T16:09:00.227818153Z,10,2,1108,A,A,3,14.1,100,130,165330,278296411,13.11,100,1,13.81,15,1,13.01,2,1,13.82,100,1,12.98,200,2,13.98,2,1,12.86,100,1,14.1,100,1,12.73,100,1,14.28,100,1,12.71,100,1,14.46,100,1,12.5,700,1,14.48,700,1,12.49,200,2,14.56,800,2,12.46,100,1,14.6,700,1,12.43,700,1,14.61,100,1,ARL,334190225
2122,2025-07-17T16:09:00.232743323Z,2025-07-17T16:09:00.232743323Z,10,2,1108,C,A,13,14.94,100,0,165559,278296544,13.11,100,1,13.81,15,1,13.01,2,1,13.82,100,1,12.98,200,2,13.98,2,1,12.86,100,1,14.1,100,1,12.73,100,1,14.28,100,1,12.71,100,1,14.46,100,1,12.5,700,1,14.48,700,1,12.49,200,2,14.56,800,2,12.46,100,1,14.6,700,1,12.43,700,1,14.61,100,1,ARL,333581429
2123,2025-07-17T16:09:00.232743323Z,2025-07-17T16:09:00.232743323Z,10,2,1108,A,A,12,14.79,100,130,165559,278296544,13.11,100,1,13.81,15,1,13.01,2,1,13.82,100,1,12.98,200,2,13.98,2,1,12.86,100,1,14.1,100,1,12.73,100,1,14.28,100,1,12.71,100,1,14.46,100,1,12.5,700,1,14.48,700,1,12.49,200,2,14.56,800,2,12.46,100,1,14.6,700,1,12.43,700,1,14.61,100,1,ARL,334190353
2124,2025-07-17T16:09:00.326127587Z,2025-07-17T16:09:00.326127587Z,10,2,1108,C,A,0,17.73,100,0,165699,278298302,13.11,100,1,13.81,15,1,13.01,2,1,13.82,100,1,12.98,200,2,13.98,2,1,12.86,100,1,14.1,100,1,12.73,100,1,14.28,100,1,12.71,100,1,14.46,100,1,12.5,700,1,14.48,700,1,12.49,200,2,14.56,800,2,12.46,100,1,14.6,700,1,12.43,700,1,14.61,100,1,ARL,333581425
2125,2025-07-17T16:09:00.326127587Z,2025-07-17T16:09:00.326127587Z,10,2,1108,A,A,22,17.56,100,130,165699,278298302,13.11,100,1,13.81,15,1,13.01,2,1,13.82,100,1,12.98,200,2,13.98,2,1,12.86,100,1,14.1,100,1,12.73,100,1,14.28,100,1,12.71,100,1,14.46,100,1,12.5,700,1,14.48,700,1,12.49,200,2,14.56,800,2,12.46,100,1,14.6,700,1,12.43,700,1,14.61,100,1,ARL,334192253
2126,2025-07-17T16:09:00.335442266Z,2025-07-17T16:09:00.335442266Z,10,2,1108,C,A,0,16.06,100,0,165561,278298372,13.11,100,1,13.81,15,1,13.01,2,1,13.82,100,1,12.98,200,2,13.98,2,1,12.86,100,1,14.1,100,1,12.73,100,1,14.28,100,1,12.71,100,1,14.46,100,1,12.5,700,1,14.48,700,1,12.49,200,2,14.56,800,2,12.46,100,1,14.6,700,1,12.43,700,1,14.61,100,1,ARL,333581433
2127,2025-07-17T16:09:00.335442266Z,2025-07-17T16:09:00.335442266Z,10,2,1108,A,A,19,15.9,100,130,165561,278298372,13.11,100,1,13.81,15,1,13.01,2,1,13.82,100,1,12.98,200,2,13.98,2,1,12.86,100,1,14.1,100,1,12.73,100,1,14.28,100,1,12.71,100,1,14.46,100,1,12.5,700,1,14.48,700,1,12.49,200,2,14.56,800,2,12.46,100,1,14.6,700,1,12.43,700,1,14.61,100,1,ARL,334192405
2128,2025-07-17T16:09:00.695610142Z,2025-07-17T16:09:00.695610142Z,10,2,1108,C,A,0,14.94,100,0,165868,278304343,13.11,100,1,13.81,15,1,13.01,2,1,13.82,100,1,12.98,200,2,13.98,2,1,12.86,100,1,14.1,100,1,12.73,100,1,14.28,100,1,12.71,100,1,14.46,100,1,12.5,700,1,14.48,700,1,12.49,200,2,14.56,800,2,12.46,100,1,14.6,700,1,12.43,700,1,14.61,100,1,ARL,333581409
2129,2025-07-17T16:09:00.695610142Z,2025-07-17T16:09:00.695610142Z,10,2,1108,A,A,12,14.79,100,130,165868,278304343,13.11,100,1,13.81,15,1,13.01,2,1,13.82,100,1,12.98,200,2,13.98,2,1,12.86,100,1,14.1,100,1,12.73,100,1,14.28,100,1,12.71,100,1,14.46,100,1,12.5,700,1,14.48,700,1,12.49,200,2,14.56,800,2,12.46,100,1,14.6,700,1,12.43,700,1,14.61,100,1,ARL,334199009
2130,2025-07-17T16:09:08.719524374Z,2025-07-17T16:09:08.719524374Z,10,2,1108,A,A,0,13.75,15,130,166319,278436950,13.11,100,1,13.75,15,1,13.01,2,1,13.81,15,1,12.98,200,2,13.82,100,1,12.86,100,1,13.98,2,1,12.73,100,1,14.1,100,1,12.71,100,1,14.28,100,1,12.5,700,1,14.46,100,1,12.49,200,2,14.48,700,1,12.46,100,1,14.56,800,2,12.43,700,1,14.6,700,1,ARL,334366613
2131,2025-07-17T16:09:08.719706070Z,2025-07-17T16:09:08.719706070Z,10,2,1108,C,A,0,13.82,100,0,165340,278436967,13.11,100,1,13.75,15,1,13.01,2,1,13.81,15,1,12.98,200,2,13.98,2,1,12.86,100,1,14.1,100,1,12.73,100,1,14.28,100,1,12.71,100,1,14.46,100,1,12.5,700,1,14.48,700,1,12.49,200,2,14.56,800,2,12.46,100,1,14.6,700,1,12.43,700,1,14.61,100,1,ARL,334189729
2132,2025-07-17T16:09:08.719706070Z,2025-07-17T16:09:08.719706070Z,10,2,1108,A,A,1,13.76,100,130,165340,278436967,13.11,100,1,13.75,15,1,13.01,2,1,13.76,100,1,12.98,200,2,13.81,15,1,12.86,100,1,13.98,2,1,12.73,100,1,14.1,100,1,12.71,100,1,14.28,100,1,12.5,700,1,14.46,100,1,12.49,200,2,14.48,700,1,12.46,100,1,14.56,800,2,12.43,700,1,14.6,700,1,ARL,334366617
2133,2025-07-17T16:09:08.720442245Z,2025-07-17T16:09:08.720442245Z,10,2,1108,C,A,0,14.89,100,0,165687,278436994,13.11,100,1,13.75,15,1,13.01,2,1,13.76,100,1,12.98,200,2,13.81,15,1,12.86,100,1,13.98,2,1,12.73,100,1,14.1,100,1,12.71,100,1,14.28,100,1,12.5,700,1,14.46,100,1,12.49,200,2,14.48,700,1,12.46,100,1,14.56,800,2,12.43,700,1,14.6,700,1,ARL,334189777
2134,2025-07-17T16:09:08.720442245Z,2025-07-17T16:09:08.720442245Z,10,2,1108,A,A,14,14.83,100,130,165687,278436994,13.11,100,1,13.75,15,1,13.01,2,1,13.76,100,1,12.98,200,2,13.81,15,1,12.86,100,1,13.98,2,1,12.73,100,1,14.1,100,1,12.71,100,1,14.28,100,1,12.5,700,1,14.46,100,1,12.49,200,2,14.48,700,1,12.46,100,1,14.56,800,2,12.43,700,1,14.6,700,1,ARL,334366645
2135,2025-07-17T16:09:18.819135505Z,2025-07-17T16:09:18.819135505Z,10,2,1108,C,A,0,13.81,15,130,165230,278596985,13.11,100,1,13.75,15,1,13.01,2,1,13.76,100,1,12.98,200,2,13.98,2,1,12.86,100,1,14.1,100,1,12.73,100,1,14.28,100,1,12.71,100,1,14.46,100,1,12.5,700,1,14.48,700,1,12.49,200,2,14.56,800,2,12.46,100,1,14.6,700,1,12.43,700,1,14.61,100,1,ARL,334141429
2136,2025-07-17T16:09:19.927039122Z,2025-07-17T16:09:19.927039122Z,10,2,1108,A,A,0,13.73,15,130,165901,278621672,13.11,100,1,13.73,15,1,13.01,2,1,13.75,15,1,12.98,200,2,13.76,100,1,12.86,100,1,13.98,2,1,12.73,100,1,14.1,100,1,12.71,100,1,14.28,100,1,12.5,700,1,14.46,100,1,12.49,200,2,14.48,700,1,12.46,100,1,14.56,800,2,12.43,700,1,14.6,700,1,ARL,334583329
2137,2025-07-17T16:09:19.927745104Z,2025-07-17T16:09:19.927745104Z,10,2,1108,C,A,12,14.74,100,0,165599,278621693,13.11,100,1,13.73,15,1,13.01,2,1,13.75,15,1,12.98,200,2,13.76,100,1,12.86,100,1,13.98,2,1,12.73,100,1,14.1,100,1,12.71,100,1,14.28,100,1,12.5,700,1,14.46,100,1,12.49,200,2,14.48,700,1,12.46,100,1,14.56,800,2,12.43,700,1,14.6,700,1,ARL,333581393
2138,2025-07-17T16:09:19.927745104Z,2025-07-17T16:09:19.927745104Z,10,2,1108,A,A,11,14.62,100,130,165599,278621693,13.11,100,1,13.73,15,1,13.01,2,1,13.75,15,1,12.98,200,2,13.76,100,1,12.86,100,1,13.98,2,1,12.73,100,1,14.1,100,1,12.71,100,1,14.28,100,1,12.5,700,1,14.46,100,1,12.49,200,2,14.48,700,1,12.46,100,1,14.56,800,2,12.43,700,1,14.6,700,1,ARL,334583349
2139,2025-07-17T16:09:19.928153837Z,2025-07-17T16:09:19.928153837Z,10,2,1108,C,A,0,14.74,100,0,165532,278621695,13.11,100,1,13.73,15,1,13.01,2,1,13.75,15,1,12.98,200,2,13.76,100,1,12.86,100,1,13.98,2,1,12.73,100,1,14.1,100,1,12.71,100,1,14.28,100,1,12.5,700,1,14.46,100,1,12.49,200,2,14.48,700,1,12.46,100,1,14.56,800,2,12.43,700,1,14.6,700,1,ARL,333581481
2140,2025-07-17T16:09:19.928153837Z,2025-07-17T16:09:19.928153837Z,10,2,1108,A,A,11,14.62,100,130,165532,278621695,13.11,100,1,13.73,15,1,13.01,2,1,13.75,15,1,12.98,200,2,13.76,100,1,12.86,100,1,13.98,2,1,12.73,100,1,14.1,100,1,12.71,100,1,14.28,100,1,12.5,700,1,14.46,100,1,12.49,200,2,14.48,700,1,12.46,100,1,14.56,800,2,12.43,700,1,14.6,700,1,ARL,334583361
2141,2025-07-17T16:09:20.284695585Z,2025-07-17T16:09:20.284695585Z,10,2,1108,C,A,0,13.76,100,0,165490,278629057,13.11,100,1,13.73,15,1,13.01,2,1,13.75,15,1,12.98,200,2,13.98,2,1,12.86,100,1,14.1,100,1,12.73,100,1,14.28,100,1,12.71,100,1,14.46,100,1,12.5,700,1,14.48,700,1,12.49,200,2,14.56,800,2,12.46,100,1,14.6,700,1,12.43,700,1,14.61,100,1,ARL,334366617
2142,2025-07-17T16:09:20.284695585Z,2025-07-17T16:09:20.284695585Z,10,2,1108,A,A,1,13.74,100,130,165490,278629057,13.11,100,1,13.73,15,1,13.01,2,1,13.74,100,1,12.98,200,2,13.75,15,1,12.86,100,1,13.98,2,1,12.73,100,1,14.1,100,1,12.71,100,1,14.28,100,1,12.5,700,1,14.46,100,1,12.49,200,2,14.48,700,1,12.46,100,1,14.56,800,2,12.43,700,1,14.6,700,1,ARL,334593569
2143,2025-07-17T16:09:20.293106270Z,2025-07-17T16:09:20.293106270Z,10,2,1108,C,A,0,14.1,100,130,165350,278629219,13.11,100,1,13.73,15,1,13.01,2,1,13.74,100,1,12.98,200,2,13.75,15,1,12.86,100,1,13.98,2,1,12.73,100,1,14.28,100,1,12.71,100,1,14.46,100,1,12.5,700,1,14.48,700,1,12.49,200,2,14.56,800,2,12.46,100,1,14.6,700,1,12.43,700,1,14.61,100,1,ARL,334190225
2144,2025-07-17T16:09:20.293161454Z,2025-07-17T16:09:20.293161454Z,10,2,1108,A,A,4,14.01,100,130,165187,278629220,13.11,100,1,13.73,15,1,13.01,2,1,13.74,100,1,12.98,200,2,13.75,15,1,12.86,100,1,13.98,2,1,12.73,100,1,14.01,100,1,12.71,100,1,14.28,100,1,12.5,700,1,14.46,100,1,12.49,200,2,14.48,700,1,12.46,100,1,14.56,800,2,12.43,700,1,14.6,700,1,ARL,334593753
2145,2025-07-17T16:09:20.818648795Z,2025-07-17T16:09:20.818648795Z,10,2,1108,C,A,0,13.73,15,130,165140,278640667,13.11,100,1,13.74,100,1,13.01,2,1,13.75,15,1,12.98,200,2,13.98,2,1,12.86,100,1,14.01,100,1,12.73,100,1,14.28,100,1,12.71,100,1,14.46,100,1,12.5,700,1,14.48,700,1,12.49,200,2,14.56,800,2,12.46,100,1,14.6,700,1,12.43,700,1,14.61,100,1,ARL,334583329
2146,2025-07-17T16:09:20.818761228Z,2025-07-17T16:09:20.818761228Z,10,2,1108,C,A,0,13.75,15,130,165128,278640670,13.11,100,1,13.74,100,1,13.01,2,1,13.98,2,1,12.98,200,2,14.01,100,1,12.86,100,1,14.28,100,1,12.73,100,1,14.46,100,1,12.71,100,1,14.48,700,1,12.5,700,1,14.56,800,2,12.49,200,2,14.6,700,1,12.46,100,1,14.61,100,1,12.43,700,1,14.62,200,2,ARL,334366613
2147,2025-07-17T16:09:28.985956629Z,2025-07-17T16:09:28.985956629Z,10,2,1108,C,A,0,13.98,2,0,165803,278784943,13.11,100,1,13.74,100,1,13.01,2,1,14.01,100,1,12.98,200,2,14.28,100,1,12.86,100,1,14.46,100,1,12.73,100,1,14.48,700,1,12.71,100,1,14.56,800,2,12.5,700,1,14.6,700,1,12.49,200,2,14.61,100,1,12.46,100,1,14.62,200,2,12.43,700,1,14.68,700,1,ARL,333581677
2148,2025-07-17T16:09:28.985956629Z,2025-07-17T16:09:28.985956629Z,10,2,1108,A,A,1,13.9,2,130,165803,278784943,13.11,100,1,13.74,100,1,13.01,2,1,13.9,2,1,12.98,200,2,14.01,100,1,12.86,100,1,14.28,100,1,12.73,100,1,14.46,100,1,12.71,100,1,14.48,700,1,12.5,700,1,14.56,800,2,12.49,200,2,14.6,700,1,12.46,100,1,14.61,100,1,12.43,700,1,14.62,200,2,ARL,334804177
2149,2025-07-17T16:09:40.821522565Z,2025-07-17T16:09:40.821522565Z,10,2,1108,A,A,0,13.7,15,130,165340,278938091,13.11,100,1,13.7,15,1,13.01,2,1,13.74,100,1,12.98,200,2,13.9,2,1,12.86,100,1,14.01,100,1,12.73,100,1,14.28,100,1,12.71,100,1,14.46,100,1,12.5,700,1,14.48,700,1,12.49,200,2,14.56,800,2,12.46,100,1,14.6,700,1,12.43,700,1,14.61,100,1,ARL,335003269
2150,2025-07-17T16:09:40.853439053Z,2025-07-17T16:09:40.853439053Z,10,2,1108,C,A,0,13.74,100,0,165524,278938747,13.11,100,1,13.7,15,1,13.01,2,1,13.9,2,1,12.98,200,2,14.01,100,1,12.86,100,1,14.28,100,1,12.73,100,1,14.46,100,1,12.71,100,1,14.48,700,1,12.5,700,1,14.56,800,2,12.49,200,2,14.6,700,1,12.46,100,1,14.61,100,1,12.43,700,1,14.62,200,2,ARL,334593569
2151,2025-07-17T16:09:40.853439053Z,2025-07-17T16:09:40.853439053Z,10,2,1108,A,A,1,13.71,100,130,165524,278938747,13.11,100,1,13.7,15,1,13.01,2,1,13.71,100,1,12.98,200,2,13.9,2,1,12.86,100,1,14.01,100,1,12.73,100,1,14.28,100,1,12.71,100,1,14.46,100,1,12.5,700,1,14.48,700,1,12.49,200,2,14.56,800,2,12.46,100,1,14.6,700,1,12.43,700,1,14.61,100,1,ARL,335003813
2152,2025-07-17T16:09:40.854190408Z,2025-07-17T16:09:40.854190408Z,10,2,1108,C,A,0,14.83,100,0,165614,278938765,13.11,100,1,13.7,15,1,13.01,2,1,13.71,100,1,12.98,200,2,13.9,2,1,12.86,100,1,14.01,100,1,12.73,100,1,14.28,100,1,12.71,100,1,14.46,100,1,12.5,700,1,14.48,700,1,12.49,200,2,14.56,800,2,12.46,100,1,14.6,700,1,12.43,700,1,14.61,100,1,ARL,334366645
2153,2025-07-17T16:09:40.854190408Z,2025-07-17T16:09:40.854190408Z,10,2,1108,A,A,12,14.77,100,130,165614,278938765,13.11,100,1,13.7,15,1,13.01,2,1,13.71,100,1,12.98,200,2,13.9,2,1,12.86,100,1,14.01,100,1,12.73,100,1,14.28,100,1,12.71,100,1,14.46,100,1,12.5,700,1,14.48,700,1,12.49,200,2,14.56,800,2,12.46,100,1,14.6,700,1,12.43,700,1,14.61,100,1,ARL,335003845
2154,2025-07-17T16:09:40.855558831Z,2025-07-17T16:09:40.855558831Z,10,2,1108,C,A,0,17.56,100,0,165591,278938788,13.11,100,1,13.7,15,1,13.01,2,1,13.71,100,1,12.98,200,2,13.9,2,1,12.86,100,1,14.01,100,1,12.73,100,1,14.28,100,1,12.71,100,1,14.46,100,1,12.5,700,1,14.48,700,1,12.49,200,2,14.56,800,2,12.46,100,1,14.6,700,1,12.43,700,1,14.61,100,1,ARL,334192253
2155,2025-07-17T16:09:40.855558831Z,2025-07-17T16:09:40.855558831Z,10,2,1108,A,A,21,17.42,100,130,165591,278938788,13.11,100,1,13.7,15,1,13.01,2,1,13.71,100,1,12.98,200,2,13.9,2,1,12.86,100,1,14.01,100,1,12.73,100,1,14.28,100,1,12.71,100,1,14.46,100,1,12.5,700,1,14.48,700,1,12.49,200,2,14.56,800,2,12.46,100,1,14.6,700,1,12.43,700,1,14.61,100,1,ARL,335003849
2156,2025-07-17T16:09:50.820783486Z,2025-07-17T16:09:50.820783486Z,10,2,1108,A,A,0,13.67,15,130,165645,279081140,13.11,100,1,13.67,15,1,13.01,2,1,13.7,15,1,12.98,200,2,13.71,100,1,12.86,100,1,13.9,2,1,12.73,100,1,14.01,100,1,12.71,100,1,14.28,100,1,12.5,700,1,14.46,100,1,12.49,200,2,14.48,700,1,12.46,100,1,14.56,800,2,12.43,700,1,14.6,700,1,ARL,335178437
2157,2025-07-17T16:09:52.678611805Z,2025-07-17T16:09:52.678611805Z,10,2,1108,C,A,0,13.71,100,0,165553,279109959,13.11,100,1,13.67,15,1,13.01,2,1,13.7,15,1,12.98,200,2,13.9,2,1,12.86,100,1,14.01,100,1,12.73,100,1,14.28,100,1,12.71,100,1,14.46,100,1,12.5,700,1,14.48,700,1,12.49,200,2,14.56,800,2,12.46,100,1,14.6,700,1,12.43,700,1,14.61,100,1,ARL,335003813
2158,2025-07-17T16:09:52.678611805Z,2025-07-17T16:09:52.678611805Z,10,2,1108,A,A,1,13.68,100,130,165553,279109959,13.11,100,1,13.67,15,1,13.01,2,1,13.68,100,1,12.98,200,2,13.7,15,1,12.86,100,1,13.9,2,1,12.73,100,1,14.01,100,1,12.71,100,1,14.28,100,1,12.5,700,1,14.46,100,1,12.49,200,2,14.48,700,1,12.46,100,1,14.56,800,2,12.43,700,1,14.6,700,1,ARL,335220349
2159,2025-07-17T16:09:52.679678566Z,2025-07-17T16:09:52.679678566Z,10,2,1108,C,A,0,15.9,100,0,165772,279109991,13.11,100,1,13.67,15,1,13.01,2,1,13.68,100,1,12.98,200,2,13.7,15,1,12.86,100,1,13.9,2,1,12.73,100,1,14.01,100,1,12.71,100,1,14.28,100,1,12.5,700,1,14.46,100,1,12.49,200,2,14.48,700,1,12.46,100,1,14.56,800,2,12.43,700,1,14.6,700,1,ARL,334192405
2160,2025-07-17T16:09:52.679678566Z,2025-07-17T16:09:52.679678566Z,10,2,1108,A,A,19,15.74,100,130,165772,279109991,13.11,100,1,13.67,15,1,13.01,2,1,13.68,100,1,12.98,200,2,13.7,15,1,12.86,100,1,13.9,2,1,12.73,100,1,14.01,100,1,12.71,100,1,14.28,100,1,12.5,700,1,14.46,100,1,12.49,200,2,14.48,700,1,12.46,100,1,14.56,800,2,12.43,700,1,14.6,700,1,ARL,335220497
2161,2025-07-17T16:09:52.679769832Z,2025-07-17T16:09:52.679769832Z,10,2,1108,C,A,14,14.79,100,0,166994,279109996,13.11,100,1,13.67,15,1,13.01,2,1,13.68,100,1,12.98,200,2,13.7,15,1,12.86,100,1,13.9,2,1,12.73,100,1,14.01,100,1,12.71,100,1,14.28,100,1,12.5,700,1,14.46,100,1,12.49,200,2,14.48,700,1,12.46,100,1,14.56,800,2,12.43,700,1,14.6,700,1,ARL,334190353
2162,2025-07-17T16:09:52.679769832Z,2025-07-17T16:09:52.679769832Z,10,2,1108,A,A,12,14.64,100,130,166994,279109996,13.11,100,1,13.67,15,1,13.01,2,1,13.68,100,1,12.98,200,2,13.7,15,1,12.86,100,1,13.9,2,1,12.73,100,1,14.01,100,1,12.71,100,1,14.28,100,1,12.5,700,1,14.46,100,1,12.49,200,2,14.48,700,1,12.46,100,1,14.56,800,2,12.43,700,1,14.6,700,1,ARL,335220525
2163,2025-07-17T16:09:52.680672148Z,2025-07-17T16:09:52.680672148Z,10,2,1108,C,A,0,15.36,100,0,165588,279110032,13.11,100,1,13.67,15,1,13.01,2,1,13.68,100,1,12.98,200,2,13.7,15,1,12.86,100,1,13.9,2,1,12.73,100,1,14.01,100,1,12.71,100,1,14.28,100,1,12.5,700,1,14.46,100,1,12.49,200,2,14.48,700,1,12.46,100,1,14.56,800,2,12.43,700,1,14.6,700,1,ARL,333581441
2164,2025-07-17T16:09:52.680672148Z,2025-07-17T16:09:52.680672148Z,10,2,1108,A,A,16,15.05,100,130,165588,279110032,13.11,100,1,13.67,15,1,13.01,2,1,13.68,100,1,12.98,200,2,13.7,15,1,12.86,100,1,13.9,2,1,12.73,100,1,14.01,100,1,12.71,100,1,14.28,100,1,12.5,700,1,14.46,100,1,12.49,200,2,14.48,700,1,12.46,100,1,14.56,800,2,12.43,700,1,14.6,700,1,ARL,335220549
2165,2025-07-17T16:09:52.681844377Z,2025-07-17T16:09:52.681844377Z,10,2,1108,C,A,0,14.61,100,130,165561,279110066,13.11,100,1,13.67,15,1,13.01,2,1,13.68,100,1,12.98,200,2,13.7,15,1,12.86,100,1,13.9,2,1,12.73,100,1,14.01,100,1,12.71,100,1,14.28,100,1,12.5,700,1,14.46,100,1,12.49,200,2,14.48,700,1,12.46,100,1,14.56,800,2,12.43,700,1,14.6,700,1,ARL,334190189
2166,2025-07-17T16:09:52.681961200Z,2025-07-17T16:09:52.681961200Z,10,2,1108,A,A,7,14.47,100,130,166330,279110068,13.11,100,1,13.67,15,1,13.01,2,1,13.68,100,1,12.98,200,2,13.7,15,1,12.86,100,1,13.9,2,1,12.73,100,1,14.01,100,1,12.71,100,1,14.28,100,1,12.5,700,1,14.46,100,1,12.49,200,2,14.47,100,1,12.46,100,1,14.48,700,1,12.43,700,1,14.56,800,2,ARL,335220561
2167,2025-07-17T16:09:52.683757265Z,2025-07-17T16:09:52.683757265Z,10,2,1108,C,A,0,14.79,100,0,165442,279110090,13.11,100,1,13.67,15,1,13.01,2,1,13.68,100,1,12.98,200,2,13.7,15,1,12.86,100,1,13.9,2,1,12.73,100,1,14.01,100,1,12.71,100,1,14.28,100,1,12.5,700,1,14.46,100,1,12.49,200,2,14.47,100,1,12.46,100,1,14.48,700,1,12.43,700,1,14.56,800,2,ARL,334199009
2168,2025-07-17T16:09:52.683757265Z,2025-07-17T16:09:52.683757265Z,10,2,1108,A,A,12,14.64,100,130,165442,279110090,13.11,100,1,13.67,15,1,13.01,2,1,13.68,100,1,12.98,200,2,13.7,15,1,12.86,100,1,13.9,2,1,12.73,100,1,14.01,100,1,12.71,100,1,14.28,100,1,12.5,700,1,14.46,100,1,12.49,200,2,14.47,100,1,12.46,100,1,14.48,700,1,12.43,700,1,14.56,800,2,ARL,335220629
2169,2025-07-17T16:10:04.521306513Z,2025-07-17T16:10:04.521306513Z,10,2,1108,C,A,0,13.67,15,130,165291,279306715,13.11,100,1,13.68,100,1,13.01,2,1,13.7,15,1,12.98,200,2,13.9,2,1,12.86,100,1,14.01,100,1,12.73,100,1,14.28,100,1,12.71,100,1,14.46,100,1,12.5,700,1,14.47,100,1,12.49,200,2,14.48,700,1,12.46,100,1,14.56,800,2,12.43,700,1,14.6,700,1,ARL,335178437
2170,2025-07-17T16:10:04.561688313Z,2025-07-17T16:10:04.561688313Z,10,2,1108,C,A,0,13.7,15,128,166543,279312083,13.11,100,1,13.68,100,1,13.01,2,1,13.9,2,1,12.98,200,2,14.01,100,1,12.86,100,1,14.28,100,1,12.73,100,1,14.46,100,1,12.71,100,1,14.47,100,1,12.5,700,1,14.48,700,1,12.49,200,2,14.56,800,2,12.46,100,1,14.6,700,1,12.43,700,1,14.62,200,2,ARL,335003269
2171,2025-07-17T16:10:32.822495087Z,2025-07-17T16:10:32.822495087Z,10,2,1108,A,A,0,13.65,15,130,165411,279705339,13.11,100,1,13.65,15,1,13.01,2,1,13.68,100,1,12.98,200,2,13.9,2,1,12.86,100,1,14.01,100,1,12.73,100,1,14.28,100,1,12.71,100,1,14.46,100,1,12.5,700,1,14.47,100,1,12.49,200,2,14.48,700,1,12.46,100,1,14.56,800,2,12.43,700,1,14.6,700,1,ARL,335996705
2172,2025-07-17T16:10:32.822757517Z,2025-07-17T16:10:32.822757517Z,10,2,1108,C,A,0,13.68,100,0,165621,279705347,13.11,100,1,13.65,15,1,13.01,2,1,13.9,2,1,12.98,200,2,14.01,100,1,12.86,100,1,14.28,100,1,12.73,100,1,14.46,100,1,12.71,100,1,14.47,100,1,12.5,700,1,14.48,700,1,12.49,200,2,14.56,800,2,12.46,100,1,14.6,700,1,12.43,700,1,14.62,200,2,ARL,335220349
2173,2025-07-17T16:10:32.822757517Z,2025-07-17T16:10:32.822757517Z,10,2,1108,A,A,1,13.66,100,130,165621,279705347,13.11,100,1,13.65,15,1,13.01,2,1,13.66,100,1,12.98,200,2,13.9,2,1,12.86,100,1,14.01,100,1,12.73,100,1,14.28,100,1,12.71,100,1,14.46,100,1,12.5,700,1,14.47,100,1,12.49,200,2,14.48,700,1,12.46,100,1,14.56,800,2,12.43,700,1,14.6,700,1,ARL,335996709
2174,2025-07-17T16:10:32.823491276Z,2025-07-17T16:10:32.823491276Z,10,2,1108,C,A,0,14.77,100,0,165627,279705362,13.11,100,1,13.65,15,1,13.01,2,1,13.66,100,1,12.98,200,2,13.9,2,1,12.86,100,1,14.01,100,1,12.73,100,1,14.28,100,1,12.71,100,1,14.46,100,1,12.5,700,1,14.47,100,1,12.49,200,2,14.48,700,1,12.46,100,1,14.56,800,2,12.43,700,1,14.6,700,1,ARL,335003845
2175,2025-07-17T16:10:32.823491276Z,2025-07-17T16:10:32.823491276Z,10,2,1108,A,A,13,14.72,100,130,165627,279705362,13.11,100,1,13.65,15,1,13.01,2,1,13.66,100,1,12.98,200,2,13.9,2,1,12.86,100,1,14.01,100,1,12.73,100,1,14.28,100,1,12.71,100,1,14.46,100,1,12.5,700,1,14.47,100,1,12.49,200,2,14.48,700,1,12.46,100,1,14.56,800,2,12.43,700,1,14.6,700,1,ARL,335996725
2176,2025-07-17T16:10:32.830032662Z,2025-07-17T16:10:32.830032662Z,10,2,1108,C,A,0,14.01,100,130,168182,279705485,13.11,100,1,13.65,15,1,13.01,2,1,13.66,100,1,12.98,200,2,13.9,2,1,12.86,100,1,14.28,100,1,12.73,100,1,14.46,100,1,12.71,100,1,14.47,100,1,12.5,700,1,14.48,700,1,12.49,200,2,14.56,800,2,12.46,100,1,14.6,700,1,12.43,700,1,14.62,200,2,ARL,334593753
2177,2025-07-17T16:10:32.830085472Z,2025-07-17T16:10:32.830085472Z,10,2,1108,A,A,3,13.93,100,130,165248,279705486,13.11,100,1,13.65,15,1,13.01,2,1,13.66,100,1,12.98,200,2,13.9,2,1,12.86,100,1,13.93,100,1,12.73,100,1,14.28,100,1,12.71,100,1,14.46,100,1,12.5,700,1,14.47,100,1,12.49,200,2,14.48,700,1,12.46,100,1,14.56,800,2,12.43,700,1,14.6,700,1,ARL,335996777
2178,2025-07-17T16:10:42.822189504Z,2025-07-17T16:10:42.822189504Z,10,2,1108,A,A,0,13.63,15,130,165365,279834760,13.11,100,1,13.63,15,1,13.01,2,1,13.65,15,1,12.98,200,2,13.66,100,1,12.86,100,1,13.9,2,1,12.73,100,1,13.93,100,1,12.71,100,1,14.28,100,1,12.5,700,1,14.46,100,1,12.49,200,2,14.47,100,1,12.46,100,1,14.48,700,1,12.43,700,1,14.56,800,2,ARL,336161333
2179,2025-07-17T16:10:42.822258887Z,2025-07-17T16:10:42.822258887Z,10,2,1108,C,A,0,13.66,100,0,165776,279834761,13.11,100,1,13.63,15,1,13.01,2,1,13.65,15,1,12.98,200,2,13.9,2,1,12.86,100,1,13.93,100,1,12.73,100,1,14.28,100,1,12.71,100,1,14.46,100,1,12.5,700,1,14.47,100,1,12.49,200,2,14.48,700,1,12.46,100,1,14.56,800,2,12.43,700,1,14.6,700,1,ARL,335996709
2180,2025-07-17T16:10:42.822258887Z,2025-07-17T16:10:42.822258887Z,10,2,1108,A,A,1,13.64,100,130,165776,279834761,13.11,100,1,13.63,15,1,13.01,2,1,13.64,100,1,12.98,200,2,13.65,15,1,12.86,100,1,13.9,2,1,12.73,100,1,13.93,100,1,12.71,100,1,14.28,100,1,12.5,700,1,14.46,100,1,12.49,200,2,14.47,100,1,12.46,100,1,14.48,700,1,12.43,700,1,14.56,800,2,ARL,336161337
2181,2025-07-17T16:10:42.822998664Z,2025-07-17T16:10:42.822998664Z,10,2,1108,C,A,0,14.46,100,130,165265,279834765,13.11,100,1,13.63,15,1,13.01,2,1,13.64,100,1,12.98,200,2,13.65,15,1,12.86,100,1,13.9,2,1,12.73,100,1,13.93,100,1,12.71,100,1,14.28,100,1,12.5,700,1,14.47,100,1,12.49,200,2,14.48,700,1,12.46,100,1,14.56,800,2,12.43,700,1,14.6,700,1,ARL,331927161
2182,2025-07-17T16:10:42.823352130Z,2025-07-17T16:10:42.823352130Z,10,2,1108,A,A,5,14.25,100,130,165314,279834767,13.11,100,1,13.63,15,1,13.01,2,1,13.64,100,1,12.98,200,2,13.65,15,1,12.86,100,1,13.9,2,1,12.73,100,1,13.93,100,1,12.71,100,1,14.25,100,1,12.5,700,1,14.28,100,1,12.49,200,2,14.47,100,1,12.46,100,1,14.48,700,1,12.43,700,1,14.56,800,2,ARL,336161365
2183,2025-07-17T16:10:46.533890361Z,2025-07-17T16:10:46.533890361Z,10,2,1108,C,A,11,14.62,100,0,165581,279921726,13.11,100,1,13.63,15,1,13.01,2,1,13.64,100,1,12.98,200,2,13.65,15,1,12.86,100,1,13.9,2,1,12.73,100,1,13.93,100,1,12.71,100,1,14.25,100,1,12.5,700,1,14.28,100,1,12.49,200,2,14.47,100,1,12.46,100,1,14.48,700,1,12.43,700,1,14.56,800,2,ARL,334583349
2184,2025-07-17T16:10:46.533890361Z,2025-07-17T16:10:46.533890361Z,10,2,1108,A,A,9,14.51,100,130,165581,279921726,13.11,100,1,13.63,15,1,13.01,2,1,13.64,100,1,12.98,200,2,13.65,15,1,12.86,100,1,13.9,2,1,12.73,100,1,13.93,100,1,12.71,100,1,14.25,100,1,12.5,700,1,14.28,100,1,12.49,200,2,14.47,100,1,12.46,100,1,14.48,700,1,12.43,700,1,14.51,100,1,ARL,336259225
2185,2025-07-17T16:10:46.537992315Z,2025-07-17T16:10:46.537992315Z,10,2,1108,C,A,0,13.65,15,128,166559,279921911,13.11,100,1,13.63,15,1,13.01,2,1,13.64,100,1,12.98,200,2,13.9,2,1,12.86,100,1,13.93,100,1,12.73,100,1,14.25,100,1,12.71,100,1,14.28,100,1,12.5,700,1,14.47,100,1,12.49,200,2,14.48,700,1,12.46,100,1,14.51,100,1,12.43,700,1,14.56,800,2,ARL,335996705
2186,2025-07-17T16:10:46.561080616Z,2025-07-17T16:10:46.561080616Z,10,2,1108,C,A,0,14.62,100,0,165414,279924883,13.11,100,1,13.63,15,1,13.01,2,1,13.64,100,1,12.98,200,2,13.9,2,1,12.86,100,1,13.93,100,1,12.73,100,1,14.25,100,1,12.71,100,1,14.28,100,1,12.5,700,1,14.47,100,1,12.49,200,2,14.48,700,1,12.46,100,1,14.51,100,1,12.43,700,1,14.56,800,2,ARL,334583361
2187,2025-07-17T16:10:46.561080616Z,2025-07-17T16:10:46.561080616Z,10,2,1108,A,A,8,14.51,100,130,165414,279924883,13.11,100,1,13.63,15,1,13.01,2,1,13.64,100,1,12.98,200,2,13.9,2,1,12.86,100,1,13.93,100,1,12.73,100,1,14.25,100,1,12.71,100,1,14.28,100,1,12.5,700,1,14.47,100,1,12.49,200,2,14.48,700,1,12.46,100,1,14.51,200,2,12.43,700,1,14.56,800,2,ARL,336261905
2188,2025-07-17T16:10:47.543238729Z,2025-07-17T16:10:47.543238729Z,10,2,1108,A,A,0,13.61,15,130,165272,279938097,13.11,100,1,13.61,15,1,13.01,2,1,13.63,15,1,12.98,200,2,13.64,100,1,12.86,100,1,13.9,2,1,12.73,100,1,13.93,100,1,12.71,100,1,14.25,100,1,12.5,700,1,14.28,100,1,12.49,200,2,14.47,100,1,12.46,100,1,14.48,700,1,12.43,700,1,14.51,200,2,ARL,336278197
2189,2025-07-17T16:10:48.657290980Z,2025-07-17T16:10:48.657290980Z,10,2,1108,C,A,0,13.64,100,0,165415,279952266,13.11,100,1,13.61,15,1,13.01,2,1,13.63,15,1,12.98,200,2,13.9,2,1,12.86,100,1,13.93,100,1,12.73,100,1,14.25,100,1,12.71,100,1,14.28,100,1,12.5,700,1,14.47,100,1,12.49,200,2,14.48,700,1,12.46,100,1,14.51,200,2,12.43,700,1,14.56,800,2,ARL,336161337
2190,2025-07-17T16:10:48.657290980Z,2025-07-17T16:10:48.657290980Z,10,2,1108,A,A,1,13.62,100,130,165415,279952266,13.11,100,1,13.61,15,1,13.01,2,1,13.62,100,1,12.98,200,2,13.63,15,1,12.86,100,1,13.9,2,1,12.73,100,1,13.93,100,1,12.71,100,1,14.25,100,1,12.5,700,1,14.28,100,1,12.49,200,2,14.47,100,1,12.46,100,1,14.48,700,1,12.43,700,1,14.51,200,2,ARL,336295769
2191,2025-07-17T16:10:48.658033954Z,2025-07-17T16:10:48.658033954Z,10,2,1108,C,A,0,14.72,100,0,165471,279952282,13.11,100,1,13.61,15,1,13.01,2,1,13.62,100,1,12.98,200,2,13.63,15,1,12.86,100,1,13.9,2,1,12.73,100,1,13.93,100,1,12.71,100,1,14.25,100,1,12.5,700,1,14.28,100,1,12.49,200,2,14.47,100,1,12.46,100,1,14.48,700,1,12.43,700,1,14.51,200,2,ARL,335996725
2192,2025-07-17T16:10:48.658033954Z,2025-07-17T16:10:48.658033954Z,10,2,1108,A,A,13,14.68,100,130,165471,279952282,13.11,100,1,13.61,15,1,13.01,2,1,13.62,100,1,12.98,200,2,13.63,15,1,12.86,100,1,13.9,2,1,12.73,100,1,13.93,100,1,12.71,100,1,14.25,100,1,12.5,700,1,14.28,100,1,12.49,200,2,14.47,100,1,12.46,100,1,14.48,700,1,12.43,700,1,14.51,200,2,ARL,336295845
2193,2025-07-17T16:10:51.058878264Z,2025-07-17T16:10:51.058878264Z,10,2,1108,C,A,0,13.61,15,128,166028,280001840,13.11,100,1,13.62,100,1,13.01,2,1,13.63,15,1,12.98,200,2,13.9,2,1,12.86,100,1,13.93,100,1,12.73,100,1,14.25,100,1,12.71,100,1,14.28,100,1,12.5,700,1,14.47,100,1,12.49,200,2,14.48,700,1,12.46,100,1,14.51,200,2,12.43,700,1,14.56,800,2,ARL,336278197
2194,2025-07-17T16:10:51.059016199Z,2025-07-17T16:10:51.059016199Z,10,2,1108,C,A,0,13.63,15,128,167724,280001873,13.11,100,1,13.62,100,1,13.01,2,1,13.9,2,1,12.98,200,2,13.93,100,1,12.86,100,1,14.25,100,1,12.73,100,1,14.28,100,1,12.71,100,1,14.47,100,1,12.5,700,1,14.48,700,1,12.49,200,2,14.51,200,2,12.46,100,1,14.56,800,2,12.43,700,1,14.6,700,1,ARL,336161333
2195,2025-07-17T16:10:51.059443298Z,2025-07-17T16:10:51.059443298Z,10,2,1108,C,A,0,13.62,100,130,165455,280001952,13.11,100,1,13.9,2,1,13.01,2,1,13.93,100,1,12.98,200,2,14.25,100,1,12.86,100,1,14.28,100,1,12.73,100,1,14.47,100,1,12.71,100,1,14.48,700,1,12.5,700,1,14.51,200,2,12.49,200,2,14.56,800,2,12.46,100,1,14.6,700,1,12.43,700,1,14.64,200,2,ARL,336295769
2196,2025-07-17T16:10:51.170545251Z,2025-07-17T16:10:51.170545251Z,10,2,1108,A,A,1,13.91,100,130,165358,280003702,13.11,100,1,13.9,2,1,13.01,2,1,13.91,100,1,12.98,200,2,13.93,100,1,12.86,100,1,14.25,100,1,12.73,100,1,14.28,100,1,12.71,100,1,14.47,100,1,12.5,700,1,14.48,700,1,12.49,200,2,14.51,200,2,12.46,100,1,14.56,800,2,12.43,700,1,14.6,700,1,ARL,336351081
2197,2025-07-17T16:10:52.958288317Z,2025-07-17T16:10:52.958288317Z,10,2,1108,A,A,0,13.6,15,130,165324,280050139,13.11,100,1,13.6,15,1,13.01,2,1,13.9,2,1,12.98,200,2,13.91,100,1,12.86,100,1,13.93,100,1,12.73,100,1,14.25,100,1,12.71,100,1,14.28,100,1,12.5,700,1,14.47,100,1,12.49,200,2,14.48,700,1,12.46,100,1,14.51,200,2,12.43,700,1,14.56,800,2,ARL,336402845
2198,2025-07-17T16:10:53.101871639Z,2025-07-17T16:10:53.101871639Z,10,2,1108,C,A,0,13.91,100,0,165534,280057228,13.11,100,1,13.6,15,1,13.01,2,1,13.9,2,1,12.98,200,2,13.93,100,1,12.86,100,1,14.25,100,1,12.73,100,1,14.28,100,1,12.71,100,1,14.47,100,1,12.5,700,1,14.48,700,1,12.49,200,2,14.51,200,2,12.46,100,1,14.56,800,2,12.43,700,1,14.6,700,1,ARL,336351081
2199,2025-07-17T16:10:53.101871639Z,2025-07-17T16:10:53.101871639Z,10,2,1108,A,A,1,13.61,100,130,165534,280057228,13.11,100,1,13.6,15,1,13.01,2,1,13.61,100,1,12.98,200,2,13.9,2,1,12.86,100,1,13.93,100,1,12.73,100,1,14.25,100,1,12.71,100,1,14.28,100,1,12.5,700,1,14.47,100,1,12.49,200,2,14.48,700,1,12.46,100,1,14.51,200,2,12.43,700,1,14.56,800,2,ARL,336410125
2200,2025-07-17T16:10:54.959141873Z,2025-07-17T16:10:54.959141873Z,10,2,1108,C,A,0,13.9,2,0,165719,280084546,13.11,100,1,13.6,15,1,13.01,2,1,13.61,100,1,12.98,200,2,13.93,100,1,12.86,100,1,14.25,100,1,12.73,100,1,14.28,100,1,12.71,100,1,14.47,100,1,12.5,700,1,14.48,700,1,12.49,200,2,14.51,200,2,12.46,100,1,14.56,800,2,12.43,700,1,14.6,700,1,ARL,334804177
2201,2025-07-17T16:10:54.959141873Z,2025-07-17T16:10:54.959141873Z,10,2,1108,A,A,2,13.82,2,130,165719,280084546,13.11,100,1,13.6,15,1,13.01,2,1,13.61,100,1,12.98,200,2,13.82,2,1,12.86,100,1,13.93,100,1,12.73,100,1,14.25,100,1,12.71,100,1,14.28,100,1,12.5,700,1,14.47,100,1,12.49,200,2,14.48,700,1,12.46,100,1,14.51,200,2,12.43,700,1,14.56,800,2,ARL,336447325
2202,2025-07-17T16:10:59.517870358Z,2025-07-17T16:10:59.517870358Z,10,2,1108,A,A,0,13.58,15,130,165447,280173685,13.11,100,1,13.58,15,1,13.01,2,1,13.6,15,1,12.98,200,2,13.61,100,1,12.86,100,1,13.82,2,1,12.73,100,1,13.93,100,1,12.71,100,1,14.25,100,1,12.5,700,1,14.28,100,1,12.49,200,2,14.47,100,1,12.46,100,1,14.48,700,1,12.43,700,1,14.51,200,2,ARL,336555153
2203,2025-07-17T16:11:00.215719725Z,2025-07-17T16:11:00.215719725Z,10,2,1108,C,A,0,13.61,100,0,165569,280184406,13.11,100,1,13.58,15,1,13.01,2,1,13.6,15,1,12.98,200,2,13.82,2,1,12.86,100,1,13.93,100,1,12.73,100,1,14.25,100,1,12.71,100,1,14.28,100,1,12.5,700,1,14.47,100,1,12.49,200,2,14.48,700,1,12.46,100,1,14.51,200,2,12.43,700,1,14.56,800,2,ARL,336410125
2204,2025-07-17T16:11:00.215719725Z,2025-07-17T16:11:00.215719725Z,10,2,1108,A,A,1,13.59,100,130,165569,280184406,13.11,100,1,13.58,15,1,13.01,2,1,13.59,100,1,12.98,200,2,13.6,15,1,12.86,100,1,13.82,2,1,12.73,100,1,13.93,100,1,12.71,100,1,14.25,100,1,12.5,700,1,14.28,100,1,12.49,200,2,14.47,100,1,12.46,100,1,14.48,700,1,12.43,700,1,14.51,200,2,ARL,336567189
2205,2025-07-17T16:11:00.216456547Z,2025-07-17T16:11:00.216456547Z,10,2,1108,C,A,13,14.68,100,0,165574,280184418,13.11,100,1,13.58,15,1,13.01,2,1,13.59,100,1,12.98,200,2,13.6,15,1,12.86,100,1,13.82,2,1,12.73,100,1,13.93,100,1,12.71,100,1,14.25,100,1,12.5,700,1,14.28,100,1,12.49,200,2,14.47,100,1,12.46,100,1,14.48,700,1,12.43,700,1,14.51,200,2,ARL,336295845
2206,2025-07-17T16:11:00.216456547Z,2025-07-17T16:11:00.216456547Z,10,2,1108,A,A,12,14.64,100,130,165574,280184418,13.11,100,1,13.58,15,1,13.01,2,1,13.59,100,1,12.98,200,2,13.6,15,1,12.86,100,1,13.82,2,1,12.73,100,1,13.93,100,1,12.71,100,1,14.25,100,1,12.5,700,1,14.28,100,1,12.49,200,2,14.47,100,1,12.46,100,1,14.48,700,1,12.43,700,1,14.51,200,2,ARL,336567213
2207,2025-07-17T16:11:00.228833925Z,2025-07-17T16:11:00.228833925Z,10,2,1108,C,A,0,13.93,100,130,165452,280184613,13.11,100,1,13.58,15,1,13.01,2,1,13.59,100,1,12.98,200,2,13.6,15,1,12.86,100,1,13.82,2,1,12.73,100,1,14.25,100,1,12.71,100,1,14.28,100,1,12.5,700,1,14.47,100,1,12.49,200,2,14.48,700,1,12.46,100,1,14.51,200,2,12.43,700,1,14.56,800,2,ARL,335996777
2208,2025-07-17T16:11:00.228885790Z,2025-07-17T16:11:00.228885790Z,10,2,1108,A,A,4,13.86,100,130,165334,280184614,13.11,100,1,13.58,15,1,13.01,2,1,13.59,100,1,12.98,200,2,13.6,15,1,12.86,100,1,13.82,2,1,12.73,100,1,13.86,100,1,12.71,100,1,14.25,100,1,12.5,700,1,14.28,100,1,12.49,200,2,14.47,100,1,12.46,100,1,14.48,700,1,12.43,700,1,14.51,200,2,ARL,336567333
2209,2025-07-17T16:11:00.312921679Z,2025-07-17T16:11:00.312921679Z,10,2,1108,C,A,0,17.42,100,0,165450,280188038,13.11,100,1,13.58,15,1,13.01,2,1,13.59,100,1,12.98,200,2,13.6,15,1,12.86,100,1,13.82,2,1,12.73,100,1,13.86,100,1,12.71,100,1,14.25,100,1,12.5,700,1,14.28,100,1,12.49,200,2,14.47,100,1,12.46,100,1,14.48,700,1,12.43,700,1,14.51,200,2,ARL,335003849
2210,2025-07-17T16:11:00.312921679Z,2025-07-17T16:11:00.312921679Z,10,2,1108,A,A,21,17.26,100,130,165450,280188038,13.11,100,1,13.58,15,1,13.01,2,1,13.59,100,1,12.98,200,2,13.6,15,1,12.86,100,1,13.82,2,1,12.73,100,1,13.86,100,1,12.71,100,1,14.25,100,1,12.5,700,1,14.28,100,1,12.49,200,2,14.47,100,1,12.46,100,1,14.48,700,1,12.43,700,1,14.51,200,2,ARL,336570921
2211,2025-07-17T16:11:00.366645846Z,2025-07-17T16:11:00.366645846Z,10,2,1108,A,A,3,13.62,1,130,165695,280189435,13.11,100,1,13.58,15,1,13.01,2,1,13.59,100,1,12.98,200,2,13.6,15,1,12.86,100,1,13.62,1,1,12.73,100,1,13.82,2,1,12.71,100,1,13.86,100,1,12.5,700,1,14.25,100,1,12.49,200,2,14.28,100,1,12.46,100,1,14.47,100,1,12.43,700,1,14.48,700,1,ARL,336572049
2212,2025-07-17T16:11:00.367209243Z,2025-07-17T16:11:00.367209243Z,10,2,1108,C,B,7,12.49,100,0,165530,280189439,13.11,100,1,13.58,15,1,13.01,2,1,13.59,100,1,12.98,200,2,13.6,15,1,12.86,100,1,13.62,1,1,12.73,100,1,13.82,2,1,12.71,100,1,13.86,100,1,12.5,700,1,14.25,100,1,12.49,100,1,14.28,100,1,12.46,100,1,14.47,100,1,12.43,700,1,14.48,700,1,ARL,331942945
2213,2025-07-17T16:11:00.367209243Z,2025-07-17T16:11:00.367209243Z,10,2,1108,A,B,12,12.36,100,130,165530,280189439,13.11,100,1,13.58,15,1,13.01,2,1,13.59,100,1,12.98,200,2,13.6,15,1,12.86,100,1,13.62,1,1,12.73,100,1,13.82,2,1,12.71,100,1,13.86,100,1,12.5,700,1,14.25,100,1,12.49,100,1,14.28,100,1,12.46,100,1,14.47,100,1,12.43,700,1,14.48,700,1,ARL,336572057
2214,2025-07-17T16:11:00.367319059Z,2025-07-17T16:11:00.367319059Z,10,2,1108,C,B,0,12.49,100,0,166035,280189441,13.11,100,1,13.58,15,1,13.01,2,1,13.59,100,1,12.98,200,2,13.6,15,1,12.86,100,1,13.62,1,1,12.73,100,1,13.82,2,1,12.71,100,1,13.86,100,1,12.5,700,1,14.25,100,1,12.46,100,1,14.28,100,1,12.43,700,1,14.47,100,1,12.42,700,1,14.48,700,1,ARL,331942901
2215,2025-07-17T16:11:00.367319059Z,2025-07-17T16:11:00.367319059Z,10,2,1108,A,B,11,12.36,100,130,166035,280189441,13.11,100,1,13.58,15,1,13.01,2,1,13.59,100,1,12.98,200,2,13.6,15,1,12.86,100,1,13.62,1,1,12.73,100,1,13.82,2,1,12.71,100,1,13.86,100,1,12.5,700,1,14.25,100,1,12.46,100,1,14.28,100,1,12.43,700,1,14.47,100,1,12.42,700,1,14.48,700,1,ARL,336572069
2216,2025-07-17T16:11:00.466703632Z,2025-07-17T16:11:00.466703632Z,10,2,1108,C,A,0,13.62,1,130,164992,280191783,13.11,100,1,13.58,15,1,13.01,2,1,13.59,100,1,12.98,200,2,13.6,15,1,12.86,100,1,13.82,2,1,12.73,100,1,13.86,100,1,12.71,100,1,14.25,100,1,12.5,700,1,14.28,100,1,12.46,100,1,14.47,100,1,12.43,700,1,14.48,700,1,12.42,700,1,14.51,200,2,ARL,336572049
2217,2025-07-17T16:11:06.626666474Z,2025-07-17T16:11:06.626666474Z,10,2,1108,A,A,6,14.27,700,130,165325,280342316,13.11,100,1,13.58,15,1,13.01,2,1,13.59,100,1,12.98,200,2,13.6,15,1,12.86,100,1,13.82,2,1,12.73,100,1,13.86,100,1,12.71,100,1,14.25,100,1,12.5,700,1,14.27,700,1,12.46,100,1,14.28,100,1,12.43,700,1,14.47,100,1,12.42,700,1,14.48,700,1,ARL,336747457
2218,2025-07-17T16:11:06.626741446Z,2025-07-17T16:11:06.626741446Z,10,2,1108,C,A,0,14.68,700,130,165254,280342318,13.11,100,1,13.58,15,1,13.01,2,1,13.59,100,1,12.98,200,2,13.6,15,1,12.86,100,1,13.82,2,1,12.73,100,1,13.86,100,1,12.71,100,1,14.25,100,1,12.5,700,1,14.27,700,1,12.46,100,1,14.28,100,1,12.43,700,1,14.47,100,1,12.42,700,1,14.48,700,1,ARL,331929977
2219,2025-07-17T16:11:08.307868957Z,2025-07-17T16:11:08.307868957Z,10,2,1108,C,A,0,13.6,15,130,165581,280374785,13.11,100,1,13.58,15,1,13.01,2,1,13.59,100,1,12.98,200,2,13.82,2,1,12.86,100,1,13.86,100,1,12.73,100,1,14.25,100,1,12.71,100,1,14.27,700,1,12.5,700,1,14.28,100,1,12.46,100,1,14.47,100,1,12.43,700,1,14.48,700,1,12.42,700,1,14.51,200,2,ARL,336402845
2220,2025-07-17T16:11:09.568370995Z,2025-07-17T16:11:09.568370995Z,10,2,1108,A,A,0,13.56,15,130,165297,280401189,13.11,100,1,13.56,15,1,13.01,2,1,13.58,15,1,12.98,200,2,13.59,100,1,12.86,100,1,13.82,2,1,12.73,100,1,13.86,100,1,12.71,100,1,14.25,100,1,12.5,700,1,14.27,700,1,12.46,100,1,14.28,100,1,12.43,700,1,14.47,100,1,12.42,700,1,14.48,700,1,ARL,336816813
2221,2025-07-17T16:11:10.341788521Z,2025-07-17T16:11:10.341788521Z,10,2,1108,C,A,0,13.59,100,0,165450,280411396,13.11,100,1,13.56,15,1,13.01,2,1,13.58,15,1,12.98,200,2,13.82,2,1,12.86,100,1,13.86,100,1,12.73,100,1,14.25,100,1,12.71,100,1,14.27,700,1,12.5,700,1,14.28,100,1,12.46,100,1,14.47,100,1,12.43,700,1,14.48,700,1,12.42,700,1,14.51,200,2,ARL,336567189
2222,2025-07-17T16:11:10.341788521Z,2025-07-17T16:11:10.341788521Z,10,2,1108,A,A,1,13.57,100,130,165450,280411396,13.11,100,1,13.56,15,1,13.01,2,1,13.57,100,1,12.98,200,2,13.58,15,1,12.86,100,1,13.82,2,1,12.73,100,1,13.86,100,1,12.71,100,1,14.25,100,1,12.5,700,1,14.27,700,1,12.46,100,1,14.28,100,1,12.43,700,1,14.47,100,1,12.42,700,1,14.48,700,1,ARL,336828765
2223,2025-07-17T16:11:14.610535763Z,2025-07-17T16:11:14.610535763Z,10,2,1108,C,A,0,13.58,15,130,165687,280482371,13.11,100,1,13.56,15,1,13.01,2,1,13.57,100,1,12.98,200,2,13.82,2,1,12.86,100,1,13.86,100,1,12.73,100,1,14.25,100,1,12.71,100,1,14.27,700,1,12.5,700,1,14.28,100,1,12.46,100,1,14.47,100,1,12.43,700,1,14.48,700,1,12.42,700,1,14.51,200,2,ARL,336555153
2224,2025-07-17T16:11:16.025292936Z,2025-07-17T16:11:16.025292936Z,10,2,1108,C,A,0,13.56,15,130,165295,280514282,13.11,100,1,13.57,100,1,13.01,2,1,13.82,2,1,12.98,200,2,13.86,100,1,12.86,100,1,14.25,100,1,12.73,100,1,14.27,700,1,12.71,100,1,14.28,100,1,12.5,700,1,14.47,100,1,12.46,100,1,14.48,700,1,12.43,700,1,14.51,200,2,12.42,700,1,14.56,800,2,ARL,336816813
2225,2025-07-17T16:11:50.026672014Z,2025-07-17T16:11:50.026672014Z,10,2,1108,A,A,0,13.55,15,130,165344,281078802,13.11,100,1,13.55,15,1,13.01,2,1,13.57,100,1,12.98,200,2,13.82,2,1,12.86,100,1,13.86,100,1,12.73,100,1,14.25,100,1,12.71,100,1,14.27,700,1,12.5,700,1,14.28,100,1,12.46,100,1,14.47,100,1,12.43,700,1,14.48,700,1,12.42,700,1,14.51,200,2,ARL,337690189
2226,2025-07-17T16:11:50.026839463Z,2025-07-17T16:11:50.026839463Z,10,2,1108,C,A,0,13.57,100,0,165514,281078803,13.11,100,1,13.55,15,1,13.01,2,1,13.82,2,1,12.98,200,2,13.86,100,1,12.86,100,1,14.25,100,1,12.73,100,1,14.27,700,1,12.71,100,1,14.28,100,1,12.5,700,1,14.47,100,1,12.46,100,1,14.48,700,1,12.43,700,1,14.51,200,2,12.42,700,1,14.56,800,2,ARL,336828765
2227,2025-07-17T16:11:50.026839463Z,2025-07-17T16:11:50.026839463Z,10,2,1108,A,A,1,13.56,100,130,165514,281078803,13.11,100,1,13.55,15,1,13.01,2,1,13.56,100,1,12.98,200,2,13.82,2,1,12.86,100,1,13.86,100,1,12.73,100,1,14.25,100,1,12.71,100,1,14.27,700,1,12.5,700,1,14.28,100,1,12.46,100,1,14.47,100,1,12.43,700,1,14.48,700,1,12.42,700,1,14.51,200,2,ARL,337690193
2228,2025-07-17T16:11:50.032845393Z,2025-07-17T16:11:50.032845393Z,10,2,1108,C,A,0,15.74,100,0,165405,281078903,13.11,100,1,13.55,15,1,13.01,2,1,13.56,100,1,12.98,200,2,13.82,2,1,12.86,100,1,13.86,100,1,12.73,100,1,14.25,100,1,12.71,100,1,14.27,700,1,12.5,700,1,14.28,100,1,12.46,100,1,14.47,100,1,12.43,700,1,14.48,700,1,12.42,700,1,14.51,200,2,ARL,335220497
2229,2025-07-17T16:11:50.032845393Z,2025-07-17T16:11:50.032845393Z,10,2,1108,A,A,16,15.6,100,130,165405,281078903,13.11,100,1,13.55,15,1,13.01,2,1,13.56,100,1,12.98,200,2,13.82,2,1,12.86,100,1,13.86,100,1,12.73,100,1,14.25,100,1,12.71,100,1,14.27,700,1,12.5,700,1,14.28,100,1,12.46,100,1,14.47,100,1,12.43,700,1,14.48,700,1,12.42,700,1,14.51,200,2,ARL,337690641
2230,2025-07-17T16:11:53.859743991Z,2025-07-17T16:11:53.859743991Z,10,2,1108,A,A,0,13.53,15,130,165471,281142794,13.11,100,1,13.53,15,1,13.01,2,1,13.55,15,1,12.98,200,2,13.56,100,1,12.86,100,1,13.82,2,1,12.73,100,1,13.86,100,1,12.71,100,1,14.25,100,1,12.5,700,1,14.27,700,1,12.46,100,1,14.28,100,1,12.43,700,1,14.47,100,1,12.42,700,1,14.48,700,1,ARL,337772837
2231,2025-07-17T16:11:54.662361841Z,2025-07-17T16:11:54.662361841Z,10,2,1108,C,A,0,13.56,100,0,165491,281156215,13.11,100,1,13.53,15,1,13.01,2,1,13.55,15,1,12.98,200,2,13.82,2,1,12.86,100,1,13.86,100,1,12.73,100,1,14.25,100,1,12.71,100,1,14.27,700,1,12.5,700,1,14.28,100,1,12.46,100,1,14.47,100,1,12.43,700,1,14.48,700,1,12.42,700,1,14.51,200,2,ARL,337690193
2232,2025-07-17T16:11:54.662361841Z,2025-07-17T16:11:54.662361841Z,10,2,1108,A,A,1,13.54,100,130,165491,281156215,13.11,100,1,13.53,15,1,13.01,2,1,13.54,100,1,12.98,200,2,13.55,15,1,12.86,100,1,13.82,2,1,12.73,100,1,13.86,100,1,12.71,100,1,14.25,100,1,12.5,700,1,14.27,700,1,12.46,100,1,14.28,100,1,12.43,700,1,14.47,100,1,12.42,700,1,14.48,700,1,ARL,337790717
2233,2025-07-17T16:11:54.663112543Z,2025-07-17T16:11:54.663112543Z,10,2,1108,C,A,13,14.64,100,0,165657,281156222,13.11,100,1,13.53,15,1,13.01,2,1,13.54,100,1,12.98,200,2,13.55,15,1,12.86,100,1,13.82,2,1,12.73,100,1,13.86,100,1,12.71,100,1,14.25,100,1,12.5,700,1,14.27,700,1,12.46,100,1,14.28,100,1,12.43,700,1,14.47,100,1,12.42,700,1,14.48,700,1,ARL,336567213
2234,2025-07-17T16:11:54.663112543Z,2025-07-17T16:11:54.663112543Z,10,2,1108,A,A,12,14.59,100,130,165657,281156222,13.11,100,1,13.53,15,1,13.01,2,1,13.54,100,1,12.98,200,2,13.55,15,1,12.86,100,1,13.82,2,1,12.73,100,1,13.86,100,1,12.71,100,1,14.25,100,1,12.5,700,1,14.27,700,1,12.46,100,1,14.28,100,1,12.43,700,1,14.47,100,1,12.42,700,1,14.48,700,1,ARL,337790737
2235,2025-07-17T16:11:54.663968656Z,2025-07-17T16:11:54.663968656Z,10,2,1108,C,A,14,14.64,100,0,165370,281156223,13.11,100,1,13.53,15,1,13.01,2,1,13.54,100,1,12.98,200,2,13.55,15,1,12.86,100,1,13.82,2,1,12.73,100,1,13.86,100,1,12.71,100,1,14.25,100,1,12.5,700,1,14.27,700,1,12.46,100,1,14.28,100,1,12.43,700,1,14.47,100,1,12.42,700,1,14.48,700,1,ARL,335220525
2236,2025-07-17T16:11:54.663968656Z,2025-07-17T16:11:54.663968656Z,10,2,1108,A,A,10,14.49,100,130,165370,281156223,13.11,100,1,13.53,15,1,13.01,2,1,13.54,100,1,12.98,200,2,13.55,15,1,12.86,100,1,13.82,2,1,12.73,100,1,13.86,100,1,12.71,100,1,14.25,100,1,12.5,700,1,14.27,700,1,12.46,100,1,14.28,100,1,12.43,700,1,14.47,100,1,12.42,700,1,14.48,700,1,ARL,337790745
2237,2025-07-17T16:11:54.666160990Z,2025-07-17T16:11:54.666160990Z,10,2,1108,C,A,0,14.47,100,0,165610,281156243,13.11,100,1,13.53,15,1,13.01,2,1,13.54,100,1,12.98,200,2,13.55,15,1,12.86,100,1,13.82,2,1,12.73,100,1,13.86,100,1,12.71,100,1,14.25,100,1,12.5,700,1,14.27,700,1,12.46,100,1,14.28,100,1,12.43,700,1,14.48,700,1,12.42,700,1,14.49,100,1,ARL,335220561
2238,2025-07-17T16:11:54.666160990Z,2025-07-17T16:11:54.666160990Z,10,2,1108,A,A,8,14.33,100,130,165610,281156243,13.11,100,1,13.53,15,1,13.01,2,1,13.54,100,1,12.98,200,2,13.55,15,1,12.86,100,1,13.82,2,1,12.73,100,1,13.86,100,1,12.71,100,1,14.25,100,1,12.5,700,1,14.27,700,1,12.46,100,1,14.28,100,1,12.43,700,1,14.33,100,1,12.42,700,1,14.48,700,1,ARL,337790761
2239,2025-07-17T16:11:54.667339002Z,2025-07-17T16:11:54.667339002Z,10,2,1108,C,A,0,14.64,100,0,165544,281156250,13.11,100,1,13.53,15,1,13.01,2,1,13.54,100,1,12.98,200,2,13.55,15,1,12.86,100,1,13.82,2,1,12.73,100,1,13.86,100,1,12.71,100,1,14.25,100,1,12.5,700,1,14.27,700,1,12.46,100,1,14.28,100,1,12.43,700,1,14.33,100,1,12.42,700,1,14.48,700,1,ARL,335220629
2240,2025-07-17T16:11:54.667339002Z,2025-07-17T16:11:54.667339002Z,10,2,1108,A,A,10,14.49,100,130,165544,281156250,13.11,100,1,13.53,15,1,13.01,2,1,13.54,100,1,12.98,200,2,13.55,15,1,12.86,100,1,13.82,2,1,12.73,100,1,13.86,100,1,12.71,100,1,14.25,100,1,12.5,700,1,14.27,700,1,12.46,100,1,14.28,100,1,12.43,700,1,14.33,100,1,12.42,700,1,14.48,700,1,ARL,337790777
2241,2025-07-17T16:11:59.382350338Z,2025-07-17T16:11:59.382350338Z,10,2,1108,C,A,0,13.55,15,130,165340,281270010,13.11,100,1,13.53,15,1,13.01,2,1,13.54,100,1,12.98,200,2,13.82,2,1,12.86,100,1,13.86,100,1,12.73,100,1,14.25,100,1,12.71,100,1,14.27,700,1,12.5,700,1,14.28,100,1,12.46,100,1,14.33,100,1,12.43,700,1,14.48,700,1,12.42,700,1,14.49,200,2,ARL,337690189
2242,2025-07-17T16:12:02.981913204Z,2025-07-17T16:12:02.981913204Z,10,2,1108,A,A,0,13.51,15,130,165515,281348152,13.11,100,1,13.51,15,1,13.01,2,1,13.53,15,1,12.98,200,2,13.54,100,1,12.86,100,1,13.82,2,1,12.73,100,1,13.86,100,1,12.71,100,1,14.25,100,1,12.5,700,1,14.27,700,1,12.46,100,1,14.28,100,1,12.43,700,1,14.33,100,1,12.42,700,1,14.48,700,1,ARL,338041605
2243,2025-07-17T16:12:03.063997054Z,2025-07-17T16:12:03.063997054Z,10,2,1108,C,A,0,13.54,100,0,165551,281351122,13.11,100,1,13.51,15,1,13.01,2,1,13.53,15,1,12.98,200,2,13.82,2,1,12.86,100,1,13.86,100,1,12.73,100,1,14.25,100,1,12.71,100,1,14.27,700,1,12.5,700,1,14.28,100,1,12.46,100,1,14.33,100,1,12.43,700,1,14.48,700,1,12.42,700,1,14.49,200,2,ARL,337790717
2244,2025-07-17T16:12:03.063997054Z,2025-07-17T16:12:03.063997054Z,10,2,1108,A,A,1,13.52,100,130,165551,281351122,13.11,100,1,13.51,15,1,13.01,2,1,13.52,100,1,12.98,200,2,13.53,15,1,12.86,100,1,13.82,2,1,12.73,100,1,13.86,100,1,12.71,100,1,14.25,100,1,12.5,700,1,14.27,700,1,12.46,100,1,14.28,100,1,12.43,700,1,14.33,100,1,12.42,700,1,14.48,700,1,ARL,338044041
2245,2025-07-17T16:12:03.068301745Z,2025-07-17T16:12:03.068301745Z,10,2,1108,C,B,0,13.01,2,0,165401,281351235,13.11,100,1,13.51,15,1,12.98,200,2,13.52,100,1,12.86,100,1,13.53,15,1,12.73,100,1,13.82,2,1,12.71,100,1,13.86,100,1,12.5,700,1,14.25,100,1,12.46,100,1,14.27,700,1,12.43,700,1,14.28,100,1,12.42,700,1,14.33,100,1,12.37,700,1,14.48,700,1,ARL,332494213
2246,2025-07-17T16:12:03.068301745Z,2025-07-17T16:12:03.068301745Z,10,2,1108,A,B,2,12.92,2,130,165401,281351235,13.11,100,1,13.51,15,1,12.98,200,2,13.52,100,1,12.92,2,1,13.53,15,1,12.86,100,1,13.82,2,1,12.73,100,1,13.86,100,1,12.71,100,1,14.25,100,1,12.5,700,1,14.27,700,1,12.46,100,1,14.28,100,1,12.43,700,1,14.33,100,1,12.42,700,1,14.48,700,1,ARL,338044113
2247,2025-07-17T16:12:03.075034550Z,2025-07-17T16:12:03.075034550Z,10,2,1108,C,A,0,13.86,100,130,165488,281351372,13.11,100,1,13.51,15,1,12.98,200,2,13.52,100,1,12.92,2,1,13.53,15,1,12.86,100,1,13.82,2,1,12.73,100,1,14.25,100,1,12.71,100,1,14.27,700,1,12.5,700,1,14.28,100,1,12.46,100,1,14.33,100,1,12.43,700,1,14.48,700,1,12.42,700,1,14.49,200,2,ARL,336567333
2248,2025-07-17T16:12:03.075095341Z,2025-07-17T16:12:03.075095341Z,10,2,1108,A,A,3,13.79,100,130,165188,281351373,13.11,100,1,13.51,15,1,12.98,200,2,13.52,100,1,12.92,2,1,13.53,15,1,12.86,100,1,13.79,100,1,12.73,100,1,13.82,2,1,12.71,100,1,14.25,100,1,12.5,700,1,14.27,700,1,12.46,100,1,14.28,100,1,12.43,700,1,14.33,100,1,12.42,700,1,14.48,700,1,ARL,338044233
2249,2025-07-17T16:12:06.775011783Z,2025-07-17T16:12:06.775011783Z,10,2,1108,C,A,11,14.51,100,0,165854,281422697,13.11,100,1,13.51,15,1,12.98,200,2,13.52,100,1,12.92,2,1,13.53,15,1,12.86,100,1,13.79,100,1,12.73,100,1,13.82,2,1,12.71,100,1,14.25,100,1,12.5,700,1,14.27,700,1,12.46,100,1,14.28,100,1,12.43,700,1,14.33,100,1,12.42,700,1,14.48,700,1,ARL,336259225
2250,2025-07-17T16:12:06.775011783Z,2025-07-17T16:12:06.775011783Z,10,2,1108,A,A,9,14.4,100,130,165854,281422697,13.11,100,1,13.51,15,1,12.98,200,2,13.52,100,1,12.92,2,1,13.53,15,1,12.86,100,1,13.79,100,1,12.73,100,1,13.82,2,1,12.71,100,1,14.25,100,1,12.5,700,1,14.27,700,1,12.46,100,1,14.28,100,1,12.43,700,1,14.33,100,1,12.42,700,1,14.4,100,1,ARL,338139585
2251,2025-07-17T16:12:06.775449017Z,2025-07-17T16:12:06.775449017Z,10,2,1108,C,A,0,14.51,100,0,165519,281422702,13.11,100,1,13.51,15,1,12.98,200,2,13.52,100,1,12.92,2,1,13.53,15,1,12.86,100,1,13.79,100,1,12.73,100,1,13.82,2,1,12.71,100,1,14.25,100,1,12.5,700,1,14.27,700,1,12.46,100,1,14.28,100,1,12.43,700,1,14.33,100,1,12.42,700,1,14.4,100,1,ARL,336261905
2252,2025-07-17T16:12:06.775449017Z,2025-07-17T16:12:06.775449017Z,10,2,1108,A,A,9,14.4,100,130,165519,281422702,13.11,100,1,13.51,15,1,12.98,200,2,13.52,100,1,12.92,2,1,13.53,15,1,12.86,100,1,13.79,100,1,12.73,100,1,13.82,2,1,12.71,100,1,14.25,100,1,12.5,700,1,14.27,700,1,12.46,100,1,14.28,100,1,12.43,700,1,14.33,100,1,12.42,700,1,14.4,200,2,ARL,338139601
2253,2025-07-17T16:12:06.779540143Z,2025-07-17T16:12:06.779540143Z,10,2,1108,C,A,0,13.53,15,130,165574,281422782,13.11,100,1,13.51,15,1,12.98,200,2,13.52,100,1,12.92,2,1,13.79,100,1,12.86,100,1,13.82,2,1,12.73,100,1,14.25,100,1,12.71,100,1,14.27,700,1,12.5,700,1,14.28,100,1,12.46,100,1,14.33,100,1,12.43,700,1,14.4,200,2,12.42,700,1,14.48,700,1,ARL,337772837
2254,2025-07-17T16:12:07.784533539Z,2025-07-17T16:12:07.784533539Z,10,2,1108,A,A,0,13.49,15,130,165354,281443568,13.11,100,1,13.49,15,1,12.98,200,2,13.51,15,1,12.92,2,1,13.52,100,1,12.86,100,1,13.79,100,1,12.73,100,1,13.82,2,1,12.71,100,1,14.25,100,1,12.5,700,1,14.27,700,1,12.46,100,1,14.28,100,1,12.43,700,1,14.33,100,1,12.42,700,1,14.4,200,2,ARL,338167057
